Workbook

Sheet Motivos De Parada
A1: ANO | B1: MÊS | C1: OPERADOR | D1: TURNO | E1: DATA APONTAMENTO | F1: EQUIPAMENTO DIGITADO | G1: EQUIPAMENTO | H1: TIPO DE EQUIPAMENTO | I1: HORA INICIO PARADA | J1: HORA FINAL PARADA | K1: TEMPO DE PARADA | L1: CÓDIGO MOTIVO PARADA | M1: DETALHAMENTO | N1: DESCRIÇÃO | O1: TIPO INDISPONIBILIDADE | P1: DESCONSIDERADO ? | Q1: STATUS | R1: QUANTIDADE DE PARADAS POR TURNO | S1: CONSIDERAR?
A2: =IFERROR(YEAR(E2),"-") -> 2026 | B2: =IFERROR(DATE(YEAR(E2),MONTH(E2),MONTH(E2)),"-") -> 46023 | C2: OPERADOR 1 | D2: =IF(AND(I2>=TIME(6,0,0),I2<TIME(18,0,0),OR(J2<=TIME(18,0,0),J2<TIME(6,0,0))),"TURNO 1","TURNO 2") -> TURNO 1 | E2: 46023 | F2: FELLER1 | G2: =IFERROR(VLOOKUP(F2,Cadastros!A:B,2,FALSE),"-") -> FELLER BUNCHER 1 | H2: =IFERROR(VLOOKUP(G2,Cadastros!B:D,3,FALSE),"-") -> CORTE | I2: 0.25 | J2: 0.25 | K2: =IFERROR(IF(J2="-","-",((J2-I2)-INT(J2-I2))*24),"0") -> 0 | L2: 13 | M2: =IFERROR(VLOOKUP($L2,Justificativas!$A:$E,2,FALSE),"-") -> DETALHE 13 | N2: =IFERROR(VLOOKUP($L2,Justificativas!$A:$E,3,FALSE),"-") -> DESCRIÇÃO 12 | O2: =IFERROR(VLOOKUP($L2,Justificativas!$A:$E,4,FALSE),"-") -> DISPONIBILIDADE MECÂNICA | P2: =IFERROR(VLOOKUP($L2,Justificativas!$A:$E,5,FALSE),"-") -> NÃO | Q2: =IF(K2=0,"NÃO PUXA NO BI","PUXA") -> NÃO PUXA NO BI | R2: =COUNTIFS($B$1:B1,B2,$E$1:E1,E2,$G$1:G1,G2,$D$1:D1,D2) -> 0 | S2: =IF(OR(L2="100-1",L2="100-2",L2="100-3"),"NÃO","SIM") -> SIM
A3: =IFERROR(YEAR(E3),"-") -> 2026 | B3: =IFERROR(DATE(YEAR(E3),MONTH(E3),MONTH(E3)),"-") -> 46023 | C3: OPERADOR 1 | D3: =IF(AND(I3>=TIME(6,0,0),I3<TIME(18,0,0),OR(J3<=TIME(18,0,0),J3<TIME(6,0,0))),"TURNO 1","TURNO 2") -> TURNO 1 | E3: 46023 | F3: FELLER1 | G3: =IFERROR(VLOOKUP(F3,Cadastros!A:B,2,FALSE),"-") -> FELLER BUNCHER 1 | H3: =IFERROR(VLOOKUP(G3,Cadastros!B:D,3,FALSE),"-") -> CORTE | I3: =J2 -> 0.25 | J3: 0.33333333 | K3: =IFERROR(IF(J3="-","-",((J3-I3)-INT(J3-I3))*24),"0") -> 2 | L3: 3 | M3: =IFERROR(VLOOKUP($L3,Justificativas!$A:$E,2,FALSE),"-") -> DETALHE 3 | N3: =IFERROR(VLOOKUP($L3,Justificativas!$A:$E,3,FALSE),"-") -> DESCRIÇÃO 2 | O3: =IFERROR(VLOOKUP($L3,Justificativas!$A:$E,4,FALSE),"-") -> NÃO É INDISPONIBILIDADE | P3: =IFERROR(VLOOKUP($L3,Justificativas!$A:$E,5,FALSE),"-") -> SIM | Q3: =IF(K3=0,"NÃO PUXA NO BI","PUXA") -> PUXA | R3: =COUNTIFS($B$1:B2,B3,$E$1:E2,E3,$G$1:G2,G3,$D$1:D2,D3) -> 1 | S3: =IF(OR(L3="100-1",L3="100-2",L3="100-3"),"NÃO","SIM") -> SIM
A4: =IFERROR(YEAR(E4),"-") -> 2026 | B4: =IFERROR(DATE(YEAR(E4),MONTH(E4),MONTH(E4)),"-") -> 46023 | C4: OPERADOR 1 | D4: =IF(AND(I4>=TIME(6,0,0),I4<TIME(18,0,0),OR(J4<=TIME(18,0,0),J4<TIME(6,0,0))),"TURNO 1","TURNO 2") -> TURNO 1 | E4: 46023 | F4: FELLER1 | G4: =IFERROR(VLOOKUP(F4,Cadastros!A:B,2,FALSE),"-") -> FELLER BUNCHER 1 | H4: =IFERROR(VLOOKUP(G4,Cadastros!B:D,3,FALSE),"-") -> CORTE | I4: =J3 -> 0.33333333 | J4: 0.45833333 | K4: =IFERROR(IF(J4="-","-",((J4-I4)-INT(J4-I4))*24),"0") -> 3 | L4: 8 | M4: =IFERROR(VLOOKUP($L4,Justificativas!$A:$E,2,FALSE),"-") -> DETALHE 8 | N4: =IFERROR(VLOOKUP($L4,Justificativas!$A:$E,3,FALSE),"-") -> DESCRIÇÃO 7 | O4: =IFERROR(VLOOKUP($L4,Justificativas!$A:$E,4,FALSE),"-") -> DISPONIBILIDADE OPERACIONAL | P4: =IFERROR(VLOOKUP($L4,Justificativas!$A:$E,5,FALSE),"-") -> NÃO | Q4: =IF(K4=0,"NÃO PUXA NO BI","PUXA") -> PUXA | R4: =COUNTIFS($B$1:B3,B4,$E$1:E3,E4,$G$1:G3,G4,$D$1:D3,D4) -> 2 | S4: =IF(OR(L4="100-1",L4="100-2",L4="100-3"),"NÃO","SIM") -> SIM
A5: =IFERROR(YEAR(E5),"-") -> 2026 | B5: =IFERROR(DATE(YEAR(E5),MONTH(E5),MONTH(E5)),"-") -> 46023 | C5: OPERADOR 1 | D5: =IF(AND(I5>=TIME(6,0,0),I5<TIME(18,0,0),OR(J5<=TIME(18,0,0),J5<TIME(6,0,0))),"TURNO 1","TURNO 2") -> TURNO 1 | E5: 46023 | F5: FELLER1 | G5: =IFERROR(VLOOKUP(F5,Cadastros!A:B,2,FALSE),"-") -> FELLER BUNCHER 1 | H5: =IFERROR(VLOOKUP(G5,Cadastros!B:D,3,FALSE),"-") -> CORTE | I5: =J4 -> 0.45833333 | J5: 0.625 | K5: =IFERROR(IF(J5="-","-",((J5-I5)-INT(J5-I5))*24),"0") -> 4 | L5: 17 | M5: =IFERROR(VLOOKUP($L5,Justificativas!$A:$E,2,FALSE),"-") -> DETALHE 17 | N5: =IFERROR(VLOOKUP($L5,Justificativas!$A:$E,3,FALSE),"-") -> DESCRIÇÃO 16 | O5: =IFERROR(VLOOKUP($L5,Justificativas!$A:$E,4,FALSE),"-") -> DISPONIBILIDADE MECÂNICA | P5: =IFERROR(VLOOKUP($L5,Justificativas!$A:$E,5,FALSE),"-") -> NÃO | Q5: =IF(K5=0,"NÃO PUXA NO BI","PUXA") -> PUXA | R5: =COUNTIFS($B$1:B4,B5,$E$1:E4,E5,$G$1:G4,G5,$D$1:D4,D5) -> 3 | S5: =IF(OR(L5="100-1",L5="100-2",L5="100-3"),"NÃO","SIM") -> SIM
A6: =IFERROR(YEAR(E6),"-") -> 2026 | B6: =IFERROR(DATE(YEAR(E6),MONTH(E6),MONTH(E6)),"-") -> 46023 | C6: OPERADOR 1 | D6: =IF(AND(I6>=TIME(6,0,0),I6<TIME(18,0,0),OR(J6<=TIME(18,0,0),J6<TIME(6,0,0))),"TURNO 1","TURNO 2") -> TURNO 1 | E6: 46023 | F6: FELLER1 | G6: =IFERROR(VLOOKUP(F6,Cadastros!A:B,2,FALSE),"-") -> FELLER BUNCHER 1 | H6: =IFERROR(VLOOKUP(G6,Cadastros!B:D,3,FALSE),"-") -> CORTE | I6: =J5 -> 0.625 | J6: 0.75 | K6: =IFERROR(IF(J6="-","-",((J6-I6)-INT(J6-I6))*24),"0") -> 3 | L6: 11 | M6: =IFERROR(VLOOKUP($L6,Justificativas!$A:$E,2,FALSE),"-") -> DETALHE 11 | N6: =IFERROR(VLOOKUP($L6,Justificativas!$A:$E,3,FALSE),"-") -> DESCRIÇÃO 10 | O6: =IFERROR(VLOOKUP($L6,Justificativas!$A:$E,4,FALSE),"-") -> DISPONIBILIDADE OPERACIONAL | P6: =IFERROR(VLOOKUP($L6,Justificativas!$A:$E,5,FALSE),"-") -> NÃO | Q6: =IF(K6=0,"NÃO PUXA NO BI","PUXA") -> PUXA | R6: =COUNTIFS($B$1:B5,B6,$E$1:E5,E6,$G$1:G5,G6,$D$1:D5,D6) -> 4 | S6: =IF(OR(L6="100-1",L6="100-2",L6="100-3"),"NÃO","SIM") -> SIM
A7: =IFERROR(YEAR(E7),"-") -> 2026 | B7: =IFERROR(DATE(YEAR(E7),MONTH(E7),MONTH(E7)),"-") -> 46023 | C7: OPERADOR 2 | D7: =IF(AND(I7>=TIME(6,0,0),I7<TIME(18,0,0),OR(J7<=TIME(18,0,0),J7<TIME(6,0,0))),"TURNO 1","TURNO 2") -> TURNO 2 | E7: 46023 | F7: FELLER1 | G7: =IFERROR(VLOOKUP(F7,Cadastros!A:B,2,FALSE),"-") -> FELLER BUNCHER 1 | H7: =IFERROR(VLOOKUP(G7,Cadastros!B:D,3,FALSE),"-") -> CORTE | I7: =J6 -> 0.75 | J7: 0.83333333 | K7: =IFERROR(IF(J7="-","-",((J7-I7)-INT(J7-I7))*24),"0") -> 2 | L7: 19 | M7: =IFERROR(VLOOKUP($L7,Justificativas!$A:$E,2,FALSE),"-") -> DETALHE 19 | N7: =IFERROR(VLOOKUP($L7,Justificativas!$A:$E,3,FALSE),"-") -> DESCRIÇÃO 18 | O7: =IFERROR(VLOOKUP($L7,Justificativas!$A:$E,4,FALSE),"-") -> DISPONIBILIDADE MECÂNICA | P7: =IFERROR(VLOOKUP($L7,Justificativas!$A:$E,5,FALSE),"-") -> NÃO | Q7: =IF(K7=0,"NÃO PUXA NO BI","PUXA") -> PUXA | R7: =COUNTIFS($B$1:B6,B7,$E$1:E6,E7,$G$1:G6,G7,$D$1:D6,D7) -> 0 | S7: =IF(OR(L7="100-1",L7="100-2",L7="100-3"),"NÃO","SIM") -> SIM
A8: =IFERROR(YEAR(E8),"-") -> 2026 | B8: =IFERROR(DATE(YEAR(E8),MONTH(E8),MONTH(E8)),"-") -> 46023 | C8: OPERADOR 2 | D8: =IF(AND(I8>=TIME(6,0,0),I8<TIME(18,0,0),OR(J8<=TIME(18,0,0),J8<TIME(6,0,0))),"TURNO 1","TURNO 2") -> TURNO 2 | E8: 46023 | F8: FELLER1 | G8: =IFERROR(VLOOKUP(F8,Cadastros!A:B,2,FALSE),"-") -> FELLER BUNCHER 1 | H8: =IFERROR(VLOOKUP(G8,Cadastros!B:D,3,FALSE),"-") -> CORTE | I8: =J7 -> 0.83333333 | J8: 0.041666667 | K8: =IFERROR(IF(J8="-","-",((J8-I8)-INT(J8-I8))*24),"0") -> 5 | L8: 6 | M8: =IFERROR(VLOOKUP($L8,Justificativas!$A:$E,2,FALSE),"-") -> DETALHE 6 | N8: =IFERROR(VLOOKUP($L8,Justificativas!$A:$E,3,FALSE),"-") -> DESCRIÇÃO 5 | O8: =IFERROR(VLOOKUP($L8,Justificativas!$A:$E,4,FALSE),"-") -> DISPONIBILIDADE OPERACIONAL | P8: =IFERROR(VLOOKUP($L8,Justificativas!$A:$E,5,FALSE),"-") -> NÃO | Q8: =IF(K8=0,"NÃO PUXA NO BI","PUXA") -> PUXA | R8: =COUNTIFS($B$1:B7,B8,$E$1:E7,E8,$G$1:G7,G8,$D$1:D7,D8) -> 1 | S8: =IF(OR(L8="100-1",L8="100-2",L8="100-3"),"NÃO","SIM") -> SIM
A9: =IFERROR(YEAR(E9),"-") -> 2026 | B9: =IFERROR(DATE(YEAR(E9),MONTH(E9),MONTH(E9)),"-") -> 46023 | C9: OPERADOR 2 | D9: =IF(AND(I9>=TIME(6,0,0),I9<TIME(18,0,0),OR(J9<=TIME(18,0,0),J9<TIME(6,0,0))),"TURNO 1","TURNO 2") -> TURNO 2 | E9: 46023 | F9: FELLER1 | G9: =IFERROR(VLOOKUP(F9,Cadastros!A:B,2,FALSE),"-") -> FELLER BUNCHER 1 | H9: =IFERROR(VLOOKUP(G9,Cadastros!B:D,3,FALSE),"-") -> CORTE | I9: =J8 -> 0.041666667 | J9: 0.25 | K9: =IFERROR(IF(J9="-","-",((J9-I9)-INT(J9-I9))*24),"0") -> 5 | L9: 14 | M9: =IFERROR(VLOOKUP($L9,Justificativas!$A:$E,2,FALSE),"-") -> DETALHE 14 | N9: =IFERROR(VLOOKUP($L9,Justificativas!$A:$E,3,FALSE),"-") -> DESCRIÇÃO 13 | O9: =IFERROR(VLOOKUP($L9,Justificativas!$A:$E,4,FALSE),"-") -> DISPONIBILIDADE MECÂNICA | P9: =IFERROR(VLOOKUP($L9,Justificativas!$A:$E,5,FALSE),"-") -> NÃO | Q9: =IF(K9=0,"NÃO PUXA NO BI","PUXA") -> PUXA | R9: =COUNTIFS($B$1:B8,B9,$E$1:E8,E9,$G$1:G8,G9,$D$1:D8,D9) -> 2 | S9: =IF(OR(L9="100-1",L9="100-2",L9="100-3"),"NÃO","SIM") -> SIM
A10: =IFERROR(YEAR(E10),"-") -> 2026 | B10: =IFERROR(DATE(YEAR(E10),MONTH(E10),MONTH(E10)),"-") -> 46023 | C10: OPERADOR 3 | D10: =IF(AND(I10>=TIME(6,0,0),I10<TIME(18,0,0),OR(J10<=TIME(18,0,0),J10<TIME(6,0,0))),"TURNO 1","TURNO 2") -> TURNO 1 | E10: 46024 | F10: SKIDDER2 | G10: =IFERROR(VLOOKUP(F10,Cadastros!A:B,2,FALSE),"-") -> SKIDDER 2 | H10: =IFERROR(VLOOKUP(G10,Cadastros!B:D,3,FALSE),"-") -> ARRASTE | I10: =J9 -> 0.25 | J10: 0.75 | K10: =IFERROR(IF(J10="-","-",((J10-I10)-INT(J10-I10))*24),"0") -> 12 | L10: 15 | M10: =IFERROR(VLOOKUP($L10,Justificativas!$A:$E,2,FALSE),"-") -> DETALHE 15 | N10: =IFERROR(VLOOKUP($L10,Justificativas!$A:$E,3,FALSE),"-") -> DESCRIÇÃO 14 | O10: =IFERROR(VLOOKUP($L10,Justificativas!$A:$E,4,FALSE),"-") -> DISPONIBILIDADE MECÂNICA | P10: =IFERROR(VLOOKUP($L10,Justificativas!$A:$E,5,FALSE),"-") -> NÃO | Q10: =IF(K10=0,"NÃO PUXA NO BI","PUXA") -> PUXA | R10: =COUNTIFS($B$1:B9,B10,$E$1:E9,E10,$G$1:G9,G10,$D$1:D9,D10) -> 0 | S10: =IF(OR(L10="100-1",L10="100-2",L10="100-3"),"NÃO","SIM") -> SIM
A11: =IFERROR(YEAR(E11),"-") -> 2026 | B11: =IFERROR(DATE(YEAR(E11),MONTH(E11),MONTH(E11)),"-") -> 46023 | C11: OPERADOR 4 | D11: =IF(AND(I11>=TIME(6,0,0),I11<TIME(18,0,0),OR(J11<=TIME(18,0,0),J11<TIME(6,0,0))),"TURNO 1","TURNO 2") -> TURNO 2 | E11: 46024 | F11: SKIDDER2 | G11: =IFERROR(VLOOKUP(F11,Cadastros!A:B,2,FALSE),"-") -> SKIDDER 2 | H11: =IFERROR(VLOOKUP(G11,Cadastros!B:D,3,FALSE),"-") -> ARRASTE | I11: =J10 -> 0.75 | J11: 0.25 | K11: =IFERROR(IF(J11="-","-",((J11-I11)-INT(J11-I11))*24),"0") -> 12 | L11: 10 | M11: =IFERROR(VLOOKUP($L11,Justificativas!$A:$E,2,FALSE),"-") -> DETALHE 10 | N11: =IFERROR(VLOOKUP($L11,Justificativas!$A:$E,3,FALSE),"-") -> DESCRIÇÃO 9 | O11: =IFERROR(VLOOKUP($L11,Justificativas!$A:$E,4,FALSE),"-") -> DISPONIBILIDADE OPERACIONAL | P11: =IFERROR(VLOOKUP($L11,Justificativas!$A:$E,5,FALSE),"-") -> NÃO | Q11: =IF(K11=0,"NÃO PUXA NO BI","PUXA") -> PUXA | R11: =COUNTIFS($B$1:B10,B11,$E$1:E10,E11,$G$1:G10,G11,$D$1:D10,D11) -> 0 | S11: =IF(OR(L11="100-1",L11="100-2",L11="100-3"),"NÃO","SIM") -> SIM
A12: =IFERROR(YEAR(E12),"-") -> 2026 | B12: =IFERROR(DATE(YEAR(E12),MONTH(E12),MONTH(E12)),"-") -> 46023 | C12: OPERADOR 1 | D12: =IF(AND(I12>=TIME(6,0,0),I12<TIME(18,0,0),OR(J12<=TIME(18,0,0),J12<TIME(6,0,0))),"TURNO 1","TURNO 2") -> TURNO 1 | E12: 46025 | F12: FELLER1 | G12: =IFERROR(VLOOKUP(F12,Cadastros!A:B,2,FALSE),"-") -> FELLER BUNCHER 1 | H12: =IFERROR(VLOOKUP(G12,Cadastros!B:D,3,FALSE),"-") -> CORTE | I12: =J11 -> 0.25 | J12: 0.75 | K12: =IFERROR(IF(J12="-","-",((J12-I12)-INT(J12-I12))*24),"0") -> 12 | L12: 1 | M12: =IFERROR(VLOOKUP($L12,Justificativas!$A:$E,2,FALSE),"-") -> OPERAÇÃO | N12: =IFERROR(VLOOKUP($L12,Justificativas!$A:$E,3,FALSE),"-") -> EM OPERAÇÃO | O12: =IFERROR(VLOOKUP($L12,Justificativas!$A:$E,4,FALSE),"-") -> OPERAÇÃO | P12: =IFERROR(VLOOKUP($L12,Justificativas!$A:$E,5,FALSE),"-") -> NÃO | Q12: =IF(K12=0,"NÃO PUXA NO BI","PUXA") -> PUXA | R12: =COUNTIFS($B$1:B11,B12,$E$1:E11,E12,$G$1:G11,G12,$D$1:D11,D12) -> 0 | S12: =IF(OR(L12="100-1",L12="100-2",L12="100-3"),"NÃO","SIM") -> SIM
A13: =IFERROR(YEAR(E13),"-") -> 2026 | B13: =IFERROR(DATE(YEAR(E13),MONTH(E13),MONTH(E13)),"-") -> 46023 | C13: OPERADOR 2 | D13: =IF(AND(I13>=TIME(6,0,0),I13<TIME(18,0,0),OR(J13<=TIME(18,0,0),J13<TIME(6,0,0))),"TURNO 1","TURNO 2") -> TURNO 2 | E13: 46025 | F13: FELLER1 | G13: =IFERROR(VLOOKUP(F13,Cadastros!A:B,2,FALSE),"-") -> FELLER BUNCHER 1 | H13: =IFERROR(VLOOKUP(G13,Cadastros!B:D,3,FALSE),"-") -> CORTE | I13: =J12 -> 0.75 | J13: 0.25 | K13: =IFERROR(IF(J13="-","-",((J13-I13)-INT(J13-I13))*24),"0") -> 12 | L13: 20 | M13: =IFERROR(VLOOKUP($L13,Justificativas!$A:$E,2,FALSE),"-") -> DETALHE 20 | N13: =IFERROR(VLOOKUP($L13,Justificativas!$A:$E,3,FALSE),"-") -> DESCRIÇÃO 19 | O13: =IFERROR(VLOOKUP($L13,Justificativas!$A:$E,4,FALSE),"-") -> DISPONIBILIDADE MECÂNICA | P13: =IFERROR(VLOOKUP($L13,Justificativas!$A:$E,5,FALSE),"-") -> NÃO | Q13: =IF(K13=0,"NÃO PUXA NO BI","PUXA") -> PUXA | R13: =COUNTIFS($B$1:B12,B13,$E$1:E12,E13,$G$1:G12,G13,$D$1:D12,D13) -> 0 | S13: =IF(OR(L13="100-1",L13="100-2",L13="100-3"),"NÃO","SIM") -> SIM
A14: =IFERROR(YEAR(E14),"-") -> 2026 | B14: =IFERROR(DATE(YEAR(E14),MONTH(E14),MONTH(E14)),"-") -> 46023 | C14: OPERADOR 3 | D14: =IF(AND(I14>=TIME(6,0,0),I14<TIME(18,0,0),OR(J14<=TIME(18,0,0),J14<TIME(6,0,0))),"TURNO 1","TURNO 2") -> TURNO 1 | E14: 46026 | F14: SKIDDER2 | G14: =IFERROR(VLOOKUP(F14,Cadastros!A:B,2,FALSE),"-") -> SKIDDER 2 | H14: =IFERROR(VLOOKUP(G14,Cadastros!B:D,3,FALSE),"-") -> ARRASTE | I14: =J13 -> 0.25 | J14: 0.75 | K14: =IFERROR(IF(J14="-","-",((J14-I14)-INT(J14-I14))*24),"0") -> 12 | L14: 8 | M14: =IFERROR(VLOOKUP($L14,Justificativas!$A:$E,2,FALSE),"-") -> DETALHE 8 | N14: =IFERROR(VLOOKUP($L14,Justificativas!$A:$E,3,FALSE),"-") -> DESCRIÇÃO 7 | O14: =IFERROR(VLOOKUP($L14,Justificativas!$A:$E,4,FALSE),"-") -> DISPONIBILIDADE OPERACIONAL | P14: =IFERROR(VLOOKUP($L14,Justificativas!$A:$E,5,FALSE),"-") -> NÃO | Q14: =IF(K14=0,"NÃO PUXA NO BI","PUXA") -> PUXA | R14: =COUNTIFS($B$1:B13,B14,$E$1:E13,E14,$G$1:G13,G14,$D$1:D13,D14) -> 0 | S14: =IF(OR(L14="100-1",L14="100-2",L14="100-3"),"NÃO","SIM") -> SIM
... A30: =IFERROR(YEAR(E30),"-") -> 2026 | B30: =IFERROR(DATE(YEAR(E30),MONTH(E30),MONTH(E30)),"-") -> 46023 | C30: OPERADOR 8 | D30: =IF(AND(I30>=TIME(6,0,0),I30<TIME(18,0,0),OR(J30<=TIME(18,0,0),J30<TIME(6,0,0))),"TURNO 1","TURNO 2") -> TURNO 2 | E30: 46028 | F30: FELLER2 | G30: =IFERROR(VLOOKUP(F30,Cadastros!A:B,2,FALSE),"-") -> FELLER BUNCHER 2 | H30: =IFERROR(VLOOKUP(G30,Cadastros!B:D,3,FALSE),"-") -> CORTE | I30: =J29 -> 0.125 | J30: 0.25 | K30: =IFERROR(IF(J30="-","-",((J30-I30)-INT(J30-I30))*24),"0") -> 3 | L30: 11 | M30: =IFERROR(VLOOKUP($L30,Justificativas!$A:$E,2,FALSE),"-") -> DETALHE 11 | N30: =IFERROR(VLOOKUP($L30,Justificativas!$A:$E,3,FALSE),"-") -> DESCRIÇÃO 10 | O30: =IFERROR(VLOOKUP($L30,Justificativas!$A:$E,4,FALSE),"-") -> DISPONIBILIDADE OPERACIONAL | P30: =IFERROR(VLOOKUP($L30,Justificativas!$A:$E,5,FALSE),"-") -> NÃO | Q30: =IF(K30=0,"NÃO PUXA NO BI","PUXA") -> PUXA | R30: =COUNTIFS($B$1:B29,B30,$E$1:E29,E30,$G$1:G29,G30,$D$1:D29,D30) -> 1 | S30: =IF(OR(L30="100-1",L30="100-2",L30="100-3"),"NÃO","SIM") -> SIM

Sheet Disponibilidade
A1: ANO | B1: MÊS | C1: DATA | D1: EQUIPAMENTO DIGITADO | E1: TURNO | F1: OPERADOR | G1: EQUIPAMENTO | H1: TIPO DE EQUIPAMENTO | I1: DISPONIBILIDADE MECÂNICA | J1: D.M | K1: META D.M BASE | L1: META D.M DESAFIO | M1: TETO META D.M | N1: STATUS D.M | O1: DISPONIBILIDADE OPERACIONAL | P1: D.O | Q1: META D.O BASE | R1: META D.O DESAFIO | S1: TETO META D.O | T1: STATUS D.O | U1: HORAS | V1: HORAS D.M | W1: HORAS D.O | X1: MÉDIA HORAS PARADAS | Y1: TOTAL HORAS | Z1: CHECK TOTAL HORAS | AA1: TOTAL HORAS PARADAS | AB1: TEMPO REFEIÇÃO | AC1: HORAS RODADAS | AD1: CHECK HORAS RODADAS | AE1: HORAS PARADAS | AF1: HORAS DESCONSIDERADAS | AG1: HORAS TRABALHADAS REAL | AH1: CHECK HORAS TRABALHADAS | AI1: META HORAS BASE | AJ1: META HORAS DESAFIO | AK1: TETO META HORAS | AL1: STATUS META HORAS
A2: =IFERROR(YEAR(C2),"-") -> 2026 | B2: =IFERROR(DATE(YEAR(C2),MONTH(C2),MONTH(C2)),"-") -> 46023 | C2: 46023 | D2: FELLER1 | E2: TURNO 1 | F2: {=IFERROR(INDEX('Motivos De Parada'!C:C,MATCH(1,('Motivos De Parada'!E:E=Disponibilidade!C2)*('Motivos De Parada'!G:G=Disponibilidade!G2)*('Motivos De Parada'!D:D=Disponibilidade!E2),0)),"-")} -> OPERADOR 1 | G2: =IFERROR(VLOOKUP(D2,Cadastros!A:B,2,FALSE),"-") -> FELLER BUNCHER 1 | H2: =IFERROR(VLOOKUP(G2,Cadastros!B:D,3,FALSE),"-") -> CORTE | I2: DISPONIBILIDADE MECÂNICA | J2: =IFERROR(MAX(0,1 - (SUMIFS('Motivos De Parada'!K:K,'Motivos De Parada'!G:G,Disponibilidade!G2,'Motivos De Parada'!H:H,Disponibilidade!H2,'Motivos De Parada'!O:O,Disponibilidade!I2,'Motivos De Parada'!E:E,Disponibilidade!C2,'Motivos De Parada'!D:D,Disponibilidade!E2) / 24)),"-") -> 0.83333333 | K2: {=IFERROR(INDEX('Metas DM & DO'!$A:$AAD,MATCH(Disponibilidade!$G2,'Metas DM & DO'!$A:$A,0),MATCH(Disponibilidade!$I2,'Metas DM & DO'!$1:$1,0)+1),"-")} -> 0.45882353 | L2: {=IFERROR(INDEX('Metas DM & DO'!$A:$AAD,MATCH(Disponibilidade!$G2,'Metas DM & DO'!$A:$A,0),MATCH(Disponibilidade!$I2,'Metas DM & DO'!$1:$1,0)+2),"-")} -> 0.66341463 | M2: {=IFERROR(INDEX('Metas DM & DO'!$A:$AAD,MATCH(Disponibilidade!$G2,'Metas DM & DO'!$A:$A,0),MATCH(Disponibilidade!$I2,'Metas DM & DO'!$1:$1,0)+3),"-")} -> 0.83333333 | N2: =IFERROR(IF(J2<K2,"RUIM",IF(AND(J2>=K2,J2<L2),"MEDIA",IF(AND(J2>=L2,J2<M2),"BOA","-"))),"-") -> - | O2: DISPONIBILIDADE OPERACIONAL | P2: =IFERROR(MAX(0,1 - (SUMIFS('Motivos De Parada'!K:K,'Motivos De Parada'!G:G,Disponibilidade!G2,'Motivos De Parada'!H:H,Disponibilidade!H2,'Motivos De Parada'!O:O,Disponibilidade!O2,'Motivos De Parada'!E:E,Disponibilidade!C2,'Motivos De Parada'!D:D,Disponibilidade!E2) / 24)),"-") -> 0.75 | Q2: {=IFERROR(INDEX('Metas DM & DO'!$A:$AAD,MATCH(Disponibilidade!$G2,'Metas DM & DO'!$A:$A,0),MATCH(Disponibilidade!$O2,'Metas DM & DO'!$1:$1,0)+1),"-")} -> 0.74117647 | R2: {=IFERROR(INDEX('Metas DM & DO'!$A:$AAD,MATCH(Disponibilidade!$G2,'Metas DM & DO'!$A:$A,0),MATCH(Disponibilidade!$O2,'Metas DM & DO'!$1:$1,0)+2),"-")} -> 0.83902439 | S2: {=IFERROR(INDEX('Metas DM & DO'!$A:$AAD,MATCH(Disponibilidade!$G2,'Metas DM & DO'!$A:$A,0),MATCH(Disponibilidade!$O2,'Metas DM & DO'!$1:$1,0)+3),"-")} -> 0.79166667 | T2: =IFERROR(IF(P2<Q2,"RUIM",IF(AND(P2>=Q2,P2<R2),"MEDIA",IF(AND(P2>=R2,P2<S2),"BOA","-"))),"-") -> MEDIA | U2: HORAS | V2: =IFERROR(SUMIFS('Motivos De Parada'!K:K,'Motivos De Parada'!G:G,Disponibilidade!G2,'Motivos De Parada'!H:H,Disponibilidade!H2,'Motivos De Parada'!O:O,Disponibilidade!I2,'Motivos De Parada'!E:E,Disponibilidade!C2,'Motivos De Parada'!D:D,Disponibilidade!E2),"-") -> 4 | W2: =IFERROR(SUMIFS('Motivos De Parada'!K:K,'Motivos De Parada'!G:G,Disponibilidade!G2,'Motivos De Parada'!H:H,Disponibilidade!H2,'Motivos De Parada'!O:O,Disponibilidade!O2,'Motivos De Parada'!E:E,Disponibilidade!C2,'Motivos De Parada'!D:D,Disponibilidade!E2),"-") -> 6 | X2: =IFERROR(AVERAGE(V2,W2),"-") -> 5 | Y2: =IFERROR(SUMIFS('Motivos De Parada'!K:K,'Motivos De Parada'!G:G,Disponibilidade!G2,'Motivos De Parada'!H:H,Disponibilidade!H2,'Motivos De Parada'!E:E,Disponibilidade!C2,'Motivos De Parada'!D:D,Disponibilidade!E2),"-") -> 12 | Z2: =IFERROR(IF(Y2=0,"OK",IF(OR(Y2>12,Y2<12),"VERIFICAR","OK")),"-") -> OK | AA2: =IFERROR(W2+V2,"-") -> 10 | AB2: =IFERROR(SUMIFS('Motivos De Parada'!K:K,'Motivos De Parada'!G:G,Disponibilidade!G2,'Motivos De Parada'!H:H,Disponibilidade!H2,'Motivos De Parada'!E:E,Disponibilidade!C2,'Motivos De Parada'!D:D,Disponibilidade!E2,'Motivos De Parada'!M:M,"REFEIÇÃO"),"-") -> 0 | AC2: =IFERROR(Y2-AA2-AB2,"-") -> 2 | AD2: =IFERROR(IF(AC2<0,"VERIFICAR","OK"),"-") -> OK | AE2: {=IFERROR(SUM(SUMIFS('Motivos De Parada'!K:K,'Motivos De Parada'!G:G,Disponibilidade!G2,'Motivos De Parada'!H:H,Disponibilidade!H2,'Motivos De Parada'!E:E,Disponibilidade!C2,'Motivos De Parada'!D:D,Disponibilidade!E2,'Motivos De Parada'!O:O,{"DISPONIBILIDADE MECÂNICA";"DISPONIBILIDADE OPERACIONAL"},'Motivos De Parada'!P:P,"NÃO")),"-")} -> 10 | AF2: {=IFERROR(SUM(SUMIFS('Motivos De Parada'!K:K,'Motivos De Parada'!G:G,Disponibilidade!G2,'Motivos De Parada'!H:H,Disponibilidade!H2,'Motivos De Parada'!E:E,Disponibilidade!C2,'Motivos De Parada'!D:D,Disponibilidade!E2,'Motivos De Parada'!O:O,{"DISPONIBILIDADE MECÂNICA";"DISPONIBILIDADE OPERACIONAL"},'Motivos De Parada'!P:P,"SIM")),"-")} -> 0 | AG2: =IFERROR(IF((AC2-AF2)<0,0,(AC2-AF2)),"-") -> 2 | AH2: =IFERROR(IF(AND(AG2=0,AC2=0),"OK",IF(AG2=AC2,"VERIFICAR","OK")),"-") -> VERIFICAR | AI2: {=IFERROR(INDEX('Metas DM & DO'!$A:$AAD,MATCH(Disponibilidade!$G2,'Metas DM & DO'!$A:$A,0),MATCH(Disponibilidade!$U2,'Metas DM & DO'!$1:$1,0)+2),"-")} -> 4.8 | AJ2: {=IFERROR(INDEX('Metas DM & DO'!$A:$AAD,MATCH(Disponibilidade!$G2,'Metas DM & DO'!$A:$A,0),MATCH(Disponibilidade!$U2,'Metas DM & DO'!$1:$1,0)+3),"-")} -> 2.9853659 | AK2: {=IFERROR(INDEX('Metas DM & DO'!$A:$AAD,MATCH(Disponibilidade!$G2,'Metas DM & DO'!$A:$A,0),MATCH(Disponibilidade!$U2,'Metas DM & DO'!$1:$1,0)+4),"-")} -> 12 | AL2: =IFERROR(IF(X2<=AJ2,"EXCELENTE", IF(X2<=AI2,"BOM", IF(X2<=AK2,"ATENÇÃO",IF(X2>AK2,"CRÍTICO","-")))),"-") -> ATENÇÃO
A3: =IFERROR(YEAR(C3),"-") -> 2026 | B3: =IFERROR(DATE(YEAR(C3),MONTH(C3),MONTH(C3)),"-") -> 46023 | C3: 46023 | D3: FELLER1 | E3: TURNO 2 | F3: {=IFERROR(INDEX('Motivos De Parada'!C:C,MATCH(1,('Motivos De Parada'!E:E=Disponibilidade!C3)*('Motivos De Parada'!G:G=Disponibilidade!G3)*('Motivos De Parada'!D:D=Disponibilidade!E3),0)),"-")} -> OPERADOR 2 | G3: =IFERROR(VLOOKUP(D3,Cadastros!A:B,2,FALSE),"-") -> FELLER BUNCHER 1 | H3: =IFERROR(VLOOKUP(G3,Cadastros!B:D,3,FALSE),"-") -> CORTE | I3: DISPONIBILIDADE MECÂNICA | J3: =IFERROR(MAX(0,1 - (SUMIFS('Motivos De Parada'!K:K,'Motivos De Parada'!G:G,Disponibilidade!G3,'Motivos De Parada'!H:H,Disponibilidade!H3,'Motivos De Parada'!O:O,Disponibilidade!I3,'Motivos De Parada'!E:E,Disponibilidade!C3,'Motivos De Parada'!D:D,Disponibilidade!E3) / 24)),"-") -> 0.70833333 | K3: {=IFERROR(INDEX('Metas DM & DO'!$A:$AAD,MATCH(Disponibilidade!$G3,'Metas DM & DO'!$A:$A,0),MATCH(Disponibilidade!$I3,'Metas DM & DO'!$1:$1,0)+1),"-")} -> 0.45882353 | L3: {=IFERROR(INDEX('Metas DM & DO'!$A:$AAD,MATCH(Disponibilidade!$G3,'Metas DM & DO'!$A:$A,0),MATCH(Disponibilidade!$I3,'Metas DM & DO'!$1:$1,0)+2),"-")} -> 0.66341463 | M3: {=IFERROR(INDEX('Metas DM & DO'!$A:$AAD,MATCH(Disponibilidade!$G3,'Metas DM & DO'!$A:$A,0),MATCH(Disponibilidade!$I3,'Metas DM & DO'!$1:$1,0)+3),"-")} -> 0.83333333 | N3: =IFERROR(IF(J3<K3,"RUIM",IF(AND(J3>=K3,J3<L3),"MEDIA",IF(AND(J3>=L3,J3<M3),"BOA","-"))),"-") -> BOA | O3: DISPONIBILIDADE OPERACIONAL | P3: =IFERROR(MAX(0,1 - (SUMIFS('Motivos De Parada'!K:K,'Motivos De Parada'!G:G,Disponibilidade!G3,'Motivos De Parada'!H:H,Disponibilidade!H3,'Motivos De Parada'!O:O,Disponibilidade!O3,'Motivos De Parada'!E:E,Disponibilidade!C3,'Motivos De Parada'!D:D,Disponibilidade!E3) / 24)),"-") -> 0.79166667 | Q3: {=IFERROR(INDEX('Metas DM & DO'!$A:$AAD,MATCH(Disponibilidade!$G3,'Metas DM & DO'!$A:$A,0),MATCH(Disponibilidade!$O3,'Metas DM & DO'!$1:$1,0)+1),"-")} -> 0.74117647 | R3: {=IFERROR(INDEX('Metas DM & DO'!$A:$AAD,MATCH(Disponibilidade!$G3,'Metas DM & DO'!$A:$A,0),MATCH(Disponibilidade!$O3,'Metas DM & DO'!$1:$1,0)+2),"-")} -> 0.83902439 | S3: {=IFERROR(INDEX('Metas DM & DO'!$A:$AAD,MATCH(Disponibilidade!$G3,'Metas DM & DO'!$A:$A,0),MATCH(Disponibilidade!$O3,'Metas DM & DO'!$1:$1,0)+3),"-")} -> 0.79166667 | T3: =IFERROR(IF(P3<Q3,"RUIM",IF(AND(P3>=Q3,P3<R3),"MEDIA",IF(AND(P3>=R3,P3<S3),"BOA","-"))),"-") -> MEDIA | U3: HORAS | V3: =IFERROR(SUMIFS('Motivos De Parada'!K:K,'Motivos De Parada'!G:G,Disponibilidade!G3,'Motivos De Parada'!H:H,Disponibilidade!H3,'Motivos De Parada'!O:O,Disponibilidade!I3,'Motivos De Parada'!E:E,Disponibilidade!C3,'Motivos De Parada'!D:D,Disponibilidade!E3),"-") -> 7 | W3: =IFERROR(SUMIFS('Motivos De Parada'!K:K,'Motivos De Parada'!G:G,Disponibilidade!G3,'Motivos De Parada'!H:H,Disponibilidade!H3,'Motivos De Parada'!O:O,Disponibilidade!O3,'Motivos De Parada'!E:E,Disponibilidade!C3,'Motivos De Parada'!D:D,Disponibilidade!E3),"-") -> 5 | X3: =IFERROR(AVERAGE(V3,W3),"-") -> 6 | Y3: =IFERROR(SUMIFS('Motivos De Parada'!K:K,'Motivos De Parada'!G:G,Disponibilidade!G3,'Motivos De Parada'!H:H,Disponibilidade!H3,'Motivos De Parada'!E:E,Disponibilidade!C3,'Motivos De Parada'!D:D,Disponibilidade!E3),"-") -> 12 | Z3: =IFERROR(IF(Y3=0,"OK",IF(OR(Y3>12,Y3<12),"VERIFICAR","OK")),"-") -> OK | AA3: =IFERROR(W3+V3,"-") -> 12 | AB3: =IFERROR(SUMIFS('Motivos De Parada'!K:K,'Motivos De Parada'!G:G,Disponibilidade!G3,'Motivos De Parada'!H:H,Disponibilidade!H3,'Motivos De Parada'!E:E,Disponibilidade!C3,'Motivos De Parada'!D:D,Disponibilidade!E3,'Motivos De Parada'!M:M,"REFEIÇÃO"),"-") -> 0 | AC3: =IFERROR(Y3-AA3-AB3,"-") -> 0 | AD3: =IFERROR(IF(AC3<0,"VERIFICAR","OK"),"-") -> OK | AE3: {=IFERROR(SUM(SUMIFS('Motivos De Parada'!K:K,'Motivos De Parada'!G:G,Disponibilidade!G3,'Motivos De Parada'!H:H,Disponibilidade!H3,'Motivos De Parada'!E:E,Disponibilidade!C3,'Motivos De Parada'!D:D,Disponibilidade!E3,'Motivos De Parada'!O:O,{"DISPONIBILIDADE MECÂNICA";"DISPONIBILIDADE OPERACIONAL"},'Motivos De Parada'!P:P,"NÃO")),"-")} -> 12 | AF3: {=IFERROR(SUM(SUMIFS('Motivos De Parada'!K:K,'Motivos De Parada'!G:G,Disponibilidade!G3,'Motivos De Parada'!H:H,Disponibilidade!H3,'Motivos De Parada'!E:E,Disponibilidade!C3,'Motivos De Parada'!D:D,Disponibilidade!E3,'Motivos De Parada'!O:O,{"DISPONIBILIDADE MECÂNICA";"DISPONIBILIDADE OPERACIONAL"},'Motivos De Parada'!P:P,"SIM")),"-")} -> 0 | AG3: =IFERROR(IF((AC3-AF3)<0,0,(AC3-AF3)),"-") -> 0 | AH3: =IFERROR(IF(AND(AG3=0,AC3=0),"OK",IF(AG3=AC3,"VERIFICAR","OK")),"-") -> OK | AI3: {=IFERROR(INDEX('Metas DM & DO'!$A:$AAD,MATCH(Disponibilidade!$G3,'Metas DM & DO'!$A:$A,0),MATCH(Disponibilidade!$U3,'Metas DM & DO'!$1:$1,0)+2),"-")} -> 4.8 | AJ3: {=IFERROR(INDEX('Metas DM & DO'!$A:$AAD,MATCH(Disponibilidade!$G3,'Metas DM & DO'!$A:$A,0),MATCH(Disponibilidade!$U3,'Metas DM & DO'!$1:$1,0)+3),"-")} -> 2.9853659 | AK3: {=IFERROR(INDEX('Metas DM & DO'!$A:$AAD,MATCH(Disponibilidade!$G3,'Metas DM & DO'!$A:$A,0),MATCH(Disponibilidade!$U3,'Metas DM & DO'!$1:$1,0)+4),"-")} -> 12 | AL3: =IFERROR(IF(X3<=AJ3,"EXCELENTE", IF(X3<=AI3,"BOM", IF(X3<=AK3,"ATENÇÃO",IF(X3>AK3,"CRÍTICO","-")))),"-") -> ATENÇÃO
A4: =IFERROR(YEAR(C4),"-") -> 2026 | B4: =IFERROR(DATE(YEAR(C4),MONTH(C4),MONTH(C4)),"-") -> 46023 | C4: 46023 | D4: FELLER2 | E4: TURNO 1 | F4: {=IFERROR(INDEX('Motivos De Parada'!C:C,MATCH(1,('Motivos De Parada'!E:E=Disponibilidade!C4)*('Motivos De Parada'!G:G=Disponibilidade!G4)*('Motivos De Parada'!D:D=Disponibilidade!E4),0)),"-")} -> - | G4: =IFERROR(VLOOKUP(D4,Cadastros!A:B,2,FALSE),"-") -> FELLER BUNCHER 2 | H4: =IFERROR(VLOOKUP(G4,Cadastros!B:D,3,FALSE),"-") -> CORTE | I4: DISPONIBILIDADE MECÂNICA | J4: =IFERROR(MAX(0,1 - (SUMIFS('Motivos De Parada'!K:K,'Motivos De Parada'!G:G,Disponibilidade!G4,'Motivos De Parada'!H:H,Disponibilidade!H4,'Motivos De Parada'!O:O,Disponibilidade!I4,'Motivos De Parada'!E:E,Disponibilidade!C4,'Motivos De Parada'!D:D,Disponibilidade!E4) / 24)),"-") -> 1 | K4: {=IFERROR(INDEX('Metas DM & DO'!$A:$AAD,MATCH(Disponibilidade!$G4,'Metas DM & DO'!$A:$A,0),MATCH(Disponibilidade!$I4,'Metas DM & DO'!$1:$1,0)+1),"-")} -> 1 | L4: {=IFERROR(INDEX('Metas DM & DO'!$A:$AAD,MATCH(Disponibilidade!$G4,'Metas DM & DO'!$A:$A,0),MATCH(Disponibilidade!$I4,'Metas DM & DO'!$1:$1,0)+2),"-")} -> 1 | M4: {=IFERROR(INDEX('Metas DM & DO'!$A:$AAD,MATCH(Disponibilidade!$G4,'Metas DM & DO'!$A:$A,0),MATCH(Disponibilidade!$I4,'Metas DM & DO'!$1:$1,0)+3),"-")} -> - | N4: =IFERROR(IF(J4<K4,"RUIM",IF(AND(J4>=K4,J4<L4),"MEDIA",IF(AND(J4>=L4,J4<M4),"BOA","-"))),"-") -> BOA | O4: DISPONIBILIDADE OPERACIONAL | P4: =IFERROR(MAX(0,1 - (SUMIFS('Motivos De Parada'!K:K,'Motivos De Parada'!G:G,Disponibilidade!G4,'Motivos De Parada'!H:H,Disponibilidade!H4,'Motivos De Parada'!O:O,Disponibilidade!O4,'Motivos De Parada'!E:E,Disponibilidade!C4,'Motivos De Parada'!D:D,Disponibilidade!E4) / 24)),"-") -> 1 | Q4: {=IFERROR(INDEX('Metas DM & DO'!$A:$AAD,MATCH(Disponibilidade!$G4,'Metas DM & DO'!$A:$A,0),MATCH(Disponibilidade!$O4,'Metas DM & DO'!$1:$1,0)+1),"-")} -> 0.12 | R4: {=IFERROR(INDEX('Metas DM & DO'!$A:$AAD,MATCH(Disponibilidade!$G4,'Metas DM & DO'!$A:$A,0),MATCH(Disponibilidade!$O4,'Metas DM & DO'!$1:$1,0)+2),"-")} -> 0.25842697 | S4: {=IFERROR(INDEX('Metas DM & DO'!$A:$AAD,MATCH(Disponibilidade!$G4,'Metas DM & DO'!$A:$A,0),MATCH(Disponibilidade!$O4,'Metas DM & DO'!$1:$1,0)+3),"-")} -> 0.58333333 | T4: =IFERROR(IF(P4<Q4,"RUIM",IF(AND(P4>=Q4,P4<R4),"MEDIA",IF(AND(P4>=R4,P4<S4),"BOA","-"))),"-") -> - | U4: HORAS | V4: =IFERROR(SUMIFS('Motivos De Parada'!K:K,'Motivos De Parada'!G:G,Disponibilidade!G4,'Motivos De Parada'!H:H,Disponibilidade!H4,'Motivos De Parada'!O:O,Disponibilidade!I4,'Motivos De Parada'!E:E,Disponibilidade!C4,'Motivos De Parada'!D:D,Disponibilidade!E4),"-") -> 0 | W4: =IFERROR(SUMIFS('Motivos De Parada'!K:K,'Motivos De Parada'!G:G,Disponibilidade!G4,'Motivos De Parada'!H:H,Disponibilidade!H4,'Motivos De Parada'!O:O,Disponibilidade!O4,'Motivos De Parada'!E:E,Disponibilidade!C4,'Motivos De Parada'!D:D,Disponibilidade!E4),"-") -> 0 | X4: =IFERROR(AVERAGE(V4,W4),"-") -> 0 | Y4: =IFERROR(SUMIFS('Motivos De Parada'!K:K,'Motivos De Parada'!G:G,Disponibilidade!G4,'Motivos De Parada'!H:H,Disponibilidade!H4,'Motivos De Parada'!E:E,Disponibilidade!C4,'Motivos De Parada'!D:D,Disponibilidade!E4),"-") -> 0 | Z4: =IFERROR(IF(Y4=0,"OK",IF(OR(Y4>12,Y4<12),"VERIFICAR","OK")),"-") -> OK | AA4: =IFERROR(W4+V4,"-") -> 0 | AB4: =IFERROR(SUMIFS('Motivos De Parada'!K:K,'Motivos De Parada'!G:G,Disponibilidade!G4,'Motivos De Parada'!H:H,Disponibilidade!H4,'Motivos De Parada'!E:E,Disponibilidade!C4,'Motivos De Parada'!D:D,Disponibilidade!E4,'Motivos De Parada'!M:M,"REFEIÇÃO"),"-") -> 0 | AC4: =IFERROR(Y4-AA4-AB4,"-") -> 0 | AD4: =IFERROR(IF(AC4<0,"VERIFICAR","OK"),"-") -> OK | AE4: {=IFERROR(SUM(SUMIFS('Motivos De Parada'!K:K,'Motivos De Parada'!G:G,Disponibilidade!G4,'Motivos De Parada'!H:H,Disponibilidade!H4,'Motivos De Parada'!E:E,Disponibilidade!C4,'Motivos De Parada'!D:D,Disponibilidade!E4,'Motivos De Parada'!O:O,{"DISPONIBILIDADE MECÂNICA";"DISPONIBILIDADE OPERACIONAL"},'Motivos De Parada'!P:P,"NÃO")),"-")} -> 0 | AF4: {=IFERROR(SUM(SUMIFS('Motivos De Parada'!K:K,'Motivos De Parada'!G:G,Disponibilidade!G4,'Motivos De Parada'!H:H,Disponibilidade!H4,'Motivos De Parada'!E:E,Disponibilidade!C4,'Motivos De Parada'!D:D,Disponibilidade!E4,'Motivos De Parada'!O:O,{"DISPONIBILIDADE MECÂNICA";"DISPONIBILIDADE OPERACIONAL"},'Motivos De Parada'!P:P,"SIM")),"-")} -> 0 | AG4: =IFERROR(IF((AC4-AF4)<0,0,(AC4-AF4)),"-") -> 0 | AH4: =IFERROR(IF(AND(AG4=0,AC4=0),"OK",IF(AG4=AC4,"VERIFICAR","OK")),"-") -> OK | AI4: {=IFERROR(INDEX('Metas DM & DO'!$A:$AAD,MATCH(Disponibilidade!$G4,'Metas DM & DO'!$A:$A,0),MATCH(Disponibilidade!$U4,'Metas DM & DO'!$1:$1,0)+2),"-")} -> 5.28 | AJ4: {=IFERROR(INDEX('Metas DM & DO'!$A:$AAD,MATCH(Disponibilidade!$G4,'Metas DM & DO'!$A:$A,0),MATCH(Disponibilidade!$U4,'Metas DM & DO'!$1:$1,0)+3),"-")} -> 4.4494382 | AK4: {=IFERROR(INDEX('Metas DM & DO'!$A:$AAD,MATCH(Disponibilidade!$G4,'Metas DM & DO'!$A:$A,0),MATCH(Disponibilidade!$U4,'Metas DM & DO'!$1:$1,0)+4),"-")} -> 9 | AL4: =IFERROR(IF(X4<=AJ4,"EXCELENTE", IF(X4<=AI4,"BOM", IF(X4<=AK4,"ATENÇÃO",IF(X4>AK4,"CRÍTICO","-")))),"-") -> EXCELENTE
A5: =IFERROR(YEAR(C5),"-") -> 2026 | B5: =IFERROR(DATE(YEAR(C5),MONTH(C5),MONTH(C5)),"-") -> 46023 | C5: 46023 | D5: FELLER2 | E5: TURNO 2 | F5: {=IFERROR(INDEX('Motivos De Parada'!C:C,MATCH(1,('Motivos De Parada'!E:E=Disponibilidade!C5)*('Motivos De Parada'!G:G=Disponibilidade!G5)*('Motivos De Parada'!D:D=Disponibilidade!E5),0)),"-")} -> - | G5: =IFERROR(VLOOKUP(D5,Cadastros!A:B,2,FALSE),"-") -> FELLER BUNCHER 2 | H5: =IFERROR(VLOOKUP(G5,Cadastros!B:D,3,FALSE),"-") -> CORTE | I5: DISPONIBILIDADE MECÂNICA | J5: =IFERROR(MAX(0,1 - (SUMIFS('Motivos De Parada'!K:K,'Motivos De Parada'!G:G,Disponibilidade!G5,'Motivos De Parada'!H:H,Disponibilidade!H5,'Motivos De Parada'!O:O,Disponibilidade!I5,'Motivos De Parada'!E:E,Disponibilidade!C5,'Motivos De Parada'!D:D,Disponibilidade!E5) / 24)),"-") -> 1 | K5: {=IFERROR(INDEX('Metas DM & DO'!$A:$AAD,MATCH(Disponibilidade!$G5,'Metas DM & DO'!$A:$A,0),MATCH(Disponibilidade!$I5,'Metas DM & DO'!$1:$1,0)+1),"-")} -> 1 | L5: {=IFERROR(INDEX('Metas DM & DO'!$A:$AAD,MATCH(Disponibilidade!$G5,'Metas DM & DO'!$A:$A,0),MATCH(Disponibilidade!$I5,'Metas DM & DO'!$1:$1,0)+2),"-")} -> 1 | M5: {=IFERROR(INDEX('Metas DM & DO'!$A:$AAD,MATCH(Disponibilidade!$G5,'Metas DM & DO'!$A:$A,0),MATCH(Disponibilidade!$I5,'Metas DM & DO'!$1:$1,0)+3),"-")} -> - | N5: =IFERROR(IF(J5<K5,"RUIM",IF(AND(J5>=K5,J5<L5),"MEDIA",IF(AND(J5>=L5,J5<M5),"BOA","-"))),"-") -> BOA | O5: DISPONIBILIDADE OPERACIONAL | P5: =IFERROR(MAX(0,1 - (SUMIFS('Motivos De Parada'!K:K,'Motivos De Parada'!G:G,Disponibilidade!G5,'Motivos De Parada'!H:H,Disponibilidade!H5,'Motivos De Parada'!O:O,Disponibilidade!O5,'Motivos De Parada'!E:E,Disponibilidade!C5,'Motivos De Parada'!D:D,Disponibilidade!E5) / 24)),"-") -> 1 | Q5: {=IFERROR(INDEX('Metas DM & DO'!$A:$AAD,MATCH(Disponibilidade!$G5,'Metas DM & DO'!$A:$A,0),MATCH(Disponibilidade!$O5,'Metas DM & DO'!$1:$1,0)+1),"-")} -> 0.12 | R5: {=IFERROR(INDEX('Metas DM & DO'!$A:$AAD,MATCH(Disponibilidade!$G5,'Metas DM & DO'!$A:$A,0),MATCH(Disponibilidade!$O5,'Metas DM & DO'!$1:$1,0)+2),"-")} -> 0.25842697 | S5: {=IFERROR(INDEX('Metas DM & DO'!$A:$AAD,MATCH(Disponibilidade!$G5,'Metas DM & DO'!$A:$A,0),MATCH(Disponibilidade!$O5,'Metas DM & DO'!$1:$1,0)+3),"-")} -> 0.58333333 | T5: =IFERROR(IF(P5<Q5,"RUIM",IF(AND(P5>=Q5,P5<R5),"MEDIA",IF(AND(P5>=R5,P5<S5),"BOA","-"))),"-") -> - | U5: HORAS | V5: =IFERROR(SUMIFS('Motivos De Parada'!K:K,'Motivos De Parada'!G:G,Disponibilidade!G5,'Motivos De Parada'!H:H,Disponibilidade!H5,'Motivos De Parada'!O:O,Disponibilidade!I5,'Motivos De Parada'!E:E,Disponibilidade!C5,'Motivos De Parada'!D:D,Disponibilidade!E5),"-") -> 0 | W5: =IFERROR(SUMIFS('Motivos De Parada'!K:K,'Motivos De Parada'!G:G,Disponibilidade!G5,'Motivos De Parada'!H:H,Disponibilidade!H5,'Motivos De Parada'!O:O,Disponibilidade!O5,'Motivos De Parada'!E:E,Disponibilidade!C5,'Motivos De Parada'!D:D,Disponibilidade!E5),"-") -> 0 | X5: =IFERROR(AVERAGE(V5,W5),"-") -> 0 | Y5: =IFERROR(SUMIFS('Motivos De Parada'!K:K,'Motivos De Parada'!G:G,Disponibilidade!G5,'Motivos De Parada'!H:H,Disponibilidade!H5,'Motivos De Parada'!E:E,Disponibilidade!C5,'Motivos De Parada'!D:D,Disponibilidade!E5),"-") -> 0 | Z5: =IFERROR(IF(Y5=0,"OK",IF(OR(Y5>12,Y5<12),"VERIFICAR","OK")),"-") -> OK | AA5: =IFERROR(W5+V5,"-") -> 0 | AB5: =IFERROR(SUMIFS('Motivos De Parada'!K:K,'Motivos De Parada'!G:G,Disponibilidade!G5,'Motivos De Parada'!H:H,Disponibilidade!H5,'Motivos De Parada'!E:E,Disponibilidade!C5,'Motivos De Parada'!D:D,Disponibilidade!E5,'Motivos De Parada'!M:M,"REFEIÇÃO"),"-") -> 0 | AC5: =IFERROR(Y5-AA5-AB5,"-") -> 0 | AD5: =IFERROR(IF(AC5<0,"VERIFICAR","OK"),"-") -> OK | AE5: {=IFERROR(SUM(SUMIFS('Motivos De Parada'!K:K,'Motivos De Parada'!G:G,Disponibilidade!G5,'Motivos De Parada'!H:H,Disponibilidade!H5,'Motivos De Parada'!E:E,Disponibilidade!C5,'Motivos De Parada'!D:D,Disponibilidade!E5,'Motivos De Parada'!O:O,{"DISPONIBILIDADE MECÂNICA";"DISPONIBILIDADE OPERACIONAL"},'Motivos De Parada'!P:P,"NÃO")),"-")} -> 0 | AF5: {=IFERROR(SUM(SUMIFS('Motivos De Parada'!K:K,'Motivos De Parada'!G:G,Disponibilidade!G5,'Motivos De Parada'!H:H,Disponibilidade!H5,'Motivos De Parada'!E:E,Disponibilidade!C5,'Motivos De Parada'!D:D,Disponibilidade!E5,'Motivos De Parada'!O:O,{"DISPONIBILIDADE MECÂNICA";"DISPONIBILIDADE OPERACIONAL"},'Motivos De Parada'!P:P,"SIM")),"-")} -> 0 | AG5: =IFERROR(IF((AC5-AF5)<0,0,(AC5-AF5)),"-") -> 0 | AH5: =IFERROR(IF(AND(AG5=0,AC5=0),"OK",IF(AG5=AC5,"VERIFICAR","OK")),"-") -> OK | AI5: {=IFERROR(INDEX('Metas DM & DO'!$A:$AAD,MATCH(Disponibilidade!$G5,'Metas DM & DO'!$A:$A,0),MATCH(Disponibilidade!$U5,'Metas DM & DO'!$1:$1,0)+2),"-")} -> 5.28 | AJ5: {=IFERROR(INDEX('Metas DM & DO'!$A:$AAD,MATCH(Disponibilidade!$G5,'Metas DM & DO'!$A:$A,0),MATCH(Disponibilidade!$U5,'Metas DM & DO'!$1:$1,0)+3),"-")} -> 4.4494382 | AK5: {=IFERROR(INDEX('Metas DM & DO'!$A:$AAD,MATCH(Disponibilidade!$G5,'Metas DM & DO'!$A:$A,0),MATCH(Disponibilidade!$U5,'Metas DM & DO'!$1:$1,0)+4),"-")} -> 9 | AL5: =IFERROR(IF(X5<=AJ5,"EXCELENTE", IF(X5<=AI5,"BOM", IF(X5<=AK5,"ATENÇÃO",IF(X5>AK5,"CRÍTICO","-")))),"-") -> EXCELENTE
A6: =IFERROR(YEAR(C6),"-") -> 2026 | B6: =IFERROR(DATE(YEAR(C6),MONTH(C6),MONTH(C6)),"-") -> 46023 | C6: 46023 | D6: SKIDDER1 | E6: TURNO 1 | F6: {=IFERROR(INDEX('Motivos De Parada'!C:C,MATCH(1,('Motivos De Parada'!E:E=Disponibilidade!C6)*('Motivos De Parada'!G:G=Disponibilidade!G6)*('Motivos De Parada'!D:D=Disponibilidade!E6),0)),"-")} -> - | G6: =IFERROR(VLOOKUP(D6,Cadastros!A:B,2,FALSE),"-") -> SKIDDER 1 | H6: =IFERROR(VLOOKUP(G6,Cadastros!B:D,3,FALSE),"-") -> ARRASTE | I6: DISPONIBILIDADE MECÂNICA | J6: =IFERROR(MAX(0,1 - (SUMIFS('Motivos De Parada'!K:K,'Motivos De Parada'!G:G,Disponibilidade!G6,'Motivos De Parada'!H:H,Disponibilidade!H6,'Motivos De Parada'!O:O,Disponibilidade!I6,'Motivos De Parada'!E:E,Disponibilidade!C6,'Motivos De Parada'!D:D,Disponibilidade!E6) / 24)),"-") -> 1 | K6: {=IFERROR(INDEX('Metas DM & DO'!$A:$AAD,MATCH(Disponibilidade!$G6,'Metas DM & DO'!$A:$A,0),MATCH(Disponibilidade!$I6,'Metas DM & DO'!$1:$1,0)+1),"-")} -> - | L6: {=IFERROR(INDEX('Metas DM & DO'!$A:$AAD,MATCH(Disponibilidade!$G6,'Metas DM & DO'!$A:$A,0),MATCH(Disponibilidade!$I6,'Metas DM & DO'!$1:$1,0)+2),"-")} -> - | M6: {=IFERROR(INDEX('Metas DM & DO'!$A:$AAD,MATCH(Disponibilidade!$G6,'Metas DM & DO'!$A:$A,0),MATCH(Disponibilidade!$I6,'Metas DM & DO'!$1:$1,0)+3),"-")} -> - | N6: =IFERROR(IF(J6<K6,"RUIM",IF(AND(J6>=K6,J6<L6),"MEDIA",IF(AND(J6>=L6,J6<M6),"BOA","-"))),"-") -> RUIM | O6: DISPONIBILIDADE OPERACIONAL | P6: =IFERROR(MAX(0,1 - (SUMIFS('Motivos De Parada'!K:K,'Motivos De Parada'!G:G,Disponibilidade!G6,'Motivos De Parada'!H:H,Disponibilidade!H6,'Motivos De Parada'!O:O,Disponibilidade!O6,'Motivos De Parada'!E:E,Disponibilidade!C6,'Motivos De Parada'!D:D,Disponibilidade!E6) / 24)),"-") -> 1 | Q6: {=IFERROR(INDEX('Metas DM & DO'!$A:$AAD,MATCH(Disponibilidade!$G6,'Metas DM & DO'!$A:$A,0),MATCH(Disponibilidade!$O6,'Metas DM & DO'!$1:$1,0)+1),"-")} -> - | R6: {=IFERROR(INDEX('Metas DM & DO'!$A:$AAD,MATCH(Disponibilidade!$G6,'Metas DM & DO'!$A:$A,0),MATCH(Disponibilidade!$O6,'Metas DM & DO'!$1:$1,0)+2),"-")} -> - | S6: {=IFERROR(INDEX('Metas DM & DO'!$A:$AAD,MATCH(Disponibilidade!$G6,'Metas DM & DO'!$A:$A,0),MATCH(Disponibilidade!$O6,'Metas DM & DO'!$1:$1,0)+3),"-")} -> - | T6: =IFERROR(IF(P6<Q6,"RUIM",IF(AND(P6>=Q6,P6<R6),"MEDIA",IF(AND(P6>=R6,P6<S6),"BOA","-"))),"-") -> RUIM | U6: HORAS | V6: =IFERROR(SUMIFS('Motivos De Parada'!K:K,'Motivos De Parada'!G:G,Disponibilidade!G6,'Motivos De Parada'!H:H,Disponibilidade!H6,'Motivos De Parada'!O:O,Disponibilidade!I6,'Motivos De Parada'!E:E,Disponibilidade!C6,'Motivos De Parada'!D:D,Disponibilidade!E6),"-") -> 0 | W6: =IFERROR(SUMIFS('Motivos De Parada'!K:K,'Motivos De Parada'!G:G,Disponibilidade!G6,'Motivos De Parada'!H:H,Disponibilidade!H6,'Motivos De Parada'!O:O,Disponibilidade!O6,'Motivos De Parada'!E:E,Disponibilidade!C6,'Motivos De Parada'!D:D,Disponibilidade!E6),"-") -> 0 | X6: =IFERROR(AVERAGE(V6,W6),"-") -> 0 | Y6: =IFERROR(SUMIFS('Motivos De Parada'!K:K,'Motivos De Parada'!G:G,Disponibilidade!G6,'Motivos De Parada'!H:H,Disponibilidade!H6,'Motivos De Parada'!E:E,Disponibilidade!C6,'Motivos De Parada'!D:D,Disponibilidade!E6),"-") -> 0 | Z6: =IFERROR(IF(Y6=0,"OK",IF(OR(Y6>12,Y6<12),"VERIFICAR","OK")),"-") -> OK | AA6: =IFERROR(W6+V6,"-") -> 0 | AB6: =IFERROR(SUMIFS('Motivos De Parada'!K:K,'Motivos De Parada'!G:G,Disponibilidade!G6,'Motivos De Parada'!H:H,Disponibilidade!H6,'Motivos De Parada'!E:E,Disponibilidade!C6,'Motivos De Parada'!D:D,Disponibilidade!E6,'Motivos De Parada'!M:M,"REFEIÇÃO"),"-") -> 0 | AC6: =IFERROR(Y6-AA6-AB6,"-") -> 0 | AD6: =IFERROR(IF(AC6<0,"VERIFICAR","OK"),"-") -> OK | AE6: {=IFERROR(SUM(SUMIFS('Motivos De Parada'!K:K,'Motivos De Parada'!G:G,Disponibilidade!G6,'Motivos De Parada'!H:H,Disponibilidade!H6,'Motivos De Parada'!E:E,Disponibilidade!C6,'Motivos De Parada'!D:D,Disponibilidade!E6,'Motivos De Parada'!O:O,{"DISPONIBILIDADE MECÂNICA";"DISPONIBILIDADE OPERACIONAL"},'Motivos De Parada'!P:P,"NÃO")),"-")} -> 0 | AF6: {=IFERROR(SUM(SUMIFS('Motivos De Parada'!K:K,'Motivos De Parada'!G:G,Disponibilidade!G6,'Motivos De Parada'!H:H,Disponibilidade!H6,'Motivos De Parada'!E:E,Disponibilidade!C6,'Motivos De Parada'!D:D,Disponibilidade!E6,'Motivos De Parada'!O:O,{"DISPONIBILIDADE MECÂNICA";"DISPONIBILIDADE OPERACIONAL"},'Motivos De Parada'!P:P,"SIM")),"-")} -> 0 | AG6: =IFERROR(IF((AC6-AF6)<0,0,(AC6-AF6)),"-") -> 0 | AH6: =IFERROR(IF(AND(AG6=0,AC6=0),"OK",IF(AG6=AC6,"VERIFICAR","OK")),"-") -> OK | AI6: {=IFERROR(INDEX('Metas DM & DO'!$A:$AAD,MATCH(Disponibilidade!$G6,'Metas DM & DO'!$A:$A,0),MATCH(Disponibilidade!$U6,'Metas DM & DO'!$1:$1,0)+2),"-")} -> - | AJ6: {=IFERROR(INDEX('Metas DM & DO'!$A:$AAD,MATCH(Disponibilidade!$G6,'Metas DM & DO'!$A:$A,0),MATCH(Disponibilidade!$U6,'Metas DM & DO'!$1:$1,0)+3),"-")} -> - | AK6: {=IFERROR(INDEX('Metas DM & DO'!$A:$AAD,MATCH(Disponibilidade!$G6,'Metas DM & DO'!$A:$A,0),MATCH(Disponibilidade!$U6,'Metas DM & DO'!$1:$1,0)+4),"-")} -> - | AL6: =IFERROR(IF(X6<=AJ6,"EXCELENTE", IF(X6<=AI6,"BOM", IF(X6<=AK6,"ATENÇÃO",IF(X6>AK6,"CRÍTICO","-")))),"-") -> EXCELENTE
A7: =IFERROR(YEAR(C7),"-") -> 2026 | B7: =IFERROR(DATE(YEAR(C7),MONTH(C7),MONTH(C7)),"-") -> 46023 | C7: 46023 | D7: SKIDDER1 | E7: TURNO 2 | F7: {=IFERROR(INDEX('Motivos De Parada'!C:C,MATCH(1,('Motivos De Parada'!E:E=Disponibilidade!C7)*('Motivos De Parada'!G:G=Disponibilidade!G7)*('Motivos De Parada'!D:D=Disponibilidade!E7),0)),"-")} -> - | G7: =IFERROR(VLOOKUP(D7,Cadastros!A:B,2,FALSE),"-") -> SKIDDER 1 | H7: =IFERROR(VLOOKUP(G7,Cadastros!B:D,3,FALSE),"-") -> ARRASTE | I7: DISPONIBILIDADE MECÂNICA | J7: =IFERROR(MAX(0,1 - (SUMIFS('Motivos De Parada'!K:K,'Motivos De Parada'!G:G,Disponibilidade!G7,'Motivos De Parada'!H:H,Disponibilidade!H7,'Motivos De Parada'!O:O,Disponibilidade!I7,'Motivos De Parada'!E:E,Disponibilidade!C7,'Motivos De Parada'!D:D,Disponibilidade!E7) / 24)),"-") -> 1 | K7: {=IFERROR(INDEX('Metas DM & DO'!$A:$AAD,MATCH(Disponibilidade!$G7,'Metas DM & DO'!$A:$A,0),MATCH(Disponibilidade!$I7,'Metas DM & DO'!$1:$1,0)+1),"-")} -> - | L7: {=IFERROR(INDEX('Metas DM & DO'!$A:$AAD,MATCH(Disponibilidade!$G7,'Metas DM & DO'!$A:$A,0),MATCH(Disponibilidade!$I7,'Metas DM & DO'!$1:$1,0)+2),"-")} -> - | M7: {=IFERROR(INDEX('Metas DM & DO'!$A:$AAD,MATCH(Disponibilidade!$G7,'Metas DM & DO'!$A:$A,0),MATCH(Disponibilidade!$I7,'Metas DM & DO'!$1:$1,0)+3),"-")} -> - | N7: =IFERROR(IF(J7<K7,"RUIM",IF(AND(J7>=K7,J7<L7),"MEDIA",IF(AND(J7>=L7,J7<M7),"BOA","-"))),"-") -> RUIM | O7: DISPONIBILIDADE OPERACIONAL | P7: =IFERROR(MAX(0,1 - (SUMIFS('Motivos De Parada'!K:K,'Motivos De Parada'!G:G,Disponibilidade!G7,'Motivos De Parada'!H:H,Disponibilidade!H7,'Motivos De Parada'!O:O,Disponibilidade!O7,'Motivos De Parada'!E:E,Disponibilidade!C7,'Motivos De Parada'!D:D,Disponibilidade!E7) / 24)),"-") -> 1 | Q7: {=IFERROR(INDEX('Metas DM & DO'!$A:$AAD,MATCH(Disponibilidade!$G7,'Metas DM & DO'!$A:$A,0),MATCH(Disponibilidade!$O7,'Metas DM & DO'!$1:$1,0)+1),"-")} -> - | R7: {=IFERROR(INDEX('Metas DM & DO'!$A:$AAD,MATCH(Disponibilidade!$G7,'Metas DM & DO'!$A:$A,0),MATCH(Disponibilidade!$O7,'Metas DM & DO'!$1:$1,0)+2),"-")} -> - | S7: {=IFERROR(INDEX('Metas DM & DO'!$A:$AAD,MATCH(Disponibilidade!$G7,'Metas DM & DO'!$A:$A,0),MATCH(Disponibilidade!$O7,'Metas DM & DO'!$1:$1,0)+3),"-")} -> - | T7: =IFERROR(IF(P7<Q7,"RUIM",IF(AND(P7>=Q7,P7<R7),"MEDIA",IF(AND(P7>=R7,P7<S7),"BOA","-"))),"-") -> RUIM | U7: HORAS | V7: =IFERROR(SUMIFS('Motivos De Parada'!K:K,'Motivos De Parada'!G:G,Disponibilidade!G7,'Motivos De Parada'!H:H,Disponibilidade!H7,'Motivos De Parada'!O:O,Disponibilidade!I7,'Motivos De Parada'!E:E,Disponibilidade!C7,'Motivos De Parada'!D:D,Disponibilidade!E7),"-") -> 0 | W7: =IFERROR(SUMIFS('Motivos De Parada'!K:K,'Motivos De Parada'!G:G,Disponibilidade!G7,'Motivos De Parada'!H:H,Disponibilidade!H7,'Motivos De Parada'!O:O,Disponibilidade!O7,'Motivos De Parada'!E:E,Disponibilidade!C7,'Motivos De Parada'!D:D,Disponibilidade!E7),"-") -> 0 | X7: =IFERROR(AVERAGE(V7,W7),"-") -> 0 | Y7: =IFERROR(SUMIFS('Motivos De Parada'!K:K,'Motivos De Parada'!G:G,Disponibilidade!G7,'Motivos De Parada'!H:H,Disponibilidade!H7,'Motivos De Parada'!E:E,Disponibilidade!C7,'Motivos De Parada'!D:D,Disponibilidade!E7),"-") -> 0 | Z7: =IFERROR(IF(Y7=0,"OK",IF(OR(Y7>12,Y7<12),"VERIFICAR","OK")),"-") -> OK | AA7: =IFERROR(W7+V7,"-") -> 0 | AB7: =IFERROR(SUMIFS('Motivos De Parada'!K:K,'Motivos De Parada'!G:G,Disponibilidade!G7,'Motivos De Parada'!H:H,Disponibilidade!H7,'Motivos De Parada'!E:E,Disponibilidade!C7,'Motivos De Parada'!D:D,Disponibilidade!E7,'Motivos De Parada'!M:M,"REFEIÇÃO"),"-") -> 0 | AC7: =IFERROR(Y7-AA7-AB7,"-") -> 0 | AD7: =IFERROR(IF(AC7<0,"VERIFICAR","OK"),"-") -> OK | AE7: {=IFERROR(SUM(SUMIFS('Motivos De Parada'!K:K,'Motivos De Parada'!G:G,Disponibilidade!G7,'Motivos De Parada'!H:H,Disponibilidade!H7,'Motivos De Parada'!E:E,Disponibilidade!C7,'Motivos De Parada'!D:D,Disponibilidade!E7,'Motivos De Parada'!O:O,{"DISPONIBILIDADE MECÂNICA";"DISPONIBILIDADE OPERACIONAL"},'Motivos De Parada'!P:P,"NÃO")),"-")} -> 0 | AF7: {=IFERROR(SUM(SUMIFS('Motivos De Parada'!K:K,'Motivos De Parada'!G:G,Disponibilidade!G7,'Motivos De Parada'!H:H,Disponibilidade!H7,'Motivos De Parada'!E:E,Disponibilidade!C7,'Motivos De Parada'!D:D,Disponibilidade!E7,'Motivos De Parada'!O:O,{"DISPONIBILIDADE MECÂNICA";"DISPONIBILIDADE OPERACIONAL"},'Motivos De Parada'!P:P,"SIM")),"-")} -> 0 | AG7: =IFERROR(IF((AC7-AF7)<0,0,(AC7-AF7)),"-") -> 0 | AH7: =IFERROR(IF(AND(AG7=0,AC7=0),"OK",IF(AG7=AC7,"VERIFICAR","OK")),"-") -> OK | AI7: {=IFERROR(INDEX('Metas DM & DO'!$A:$AAD,MATCH(Disponibilidade!$G7,'Metas DM & DO'!$A:$A,0),MATCH(Disponibilidade!$U7,'Metas DM & DO'!$1:$1,0)+2),"-")} -> - | AJ7: {=IFERROR(INDEX('Metas DM & DO'!$A:$AAD,MATCH(Disponibilidade!$G7,'Metas DM & DO'!$A:$A,0),MATCH(Disponibilidade!$U7,'Metas DM & DO'!$1:$1,0)+3),"-")} -> - | AK7: {=IFERROR(INDEX('Metas DM & DO'!$A:$AAD,MATCH(Disponibilidade!$G7,'Metas DM & DO'!$A:$A,0),MATCH(Disponibilidade!$U7,'Metas DM & DO'!$1:$1,0)+4),"-")} -> - | AL7: =IFERROR(IF(X7<=AJ7,"EXCELENTE", IF(X7<=AI7,"BOM", IF(X7<=AK7,"ATENÇÃO",IF(X7>AK7,"CRÍTICO","-")))),"-") -> EXCELENTE
A8: =IFERROR(YEAR(C8),"-") -> 2026 | B8: =IFERROR(DATE(YEAR(C8),MONTH(C8),MONTH(C8)),"-") -> 46023 | C8: 46023 | D8: SKIDDER2 | E8: TURNO 1 | F8: {=IFERROR(INDEX('Motivos De Parada'!C:C,MATCH(1,('Motivos De Parada'!E:E=Disponibilidade!C8)*('Motivos De Parada'!G:G=Disponibilidade!G8)*('Motivos De Parada'!D:D=Disponibilidade!E8),0)),"-")} -> - | G8: =IFERROR(VLOOKUP(D8,Cadastros!A:B,2,FALSE),"-") -> SKIDDER 2 | H8: =IFERROR(VLOOKUP(G8,Cadastros!B:D,3,FALSE),"-") -> ARRASTE | I8: DISPONIBILIDADE MECÂNICA | J8: =IFERROR(MAX(0,1 - (SUMIFS('Motivos De Parada'!K:K,'Motivos De Parada'!G:G,Disponibilidade!G8,'Motivos De Parada'!H:H,Disponibilidade!H8,'Motivos De Parada'!O:O,Disponibilidade!I8,'Motivos De Parada'!E:E,Disponibilidade!C8,'Motivos De Parada'!D:D,Disponibilidade!E8) / 24)),"-") -> 1 | K8: {=IFERROR(INDEX('Metas DM & DO'!$A:$AAD,MATCH(Disponibilidade!$G8,'Metas DM & DO'!$A:$A,0),MATCH(Disponibilidade!$I8,'Metas DM & DO'!$1:$1,0)+1),"-")} -> 0.5 | L8: {=IFERROR(INDEX('Metas DM & DO'!$A:$AAD,MATCH(Disponibilidade!$G8,'Metas DM & DO'!$A:$A,0),MATCH(Disponibilidade!$I8,'Metas DM & DO'!$1:$1,0)+2),"-")} -> 0.5 | M8: {=IFERROR(INDEX('Metas DM & DO'!$A:$AAD,MATCH(Disponibilidade!$G8,'Metas DM & DO'!$A:$A,0),MATCH(Disponibilidade!$I8,'Metas DM & DO'!$1:$1,0)+3),"-")} -> 0.5 | N8: =IFERROR(IF(J8<K8,"RUIM",IF(AND(J8>=K8,J8<L8),"MEDIA",IF(AND(J8>=L8,J8<M8),"BOA","-"))),"-") -> - | O8: DISPONIBILIDADE OPERACIONAL | P8: =IFERROR(MAX(0,1 - (SUMIFS('Motivos De Parada'!K:K,'Motivos De Parada'!G:G,Disponibilidade!G8,'Motivos De Parada'!H:H,Disponibilidade!H8,'Motivos De Parada'!O:O,Disponibilidade!O8,'Motivos De Parada'!E:E,Disponibilidade!C8,'Motivos De Parada'!D:D,Disponibilidade!E8) / 24)),"-") -> 1 | Q8: {=IFERROR(INDEX('Metas DM & DO'!$A:$AAD,MATCH(Disponibilidade!$G8,'Metas DM & DO'!$A:$A,0),MATCH(Disponibilidade!$O8,'Metas DM & DO'!$1:$1,0)+1),"-")} -> 0.5 | R8: {=IFERROR(INDEX('Metas DM & DO'!$A:$AAD,MATCH(Disponibilidade!$G8,'Metas DM & DO'!$A:$A,0),MATCH(Disponibilidade!$O8,'Metas DM & DO'!$1:$1,0)+2),"-")} -> 0.5 | S8: {=IFERROR(INDEX('Metas DM & DO'!$A:$AAD,MATCH(Disponibilidade!$G8,'Metas DM & DO'!$A:$A,0),MATCH(Disponibilidade!$O8,'Metas DM & DO'!$1:$1,0)+3),"-")} -> 0.5 | T8: =IFERROR(IF(P8<Q8,"RUIM",IF(AND(P8>=Q8,P8<R8),"MEDIA",IF(AND(P8>=R8,P8<S8),"BOA","-"))),"-") -> - | U8: HORAS | V8: =IFERROR(SUMIFS('Motivos De Parada'!K:K,'Motivos De Parada'!G:G,Disponibilidade!G8,'Motivos De Parada'!H:H,Disponibilidade!H8,'Motivos De Parada'!O:O,Disponibilidade!I8,'Motivos De Parada'!E:E,Disponibilidade!C8,'Motivos De Parada'!D:D,Disponibilidade!E8),"-") -> 0 | W8: =IFERROR(SUMIFS('Motivos De Parada'!K:K,'Motivos De Parada'!G:G,Disponibilidade!G8,'Motivos De Parada'!H:H,Disponibilidade!H8,'Motivos De Parada'!O:O,Disponibilidade!O8,'Motivos De Parada'!E:E,Disponibilidade!C8,'Motivos De Parada'!D:D,Disponibilidade!E8),"-") -> 0 | X8: =IFERROR(AVERAGE(V8,W8),"-") -> 0 | Y8: =IFERROR(SUMIFS('Motivos De Parada'!K:K,'Motivos De Parada'!G:G,Disponibilidade!G8,'Motivos De Parada'!H:H,Disponibilidade!H8,'Motivos De Parada'!E:E,Disponibilidade!C8,'Motivos De Parada'!D:D,Disponibilidade!E8),"-") -> 0 | Z8: =IFERROR(IF(Y8=0,"OK",IF(OR(Y8>12,Y8<12),"VERIFICAR","OK")),"-") -> OK | AA8: =IFERROR(W8+V8,"-") -> 0 | AB8: =IFERROR(SUMIFS('Motivos De Parada'!K:K,'Motivos De Parada'!G:G,Disponibilidade!G8,'Motivos De Parada'!H:H,Disponibilidade!H8,'Motivos De Parada'!E:E,Disponibilidade!C8,'Motivos De Parada'!D:D,Disponibilidade!E8,'Motivos De Parada'!M:M,"REFEIÇÃO"),"-") -> 0 | AC8: =IFERROR(Y8-AA8-AB8,"-") -> 0 | AD8: =IFERROR(IF(AC8<0,"VERIFICAR","OK"),"-") -> OK | AE8: {=IFERROR(SUM(SUMIFS('Motivos De Parada'!K:K,'Motivos De Parada'!G:G,Disponibilidade!G8,'Motivos De Parada'!H:H,Disponibilidade!H8,'Motivos De Parada'!E:E,Disponibilidade!C8,'Motivos De Parada'!D:D,Disponibilidade!E8,'Motivos De Parada'!O:O,{"DISPONIBILIDADE MECÂNICA";"DISPONIBILIDADE OPERACIONAL"},'Motivos De Parada'!P:P,"NÃO")),"-")} -> 0 | AF8: {=IFERROR(SUM(SUMIFS('Motivos De Parada'!K:K,'Motivos De Parada'!G:G,Disponibilidade!G8,'Motivos De Parada'!H:H,Disponibilidade!H8,'Motivos De Parada'!E:E,Disponibilidade!C8,'Motivos De Parada'!D:D,Disponibilidade!E8,'Motivos De Parada'!O:O,{"DISPONIBILIDADE MECÂNICA";"DISPONIBILIDADE OPERACIONAL"},'Motivos De Parada'!P:P,"SIM")),"-")} -> 0 | AG8: =IFERROR(IF((AC8-AF8)<0,0,(AC8-AF8)),"-") -> 0 | AH8: =IFERROR(IF(AND(AG8=0,AC8=0),"OK",IF(AG8=AC8,"VERIFICAR","OK")),"-") -> OK | AI8: {=IFERROR(INDEX('Metas DM & DO'!$A:$AAD,MATCH(Disponibilidade!$G8,'Metas DM & DO'!$A:$A,0),MATCH(Disponibilidade!$U8,'Metas DM & DO'!$1:$1,0)+2),"-")} -> 12 | AJ8: {=IFERROR(INDEX('Metas DM & DO'!$A:$AAD,MATCH(Disponibilidade!$G8,'Metas DM & DO'!$A:$A,0),MATCH(Disponibilidade!$U8,'Metas DM & DO'!$1:$1,0)+3),"-")} -> 12 | AK8: {=IFERROR(INDEX('Metas DM & DO'!$A:$AAD,MATCH(Disponibilidade!$G8,'Metas DM & DO'!$A:$A,0),MATCH(Disponibilidade!$U8,'Metas DM & DO'!$1:$1,0)+4),"-")} -> 12 | AL8: =IFERROR(IF(X8<=AJ8,"EXCELENTE", IF(X8<=AI8,"BOM", IF(X8<=AK8,"ATENÇÃO",IF(X8>AK8,"CRÍTICO","-")))),"-") -> EXCELENTE
A9: =IFERROR(YEAR(C9),"-") -> 2026 | B9: =IFERROR(DATE(YEAR(C9),MONTH(C9),MONTH(C9)),"-") -> 46023 | C9: 46023 | D9: SKIDDER2 | E9: TURNO 2 | F9: {=IFERROR(INDEX('Motivos De Parada'!C:C,MATCH(1,('Motivos De Parada'!E:E=Disponibilidade!C9)*('Motivos De Parada'!G:G=Disponibilidade!G9)*('Motivos De Parada'!D:D=Disponibilidade!E9),0)),"-")} -> - | G9: =IFERROR(VLOOKUP(D9,Cadastros!A:B,2,FALSE),"-") -> SKIDDER 2 | H9: =IFERROR(VLOOKUP(G9,Cadastros!B:D,3,FALSE),"-") -> ARRASTE | I9: DISPONIBILIDADE MECÂNICA | J9: =IFERROR(MAX(0,1 - (SUMIFS('Motivos De Parada'!K:K,'Motivos De Parada'!G:G,Disponibilidade!G9,'Motivos De Parada'!H:H,Disponibilidade!H9,'Motivos De Parada'!O:O,Disponibilidade!I9,'Motivos De Parada'!E:E,Disponibilidade!C9,'Motivos De Parada'!D:D,Disponibilidade!E9) / 24)),"-") -> 1 | K9: {=IFERROR(INDEX('Metas DM & DO'!$A:$AAD,MATCH(Disponibilidade!$G9,'Metas DM & DO'!$A:$A,0),MATCH(Disponibilidade!$I9,'Metas DM & DO'!$1:$1,0)+1),"-")} -> 0.5 | L9: {=IFERROR(INDEX('Metas DM & DO'!$A:$AAD,MATCH(Disponibilidade!$G9,'Metas DM & DO'!$A:$A,0),MATCH(Disponibilidade!$I9,'Metas DM & DO'!$1:$1,0)+2),"-")} -> 0.5 | M9: {=IFERROR(INDEX('Metas DM & DO'!$A:$AAD,MATCH(Disponibilidade!$G9,'Metas DM & DO'!$A:$A,0),MATCH(Disponibilidade!$I9,'Metas DM & DO'!$1:$1,0)+3),"-")} -> 0.5 | N9: =IFERROR(IF(J9<K9,"RUIM",IF(AND(J9>=K9,J9<L9),"MEDIA",IF(AND(J9>=L9,J9<M9),"BOA","-"))),"-") -> - | O9: DISPONIBILIDADE OPERACIONAL | P9: =IFERROR(MAX(0,1 - (SUMIFS('Motivos De Parada'!K:K,'Motivos De Parada'!G:G,Disponibilidade!G9,'Motivos De Parada'!H:H,Disponibilidade!H9,'Motivos De Parada'!O:O,Disponibilidade!O9,'Motivos De Parada'!E:E,Disponibilidade!C9,'Motivos De Parada'!D:D,Disponibilidade!E9) / 24)),"-") -> 1 | Q9: {=IFERROR(INDEX('Metas DM & DO'!$A:$AAD,MATCH(Disponibilidade!$G9,'Metas DM & DO'!$A:$A,0),MATCH(Disponibilidade!$O9,'Metas DM & DO'!$1:$1,0)+1),"-")} -> 0.5 | R9: {=IFERROR(INDEX('Metas DM & DO'!$A:$AAD,MATCH(Disponibilidade!$G9,'Metas DM & DO'!$A:$A,0),MATCH(Disponibilidade!$O9,'Metas DM & DO'!$1:$1,0)+2),"-")} -> 0.5 | S9: {=IFERROR(INDEX('Metas DM & DO'!$A:$AAD,MATCH(Disponibilidade!$G9,'Metas DM & DO'!$A:$A,0),MATCH(Disponibilidade!$O9,'Metas DM & DO'!$1:$1,0)+3),"-")} -> 0.5 | T9: =IFERROR(IF(P9<Q9,"RUIM",IF(AND(P9>=Q9,P9<R9),"MEDIA",IF(AND(P9>=R9,P9<S9),"BOA","-"))),"-") -> - | U9: HORAS | V9: =IFERROR(SUMIFS('Motivos De Parada'!K:K,'Motivos De Parada'!G:G,Disponibilidade!G9,'Motivos De Parada'!H:H,Disponibilidade!H9,'Motivos De Parada'!O:O,Disponibilidade!I9,'Motivos De Parada'!E:E,Disponibilidade!C9,'Motivos De Parada'!D:D,Disponibilidade!E9),"-") -> 0 | W9: =IFERROR(SUMIFS('Motivos De Parada'!K:K,'Motivos De Parada'!G:G,Disponibilidade!G9,'Motivos De Parada'!H:H,Disponibilidade!H9,'Motivos De Parada'!O:O,Disponibilidade!O9,'Motivos De Parada'!E:E,Disponibilidade!C9,'Motivos De Parada'!D:D,Disponibilidade!E9),"-") -> 0 | X9: =IFERROR(AVERAGE(V9,W9),"-") -> 0 | Y9: =IFERROR(SUMIFS('Motivos De Parada'!K:K,'Motivos De Parada'!G:G,Disponibilidade!G9,'Motivos De Parada'!H:H,Disponibilidade!H9,'Motivos De Parada'!E:E,Disponibilidade!C9,'Motivos De Parada'!D:D,Disponibilidade!E9),"-") -> 0 | Z9: =IFERROR(IF(Y9=0,"OK",IF(OR(Y9>12,Y9<12),"VERIFICAR","OK")),"-") -> OK | AA9: =IFERROR(W9+V9,"-") -> 0 | AB9: =IFERROR(SUMIFS('Motivos De Parada'!K:K,'Motivos De Parada'!G:G,Disponibilidade!G9,'Motivos De Parada'!H:H,Disponibilidade!H9,'Motivos De Parada'!E:E,Disponibilidade!C9,'Motivos De Parada'!D:D,Disponibilidade!E9,'Motivos De Parada'!M:M,"REFEIÇÃO"),"-") -> 0 | AC9: =IFERROR(Y9-AA9-AB9,"-") -> 0 | AD9: =IFERROR(IF(AC9<0,"VERIFICAR","OK"),"-") -> OK | AE9: {=IFERROR(SUM(SUMIFS('Motivos De Parada'!K:K,'Motivos De Parada'!G:G,Disponibilidade!G9,'Motivos De Parada'!H:H,Disponibilidade!H9,'Motivos De Parada'!E:E,Disponibilidade!C9,'Motivos De Parada'!D:D,Disponibilidade!E9,'Motivos De Parada'!O:O,{"DISPONIBILIDADE MECÂNICA";"DISPONIBILIDADE OPERACIONAL"},'Motivos De Parada'!P:P,"NÃO")),"-")} -> 0 | AF9: {=IFERROR(SUM(SUMIFS('Motivos De Parada'!K:K,'Motivos De Parada'!G:G,Disponibilidade!G9,'Motivos De Parada'!H:H,Disponibilidade!H9,'Motivos De Parada'!E:E,Disponibilidade!C9,'Motivos De Parada'!D:D,Disponibilidade!E9,'Motivos De Parada'!O:O,{"DISPONIBILIDADE MECÂNICA";"DISPONIBILIDADE OPERACIONAL"},'Motivos De Parada'!P:P,"SIM")),"-")} -> 0 | AG9: =IFERROR(IF((AC9-AF9)<0,0,(AC9-AF9)),"-") -> 0 | AH9: =IFERROR(IF(AND(AG9=0,AC9=0),"OK",IF(AG9=AC9,"VERIFICAR","OK")),"-") -> OK | AI9: {=IFERROR(INDEX('Metas DM & DO'!$A:$AAD,MATCH(Disponibilidade!$G9,'Metas DM & DO'!$A:$A,0),MATCH(Disponibilidade!$U9,'Metas DM & DO'!$1:$1,0)+2),"-")} -> 12 | AJ9: {=IFERROR(INDEX('Metas DM & DO'!$A:$AAD,MATCH(Disponibilidade!$G9,'Metas DM & DO'!$A:$A,0),MATCH(Disponibilidade!$U9,'Metas DM & DO'!$1:$1,0)+3),"-")} -> 12 | AK9: {=IFERROR(INDEX('Metas DM & DO'!$A:$AAD,MATCH(Disponibilidade!$G9,'Metas DM & DO'!$A:$A,0),MATCH(Disponibilidade!$U9,'Metas DM & DO'!$1:$1,0)+4),"-")} -> 12 | AL9: =IFERROR(IF(X9<=AJ9,"EXCELENTE", IF(X9<=AI9,"BOM", IF(X9<=AK9,"ATENÇÃO",IF(X9>AK9,"CRÍTICO","-")))),"-") -> EXCELENTE
