Workbook

Sheet Diesel
A1: ANO | B1: MÊS | C1: DATA | D1: EQUIPAMENTO DIGITADO | E1: EQUIPAMENTO | F1: TIPO DE EQUIPAMENTO | G1: HORÍMETRO ANTERIOR | H1: HORÍMETRO ABASTECIMENTO | I1: CONSUMO | J1: HORAS RODADAS | K1: MÉDIA | L1: STATUS MÉDIA | M1: LITROS POR HORA | N1: META BASE | O1: META BASE POR HORA | P1: META DESAFIO | Q1: META DESAFIO POR HORA | R1: TETO META | S1: TETO META POR HORA | T1: STATUS META | U1: COMBOIO | V1: ENTRADA | W1: VALOR ENTRADA | X1: SALDO ANTERIOR | Y1: ENCERRANTE ANTERIOR | Z1: ENCERRANTE ABASTECIMENTO | AA1: SALDO | AB1: OBS
A2: =IFERROR(YEAR(C2),"-") -> 2026 | B2: =IFERROR(DATE(YEAR(C2),MONTH(C2),MONTH(C2)),"-") -> 46023 | C2: 46023 | D2: FELLER1 | E2: =IFERROR(VLOOKUP(D2,Cadastros!A:B,2,FALSE),"-") -> FELLER BUNCHER 1 | F2: =IFERROR(VLOOKUP(E2,Cadastros!B:D,3,FALSE),"-") -> CORTE | G2: 1000 | H2: 1012 | I2: =IFERROR(IF(Z2-Y2<0,"-",Z2-Y2),"-") -> 100 | J2: =IFERROR(IF(H2-G2<0,"-",H2-G2),"-") -> 12 | K2: =IFERROR(IF(C2>=TODAY(),"",SUMIFS(I:I,E:E,E2,C:C,C2,B:B,B2)/SUMIFS(J:J,E:E,E2,C:C,C2,B:B,B2)),0) -> 8.3333333 | L2: =IFERROR(IF(K2<=S2,"EXCELENTE",IF(K2<=Q2,"BOM",IF(K2<=O2,"ATENÇÃO",IF(K2>O2,"CRÍTICO","-")))),"-") -> EXCELENTE | M2: =IFERROR(I2/J2,"-") -> 8.3333333 | N2: =IFERROR(INDEX('Metas Diesel'!N:N,MATCH(Diesel!E2,'Metas Diesel'!A:A,0)),"-") -> 235.66667 | O2: =IFERROR(N2/J2,"-") -> 19.638889 | P2: =IFERROR(INDEX('Metas Diesel'!O:O,MATCH(Diesel!E2,'Metas Diesel'!A:A,0)),"-") -> 226.5449 | Q2: =IFERROR(P2/J2,"-") -> 18.878742 | R2: =IFERROR(INDEX('Metas Diesel'!P:P,MATCH(Diesel!E2,'Metas Diesel'!A:A,0)),"-") -> 100 | S2: =IFERROR(R2/J2,"-") -> 8.3333333 | T2: =IFERROR(IF(M2<=S2,"EXCELENTE",IF(M2<=Q2,"BOM",IF(M2<=O2,"ATENÇÃO",IF(M2>O2,"CRÍTICO","-")))),"-") -> EXCELENTE | U2: C01 | X2: 5000 | Y2: 0 | Z2: 100 | AA2: =IFERROR(X2-I2,"-") -> 4900
A3: =IFERROR(YEAR(C3),"-") -> 2026 | B3: =IFERROR(DATE(YEAR(C3),MONTH(C3),MONTH(C3)),"-") -> 46023 | C3: 46023 | D3: FELLER2 | E3: =IFERROR(VLOOKUP(D3,Cadastros!A:B,2,FALSE),"-") -> FELLER BUNCHER 2 | F3: =IFERROR(VLOOKUP(E3,Cadastros!B:D,3,FALSE),"-") -> CORTE | G3: 2000 | H3: 2008 | I3: =IFERROR(IF(Z3-Y3<0,"-",Z3-Y3),"-") -> 150 | J3: =IFERROR(IF(H3-G3<0,"-",H3-G3),"-") -> 8 | K3: =IFERROR(IF(C3>=TODAY(),"",SUMIFS(I:I,E:E,E3,C:C,C3,B:B,B3)/SUMIFS(J:J,E:E,E3,C:C,C3,B:B,B3)),0) -> 18.75 | L3: =IFERROR(IF(K3<=S3,"EXCELENTE",IF(K3<=Q3,"BOM",IF(K3<=O3,"ATENÇÃO",IF(K3>O3,"CRÍTICO","-")))),"-") -> EXCELENTE | M3: =IFERROR(I3/J3,"-") -> 18.75 | N3: =IFERROR(INDEX('Metas Diesel'!N:N,MATCH(Diesel!E3,'Metas Diesel'!A:A,0)),"-") -> 215.16667 | O3: =IFERROR(N3/J3,"-") -> 26.895833 | P3: =IFERROR(INDEX('Metas Diesel'!O:O,MATCH(Diesel!E3,'Metas Diesel'!A:A,0)),"-") -> 198.75796 | Q3: =IFERROR(P3/J3,"-") -> 24.844745 | R3: =IFERROR(INDEX('Metas Diesel'!P:P,MATCH(Diesel!E3,'Metas Diesel'!A:A,0)),"-") -> 150 | S3: =IFERROR(R3/J3,"-") -> 18.75 | T3: =IFERROR(IF(M3<=S3,"EXCELENTE",IF(M3<=Q3,"BOM",IF(M3<=O3,"ATENÇÃO",IF(M3>O3,"CRÍTICO","-")))),"-") -> EXCELENTE | U3: C01 | X3: {=IFERROR(W3+IF(C3<C2,LARGE(LOOKUP(U3,$U$1:$U2,$AA$1:$AA2),1),LOOKUP(2,1/($U$1:$U2=U3),($AA$1:$AA2))),"-")} -> 4900 | Y3: {=IFERROR(IF(C3<C2,LARGE(LOOKUP(U3,$U$1:$U2,$Z$1:$Z2),1),LOOKUP(2,1/($U$1:$U2=U3),($Z$1:$Z2))),"-")} -> 100 | Z3: 250 | AA3: =IFERROR(X3-I3,"-") -> 4750
A4: =IFERROR(YEAR(C4),"-") -> 2026 | B4: =IFERROR(DATE(YEAR(C4),MONTH(C4),MONTH(C4)),"-") -> 46023 | C4: 46023 | D4: SKIDDER1 | E4: =IFERROR(VLOOKUP(D4,Cadastros!A:B,2,FALSE),"-") -> SKIDDER 1 | F4: =IFERROR(VLOOKUP(E4,Cadastros!B:D,3,FALSE),"-") -> ARRASTE | G4: 1200 | H4: 1215 | I4: =IFERROR(IF(Z4-Y4<0,"-",Z4-Y4),"-") -> 370 | J4: =IFERROR(IF(H4-G4<0,"-",H4-G4),"-") -> 15 | K4: =IFERROR(IF(C4>=TODAY(),"",SUMIFS(I:I,E:E,E4,C:C,C4,B:B,B4)/SUMIFS(J:J,E:E,E4,C:C,C4,B:B,B4)),0) -> 24.666667 | L4: =IFERROR(IF(K4<=S4,"EXCELENTE",IF(K4<=Q4,"BOM",IF(K4<=O4,"ATENÇÃO",IF(K4>O4,"CRÍTICO","-")))),"-") -> BOM | M4: =IFERROR(I4/J4,"-") -> 24.666667 | N4: =IFERROR(INDEX('Metas Diesel'!N:N,MATCH(Diesel!E4,'Metas Diesel'!A:A,0)),"-") -> 426.33333 | O4: =IFERROR(N4/J4,"-") -> 28.422222 | P4: =IFERROR(INDEX('Metas Diesel'!O:O,MATCH(Diesel!E4,'Metas Diesel'!A:A,0)),"-") -> 377.8882 | Q4: =IFERROR(P4/J4,"-") -> 25.192547 | R4: =IFERROR(INDEX('Metas Diesel'!P:P,MATCH(Diesel!E4,'Metas Diesel'!A:A,0)),"-") -> 300 | S4: =IFERROR(R4/J4,"-") -> 20 | T4: =IFERROR(IF(M4<=S4,"EXCELENTE",IF(M4<=Q4,"BOM",IF(M4<=O4,"ATENÇÃO",IF(M4>O4,"CRÍTICO","-")))),"-") -> BOM | U4: C01 | X4: {=IFERROR(W4+IF(C4<C3,LARGE(LOOKUP(U4,$U$1:$U3,$AA$1:$AA3),1),LOOKUP(2,1/($U$1:$U3=U4),($AA$1:$AA3))),"-")} -> 4750 | Y4: {=IFERROR(IF(C4<C3,LARGE(LOOKUP(U4,$U$1:$U3,$Z$1:$Z3),1),LOOKUP(2,1/($U$1:$U3=U4),($Z$1:$Z3))),"-")} -> 250 | Z4: 620 | AA4: =IFERROR(X4-I4,"-") -> 4380
A5: =IFERROR(YEAR(C5),"-") -> 2026 | B5: =IFERROR(DATE(YEAR(C5),MONTH(C5),MONTH(C5)),"-") -> 46023 | C5: 46023 | D5: SKIDDER2 | E5: =IFERROR(VLOOKUP(D5,Cadastros!A:B,2,FALSE),"-") -> SKIDDER 2 | F5: =IFERROR(VLOOKUP(E5,Cadastros!B:D,3,FALSE),"-") -> ARRASTE | G5: 2100 | H5: 2106 | I5: =IFERROR(IF(Z5-Y5<0,"-",Z5-Y5),"-") -> 330 | J5: =IFERROR(IF(H5-G5<0,"-",H5-G5),"-") -> 6 | K5: =IFERROR(IF(C5>=TODAY(),"",SUMIFS(I:I,E:E,E5,C:C,C5,B:B,B5)/SUMIFS(J:J,E:E,E5,C:C,C5,B:B,B5)),0) -> 55 | L5: =IFERROR(IF(K5<=S5,"EXCELENTE",IF(K5<=Q5,"BOM",IF(K5<=O5,"ATENÇÃO",IF(K5>O5,"CRÍTICO","-")))),"-") -> CRÍTICO | M5: =IFERROR(I5/J5,"-") -> 55 | N5: =IFERROR(INDEX('Metas Diesel'!N:N,MATCH(Diesel!E5,'Metas Diesel'!A:A,0)),"-") -> 237.83333 | O5: =IFERROR(N5/J5,"-") -> 39.638889 | P5: =IFERROR(INDEX('Metas Diesel'!O:O,MATCH(Diesel!E5,'Metas Diesel'!A:A,0)),"-") -> 194.11243 | Q5: =IFERROR(P5/J5,"-") -> 32.352071 | R5: =IFERROR(INDEX('Metas Diesel'!P:P,MATCH(Diesel!E5,'Metas Diesel'!A:A,0)),"-") -> 100 | S5: =IFERROR(R5/J5,"-") -> 16.666667 | T5: =IFERROR(IF(M5<=S5,"EXCELENTE",IF(M5<=Q5,"BOM",IF(M5<=O5,"ATENÇÃO",IF(M5>O5,"CRÍTICO","-")))),"-") -> CRÍTICO | U5: C01 | X5: {=IFERROR(W5+IF(C5<C4,LARGE(LOOKUP(U5,$U$1:$U4,$AA$1:$AA4),1),LOOKUP(2,1/($U$1:$U4=U5),($AA$1:$AA4))),"-")} -> 4380 | Y5: {=IFERROR(IF(C5<C4,LARGE(LOOKUP(U5,$U$1:$U4,$Z$1:$Z4),1),LOOKUP(2,1/($U$1:$U4=U5),($Z$1:$Z4))),"-")} -> 620 | Z5: 950 | AA5: =IFERROR(X5-I5,"-") -> 4050
A6: =IFERROR(YEAR(C6),"-") -> 2026 | B6: =IFERROR(DATE(YEAR(C6),MONTH(C6),MONTH(C6)),"-") -> 46023 | C6: 46024 | D6: FELLER2 | E6: =IFERROR(VLOOKUP(D6,Cadastros!A:B,2,FALSE),"-") -> FELLER BUNCHER 2 | F6: =IFERROR(VLOOKUP(E6,Cadastros!B:D,3,FALSE),"-") -> CORTE | G6: {=IF(C6<C5,LARGE(LOOKUP(D6,$D$1:$D5,$H$1:$H5),1),LOOKUP(2,1/($D$1:$D5=D6),($H$1:$H5)))} -> 2008 | H6: 2012 | I6: =IFERROR(IF(Z6-Y6<0,"-",Z6-Y6),"-") -> 170 | J6: =IFERROR(IF(H6-G6<0,"-",H6-G6),"-") -> 4 | K6: =IFERROR(IF(C6>=TODAY(),"",SUMIFS(I:I,E:E,E6,C:C,C6,B:B,B6)/SUMIFS(J:J,E:E,E6,C:C,C6,B:B,B6)),0) -> 21.176471 | L6: =IFERROR(IF(K6<=S6,"EXCELENTE",IF(K6<=Q6,"BOM",IF(K6<=O6,"ATENÇÃO",IF(K6>O6,"CRÍTICO","-")))),"-") -> EXCELENTE | M6: =IFERROR(I6/J6,"-") -> 42.5 | N6: =IFERROR(INDEX('Metas Diesel'!N:N,MATCH(Diesel!E6,'Metas Diesel'!A:A,0)),"-") -> 215.16667 | O6: =IFERROR(N6/J6,"-") -> 53.791667 | P6: =IFERROR(INDEX('Metas Diesel'!O:O,MATCH(Diesel!E6,'Metas Diesel'!A:A,0)),"-") -> 198.75796 | Q6: =IFERROR(P6/J6,"-") -> 49.68949 | R6: =IFERROR(INDEX('Metas Diesel'!P:P,MATCH(Diesel!E6,'Metas Diesel'!A:A,0)),"-") -> 150 | S6: =IFERROR(R6/J6,"-") -> 37.5 | T6: =IFERROR(IF(M6<=S6,"EXCELENTE",IF(M6<=Q6,"BOM",IF(M6<=O6,"ATENÇÃO",IF(M6>O6,"CRÍTICO","-")))),"-") -> BOM | U6: C01 | X6: {=IFERROR(W6+IF(C6<C5,LARGE(LOOKUP(U6,$U$1:$U5,$AA$1:$AA5),1),LOOKUP(2,1/($U$1:$U5=U6),($AA$1:$AA5))),"-")} -> 4050 | Y6: {=IFERROR(IF(C6<C5,LARGE(LOOKUP(U6,$U$1:$U5,$Z$1:$Z5),1),LOOKUP(2,1/($U$1:$U5=U6),($Z$1:$Z5))),"-")} -> 950 | Z6: 1120 | AA6: =IFERROR(X6-I6,"-") -> 3880
A7: =IFERROR(YEAR(C7),"-") -> 2026 | B7: =IFERROR(DATE(YEAR(C7),MONTH(C7),MONTH(C7)),"-") -> 46023 | C7: 46024 | D7: GARRA2 | E7: =IFERROR(VLOOKUP(D7,Cadastros!A:B,2,FALSE),"-") -> GARRA TRAÇADORA 2 | F7: =IFERROR(VLOOKUP(E7,Cadastros!B:D,3,FALSE),"-") -> TRAÇAMENTO | G7: 700 | H7: 711 | I7: =IFERROR(IF(Z7-Y7<0,"-",Z7-Y7),"-") -> 380 | J7: =IFERROR(IF(H7-G7<0,"-",H7-G7),"-") -> 11 | K7: =IFERROR(IF(C7>=TODAY(),"",SUMIFS(I:I,E:E,E7,C:C,C7,B:B,B7)/SUMIFS(J:J,E:E,E7,C:C,C7,B:B,B7)),0) -> 34.545455 | L7: =IFERROR(IF(K7<=S7,"EXCELENTE",IF(K7<=Q7,"BOM",IF(K7<=O7,"ATENÇÃO",IF(K7>O7,"CRÍTICO","-")))),"-") -> CRÍTICO | M7: =IFERROR(I7/J7,"-") -> 34.545455 | N7: =IFERROR(INDEX('Metas Diesel'!N:N,MATCH(Diesel!E7,'Metas Diesel'!A:A,0)),"-") -> 368.66667 | O7: =IFERROR(N7/J7,"-") -> 33.515152 | P7: =IFERROR(INDEX('Metas Diesel'!O:O,MATCH(Diesel!E7,'Metas Diesel'!A:A,0)),"-") -> 355.06849 | Q7: =IFERROR(P7/J7,"-") -> 32.278954 | R7: =IFERROR(INDEX('Metas Diesel'!P:P,MATCH(Diesel!E7,'Metas Diesel'!A:A,0)),"-") -> 340 | S7: =IFERROR(R7/J7,"-") -> 30.909091 | T7: =IFERROR(IF(M7<=S7,"EXCELENTE",IF(M7<=Q7,"BOM",IF(M7<=O7,"ATENÇÃO",IF(M7>O7,"CRÍTICO","-")))),"-") -> CRÍTICO | U7: C01 | X7: {=IFERROR(W7+IF(C7<C6,LARGE(LOOKUP(U7,$U$1:$U6,$AA$1:$AA6),1),LOOKUP(2,1/($U$1:$U6=U7),($AA$1:$AA6))),"-")} -> 3880 | Y7: {=IFERROR(IF(C7<C6,LARGE(LOOKUP(U7,$U$1:$U6,$Z$1:$Z6),1),LOOKUP(2,1/($U$1:$U6=U7),($Z$1:$Z6))),"-")} -> 1120 | Z7: 1500 | AA7: =IFERROR(X7-I7,"-") -> 3500
A8: =IFERROR(YEAR(C8),"-") -> 2026 | B8: =IFERROR(DATE(YEAR(C8),MONTH(C8),MONTH(C8)),"-") -> 46023 | C8: 46024 | D8: FELLER2 | E8: =IFERROR(VLOOKUP(D8,Cadastros!A:B,2,FALSE),"-") -> FELLER BUNCHER 2 | F8: =IFERROR(VLOOKUP(E8,Cadastros!B:D,3,FALSE),"-") -> CORTE | G8: {=IF(C8<C7,LARGE(LOOKUP(D8,$D$1:$D7,$H$1:$H7),1),LOOKUP(2,1/($D$1:$D7=D8),($H$1:$H7)))} -> 2012 | H8: 2025 | I8: =IFERROR(IF(Z8-Y8<0,"-",Z8-Y8),"-") -> 190 | J8: =IFERROR(IF(H8-G8<0,"-",H8-G8),"-") -> 13 | K8: =IFERROR(IF(C8>=TODAY(),"",SUMIFS(I:I,E:E,E8,C:C,C8,B:B,B8)/SUMIFS(J:J,E:E,E8,C:C,C8,B:B,B8)),0) -> 21.176471 | L8: =IFERROR(IF(K8<=S8,"EXCELENTE",IF(K8<=Q8,"BOM",IF(K8<=O8,"ATENÇÃO",IF(K8>O8,"CRÍTICO","-")))),"-") -> CRÍTICO | M8: =IFERROR(I8/J8,"-") -> 14.615385 | N8: =IFERROR(INDEX('Metas Diesel'!N:N,MATCH(Diesel!E8,'Metas Diesel'!A:A,0)),"-") -> 215.16667 | O8: =IFERROR(N8/J8,"-") -> 16.551282 | P8: =IFERROR(INDEX('Metas Diesel'!O:O,MATCH(Diesel!E8,'Metas Diesel'!A:A,0)),"-") -> 198.75796 | Q8: =IFERROR(P8/J8,"-") -> 15.289074 | R8: =IFERROR(INDEX('Metas Diesel'!P:P,MATCH(Diesel!E8,'Metas Diesel'!A:A,0)),"-") -> 150 | S8: =IFERROR(R8/J8,"-") -> 11.538462 | T8: =IFERROR(IF(M8<=S8,"EXCELENTE",IF(M8<=Q8,"BOM",IF(M8<=O8,"ATENÇÃO",IF(M8>O8,"CRÍTICO","-")))),"-") -> BOM | U8: C01 | X8: {=IFERROR(W8+IF(C8<C7,LARGE(LOOKUP(U8,$U$1:$U7,$AA$1:$AA7),1),LOOKUP(2,1/($U$1:$U7=U8),($AA$1:$AA7))),"-")} -> 3500 | Y8: {=IFERROR(IF(C8<C7,LARGE(LOOKUP(U8,$U$1:$U7,$Z$1:$Z7),1),LOOKUP(2,1/($U$1:$U7=U8),($Z$1:$Z7))),"-")} -> 1500 | Z8: 1690 | AA8: =IFERROR(X8-I8,"-") -> 3310
A9: =IFERROR(YEAR(C9),"-") -> 2026 | B9: =IFERROR(DATE(YEAR(C9),MONTH(C9),MONTH(C9)),"-") -> 46023 | C9: 46024 | D9: FELLER1 | E9: =IFERROR(VLOOKUP(D9,Cadastros!A:B,2,FALSE),"-") -> FELLER BUNCHER 1 | F9: =IFERROR(VLOOKUP(E9,Cadastros!B:D,3,FALSE),"-") -> CORTE | G9: {=IF(C9<C8,LARGE(LOOKUP(D9,$D$1:$D8,$H$1:$H8),1),LOOKUP(2,1/($D$1:$D8=D9),($H$1:$H8)))} -> 1012 | H9: 1018 | I9: =IFERROR(IF(Z9-Y9<0,"-",Z9-Y9),"-") -> 110 | J9: =IFERROR(IF(H9-G9<0,"-",H9-G9),"-") -> 6 | K9: =IFERROR(IF(C9>=TODAY(),"",SUMIFS(I:I,E:E,E9,C:C,C9,B:B,B9)/SUMIFS(J:J,E:E,E9,C:C,C9,B:B,B9)),0) -> 18.333333 | L9: =IFERROR(IF(K9<=S9,"EXCELENTE",IF(K9<=Q9,"BOM",IF(K9<=O9,"ATENÇÃO",IF(K9>O9,"CRÍTICO","-")))),"-") -> BOM | M9: =IFERROR(I9/J9,"-") -> 18.333333 | N9: =IFERROR(INDEX('Metas Diesel'!N:N,MATCH(Diesel!E9,'Metas Diesel'!A:A,0)),"-") -> 235.66667 | O9: =IFERROR(N9/J9,"-") -> 39.277778 | P9: =IFERROR(INDEX('Metas Diesel'!O:O,MATCH(Diesel!E9,'Metas Diesel'!A:A,0)),"-") -> 226.5449 | Q9: =IFERROR(P9/J9,"-") -> 37.757484 | R9: =IFERROR(INDEX('Metas Diesel'!P:P,MATCH(Diesel!E9,'Metas Diesel'!A:A,0)),"-") -> 100 | S9: =IFERROR(R9/J9,"-") -> 16.666667 | T9: =IFERROR(IF(M9<=S9,"EXCELENTE",IF(M9<=Q9,"BOM",IF(M9<=O9,"ATENÇÃO",IF(M9>O9,"CRÍTICO","-")))),"-") -> BOM | U9: C01 | X9: {=IFERROR(W9+IF(C9<C8,LARGE(LOOKUP(U9,$U$1:$U8,$AA$1:$AA8),1),LOOKUP(2,1/($U$1:$U8=U9),($AA$1:$AA8))),"-")} -> 3310 | Y9: {=IFERROR(IF(C9<C8,LARGE(LOOKUP(U9,$U$1:$U8,$Z$1:$Z8),1),LOOKUP(2,1/($U$1:$U8=U9),($Z$1:$Z8))),"-")} -> 1690 | Z9: 1800 | AA9: =IFERROR(X9-I9,"-") -> 3200
A10: =IFERROR(YEAR(C10),"-") -> 2026 | B10: =IFERROR(DATE(YEAR(C10),MONTH(C10),MONTH(C10)),"-") -> 46023 | C10: 46024 | D10: SKIDDER2 | E10: =IFERROR(VLOOKUP(D10,Cadastros!A:B,2,FALSE),"-") -> SKIDDER 2 | F10: =IFERROR(VLOOKUP(E10,Cadastros!B:D,3,FALSE),"-") -> ARRASTE | G10: {=IF(C10<C9,LARGE(LOOKUP(D10,$D$1:$D9,$H$1:$H9),1),LOOKUP(2,1/($D$1:$D9=D10),($H$1:$H9)))} -> 2106 | H10: 2110 | I10: =IFERROR(IF(Z10-Y10<0,"-",Z10-Y10),"-") -> 200 | J10: =IFERROR(IF(H10-G10<0,"-",H10-G10),"-") -> 4 | K10: =IFERROR(IF(C10>=TODAY(),"",SUMIFS(I:I,E:E,E10,C:C,C10,B:B,B10)/SUMIFS(J:J,E:E,E10,C:C,C10,B:B,B10)),0) -> 33.333333 | L10: =IFERROR(IF(K10<=S10,"EXCELENTE",IF(K10<=Q10,"BOM",IF(K10<=O10,"ATENÇÃO",IF(K10>O10,"CRÍTICO","-")))),"-") -> BOM | M10: =IFERROR(I10/J10,"-") -> 50 | N10: =IFERROR(INDEX('Metas Diesel'!N:N,MATCH(Diesel!E10,'Metas Diesel'!A:A,0)),"-") -> 237.83333 | O10: =IFERROR(N10/J10,"-") -> 59.458333 | P10: =IFERROR(INDEX('Metas Diesel'!O:O,MATCH(Diesel!E10,'Metas Diesel'!A:A,0)),"-") -> 194.11243 | Q10: =IFERROR(P10/J10,"-") -> 48.528107 | R10: =IFERROR(INDEX('Metas Diesel'!P:P,MATCH(Diesel!E10,'Metas Diesel'!A:A,0)),"-") -> 100 | S10: =IFERROR(R10/J10,"-") -> 25 | T10: =IFERROR(IF(M10<=S10,"EXCELENTE",IF(M10<=Q10,"BOM",IF(M10<=O10,"ATENÇÃO",IF(M10>O10,"CRÍTICO","-")))),"-") -> ATENÇÃO | U10: C01 | X10: {=IFERROR(W10+IF(C10<C9,LARGE(LOOKUP(U10,$U$1:$U9,$AA$1:$AA9),1),LOOKUP(2,1/($U$1:$U9=U10),($AA$1:$AA9))),"-")} -> 3200 | Y10: {=IFERROR(IF(C10<C9,LARGE(LOOKUP(U10,$U$1:$U9,$Z$1:$Z9),1),LOOKUP(2,1/($U$1:$U9=U10),($Z$1:$Z9))),"-")} -> 1800 | Z10: 2000 | AA10: =IFERROR(X10-I10,"-") -> 3000
A11: =IFERROR(YEAR(C11),"-") -> 2026 | B11: =IFERROR(DATE(YEAR(C11),MONTH(C11),MONTH(C11)),"-") -> 46023 | C11: 46024 | D11: SKIDDER2 | E11: =IFERROR(VLOOKUP(D11,Cadastros!A:B,2,FALSE),"-") -> SKIDDER 2 | F11: =IFERROR(VLOOKUP(E11,Cadastros!B:D,3,FALSE),"-") -> ARRASTE | G11: {=IF(C11<C10,LARGE(LOOKUP(D11,$D$1:$D10,$H$1:$H10),1),LOOKUP(2,1/($D$1:$D10=D11),($H$1:$H10)))} -> 2110 | H11: 2115 | I11: =IFERROR(IF(Z11-Y11<0,"-",Z11-Y11),"-") -> 100 | J11: =IFERROR(IF(H11-G11<0,"-",H11-G11),"-") -> 5 | K11: =IFERROR(IF(C11>=TODAY(),"",SUMIFS(I:I,E:E,E11,C:C,C11,B:B,B11)/SUMIFS(J:J,E:E,E11,C:C,C11,B:B,B11)),0) -> 33.333333 | L11: =IFERROR(IF(K11<=S11,"EXCELENTE",IF(K11<=Q11,"BOM",IF(K11<=O11,"ATENÇÃO",IF(K11>O11,"CRÍTICO","-")))),"-") -> BOM | M11: =IFERROR(I11/J11,"-") -> 20 | N11: =IFERROR(INDEX('Metas Diesel'!N:N,MATCH(Diesel!E11,'Metas Diesel'!A:A,0)),"-") -> 237.83333 | O11: =IFERROR(N11/J11,"-") -> 47.566667 | P11: =IFERROR(INDEX('Metas Diesel'!O:O,MATCH(Diesel!E11,'Metas Diesel'!A:A,0)),"-") -> 194.11243 | Q11: =IFERROR(P11/J11,"-") -> 38.822485 | R11: =IFERROR(INDEX('Metas Diesel'!P:P,MATCH(Diesel!E11,'Metas Diesel'!A:A,0)),"-") -> 100 | S11: =IFERROR(R11/J11,"-") -> 20 | T11: =IFERROR(IF(M11<=S11,"EXCELENTE",IF(M11<=Q11,"BOM",IF(M11<=O11,"ATENÇÃO",IF(M11>O11,"CRÍTICO","-")))),"-") -> EXCELENTE | U11: C01 | X11: {=IFERROR(W11+IF(C11<C10,LARGE(LOOKUP(U11,$U$1:$U10,$AA$1:$AA10),1),LOOKUP(2,1/($U$1:$U10=U11),($AA$1:$AA10))),"-")} -> 3000 | Y11: {=IFERROR(IF(C11<C10,LARGE(LOOKUP(U11,$U$1:$U10,$Z$1:$Z10),1),LOOKUP(2,1/($U$1:$U10=U11),($Z$1:$Z10))),"-")} -> 2000 | Z11: 2100 | AA11: =IFERROR(X11-I11,"-") -> 2900
A12: =IFERROR(YEAR(C12),"-") -> 2026 | B12: =IFERROR(DATE(YEAR(C12),MONTH(C12),MONTH(C12)),"-") -> 46023 | C12: 46025 | D12: FELLER1 | E12: =IFERROR(VLOOKUP(D12,Cadastros!A:B,2,FALSE),"-") -> FELLER BUNCHER 1 | F12: =IFERROR(VLOOKUP(E12,Cadastros!B:D,3,FALSE),"-") -> CORTE | G12: {=IF(C12<C11,LARGE(LOOKUP(D12,$D$1:$D11,$H$1:$H11),1),LOOKUP(2,1/($D$1:$D11=D12),($H$1:$H11)))} -> 1018 | H12: 1025 | I12: =IFERROR(IF(Z12-Y12<0,"-",Z12-Y12),"-") -> 400 | J12: =IFERROR(IF(H12-G12<0,"-",H12-G12),"-") -> 7 | K12: =IFERROR(IF(C12>=TODAY(),"",SUMIFS(I:I,E:E,E12,C:C,C12,B:B,B12)/SUMIFS(J:J,E:E,E12,C:C,C12,B:B,B12)),0) -> 57.142857 | L12: =IFERROR(IF(K12<=S12,"EXCELENTE",IF(K12<=Q12,"BOM",IF(K12<=O12,"ATENÇÃO",IF(K12>O12,"CRÍTICO","-")))),"-") -> CRÍTICO | M12: =IFERROR(I12/J12,"-") -> 57.142857 | N12: =IFERROR(INDEX('Metas Diesel'!N:N,MATCH(Diesel!E12,'Metas Diesel'!A:A,0)),"-") -> 235.66667 | O12: =IFERROR(N12/J12,"-") -> 33.666667 | P12: =IFERROR(INDEX('Metas Diesel'!O:O,MATCH(Diesel!E12,'Metas Diesel'!A:A,0)),"-") -> 226.5449 | Q12: =IFERROR(P12/J12,"-") -> 32.363557 | R12: =IFERROR(INDEX('Metas Diesel'!P:P,MATCH(Diesel!E12,'Metas Diesel'!A:A,0)),"-") -> 100 | S12: =IFERROR(R12/J12,"-") -> 14.285714 | T12: =IFERROR(IF(M12<=S12,"EXCELENTE",IF(M12<=Q12,"BOM",IF(M12<=O12,"ATENÇÃO",IF(M12>O12,"CRÍTICO","-")))),"-") -> CRÍTICO | U12: C01 | X12: {=IFERROR(W12+IF(C12<C11,LARGE(LOOKUP(U12,$U$1:$U11,$AA$1:$AA11),1),LOOKUP(2,1/($U$1:$U11=U12),($AA$1:$AA11))),"-")} -> 2900 | Y12: {=IFERROR(IF(C12<C11,LARGE(LOOKUP(U12,$U$1:$U11,$Z$1:$Z11),1),LOOKUP(2,1/($U$1:$U11=U12),($Z$1:$Z11))),"-")} -> 2100 | Z12: 2500 | AA12: =IFERROR(X12-I12,"-") -> 2500
A13: =IFERROR(YEAR(C13),"-") -> 2026 | B13: =IFERROR(DATE(YEAR(C13),MONTH(C13),MONTH(C13)),"-") -> 46023 | C13: 46025 | D13: GARRA1 | E13: =IFERROR(VLOOKUP(D13,Cadastros!A:B,2,FALSE),"-") -> GARRA TRAÇADORA 1 | F13: =IFERROR(VLOOKUP(E13,Cadastros!B:D,3,FALSE),"-") -> TRAÇAMENTO | G13: 500 | H13: 510 | I13: =IFERROR(IF(Z13-Y13<0,"-",Z13-Y13),"-") -> 400 | J13: =IFERROR(IF(H13-G13<0,"-",H13-G13),"-") -> 10 | K13: =IFERROR(IF(C13>=TODAY(),"",SUMIFS(I:I,E:E,E13,C:C,C13,B:B,B13)/SUMIFS(J:J,E:E,E13,C:C,C13,B:B,B13)),0) -> 40 | L13: =IFERROR(IF(K13<=S13,"EXCELENTE",IF(K13<=Q13,"BOM",IF(K13<=O13,"ATENÇÃO",IF(K13>O13,"CRÍTICO","-")))),"-") -> EXCELENTE | M13: =IFERROR(I13/J13,"-") -> 40 | N13: =IFERROR(INDEX('Metas Diesel'!N:N,MATCH(Diesel!E13,'Metas Diesel'!A:A,0)),"-") -> 400 | O13: =IFERROR(N13/J13,"-") -> 40 | P13: =IFERROR(INDEX('Metas Diesel'!O:O,MATCH(Diesel!E13,'Metas Diesel'!A:A,0)),"-") -> 400 | Q13: =IFERROR(P13/J13,"-") -> 40 | R13: =IFERROR(INDEX('Metas Diesel'!P:P,MATCH(Diesel!E13,'Metas Diesel'!A:A,0)),"-") -> 400 | S13: =IFERROR(R13/J13,"-") -> 40 | T13: =IFERROR(IF(M13<=S13,"EXCELENTE",IF(M13<=Q13,"BOM",IF(M13<=O13,"ATENÇÃO",IF(M13>O13,"CRÍTICO","-")))),"-") -> EXCELENTE | U13: C01 | X13: {=IFERROR(W13+IF(C13<C12,LARGE(LOOKUP(U13,$U$1:$U12,$AA$1:$AA12),1),LOOKUP(2,1/($U$1:$U12=U13),($AA$1:$AA12))),"-")} -> 2500 | Y13: {=IFERROR(IF(C13<C12,LARGE(LOOKUP(U13,$U$1:$U12,$Z$1:$Z12),1),LOOKUP(2,1/($U$1:$U12=U13),($Z$1:$Z12))),"-")} -> 2500 | Z13: 2900 | AA13: =IFERROR(X13-I13,"-") -> 2100
A14: =IFERROR(YEAR(C14),"-") -> 2026 | B14: =IFERROR(DATE(YEAR(C14),MONTH(C14),MONTH(C14)),"-") -> 46023 | C14: 46025 | D14: SKIDDER1 | E14: =IFERROR(VLOOKUP(D14,Cadastros!A:B,2,FALSE),"-") -> SKIDDER 1 | F14: =IFERROR(VLOOKUP(E14,Cadastros!B:D,3,FALSE),"-") -> ARRASTE | G14: {=IF(C14<C13,LARGE(LOOKUP(D14,$D$1:$D13,$H$1:$H13),1),LOOKUP(2,1/($D$1:$D13=D14),($H$1:$H13)))} -> 1215 | H14: 1219 | I14: =IFERROR(IF(Z14-Y14<0,"-",Z14-Y14),"-") -> 300 | J14: =IFERROR(IF(H14-G14<0,"-",H14-G14),"-") -> 4 | K14: =IFERROR(IF(C14>=TODAY(),"",SUMIFS(I:I,E:E,E14,C:C,C14,B:B,B14)/SUMIFS(J:J,E:E,E14,C:C,C14,B:B,B14)),0) -> 133.33333 | L14: =IFERROR(IF(K14<=S14,"EXCELENTE",IF(K14<=Q14,"BOM",IF(K14<=O14,"ATENÇÃO",IF(K14>O14,"CRÍTICO","-")))),"-") -> CRÍTICO | M14: =IFERROR(I14/J14,"-") -> 75 | N14: =IFERROR(INDEX('Metas Diesel'!N:N,MATCH(Diesel!E14,'Metas Diesel'!A:A,0)),"-") -> 426.33333 | O14: =IFERROR(N14/J14,"-") -> 106.58333 | P14: =IFERROR(INDEX('Metas Diesel'!O:O,MATCH(Diesel!E14,'Metas Diesel'!A:A,0)),"-") -> 377.8882 | Q14: =IFERROR(P14/J14,"-") -> 94.47205 | R14: =IFERROR(INDEX('Metas Diesel'!P:P,MATCH(Diesel!E14,'Metas Diesel'!A:A,0)),"-") -> 300 | S14: =IFERROR(R14/J14,"-") -> 75 | T14: =IFERROR(IF(M14<=S14,"EXCELENTE",IF(M14<=Q14,"BOM",IF(M14<=O14,"ATENÇÃO",IF(M14>O14,"CRÍTICO","-")))),"-") -> EXCELENTE | U14: C01 | X14: {=IFERROR(W14+IF(C14<C13,LARGE(LOOKUP(U14,$U$1:$U13,$AA$1:$AA13),1),LOOKUP(2,1/($U$1:$U13=U14),($AA$1:$AA13))),"-")} -> 2100 | Y14: {=IFERROR(IF(C14<C13,LARGE(LOOKUP(U14,$U$1:$U13,$Z$1:$Z13),1),LOOKUP(2,1/($U$1:$U13=U14),($Z$1:$Z13))),"-")} -> 2900 | Z14: 3200 | AA14: =IFERROR(X14-I14,"-") -> 1800
A15: =IFERROR(YEAR(C15),"-") -> 2026 | B15: =IFERROR(DATE(YEAR(C15),MONTH(C15),MONTH(C15)),"-") -> 46023 | C15: 46025 | D15: GARRA2 | E15: =IFERROR(VLOOKUP(D15,Cadastros!A:B,2,FALSE),"-") -> GARRA TRAÇADORA 2 | F15: =IFERROR(VLOOKUP(E15,Cadastros!B:D,3,FALSE),"-") -> TRAÇAMENTO | G15: {=IF(C15<C14,LARGE(LOOKUP(D15,$D$1:$D14,$H$1:$H14),1),LOOKUP(2,1/($D$1:$D14=D15),($H$1:$H14)))} -> 711 | H15: 722 | I15: =IFERROR(IF(Z15-Y15<0,"-",Z15-Y15),"-") -> 340 | J15: =IFERROR(IF(H15-G15<0,"-",H15-G15),"-") -> 11 | K15: =IFERROR(IF(C15>=TODAY(),"",SUMIFS(I:I,E:E,E15,C:C,C15,B:B,B15)/SUMIFS(J:J,E:E,E15,C:C,C15,B:B,B15)),0) -> 30.909091 | L15: =IFERROR(IF(K15<=S15,"EXCELENTE",IF(K15<=Q15,"BOM",IF(K15<=O15,"ATENÇÃO",IF(K15>O15,"CRÍTICO","-")))),"-") -> EXCELENTE | M15: =IFERROR(I15/J15,"-") -> 30.909091 | N15: =IFERROR(INDEX('Metas Diesel'!N:N,MATCH(Diesel!E15,'Metas Diesel'!A:A,0)),"-") -> 368.66667 | O15: =IFERROR(N15/J15,"-") -> 33.515152 | P15: =IFERROR(INDEX('Metas Diesel'!O:O,MATCH(Diesel!E15,'Metas Diesel'!A:A,0)),"-") -> 355.06849 | Q15: =IFERROR(P15/J15,"-") -> 32.278954 | R15: =IFERROR(INDEX('Metas Diesel'!P:P,MATCH(Diesel!E15,'Metas Diesel'!A:A,0)),"-") -> 340 | S15: =IFERROR(R15/J15,"-") -> 30.909091 | T15: =IFERROR(IF(M15<=S15,"EXCELENTE",IF(M15<=Q15,"BOM",IF(M15<=O15,"ATENÇÃO",IF(M15>O15,"CRÍTICO","-")))),"-") -> EXCELENTE | U15: C01 | X15: {=IFERROR(W15+IF(C15<C14,LARGE(LOOKUP(U15,$U$1:$U14,$AA$1:$AA14),1),LOOKUP(2,1/($U$1:$U14=U15),($AA$1:$AA14))),"-")} -> 1800 | Y15: {=IFERROR(IF(C15<C14,LARGE(LOOKUP(U15,$U$1:$U14,$Z$1:$Z14),1),LOOKUP(2,1/($U$1:$U14=U15),($Z$1:$Z14))),"-")} -> 3200 | Z15: 3540 | AA15: =IFERROR(X15-I15,"-") -> 1460
A16: =IFERROR(YEAR(C16),"-") -> 2026 | B16: =IFERROR(DATE(YEAR(C16),MONTH(C16),MONTH(C16)),"-") -> 46023 | C16: 46025 | D16: SKIDDER2 | E16: =IFERROR(VLOOKUP(D16,Cadastros!A:B,2,FALSE),"-") -> SKIDDER 2 | F16: =IFERROR(VLOOKUP(E16,Cadastros!B:D,3,FALSE),"-") -> ARRASTE | G16: {=IF(C16<C15,LARGE(LOOKUP(D16,$D$1:$D15,$H$1:$H15),1),LOOKUP(2,1/($D$1:$D15=D16),($H$1:$H15)))} -> 2115 | H16: 2123 | I16: =IFERROR(IF(Z16-Y16<0,"-",Z16-Y16),"-") -> 180 | J16: =IFERROR(IF(H16-G16<0,"-",H16-G16),"-") -> 8 | K16: =IFERROR(IF(C16>=TODAY(),"",SUMIFS(I:I,E:E,E16,C:C,C16,B:B,B16)/SUMIFS(J:J,E:E,E16,C:C,C16,B:B,B16)),0) -> 22.5 | L16: =IFERROR(IF(K16<=S16,"EXCELENTE",IF(K16<=Q16,"BOM",IF(K16<=O16,"ATENÇÃO",IF(K16>O16,"CRÍTICO","-")))),"-") -> BOM | M16: =IFERROR(I16/J16,"-") -> 22.5 | N16: =IFERROR(INDEX('Metas Diesel'!N:N,MATCH(Diesel!E16,'Metas Diesel'!A:A,0)),"-") -> 237.83333 | O16: =IFERROR(N16/J16,"-") -> 29.729167 | P16: =IFERROR(INDEX('Metas Diesel'!O:O,MATCH(Diesel!E16,'Metas Diesel'!A:A,0)),"-") -> 194.11243 | Q16: =IFERROR(P16/J16,"-") -> 24.264053 | R16: =IFERROR(INDEX('Metas Diesel'!P:P,MATCH(Diesel!E16,'Metas Diesel'!A:A,0)),"-") -> 100 | S16: =IFERROR(R16/J16,"-") -> 12.5 | T16: =IFERROR(IF(M16<=S16,"EXCELENTE",IF(M16<=Q16,"BOM",IF(M16<=O16,"ATENÇÃO",IF(M16>O16,"CRÍTICO","-")))),"-") -> BOM | U16: C01 | X16: {=IFERROR(W16+IF(C16<C15,LARGE(LOOKUP(U16,$U$1:$U15,$AA$1:$AA15),1),LOOKUP(2,1/($U$1:$U15=U16),($AA$1:$AA15))),"-")} -> 1460 | Y16: {=IFERROR(IF(C16<C15,LARGE(LOOKUP(U16,$U$1:$U15,$Z$1:$Z15),1),LOOKUP(2,1/($U$1:$U15=U16),($Z$1:$Z15))),"-")} -> 3540 | Z16: 3720 | AA16: =IFERROR(X16-I16,"-") -> 1280
A17: =IFERROR(YEAR(C17),"-") -> 2026 | B17: =IFERROR(DATE(YEAR(C17),MONTH(C17),MONTH(C17)),"-") -> 46023 | C17: 46025 | D17: FELLER2 | E17: =IFERROR(VLOOKUP(D17,Cadastros!A:B,2,FALSE),"-") -> FELLER BUNCHER 2 | F17: =IFERROR(VLOOKUP(E17,Cadastros!B:D,3,FALSE),"-") -> CORTE | G17: {=IF(C17<C16,LARGE(LOOKUP(D17,$D$1:$D16,$H$1:$H16),1),LOOKUP(2,1/($D$1:$D16=D17),($H$1:$H16)))} -> 2025 | H17: 2034 | I17: =IFERROR(IF(Z17-Y17<0,"-",Z17-Y17),"-") -> 280 | J17: =IFERROR(IF(H17-G17<0,"-",H17-G17),"-") -> 9 | K17: =IFERROR(IF(C17>=TODAY(),"",SUMIFS(I:I,E:E,E17,C:C,C17,B:B,B17)/SUMIFS(J:J,E:E,E17,C:C,C17,B:B,B17)),0) -> 31.111111 | L17: =IFERROR(IF(K17<=S17,"EXCELENTE",IF(K17<=Q17,"BOM",IF(K17<=O17,"ATENÇÃO",IF(K17>O17,"CRÍTICO","-")))),"-") -> CRÍTICO | M17: =IFERROR(I17/J17,"-") -> 31.111111 | N17: =IFERROR(INDEX('Metas Diesel'!N:N,MATCH(Diesel!E17,'Metas Diesel'!A:A,0)),"-") -> 215.16667 | O17: =IFERROR(N17/J17,"-") -> 23.907407 | P17: =IFERROR(INDEX('Metas Diesel'!O:O,MATCH(Diesel!E17,'Metas Diesel'!A:A,0)),"-") -> 198.75796 | Q17: =IFERROR(P17/J17,"-") -> 22.084218 | R17: =IFERROR(INDEX('Metas Diesel'!P:P,MATCH(Diesel!E17,'Metas Diesel'!A:A,0)),"-") -> 150 | S17: =IFERROR(R17/J17,"-") -> 16.666667 | T17: =IFERROR(IF(M17<=S17,"EXCELENTE",IF(M17<=Q17,"BOM",IF(M17<=O17,"ATENÇÃO",IF(M17>O17,"CRÍTICO","-")))),"-") -> CRÍTICO | U17: C01 | X17: {=IFERROR(W17+IF(C17<C16,LARGE(LOOKUP(U17,$U$1:$U16,$AA$1:$AA16),1),LOOKUP(2,1/($U$1:$U16=U17),($AA$1:$AA16))),"-")} -> 1280 | Y17: {=IFERROR(IF(C17<C16,LARGE(LOOKUP(U17,$U$1:$U16,$Z$1:$Z16),1),LOOKUP(2,1/($U$1:$U16=U17),($Z$1:$Z16))),"-")} -> 3720 | Z17: 4000 | AA17: =IFERROR(X17-I17,"-") -> 1000
A18: =IFERROR(YEAR(C18),"-") -> 2026 | B18: =IFERROR(DATE(YEAR(C18),MONTH(C18),MONTH(C18)),"-") -> 46023 | C18: 46025 | D18: SKIDDER1 | E18: =IFERROR(VLOOKUP(D18,Cadastros!A:B,2,FALSE),"-") -> SKIDDER 1 | F18: =IFERROR(VLOOKUP(E18,Cadastros!B:D,3,FALSE),"-") -> ARRASTE | G18: {=IF(C18<C17,LARGE(LOOKUP(D18,$D$1:$D17,$H$1:$H17),1),LOOKUP(2,1/($D$1:$D17=D18),($H$1:$H17)))} -> 1219 | H18: 1221 | I18: =IFERROR(IF(Z18-Y18<0,"-",Z18-Y18),"-") -> 500 | J18: =IFERROR(IF(H18-G18<0,"-",H18-G18),"-") -> 2 | K18: =IFERROR(IF(C18>=TODAY(),"",SUMIFS(I:I,E:E,E18,C:C,C18,B:B,B18)/SUMIFS(J:J,E:E,E18,C:C,C18,B:B,B18)),0) -> 133.33333 | L18: =IFERROR(IF(K18<=S18,"EXCELENTE",IF(K18<=Q18,"BOM",IF(K18<=O18,"ATENÇÃO",IF(K18>O18,"CRÍTICO","-")))),"-") -> EXCELENTE | M18: =IFERROR(I18/J18,"-") -> 250 | N18: =IFERROR(INDEX('Metas Diesel'!N:N,MATCH(Diesel!E18,'Metas Diesel'!A:A,0)),"-") -> 426.33333 | O18: =IFERROR(N18/J18,"-") -> 213.16667 | P18: =IFERROR(INDEX('Metas Diesel'!O:O,MATCH(Diesel!E18,'Metas Diesel'!A:A,0)),"-") -> 377.8882 | Q18: =IFERROR(P18/J18,"-") -> 188.9441 | R18: =IFERROR(INDEX('Metas Diesel'!P:P,MATCH(Diesel!E18,'Metas Diesel'!A:A,0)),"-") -> 300 | S18: =IFERROR(R18/J18,"-") -> 150 | T18: =IFERROR(IF(M18<=S18,"EXCELENTE",IF(M18<=Q18,"BOM",IF(M18<=O18,"ATENÇÃO",IF(M18>O18,"CRÍTICO","-")))),"-") -> CRÍTICO | U18: C01 | X18: {=IFERROR(W18+IF(C18<C17,LARGE(LOOKUP(U18,$U$1:$U17,$AA$1:$AA17),1),LOOKUP(2,1/($U$1:$U17=U18),($AA$1:$AA17))),"-")} -> 1000 | Y18: {=IFERROR(IF(C18<C17,LARGE(LOOKUP(U18,$U$1:$U17,$Z$1:$Z17),1),LOOKUP(2,1/($U$1:$U17=U18),($Z$1:$Z17))),"-")} -> 4000 | Z18: 4500 | AA18: =IFERROR(X18-I18,"-") -> 500

Sheet Graxa
A1: ANO | B1: MÊS | C1: DATA | D1: EQUIPAMENTO DIGITADO | E1: EQUIPAMENTO | F1: TIPO DE EQUIPAMENTO | G1: HORÍMETRO ANTERIOR | H1: HORÍMETRO ABASTECIMENTO | I1: CONSUMO | J1: HORAS RODADAS | K1: MÉDIA | L1: STATUS MÉDIA | M1: KG POR HORA | N1: META BASE | O1: META BASE POR HORA | P1: META DESAFIO | Q1: META DESAFIO POR HORA | R1: TETO META | S1: TETO META POR HORA | T1: STATUS META | U1: GRAXA | V1: COMBOIO | W1: ENTRADA | X1: VALOR ENTRADA | Y1: SALDO ANTERIOR | Z1: SALDO | AA1: OBS
A2: =IFERROR(YEAR(C2),"-") -> 2026 | B2: =IFERROR(DATE(YEAR(C2),MONTH(C2),MONTH(C2)),"-") -> 46023 | C2: 46023 | D2: FELLER1 | E2: =IFERROR(VLOOKUP(D2,Cadastros!A:B,2,FALSE),"-") -> FELLER BUNCHER 1 | F2: =IFERROR(VLOOKUP(E2,Cadastros!B:D,3,FALSE),"-") -> CORTE | G2: 1000 | H2: 1012 | I2: 1 | J2: =IFERROR(IF(H2-G2<0,"-",H2-G2),"-") -> 12 | K2: =IFERROR(IF(C2>=TODAY(),"",SUMIFS(I:I,E:E,E2,C:C,C2,B:B,B2)/SUMIFS(J:J,E:E,E2,C:C,C2,B:B,B2)),0) -> 0.083333333 | L2: =IFERROR(IF(K2<=S2,"EXCELENTE",IF(K2<=Q2,"BOM",IF(K2<=O2,"ATENÇÃO",IF(K2>O2,"CRÍTICO","-")))),"-") -> BOM | M2: =IFERROR(I2/J2,"-") -> 0.083333333 | N2: {=IFERROR(INDEX('Metas Lubrificantes'!$A:$XR,MATCH(Graxa!E2,'Metas Lubrificantes'!A:A,0),MATCH(Graxa!U2,'Metas Lubrificantes'!$1:$1,0)+12),"-")} -> 1.4333333 | O2: =IFERROR(N2/J2,"-") -> 0.11944444 | P2: {=IFERROR(INDEX('Metas Lubrificantes'!$A:$XR,MATCH(Graxa!E2,'Metas Lubrificantes'!A:A,0),MATCH(Graxa!U2,'Metas Lubrificantes'!$1:$1,0)+13),"-")} -> 1.0888889 | Q2: =IFERROR(P2/J2,"-") -> 0.090740741 | R2: {=IFERROR(INDEX('Metas Lubrificantes'!$A:$XR,MATCH(Graxa!E2,'Metas Lubrificantes'!A:A,0),MATCH(Graxa!U2,'Metas Lubrificantes'!$1:$1,0)+14),"-")} -> 0.5 | S2: =IFERROR(R2/J2,"-") -> 0.041666667 | T2: =IFERROR(IF(M2<=S2,"EXCELENTE",IF(M2<=Q2,"BOM",IF(M2<=O2,"ATENÇÃO",IF(M2>O2,"CRÍTICO","-")))),"-") -> BOM | U2: GRAXA | V2: C01 | Y2: 170 | Z2: =IFERROR(Y2-I2,"-") -> 169
A3: =IFERROR(YEAR(C3),"-") -> 2026 | B3: =IFERROR(DATE(YEAR(C3),MONTH(C3),MONTH(C3)),"-") -> 46023 | C3: 46023 | D3: FELLER2 | E3: =IFERROR(VLOOKUP(D3,Cadastros!A:B,2,FALSE),"-") -> FELLER BUNCHER 2 | F3: =IFERROR(VLOOKUP(E3,Cadastros!B:D,3,FALSE),"-") -> CORTE | G3: 2000 | H3: 2008 | I3: 0.5 | J3: =IFERROR(IF(H3-G3<0,"-",H3-G3),"-") -> 8 | K3: =IFERROR(IF(C3>=TODAY(),"",SUMIFS(I:I,E:E,E3,C:C,C3,B:B,B3)/SUMIFS(J:J,E:E,E3,C:C,C3,B:B,B3)),0) -> 0.0625 | L3: =IFERROR(IF(K3<=S3,"EXCELENTE",IF(K3<=Q3,"BOM",IF(K3<=O3,"ATENÇÃO",IF(K3>O3,"CRÍTICO","-")))),"-") -> EXCELENTE | M3: =IFERROR(I3/J3,"-") -> 0.0625 | N3: {=IFERROR(INDEX('Metas Lubrificantes'!$A:$XR,MATCH(Graxa!E3,'Metas Lubrificantes'!A:A,0),MATCH(Graxa!U3,'Metas Lubrificantes'!$1:$1,0)+12),"-")} -> 0.65833333 | O3: =IFERROR(N3/J3,"-") -> 0.082291667 | P3: {=IFERROR(INDEX('Metas Lubrificantes'!$A:$XR,MATCH(Graxa!E3,'Metas Lubrificantes'!A:A,0),MATCH(Graxa!U3,'Metas Lubrificantes'!$1:$1,0)+13),"-")} -> 0.69444444 | Q3: =IFERROR(P3/J3,"-") -> 0.086805556 | R3: {=IFERROR(INDEX('Metas Lubrificantes'!$A:$XR,MATCH(Graxa!E3,'Metas Lubrificantes'!A:A,0),MATCH(Graxa!U3,'Metas Lubrificantes'!$1:$1,0)+14),"-")} -> 0.5 | S3: =IFERROR(R3/J3,"-") -> 0.0625 | T3: =IFERROR(IF(M3<=S3,"EXCELENTE",IF(M3<=Q3,"BOM",IF(M3<=O3,"ATENÇÃO",IF(M3>O3,"CRÍTICO","-")))),"-") -> EXCELENTE | U3: GRAXA | V3: C01 | Y3: {=IFERROR(X3+IF(C3<C2,LARGE(LOOKUP(V3,$V$1:$V2,$Z$1:$Z2),1),LOOKUP(2,1/($V$1:$V2=V3),($Z$1:$Z2))),"-")} -> 169 | Z3: =IFERROR(Y3-I3,"-") -> 168.5
A4: =IFERROR(YEAR(C4),"-") -> 2026 | B4: =IFERROR(DATE(YEAR(C4),MONTH(C4),MONTH(C4)),"-") -> 46023 | C4: 46023 | D4: SKIDDER1 | E4: =IFERROR(VLOOKUP(D4,Cadastros!A:B,2,FALSE),"-") -> SKIDDER 1 | F4: =IFERROR(VLOOKUP(E4,Cadastros!B:D,3,FALSE),"-") -> ARRASTE | G4: 1200 | H4: 1215 | I4: 1.5 | J4: =IFERROR(IF(H4-G4<0,"-",H4-G4),"-") -> 15 | K4: =IFERROR(IF(C4>=TODAY(),"",SUMIFS(I:I,E:E,E4,C:C,C4,B:B,B4)/SUMIFS(J:J,E:E,E4,C:C,C4,B:B,B4)),0) -> 0.1 | L4: =IFERROR(IF(K4<=S4,"EXCELENTE",IF(K4<=Q4,"BOM",IF(K4<=O4,"ATENÇÃO",IF(K4>O4,"CRÍTICO","-")))),"-") -> CRÍTICO | M4: =IFERROR(I4/J4,"-") -> 0.1 | N4: {=IFERROR(INDEX('Metas Lubrificantes'!$A:$XR,MATCH(Graxa!E4,'Metas Lubrificantes'!A:A,0),MATCH(Graxa!U4,'Metas Lubrificantes'!$1:$1,0)+12),"-")} -> 1.2166667 | O4: =IFERROR(N4/J4,"-") -> 0.081111111 | P4: {=IFERROR(INDEX('Metas Lubrificantes'!$A:$XR,MATCH(Graxa!E4,'Metas Lubrificantes'!A:A,0),MATCH(Graxa!U4,'Metas Lubrificantes'!$1:$1,0)+13),"-")} -> 0.88888889 | Q4: =IFERROR(P4/J4,"-") -> 0.059259259 | R4: {=IFERROR(INDEX('Metas Lubrificantes'!$A:$XR,MATCH(Graxa!E4,'Metas Lubrificantes'!A:A,0),MATCH(Graxa!U4,'Metas Lubrificantes'!$1:$1,0)+14),"-")} -> 0.5 | S4: =IFERROR(R4/J4,"-") -> 0.033333333 | T4: =IFERROR(IF(M4<=S4,"EXCELENTE",IF(M4<=Q4,"BOM",IF(M4<=O4,"ATENÇÃO",IF(M4>O4,"CRÍTICO","-")))),"-") -> CRÍTICO | U4: GRAXA | V4: C01 | Y4: {=IFERROR(X4+IF(C4<C3,LARGE(LOOKUP(V4,$V$1:$V3,$Z$1:$Z3),1),LOOKUP(2,1/($V$1:$V3=V4),($Z$1:$Z3))),"-")} -> 168.5 | Z4: =IFERROR(Y4-I4,"-") -> 167
A5: =IFERROR(YEAR(C5),"-") -> 2026 | B5: =IFERROR(DATE(YEAR(C5),MONTH(C5),MONTH(C5)),"-") -> 46023 | C5: 46023 | D5: SKIDDER2 | E5: =IFERROR(VLOOKUP(D5,Cadastros!A:B,2,FALSE),"-") -> SKIDDER 2 | F5: =IFERROR(VLOOKUP(E5,Cadastros!B:D,3,FALSE),"-") -> ARRASTE | G5: 2100 | H5: 2106 | I5: 1 | J5: =IFERROR(IF(H5-G5<0,"-",H5-G5),"-") -> 6 | K5: =IFERROR(IF(C5>=TODAY(),"",SUMIFS(I:I,E:E,E5,C:C,C5,B:B,B5)/SUMIFS(J:J,E:E,E5,C:C,C5,B:B,B5)),0) -> 0.16666667 | L5: =IFERROR(IF(K5<=S5,"EXCELENTE",IF(K5<=Q5,"BOM",IF(K5<=O5,"ATENÇÃO",IF(K5>O5,"CRÍTICO","-")))),"-") -> BOM | M5: =IFERROR(I5/J5,"-") -> 0.16666667 | N5: {=IFERROR(INDEX('Metas Lubrificantes'!$A:$XR,MATCH(Graxa!E5,'Metas Lubrificantes'!A:A,0),MATCH(Graxa!U5,'Metas Lubrificantes'!$1:$1,0)+12),"-")} -> 1.3166667 | O5: =IFERROR(N5/J5,"-") -> 0.21944444 | P5: {=IFERROR(INDEX('Metas Lubrificantes'!$A:$XR,MATCH(Graxa!E5,'Metas Lubrificantes'!A:A,0),MATCH(Graxa!U5,'Metas Lubrificantes'!$1:$1,0)+13),"-")} -> 1.125 | Q5: =IFERROR(P5/J5,"-") -> 0.1875 | R5: {=IFERROR(INDEX('Metas Lubrificantes'!$A:$XR,MATCH(Graxa!E5,'Metas Lubrificantes'!A:A,0),MATCH(Graxa!U5,'Metas Lubrificantes'!$1:$1,0)+14),"-")} -> 0.5 | S5: =IFERROR(R5/J5,"-") -> 0.083333333 | T5: =IFERROR(IF(M5<=S5,"EXCELENTE",IF(M5<=Q5,"BOM",IF(M5<=O5,"ATENÇÃO",IF(M5>O5,"CRÍTICO","-")))),"-") -> BOM | U5: GRAXA | V5: C01 | Y5: {=IFERROR(X5+IF(C5<C4,LARGE(LOOKUP(V5,$V$1:$V4,$Z$1:$Z4),1),LOOKUP(2,1/($V$1:$V4=V5),($Z$1:$Z4))),"-")} -> 167 | Z5: =IFERROR(Y5-I5,"-") -> 166
A6: =IFERROR(YEAR(C6),"-") -> 2026 | B6: =IFERROR(DATE(YEAR(C6),MONTH(C6),MONTH(C6)),"-") -> 46023 | C6: 46024 | D6: FELLER2 | E6: =IFERROR(VLOOKUP(D6,Cadastros!A:B,2,FALSE),"-") -> FELLER BUNCHER 2 | F6: =IFERROR(VLOOKUP(E6,Cadastros!B:D,3,FALSE),"-") -> CORTE | G6: {=IF(C6<C5,LARGE(LOOKUP(D6,$D$1:$D5,$H$1:$H5),1),LOOKUP(2,1/($D$1:$D5=D6),($H$1:$H5)))} -> 2008 | H6: 2012 | I6: 1 | J6: =IFERROR(IF(H6-G6<0,"-",H6-G6),"-") -> 4 | K6: =IFERROR(IF(C6>=TODAY(),"",SUMIFS(I:I,E:E,E6,C:C,C6,B:B,B6)/SUMIFS(J:J,E:E,E6,C:C,C6,B:B,B6)),0) -> 0.088235294 | L6: =IFERROR(IF(K6<=S6,"EXCELENTE",IF(K6<=Q6,"BOM",IF(K6<=O6,"ATENÇÃO",IF(K6>O6,"CRÍTICO","-")))),"-") -> EXCELENTE | M6: =IFERROR(I6/J6,"-") -> 0.25 | N6: {=IFERROR(INDEX('Metas Lubrificantes'!$A:$XR,MATCH(Graxa!E6,'Metas Lubrificantes'!A:A,0),MATCH(Graxa!U6,'Metas Lubrificantes'!$1:$1,0)+12),"-")} -> 0.65833333 | O6: =IFERROR(N6/J6,"-") -> 0.16458333 | P6: {=IFERROR(INDEX('Metas Lubrificantes'!$A:$XR,MATCH(Graxa!E6,'Metas Lubrificantes'!A:A,0),MATCH(Graxa!U6,'Metas Lubrificantes'!$1:$1,0)+13),"-")} -> 0.69444444 | Q6: =IFERROR(P6/J6,"-") -> 0.17361111 | R6: {=IFERROR(INDEX('Metas Lubrificantes'!$A:$XR,MATCH(Graxa!E6,'Metas Lubrificantes'!A:A,0),MATCH(Graxa!U6,'Metas Lubrificantes'!$1:$1,0)+14),"-")} -> 0.5 | S6: =IFERROR(R6/J6,"-") -> 0.125 | T6: =IFERROR(IF(M6<=S6,"EXCELENTE",IF(M6<=Q6,"BOM",IF(M6<=O6,"ATENÇÃO",IF(M6>O6,"CRÍTICO","-")))),"-") -> CRÍTICO | U6: GRAXA | V6: C01 | Y6: {=IFERROR(X6+IF(C6<C5,LARGE(LOOKUP(V6,$V$1:$V5,$Z$1:$Z5),1),LOOKUP(2,1/($V$1:$V5=V6),($Z$1:$Z5))),"-")} -> 166 | Z6: =IFERROR(Y6-I6,"-") -> 165
A7: =IFERROR(YEAR(C7),"-") -> 2026 | B7: =IFERROR(DATE(YEAR(C7),MONTH(C7),MONTH(C7)),"-") -> 46023 | C7: 46024 | D7: GARRA2 | E7: =IFERROR(VLOOKUP(D7,Cadastros!A:B,2,FALSE),"-") -> GARRA TRAÇADORA 2 | F7: =IFERROR(VLOOKUP(E7,Cadastros!B:D,3,FALSE),"-") -> TRAÇAMENTO | G7: 700 | H7: 711 | I7: 1 | J7: =IFERROR(IF(H7-G7<0,"-",H7-G7),"-") -> 11 | K7: =IFERROR(IF(C7>=TODAY(),"",SUMIFS(I:I,E:E,E7,C:C,C7,B:B,B7)/SUMIFS(J:J,E:E,E7,C:C,C7,B:B,B7)),0) -> 0.090909091 | L7: =IFERROR(IF(K7<=S7,"EXCELENTE",IF(K7<=Q7,"BOM",IF(K7<=O7,"ATENÇÃO",IF(K7>O7,"CRÍTICO","-")))),"-") -> EXCELENTE | M7: =IFERROR(I7/J7,"-") -> 0.090909091 | N7: {=IFERROR(INDEX('Metas Lubrificantes'!$A:$XR,MATCH(Graxa!E7,'Metas Lubrificantes'!A:A,0),MATCH(Graxa!U7,'Metas Lubrificantes'!$1:$1,0)+12),"-")} -> 1 | O7: =IFERROR(N7/J7,"-") -> 0.090909091 | P7: {=IFERROR(INDEX('Metas Lubrificantes'!$A:$XR,MATCH(Graxa!E7,'Metas Lubrificantes'!A:A,0),MATCH(Graxa!U7,'Metas Lubrificantes'!$1:$1,0)+13),"-")} -> 1 | Q7: =IFERROR(P7/J7,"-") -> 0.090909091 | R7: {=IFERROR(INDEX('Metas Lubrificantes'!$A:$XR,MATCH(Graxa!E7,'Metas Lubrificantes'!A:A,0),MATCH(Graxa!U7,'Metas Lubrificantes'!$1:$1,0)+14),"-")} -> 1 | S7: =IFERROR(R7/J7,"-") -> 0.090909091 | T7: =IFERROR(IF(M7<=S7,"EXCELENTE",IF(M7<=Q7,"BOM",IF(M7<=O7,"ATENÇÃO",IF(M7>O7,"CRÍTICO","-")))),"-") -> EXCELENTE | U7: GRAXA | V7: C01 | Y7: {=IFERROR(X7+IF(C7<C6,LARGE(LOOKUP(V7,$V$1:$V6,$Z$1:$Z6),1),LOOKUP(2,1/($V$1:$V6=V7),($Z$1:$Z6))),"-")} -> 165 | Z7: =IFERROR(Y7-I7,"-") -> 164
A8: =IFERROR(YEAR(C8),"-") -> 2026 | B8: =IFERROR(DATE(YEAR(C8),MONTH(C8),MONTH(C8)),"-") -> 46023 | C8: 46024 | D8: FELLER2 | E8: =IFERROR(VLOOKUP(D8,Cadastros!A:B,2,FALSE),"-") -> FELLER BUNCHER 2 | F8: =IFERROR(VLOOKUP(E8,Cadastros!B:D,3,FALSE),"-") -> CORTE | G8: {=IF(C8<C7,LARGE(LOOKUP(D8,$D$1:$D7,$H$1:$H7),1),LOOKUP(2,1/($D$1:$D7=D8),($H$1:$H7)))} -> 2012 | H8: 2025 | I8: 0.5 | J8: =IFERROR(IF(H8-G8<0,"-",H8-G8),"-") -> 13 | K8: =IFERROR(IF(C8>=TODAY(),"",SUMIFS(I:I,E:E,E8,C:C,C8,B:B,B8)/SUMIFS(J:J,E:E,E8,C:C,C8,B:B,B8)),0) -> 0.088235294 | L8: =IFERROR(IF(K8<=S8,"EXCELENTE",IF(K8<=Q8,"BOM",IF(K8<=O8,"ATENÇÃO",IF(K8>O8,"CRÍTICO","-")))),"-") -> CRÍTICO | M8: =IFERROR(I8/J8,"-") -> 0.038461538 | N8: {=IFERROR(INDEX('Metas Lubrificantes'!$A:$XR,MATCH(Graxa!E8,'Metas Lubrificantes'!A:A,0),MATCH(Graxa!U8,'Metas Lubrificantes'!$1:$1,0)+12),"-")} -> 0.65833333 | O8: =IFERROR(N8/J8,"-") -> 0.050641026 | P8: {=IFERROR(INDEX('Metas Lubrificantes'!$A:$XR,MATCH(Graxa!E8,'Metas Lubrificantes'!A:A,0),MATCH(Graxa!U8,'Metas Lubrificantes'!$1:$1,0)+13),"-")} -> 0.69444444 | Q8: =IFERROR(P8/J8,"-") -> 0.053418803 | R8: {=IFERROR(INDEX('Metas Lubrificantes'!$A:$XR,MATCH(Graxa!E8,'Metas Lubrificantes'!A:A,0),MATCH(Graxa!U8,'Metas Lubrificantes'!$1:$1,0)+14),"-")} -> 0.5 | S8: =IFERROR(R8/J8,"-") -> 0.038461538 | T8: =IFERROR(IF(M8<=S8,"EXCELENTE",IF(M8<=Q8,"BOM",IF(M8<=O8,"ATENÇÃO",IF(M8>O8,"CRÍTICO","-")))),"-") -> EXCELENTE | U8: GRAXA | V8: C01 | Y8: {=IFERROR(X8+IF(C8<C7,LARGE(LOOKUP(V8,$V$1:$V7,$Z$1:$Z7),1),LOOKUP(2,1/($V$1:$V7=V8),($Z$1:$Z7))),"-")} -> 164 | Z8: =IFERROR(Y8-I8,"-") -> 163.5
A9: =IFERROR(YEAR(C9),"-") -> 2026 | B9: =IFERROR(DATE(YEAR(C9),MONTH(C9),MONTH(C9)),"-") -> 46023 | C9: 46024 | D9: FELLER1 | E9: =IFERROR(VLOOKUP(D9,Cadastros!A:B,2,FALSE),"-") -> FELLER BUNCHER 1 | F9: =IFERROR(VLOOKUP(E9,Cadastros!B:D,3,FALSE),"-") -> CORTE | G9: {=IF(C9<C8,LARGE(LOOKUP(D9,$D$1:$D8,$H$1:$H8),1),LOOKUP(2,1/($D$1:$D8=D9),($H$1:$H8)))} -> 1012 | H9: 1018 | I9: 0.5 | J9: =IFERROR(IF(H9-G9<0,"-",H9-G9),"-") -> 6 | K9: =IFERROR(IF(C9>=TODAY(),"",SUMIFS(I:I,E:E,E9,C:C,C9,B:B,B9)/SUMIFS(J:J,E:E,E9,C:C,C9,B:B,B9)),0) -> 0.083333333 | L9: =IFERROR(IF(K9<=S9,"EXCELENTE",IF(K9<=Q9,"BOM",IF(K9<=O9,"ATENÇÃO",IF(K9>O9,"CRÍTICO","-")))),"-") -> EXCELENTE | M9: =IFERROR(I9/J9,"-") -> 0.083333333 | N9: {=IFERROR(INDEX('Metas Lubrificantes'!$A:$XR,MATCH(Graxa!E9,'Metas Lubrificantes'!A:A,0),MATCH(Graxa!U9,'Metas Lubrificantes'!$1:$1,0)+12),"-")} -> 1.4333333 | O9: =IFERROR(N9/J9,"-") -> 0.23888889 | P9: {=IFERROR(INDEX('Metas Lubrificantes'!$A:$XR,MATCH(Graxa!E9,'Metas Lubrificantes'!A:A,0),MATCH(Graxa!U9,'Metas Lubrificantes'!$1:$1,0)+13),"-")} -> 1.0888889 | Q9: =IFERROR(P9/J9,"-") -> 0.18148148 | R9: {=IFERROR(INDEX('Metas Lubrificantes'!$A:$XR,MATCH(Graxa!E9,'Metas Lubrificantes'!A:A,0),MATCH(Graxa!U9,'Metas Lubrificantes'!$1:$1,0)+14),"-")} -> 0.5 | S9: =IFERROR(R9/J9,"-") -> 0.083333333 | T9: =IFERROR(IF(M9<=S9,"EXCELENTE",IF(M9<=Q9,"BOM",IF(M9<=O9,"ATENÇÃO",IF(M9>O9,"CRÍTICO","-")))),"-") -> EXCELENTE | U9: GRAXA | V9: C01 | Y9: {=IFERROR(X9+IF(C9<C8,LARGE(LOOKUP(V9,$V$1:$V8,$Z$1:$Z8),1),LOOKUP(2,1/($V$1:$V8=V9),($Z$1:$Z8))),"-")} -> 163.5 | Z9: =IFERROR(Y9-I9,"-") -> 163
A10: =IFERROR(YEAR(C10),"-") -> 2026 | B10: =IFERROR(DATE(YEAR(C10),MONTH(C10),MONTH(C10)),"-") -> 46023 | C10: 46024 | D10: SKIDDER2 | E10: =IFERROR(VLOOKUP(D10,Cadastros!A:B,2,FALSE),"-") -> SKIDDER 2 | F10: =IFERROR(VLOOKUP(E10,Cadastros!B:D,3,FALSE),"-") -> ARRASTE | G10: {=IF(C10<C9,LARGE(LOOKUP(D10,$D$1:$D9,$H$1:$H9),1),LOOKUP(2,1/($D$1:$D9=D10),($H$1:$H9)))} -> 2106 | H10: 2110 | I10: 0.5 | J10: =IFERROR(IF(H10-G10<0,"-",H10-G10),"-") -> 4 | K10: =IFERROR(IF(C10>=TODAY(),"",SUMIFS(I:I,E:E,E10,C:C,C10,B:B,B10)/SUMIFS(J:J,E:E,E10,C:C,C10,B:B,B10)),0) -> 0.27777778 | L10: =IFERROR(IF(K10<=S10,"EXCELENTE",IF(K10<=Q10,"BOM",IF(K10<=O10,"ATENÇÃO",IF(K10>O10,"CRÍTICO","-")))),"-") -> BOM | M10: =IFERROR(I10/J10,"-") -> 0.125 | N10: {=IFERROR(INDEX('Metas Lubrificantes'!$A:$XR,MATCH(Graxa!E10,'Metas Lubrificantes'!A:A,0),MATCH(Graxa!U10,'Metas Lubrificantes'!$1:$1,0)+12),"-")} -> 1.3166667 | O10: =IFERROR(N10/J10,"-") -> 0.32916667 | P10: {=IFERROR(INDEX('Metas Lubrificantes'!$A:$XR,MATCH(Graxa!E10,'Metas Lubrificantes'!A:A,0),MATCH(Graxa!U10,'Metas Lubrificantes'!$1:$1,0)+13),"-")} -> 1.125 | Q10: =IFERROR(P10/J10,"-") -> 0.28125 | R10: {=IFERROR(INDEX('Metas Lubrificantes'!$A:$XR,MATCH(Graxa!E10,'Metas Lubrificantes'!A:A,0),MATCH(Graxa!U10,'Metas Lubrificantes'!$1:$1,0)+14),"-")} -> 0.5 | S10: =IFERROR(R10/J10,"-") -> 0.125 | T10: =IFERROR(IF(M10<=S10,"EXCELENTE",IF(M10<=Q10,"BOM",IF(M10<=O10,"ATENÇÃO",IF(M10>O10,"CRÍTICO","-")))),"-") -> EXCELENTE | U10: GRAXA | V10: C01 | Y10: {=IFERROR(X10+IF(C10<C9,LARGE(LOOKUP(V10,$V$1:$V9,$Z$1:$Z9),1),LOOKUP(2,1/($V$1:$V9=V10),($Z$1:$Z9))),"-")} -> 163 | Z10: =IFERROR(Y10-I10,"-") -> 162.5
A11: =IFERROR(YEAR(C11),"-") -> 2026 | B11: =IFERROR(DATE(YEAR(C11),MONTH(C11),MONTH(C11)),"-") -> 46023 | C11: 46024 | D11: SKIDDER2 | E11: =IFERROR(VLOOKUP(D11,Cadastros!A:B,2,FALSE),"-") -> SKIDDER 2 | F11: =IFERROR(VLOOKUP(E11,Cadastros!B:D,3,FALSE),"-") -> ARRASTE | G11: {=IF(C11<C10,LARGE(LOOKUP(D11,$D$1:$D10,$H$1:$H10),1),LOOKUP(2,1/($D$1:$D10=D11),($H$1:$H10)))} -> 2110 | H11: 2115 | I11: 2 | J11: =IFERROR(IF(H11-G11<0,"-",H11-G11),"-") -> 5 | K11: =IFERROR(IF(C11>=TODAY(),"",SUMIFS(I:I,E:E,E11,C:C,C11,B:B,B11)/SUMIFS(J:J,E:E,E11,C:C,C11,B:B,B11)),0) -> 0.27777778 | L11: =IFERROR(IF(K11<=S11,"EXCELENTE",IF(K11<=Q11,"BOM",IF(K11<=O11,"ATENÇÃO",IF(K11>O11,"CRÍTICO","-")))),"-") -> CRÍTICO | M11: =IFERROR(I11/J11,"-") -> 0.4 | N11: {=IFERROR(INDEX('Metas Lubrificantes'!$A:$XR,MATCH(Graxa!E11,'Metas Lubrificantes'!A:A,0),MATCH(Graxa!U11,'Metas Lubrificantes'!$1:$1,0)+12),"-")} -> 1.3166667 | O11: =IFERROR(N11/J11,"-") -> 0.26333333 | P11: {=IFERROR(INDEX('Metas Lubrificantes'!$A:$XR,MATCH(Graxa!E11,'Metas Lubrificantes'!A:A,0),MATCH(Graxa!U11,'Metas Lubrificantes'!$1:$1,0)+13),"-")} -> 1.125 | Q11: =IFERROR(P11/J11,"-") -> 0.225 | R11: {=IFERROR(INDEX('Metas Lubrificantes'!$A:$XR,MATCH(Graxa!E11,'Metas Lubrificantes'!A:A,0),MATCH(Graxa!U11,'Metas Lubrificantes'!$1:$1,0)+14),"-")} -> 0.5 | S11: =IFERROR(R11/J11,"-") -> 0.1 | T11: =IFERROR(IF(M11<=S11,"EXCELENTE",IF(M11<=Q11,"BOM",IF(M11<=O11,"ATENÇÃO",IF(M11>O11,"CRÍTICO","-")))),"-") -> CRÍTICO | U11: GRAXA | V11: C01 | Y11: {=IFERROR(X11+IF(C11<C10,LARGE(LOOKUP(V11,$V$1:$V10,$Z$1:$Z10),1),LOOKUP(2,1/($V$1:$V10=V11),($Z$1:$Z10))),"-")} -> 162.5 | Z11: =IFERROR(Y11-I11,"-") -> 160.5
A12: =IFERROR(YEAR(C12),"-") -> 2026 | B12: =IFERROR(DATE(YEAR(C12),MONTH(C12),MONTH(C12)),"-") -> 46023 | C12: 46025 | D12: FELLER1 | E12: =IFERROR(VLOOKUP(D12,Cadastros!A:B,2,FALSE),"-") -> FELLER BUNCHER 1 | F12: =IFERROR(VLOOKUP(E12,Cadastros!B:D,3,FALSE),"-") -> CORTE | G12: {=IF(C12<C11,LARGE(LOOKUP(D12,$D$1:$D11,$H$1:$H11),1),LOOKUP(2,1/($D$1:$D11=D12),($H$1:$H11)))} -> 1018 | H12: 1025 | I12: 2 | J12: =IFERROR(IF(H12-G12<0,"-",H12-G12),"-") -> 7 | K12: =IFERROR(IF(C12>=TODAY(),"",SUMIFS(I:I,E:E,E12,C:C,C12,B:B,B12)/SUMIFS(J:J,E:E,E12,C:C,C12,B:B,B12)),0) -> 0.28571429 | L12: =IFERROR(IF(K12<=S12,"EXCELENTE",IF(K12<=Q12,"BOM",IF(K12<=O12,"ATENÇÃO",IF(K12>O12,"CRÍTICO","-")))),"-") -> CRÍTICO | M12: =IFERROR(I12/J12,"-") -> 0.28571429 | N12: {=IFERROR(INDEX('Metas Lubrificantes'!$A:$XR,MATCH(Graxa!E12,'Metas Lubrificantes'!A:A,0),MATCH(Graxa!U12,'Metas Lubrificantes'!$1:$1,0)+12),"-")} -> 1.4333333 | O12: =IFERROR(N12/J12,"-") -> 0.2047619 | P12: {=IFERROR(INDEX('Metas Lubrificantes'!$A:$XR,MATCH(Graxa!E12,'Metas Lubrificantes'!A:A,0),MATCH(Graxa!U12,'Metas Lubrificantes'!$1:$1,0)+13),"-")} -> 1.0888889 | Q12: =IFERROR(P12/J12,"-") -> 0.15555556 | R12: {=IFERROR(INDEX('Metas Lubrificantes'!$A:$XR,MATCH(Graxa!E12,'Metas Lubrificantes'!A:A,0),MATCH(Graxa!U12,'Metas Lubrificantes'!$1:$1,0)+14),"-")} -> 0.5 | S12: =IFERROR(R12/J12,"-") -> 0.071428571 | T12: =IFERROR(IF(M12<=S12,"EXCELENTE",IF(M12<=Q12,"BOM",IF(M12<=O12,"ATENÇÃO",IF(M12>O12,"CRÍTICO","-")))),"-") -> CRÍTICO | U12: GRAXA | V12: C01 | Y12: {=IFERROR(X12+IF(C12<C11,LARGE(LOOKUP(V12,$V$1:$V11,$Z$1:$Z11),1),LOOKUP(2,1/($V$1:$V11=V12),($Z$1:$Z11))),"-")} -> 160.5 | Z12: =IFERROR(Y12-I12,"-") -> 158.5
A13: =IFERROR(YEAR(C13),"-") -> 2026 | B13: =IFERROR(DATE(YEAR(C13),MONTH(C13),MONTH(C13)),"-") -> 46023 | C13: 46025 | D13: GARRA1 | E13: =IFERROR(VLOOKUP(D13,Cadastros!A:B,2,FALSE),"-") -> GARRA TRAÇADORA 1 | F13: =IFERROR(VLOOKUP(E13,Cadastros!B:D,3,FALSE),"-") -> TRAÇAMENTO | G13: 500 | H13: 510 | I13: 1 | J13: =IFERROR(IF(H13-G13<0,"-",H13-G13),"-") -> 10 | K13: =IFERROR(IF(C13>=TODAY(),"",SUMIFS(I:I,E:E,E13,C:C,C13,B:B,B13)/SUMIFS(J:J,E:E,E13,C:C,C13,B:B,B13)),0) -> 0.1 | L13: =IFERROR(IF(K13<=S13,"EXCELENTE",IF(K13<=Q13,"BOM",IF(K13<=O13,"ATENÇÃO",IF(K13>O13,"CRÍTICO","-")))),"-") -> EXCELENTE | M13: =IFERROR(I13/J13,"-") -> 0.1 | N13: {=IFERROR(INDEX('Metas Lubrificantes'!$A:$XR,MATCH(Graxa!E13,'Metas Lubrificantes'!A:A,0),MATCH(Graxa!U13,'Metas Lubrificantes'!$1:$1,0)+12),"-")} -> 1 | O13: =IFERROR(N13/J13,"-") -> 0.1 | P13: {=IFERROR(INDEX('Metas Lubrificantes'!$A:$XR,MATCH(Graxa!E13,'Metas Lubrificantes'!A:A,0),MATCH(Graxa!U13,'Metas Lubrificantes'!$1:$1,0)+13),"-")} -> 1 | Q13: =IFERROR(P13/J13,"-") -> 0.1 | R13: {=IFERROR(INDEX('Metas Lubrificantes'!$A:$XR,MATCH(Graxa!E13,'Metas Lubrificantes'!A:A,0),MATCH(Graxa!U13,'Metas Lubrificantes'!$1:$1,0)+14),"-")} -> 1 | S13: =IFERROR(R13/J13,"-") -> 0.1 | T13: =IFERROR(IF(M13<=S13,"EXCELENTE",IF(M13<=Q13,"BOM",IF(M13<=O13,"ATENÇÃO",IF(M13>O13,"CRÍTICO","-")))),"-") -> EXCELENTE | U13: GRAXA | V13: C01 | Y13: {=IFERROR(X13+IF(C13<C12,LARGE(LOOKUP(V13,$V$1:$V12,$Z$1:$Z12),1),LOOKUP(2,1/($V$1:$V12=V13),($Z$1:$Z12))),"-")} -> 158.5 | Z13: =IFERROR(Y13-I13,"-") -> 157.5
A14: =IFERROR(YEAR(C14),"-") -> 2026 | B14: =IFERROR(DATE(YEAR(C14),MONTH(C14),MONTH(C14)),"-") -> 46023 | C14: 46025 | D14: SKIDDER1 | E14: =IFERROR(VLOOKUP(D14,Cadastros!A:B,2,FALSE),"-") -> SKIDDER 1 | F14: =IFERROR(VLOOKUP(E14,Cadastros!B:D,3,FALSE),"-") -> ARRASTE | G14: {=IF(C14<C13,LARGE(LOOKUP(D14,$D$1:$D13,$H$1:$H13),1),LOOKUP(2,1/($D$1:$D13=D14),($H$1:$H13)))} -> 1215 | H14: 1219 | I14: 1 | J14: =IFERROR(IF(H14-G14<0,"-",H14-G14),"-") -> 4 | K14: =IFERROR(IF(C14>=TODAY(),"",SUMIFS(I:I,E:E,E14,C:C,C14,B:B,B14)/SUMIFS(J:J,E:E,E14,C:C,C14,B:B,B14)),0) -> 0.25 | L14: =IFERROR(IF(K14<=S14,"EXCELENTE",IF(K14<=Q14,"BOM",IF(K14<=O14,"ATENÇÃO",IF(K14>O14,"CRÍTICO","-")))),"-") -> ATENÇÃO | M14: =IFERROR(I14/J14,"-") -> 0.25 | N14: {=IFERROR(INDEX('Metas Lubrificantes'!$A:$XR,MATCH(Graxa!E14,'Metas Lubrificantes'!A:A,0),MATCH(Graxa!U14,'Metas Lubrificantes'!$1:$1,0)+12),"-")} -> 1.2166667 | O14: =IFERROR(N14/J14,"-") -> 0.30416667 | P14: {=IFERROR(INDEX('Metas Lubrificantes'!$A:$XR,MATCH(Graxa!E14,'Metas Lubrificantes'!A:A,0),MATCH(Graxa!U14,'Metas Lubrificantes'!$1:$1,0)+13),"-")} -> 0.88888889 | Q14: =IFERROR(P14/J14,"-") -> 0.22222222 | R14: {=IFERROR(INDEX('Metas Lubrificantes'!$A:$XR,MATCH(Graxa!E14,'Metas Lubrificantes'!A:A,0),MATCH(Graxa!U14,'Metas Lubrificantes'!$1:$1,0)+14),"-")} -> 0.5 | S14: =IFERROR(R14/J14,"-") -> 0.125 | T14: =IFERROR(IF(M14<=S14,"EXCELENTE",IF(M14<=Q14,"BOM",IF(M14<=O14,"ATENÇÃO",IF(M14>O14,"CRÍTICO","-")))),"-") -> ATENÇÃO | U14: GRAXA | V14: C01 | Y14: {=IFERROR(X14+IF(C14<C13,LARGE(LOOKUP(V14,$V$1:$V13,$Z$1:$Z13),1),LOOKUP(2,1/($V$1:$V13=V14),($Z$1:$Z13))),"-")} -> 157.5 | Z14: =IFERROR(Y14-I14,"-") -> 156.5
A15: =IFERROR(YEAR(C15),"-") -> 2026 | B15: =IFERROR(DATE(YEAR(C15),MONTH(C15),MONTH(C15)),"-") -> 46023 | C15: 46025 | D15: GARRA2 | E15: =IFERROR(VLOOKUP(D15,Cadastros!A:B,2,FALSE),"-") -> GARRA TRAÇADORA 2 | F15: =IFERROR(VLOOKUP(E15,Cadastros!B:D,3,FALSE),"-") -> TRAÇAMENTO | G15: {=IF(C15<C14,LARGE(LOOKUP(D15,$D$1:$D14,$H$1:$H14),1),LOOKUP(2,1/($D$1:$D14=D15),($H$1:$H14)))} -> 711 | H15: 722 | I15: 1 | J15: =IFERROR(IF(H15-G15<0,"-",H15-G15),"-") -> 11 | K15: =IFERROR(IF(C15>=TODAY(),"",SUMIFS(I:I,E:E,E15,C:C,C15,B:B,B15)/SUMIFS(J:J,E:E,E15,C:C,C15,B:B,B15)),0) -> 0.090909091 | L15: =IFERROR(IF(K15<=S15,"EXCELENTE",IF(K15<=Q15,"BOM",IF(K15<=O15,"ATENÇÃO",IF(K15>O15,"CRÍTICO","-")))),"-") -> EXCELENTE | M15: =IFERROR(I15/J15,"-") -> 0.090909091 | N15: {=IFERROR(INDEX('Metas Lubrificantes'!$A:$XR,MATCH(Graxa!E15,'Metas Lubrificantes'!A:A,0),MATCH(Graxa!U15,'Metas Lubrificantes'!$1:$1,0)+12),"-")} -> 1 | O15: =IFERROR(N15/J15,"-") -> 0.090909091 | P15: {=IFERROR(INDEX('Metas Lubrificantes'!$A:$XR,MATCH(Graxa!E15,'Metas Lubrificantes'!A:A,0),MATCH(Graxa!U15,'Metas Lubrificantes'!$1:$1,0)+13),"-")} -> 1 | Q15: =IFERROR(P15/J15,"-") -> 0.090909091 | R15: {=IFERROR(INDEX('Metas Lubrificantes'!$A:$XR,MATCH(Graxa!E15,'Metas Lubrificantes'!A:A,0),MATCH(Graxa!U15,'Metas Lubrificantes'!$1:$1,0)+14),"-")} -> 1 | S15: =IFERROR(R15/J15,"-") -> 0.090909091 | T15: =IFERROR(IF(M15<=S15,"EXCELENTE",IF(M15<=Q15,"BOM",IF(M15<=O15,"ATENÇÃO",IF(M15>O15,"CRÍTICO","-")))),"-") -> EXCELENTE | U15: GRAXA | V15: C01 | Y15: {=IFERROR(X15+IF(C15<C14,LARGE(LOOKUP(V15,$V$1:$V14,$Z$1:$Z14),1),LOOKUP(2,1/($V$1:$V14=V15),($Z$1:$Z14))),"-")} -> 156.5 | Z15: =IFERROR(Y15-I15,"-") -> 155.5
A16: =IFERROR(YEAR(C16),"-") -> 2026 | B16: =IFERROR(DATE(YEAR(C16),MONTH(C16),MONTH(C16)),"-") -> 46023 | C16: 46025 | D16: SKIDDER2 | E16: =IFERROR(VLOOKUP(D16,Cadastros!A:B,2,FALSE),"-") -> SKIDDER 2 | F16: =IFERROR(VLOOKUP(E16,Cadastros!B:D,3,FALSE),"-") -> ARRASTE | G16: {=IF(C16<C15,LARGE(LOOKUP(D16,$D$1:$D15,$H$1:$H15),1),LOOKUP(2,1/($D$1:$D15=D16),($H$1:$H15)))} -> 2115 | H16: 2123 | I16: 1 | J16: =IFERROR(IF(H16-G16<0,"-",H16-G16),"-") -> 8 | K16: =IFERROR(IF(C16>=TODAY(),"",SUMIFS(I:I,E:E,E16,C:C,C16,B:B,B16)/SUMIFS(J:J,E:E,E16,C:C,C16,B:B,B16)),0) -> 0.125 | L16: =IFERROR(IF(K16<=S16,"EXCELENTE",IF(K16<=Q16,"BOM",IF(K16<=O16,"ATENÇÃO",IF(K16>O16,"CRÍTICO","-")))),"-") -> BOM | M16: =IFERROR(I16/J16,"-") -> 0.125 | N16: {=IFERROR(INDEX('Metas Lubrificantes'!$A:$XR,MATCH(Graxa!E16,'Metas Lubrificantes'!A:A,0),MATCH(Graxa!U16,'Metas Lubrificantes'!$1:$1,0)+12),"-")} -> 1.3166667 | O16: =IFERROR(N16/J16,"-") -> 0.16458333 | P16: {=IFERROR(INDEX('Metas Lubrificantes'!$A:$XR,MATCH(Graxa!E16,'Metas Lubrificantes'!A:A,0),MATCH(Graxa!U16,'Metas Lubrificantes'!$1:$1,0)+13),"-")} -> 1.125 | Q16: =IFERROR(P16/J16,"-") -> 0.140625 | R16: {=IFERROR(INDEX('Metas Lubrificantes'!$A:$XR,MATCH(Graxa!E16,'Metas Lubrificantes'!A:A,0),MATCH(Graxa!U16,'Metas Lubrificantes'!$1:$1,0)+14),"-")} -> 0.5 | S16: =IFERROR(R16/J16,"-") -> 0.0625 | T16: =IFERROR(IF(M16<=S16,"EXCELENTE",IF(M16<=Q16,"BOM",IF(M16<=O16,"ATENÇÃO",IF(M16>O16,"CRÍTICO","-")))),"-") -> BOM | U16: GRAXA | V16: C01 | Y16: {=IFERROR(X16+IF(C16<C15,LARGE(LOOKUP(V16,$V$1:$V15,$Z$1:$Z15),1),LOOKUP(2,1/($V$1:$V15=V16),($Z$1:$Z15))),"-")} -> 155.5 | Z16: =IFERROR(Y16-I16,"-") -> 154.5
A17: =IFERROR(YEAR(C17),"-") -> 2026 | B17: =IFERROR(DATE(YEAR(C17),MONTH(C17),MONTH(C17)),"-") -> 46023 | C17: 46025 | D17: FELLER2 | E17: =IFERROR(VLOOKUP(D17,Cadastros!A:B,2,FALSE),"-") -> FELLER BUNCHER 2 | F17: =IFERROR(VLOOKUP(E17,Cadastros!B:D,3,FALSE),"-") -> CORTE | G17: {=IF(C17<C16,LARGE(LOOKUP(D17,$D$1:$D16,$H$1:$H16),1),LOOKUP(2,1/($D$1:$D16=D17),($H$1:$H16)))} -> 2025 | H17: 2034 | I17: 0.5 | J17: =IFERROR(IF(H17-G17<0,"-",H17-G17),"-") -> 9 | K17: =IFERROR(IF(C17>=TODAY(),"",SUMIFS(I:I,E:E,E17,C:C,C17,B:B,B17)/SUMIFS(J:J,E:E,E17,C:C,C17,B:B,B17)),0) -> 0.055555556 | L17: =IFERROR(IF(K17<=S17,"EXCELENTE",IF(K17<=Q17,"BOM",IF(K17<=O17,"ATENÇÃO",IF(K17>O17,"CRÍTICO","-")))),"-") -> EXCELENTE | M17: =IFERROR(I17/J17,"-") -> 0.055555556 | N17: {=IFERROR(INDEX('Metas Lubrificantes'!$A:$XR,MATCH(Graxa!E17,'Metas Lubrificantes'!A:A,0),MATCH(Graxa!U17,'Metas Lubrificantes'!$1:$1,0)+12),"-")} -> 0.65833333 | O17: =IFERROR(N17/J17,"-") -> 0.073148148 | P17: {=IFERROR(INDEX('Metas Lubrificantes'!$A:$XR,MATCH(Graxa!E17,'Metas Lubrificantes'!A:A,0),MATCH(Graxa!U17,'Metas Lubrificantes'!$1:$1,0)+13),"-")} -> 0.69444444 | Q17: =IFERROR(P17/J17,"-") -> 0.077160494 | R17: {=IFERROR(INDEX('Metas Lubrificantes'!$A:$XR,MATCH(Graxa!E17,'Metas Lubrificantes'!A:A,0),MATCH(Graxa!U17,'Metas Lubrificantes'!$1:$1,0)+14),"-")} -> 0.5 | S17: =IFERROR(R17/J17,"-") -> 0.055555556 | T17: =IFERROR(IF(M17<=S17,"EXCELENTE",IF(M17<=Q17,"BOM",IF(M17<=O17,"ATENÇÃO",IF(M17>O17,"CRÍTICO","-")))),"-") -> EXCELENTE | U17: GRAXA | V17: C01 | Y17: {=IFERROR(X17+IF(C17<C16,LARGE(LOOKUP(V17,$V$1:$V16,$Z$1:$Z16),1),LOOKUP(2,1/($V$1:$V16=V17),($Z$1:$Z16))),"-")} -> 154.5 | Z17: =IFERROR(Y17-I17,"-") -> 154
A18: =IFERROR(YEAR(C18),"-") -> 2026 | B18: =IFERROR(DATE(YEAR(C18),MONTH(C18),MONTH(C18)),"-") -> 46023 | C18: 46025 | D18: SKIDDER1 | E18: =IFERROR(VLOOKUP(D18,Cadastros!A:B,2,FALSE),"-") -> SKIDDER 1 | F18: =IFERROR(VLOOKUP(E18,Cadastros!B:D,3,FALSE),"-") -> ARRASTE | G18: {=IF(C18<C17,LARGE(LOOKUP(D18,$D$1:$D17,$H$1:$H17),1),LOOKUP(2,1/($D$1:$D17=D18),($H$1:$H17)))} -> 1219 | H18: 1221 | I18: 0.5 | J18: =IFERROR(IF(H18-G18<0,"-",H18-G18),"-") -> 2 | K18: =IFERROR(IF(C18>=TODAY(),"",SUMIFS(I:I,E:E,E18,C:C,C18,B:B,B18)/SUMIFS(J:J,E:E,E18,C:C,C18,B:B,B18)),0) -> 0.25 | L18: =IFERROR(IF(K18<=S18,"EXCELENTE",IF(K18<=Q18,"BOM",IF(K18<=O18,"ATENÇÃO",IF(K18>O18,"CRÍTICO","-")))),"-") -> EXCELENTE | M18: =IFERROR(I18/J18,"-") -> 0.25 | N18: {=IFERROR(INDEX('Metas Lubrificantes'!$A:$XR,MATCH(Graxa!E18,'Metas Lubrificantes'!A:A,0),MATCH(Graxa!U18,'Metas Lubrificantes'!$1:$1,0)+12),"-")} -> 1.2166667 | O18: =IFERROR(N18/J18,"-") -> 0.60833333 | P18: {=IFERROR(INDEX('Metas Lubrificantes'!$A:$XR,MATCH(Graxa!E18,'Metas Lubrificantes'!A:A,0),MATCH(Graxa!U18,'Metas Lubrificantes'!$1:$1,0)+13),"-")} -> 0.88888889 | Q18: =IFERROR(P18/J18,"-") -> 0.44444444 | R18: {=IFERROR(INDEX('Metas Lubrificantes'!$A:$XR,MATCH(Graxa!E18,'Metas Lubrificantes'!A:A,0),MATCH(Graxa!U18,'Metas Lubrificantes'!$1:$1,0)+14),"-")} -> 0.5 | S18: =IFERROR(R18/J18,"-") -> 0.25 | T18: =IFERROR(IF(M18<=S18,"EXCELENTE",IF(M18<=Q18,"BOM",IF(M18<=O18,"ATENÇÃO",IF(M18>O18,"CRÍTICO","-")))),"-") -> EXCELENTE | U18: GRAXA | V18: C01 | Y18: {=IFERROR(X18+IF(C18<C17,LARGE(LOOKUP(V18,$V$1:$V17,$Z$1:$Z17),1),LOOKUP(2,1/($V$1:$V17=V18),($Z$1:$Z17))),"-")} -> 154 | Z18: =IFERROR(Y18-I18,"-") -> 153.5

Sheet 15W40
A1: ANO | B1: MÊS | C1: DATA | D1: EQUIPAMENTO DIGITADO | E1: EQUIPAMENTO | F1: TIPO DE EQUIPAMENTO | G1: HORÍMETRO ANTERIOR | H1: HORÍMETRO ABASTECIMENTO | I1: CONSUMO | J1: HORAS RODADAS | K1: MÉDIA | L1: STATUS MÉDIA | M1: LITROS POR HORA | N1: META BASE | O1: META BASE POR HORA | P1: META DESAFIO | Q1: META DESAFIO POR HORA | R1: TETO META | S1: TETO META POR HORA | T1: STATUS META | U1: 15W40 | V1: COMBOIO | W1: ENTRADA | X1: VALOR ENTRADA | Y1: SALDO ANTERIOR | Z1: SALDO | AA1: OBS
A2: =IFERROR(YEAR(C2),"-") -> 2026 | B2: =IFERROR(DATE(YEAR(C2),MONTH(C2),MONTH(C2)),"-") -> 46023 | C2: 46023 | D2: FELLER1 | E2: =IFERROR(VLOOKUP(D2,Cadastros!A:B,2,FALSE),"-") -> FELLER BUNCHER 1 | F2: =IFERROR(VLOOKUP(E2,Cadastros!B:D,3,FALSE),"-") -> CORTE | G2: 1000 | H2: 1012 | I2: 10 | J2: =IFERROR(IF(H2-G2<0,"-",H2-G2),"-") -> 12 | K2: =IFERROR(IF(C2>=TODAY(),"",SUMIFS(I:I,E:E,E2,C:C,C2,B:B,B2)/SUMIFS(J:J,E:E,E2,C:C,C2,B:B,B2)),0) -> 0.83333333 | L2: =IFERROR(IF(K2<=S2,"EXCELENTE",IF(K2<=Q2,"BOM",IF(K2<=O2,"ATENÇÃO",IF(K2>O2,"CRÍTICO","-")))),"-") -> CRÍTICO | M2: =IFERROR(I2/J2,"-") -> 0.83333333 | N2: {=IFERROR(INDEX('Metas Lubrificantes'!$A:$XR,MATCH('15W40'!E2,'Metas Lubrificantes'!A:A,0),MATCH('15W40'!U2,'Metas Lubrificantes'!$1:$1,0)+12),"-")} -> 8.8666667 | O2: =IFERROR(N2/J2,"-") -> 0.73888889 | P2: {=IFERROR(INDEX('Metas Lubrificantes'!$A:$XR,MATCH('15W40'!E2,'Metas Lubrificantes'!A:A,0),MATCH('15W40'!U2,'Metas Lubrificantes'!$1:$1,0)+13),"-")} -> 6.9150327 | Q2: =IFERROR(P2/J2,"-") -> 0.57625272 | R2: {=IFERROR(INDEX('Metas Lubrificantes'!$A:$XR,MATCH('15W40'!E2,'Metas Lubrificantes'!A:A,0),MATCH('15W40'!U2,'Metas Lubrificantes'!$1:$1,0)+14),"-")} -> 5 | S2: =IFERROR(R2/J2,"-") -> 0.41666667 | T2: =IFERROR(IF(M2<=S2,"EXCELENTE",IF(M2<=Q2,"BOM",IF(M2<=O2,"ATENÇÃO",IF(M2>O2,"CRÍTICO","-")))),"-") -> CRÍTICO | U2: 15W40 | V2: C01 | Y2: 200 | Z2: =IFERROR(Y2-I2,"-") -> 190
A3: =IFERROR(YEAR(C3),"-") -> 2026 | B3: =IFERROR(DATE(YEAR(C3),MONTH(C3),MONTH(C3)),"-") -> 46023 | C3: 46023 | D3: FELLER2 | E3: =IFERROR(VLOOKUP(D3,Cadastros!A:B,2,FALSE),"-") -> FELLER BUNCHER 2 | F3: =IFERROR(VLOOKUP(E3,Cadastros!B:D,3,FALSE),"-") -> CORTE | G3: 2000 | H3: 2008 | I3: 25 | J3: =IFERROR(IF(H3-G3<0,"-",H3-G3),"-") -> 8 | K3: =IFERROR(IF(C3>=TODAY(),"",SUMIFS(I:I,E:E,E3,C:C,C3,B:B,B3)/SUMIFS(J:J,E:E,E3,C:C,C3,B:B,B3)),0) -> 3.125 | L3: =IFERROR(IF(K3<=S3,"EXCELENTE",IF(K3<=Q3,"BOM",IF(K3<=O3,"ATENÇÃO",IF(K3>O3,"CRÍTICO","-")))),"-") -> CRÍTICO | M3: =IFERROR(I3/J3,"-") -> 3.125 | N3: {=IFERROR(INDEX('Metas Lubrificantes'!$A:$XR,MATCH('15W40'!E3,'Metas Lubrificantes'!A:A,0),MATCH('15W40'!U3,'Metas Lubrificantes'!$1:$1,0)+12),"-")} -> 13.916667 | O3: =IFERROR(N3/J3,"-") -> 1.7395833 | P3: {=IFERROR(INDEX('Metas Lubrificantes'!$A:$XR,MATCH('15W40'!E3,'Metas Lubrificantes'!A:A,0),MATCH('15W40'!U3,'Metas Lubrificantes'!$1:$1,0)+13),"-")} -> 10.376471 | Q3: =IFERROR(P3/J3,"-") -> 1.2970588 | R3: {=IFERROR(INDEX('Metas Lubrificantes'!$A:$XR,MATCH('15W40'!E3,'Metas Lubrificantes'!A:A,0),MATCH('15W40'!U3,'Metas Lubrificantes'!$1:$1,0)+14),"-")} -> 2 | S3: =IFERROR(R3/J3,"-") -> 0.25 | T3: =IFERROR(IF(M3<=S3,"EXCELENTE",IF(M3<=Q3,"BOM",IF(M3<=O3,"ATENÇÃO",IF(M3>O3,"CRÍTICO","-")))),"-") -> CRÍTICO | U3: 15W40 | V3: C01 | Y3: {=IFERROR(X3+IF(C3<C2,LARGE(LOOKUP(V3,$V$1:$V2,$Z$1:$Z2),1),LOOKUP(2,1/($V$1:$V2=V3),($Z$1:$Z2))),"-")} -> 190 | Z3: =IFERROR(Y3-I3,"-") -> 165
A4: =IFERROR(YEAR(C4),"-") -> 2026 | B4: =IFERROR(DATE(YEAR(C4),MONTH(C4),MONTH(C4)),"-") -> 46023 | C4: 46023 | D4: SKIDDER1 | E4: =IFERROR(VLOOKUP(D4,Cadastros!A:B,2,FALSE),"-") -> SKIDDER 1 | F4: =IFERROR(VLOOKUP(E4,Cadastros!B:D,3,FALSE),"-") -> ARRASTE | G4: 1200 | H4: 1215 | I4: 15 | J4: =IFERROR(IF(H4-G4<0,"-",H4-G4),"-") -> 15 | K4: =IFERROR(IF(C4>=TODAY(),"",SUMIFS(I:I,E:E,E4,C:C,C4,B:B,B4)/SUMIFS(J:J,E:E,E4,C:C,C4,B:B,B4)),0) -> 1 | L4: =IFERROR(IF(K4<=S4,"EXCELENTE",IF(K4<=Q4,"BOM",IF(K4<=O4,"ATENÇÃO",IF(K4>O4,"CRÍTICO","-")))),"-") -> CRÍTICO | M4: =IFERROR(I4/J4,"-") -> 1 | N4: {=IFERROR(INDEX('Metas Lubrificantes'!$A:$XR,MATCH('15W40'!E4,'Metas Lubrificantes'!A:A,0),MATCH('15W40'!U4,'Metas Lubrificantes'!$1:$1,0)+12),"-")} -> 10.466667 | O4: =IFERROR(N4/J4,"-") -> 0.69777778 | P4: {=IFERROR(INDEX('Metas Lubrificantes'!$A:$XR,MATCH('15W40'!E4,'Metas Lubrificantes'!A:A,0),MATCH('15W40'!U4,'Metas Lubrificantes'!$1:$1,0)+13),"-")} -> 9 | Q4: =IFERROR(P4/J4,"-") -> 0.6 | R4: {=IFERROR(INDEX('Metas Lubrificantes'!$A:$XR,MATCH('15W40'!E4,'Metas Lubrificantes'!A:A,0),MATCH('15W40'!U4,'Metas Lubrificantes'!$1:$1,0)+14),"-")} -> 5 | S4: =IFERROR(R4/J4,"-") -> 0.33333333 | T4: =IFERROR(IF(M4<=S4,"EXCELENTE",IF(M4<=Q4,"BOM",IF(M4<=O4,"ATENÇÃO",IF(M4>O4,"CRÍTICO","-")))),"-") -> CRÍTICO | U4: 15W40 | V4: C01 | Y4: {=IFERROR(X4+IF(C4<C3,LARGE(LOOKUP(V4,$V$1:$V3,$Z$1:$Z3),1),LOOKUP(2,1/($V$1:$V3=V4),($Z$1:$Z3))),"-")} -> 165 | Z4: =IFERROR(Y4-I4,"-") -> 150
