Workbook

Sheet Dados
A1: ANO | B1: MÊS | C1: CONTRATO | D1: EQUIPAMENTO / OPERAÇÃO | E1: DATA INICIO MÊS | F1: DATA FINAL MÊS | G1: DIAS PROGRAMADOS | H1: DATA ATUAL | I1: DIAS DESCONSIDERADOS | J1: DIAS CONTADOS | K1: META MENSAL | L1: META SECUNDÁRIA | M1: REALIZADO | N1: RITMO DO MÊS | O1: DIFERENÇA % | P1: META DIÁRIA | Q1: REALIZADO DIÁRIO | R1: STATUS PRODUÇÃO | S1: MÉDIA VMI | T1: RENDIMENTO | U1: HORAS RODADAS | V1: HORAS TRABALHADAS | W1: META HORAS BASE | X1: META HORAS BASE MENSAL | Y1: QUANTIDADE DE OPERADORES | Z1: META DIARIA OPERADOR | AA1: META MENSAL OPERADOR | AB1: VOLUME MÉDIO POR OPERADOR | AC1: STATUS VOLUME MÉDIO POR OPERADOR | AD1: META DE HORAS TRABALHADAS POR OPERADOR | AE1: STATUS HORAS TRABALHADAS POR OPERADOR | AF1: CONSUMO | AG1: HORAS ABASTECIMENTO | AH1: META BASE CONSUMO | AI1: META MÉDIA CONSUMO | AJ1: MÉDIA CONSUMO MÁQUINA | AK1: STATUS MÉDIA CONSUMO | AL1: META D.M | AM1: MÉDIA D.M | AN1: STATUS D.M | AO1: META D.O | AP1: MÉDIA D.O | AQ1: STATUS D.O | AR1: LTS / M³ | AS1: M³ / HORA | AT1: HORÍMETRO INICIAL | AU1: HORÍMETRO FINAL | AV1: HORAS RODADAS HORÍMETRO
A2: =IFERROR(YEAR(H2),"-") -> 2026 | B2: =IFERROR(DATE(YEAR(H2),MONTH(H2),MONTH(H2)),"-") -> 46023 | C2: {=IFERROR(IF(COUNTA(_xlfn.UNIQUE(_xlfn._xlws.FILTER('BDT''s'!C:C,('BDT''s'!K:K=Dados!D2)*('BDT''s'!I:I>=Dados!E2)*('BDT''s'!I:I<=Dados!F2))))=1,INDEX(_xlfn.UNIQUE(_xlfn._xlws.FILTER('BDT''s'!C:C,('BDT''s'!K:K=Dados!D2)*('BDT''s'!I:I>=Dados!E2)*('BDT''s'!I:I<=Dados!F2))),1),#N/A),"-")} -> CONTRATO 1 | D2: FELLER BUNCHER 1 | E2: 46023 | F2: 46053 | G2: =IFERROR(F2-E2-I2+1,"-") -> 31 | H2: 46047 | J2: =IFERROR(H2-E2-I2+1,"-") -> 25 | K2: {=IFERROR(IF(COUNTIF(Cadastros!B:B,D2)>0,INDEX('Metas Mensais'!A:ZZ,MATCH(Dados!D2,'Metas Mensais'!A:A,0),MATCH(Dados!B2,'Metas Mensais'!1:1,0)+1),SUMIFS(K:K,C:C,C2,D:D,IF(D2="CORTE","FEL*",IF(D2="ARRASTE","SKD*",IF(D2="TRAÇAMENTO","GAR*",""))),B:B,B2,A:A,A2)),"-")} -> 8803.4267 | L2: 0 | M2: =IFERROR(IF(COUNTIF(Cadastros!B:B,D2)>0,SUMIFS('BDT''s'!V:V,'BDT''s'!K:K,Dados!D2,'BDT''s'!C:C,Dados!C2,'BDT''s'!B:B,Dados!B2,'BDT''s'!A:A,Dados!A2),SUMIFS('BDT''s'!V:V,'BDT''s'!L:L,Dados!D2,'BDT''s'!C:C,Dados!C2,'BDT''s'!B:B,Dados!B2,'BDT''s'!A:A,Dados!A2)),"-") -> 2930 | N2: =IFERROR(M2/J2*G2,0) -> 3633.2 | O2: =IFERROR(IF(L2>0,N2/L2-1,N2/K2-1),0) -> -0.58729707 | P2: =IFERROR(IF(L2>0,L2/G2,K2/G2),"-") -> 283.98151 | Q2: =IFERROR(M2/J2,"-") -> 117.2 | R2: =IFERROR(IF(Q2>P2,"ALTO","BAIXO"),"-") -> BAIXO | S2: =IFERROR(IF(COUNTIF(Cadastros!B:B,D2)>0,ROUND(AVERAGEIFS('BDT''s'!E:E,'BDT''s'!K:K,Dados!D2,'BDT''s'!C:C,Dados!C2,'BDT''s'!B:B,Dados!B2,'BDT''s'!A:A,Dados!A2),2),ROUND(AVERAGEIFS('BDT''s'!E:E,'BDT''s'!L:L,Dados!D2,'BDT''s'!C:C,Dados!C2,'BDT''s'!B:B,Dados!B2,'BDT''s'!A:A,Dados!A2),2)),"-") -> 0.15 | T2: =IFERROR(M2/V2,"-") -> - | U2: =IFERROR(IF(COUNTIF(Cadastros!B:B,D2)>0,SUMIFS(Disponibilidade!Z:Z,Disponibilidade!E:E,Dados!D2,Disponibilidade!B:B,Dados!B2,Disponibilidade!A:A,Dados!A2),SUMIFS(Disponibilidade!Z:Z,Disponibilidade!F:F,Dados!D2,Disponibilidade!B:B,Dados!B2,Disponibilidade!A:A,Dados!A2)),"-") -> 0 | V2: =IFERROR(IF(COUNTIF(Cadastros!B:B,D2)>0,SUMIFS(Disponibilidade!AB:AB,Disponibilidade!E:E,Dados!D2,Disponibilidade!B:B,Dados!B2,Disponibilidade!A:A,Dados!A2),SUMIFS(Disponibilidade!AB:AB,Disponibilidade!F:F,Dados!D2,Disponibilidade!B:B,Dados!B2,Disponibilidade!A:A,Dados!A2)),"-") -> 0 | W2: =IFERROR(IF(COUNTIF(Cadastros!B:B,D2)>0,INDEX('Metas DM & DO'!X:X,MATCH(Dados!D2,'Metas DM & DO'!A:A,0)),SUMIFS(W:W,C:C,C2,D:D,IF(D2="CORTE","FEL*",IF(D2="ARRASTE","SKD*",IF(D2="TRAÇAMENTO","GAR*",""))),B:B,B2,A:A,A2)),"-") -> 4,8 | X2: =IFERROR(W2*G2,"-") -> 148.8 | Y2: {=IFERROR(IF(COUNTIF(Cadastros!B:B,D2)>0,COUNTA(_xlfn.UNIQUE(_xlfn._xlws.FILTER('BDT''s'!N:N,('BDT''s'!C:C=Dados!C2)*('BDT''s'!K:K=Dados!D2)*('BDT''s'!B:B=Dados!B2)*('BDT''s'!N:N<>"SEM OPERADOR")))),COUNTA(_xlfn.UNIQUE(_xlfn._xlws.FILTER('BDT''s'!N:N,('BDT''s'!C:C=Dados!C2)*('BDT''s'!L:L=Dados!D2)*('BDT''s'!B:B=Dados!B2)*('BDT''s'!N:N<>"SEM OPERADOR"))))),"-")} -> 2 | Z2: =IFERROR(P2/2,"-") -> 141.99075 | AA2: =IFERROR(Z2*J2,"-") -> 3549.7688 | AB2: =IFERROR(K2/Y2,"-") -> 4401.7133 | AC2: =IFERROR(IF(AB2>AA2,"ALTO","BAIXO"),"-") -> ALTO | AD2: =IFERROR(X2/Y2,0) -> 74.4 | AE2: =IFERROR(IF(AD2>V2,"ALTO","BAIXO"),"-") -> ALTO | AF2: =IFERROR(IF(COUNTIF(Cadastros!B:B,D2)>0,SUMIFS(Diesel!J:J,Diesel!F:F,Dados!D2,Diesel!D:D,Dados!C2,Diesel!B:B,Dados!B2,Diesel!A:A,Dados!A2),SUMIFS(Diesel!J:J,Diesel!G:G,Dados!D2,Diesel!D:D,Dados!C2,Diesel!B:B,Dados!B2,Diesel!A:A,Dados!A2)),"-") -> 210 | AG2: =IFERROR(IF(COUNTIF(Cadastros!B:B,D2)>0,SUMIFS(Diesel!K:K,Diesel!F:F,Dados!D2,Diesel!D:D,Dados!C2,Diesel!B:B,Dados!B2,Diesel!A:A,Dados!A2),SUMIFS(Diesel!K:K,Diesel!G:G,Dados!D2,Diesel!D:D,Dados!C2,Diesel!B:B,Dados!B2,Diesel!A:A,Dados!A2)),"-") -> 18 | AH2: =IFERROR(IF(COUNTIF(Cadastros!B:B,D2)>0,ROUND(INDEX('Metas Diesel'!N:N,MATCH(Dados!D2,'Metas Diesel'!A:A))*COUNTIFS(Diesel!F:F,Dados!D2,Diesel!B:B,Dados!B2,Diesel!D:D,Dados!C2),3),SUMIFS(AH:AH,C:C,C2,D:D,IF(D2="CORTE","FEL*",IF(D2="ARRASTE","SKD*",IF(D2="TRAÇAMENTO","GAR*",""))),B:B,B2,A:A,A2)),"-") -> 471.333 | AI2: =IFERROR(AH2/AG2,"-") -> 26.185167 | AJ2: =IFERROR(AF2/AG2,0) -> 11.666667 | AK2: =IF(AJ2<0,"-",IF(AJ2<AI2,"BOA","RUIM")) -> BOA | AL2: =IFERROR(IF(COUNTIF(Cadastros!B:B,D2)>0,INDEX('Metas DM & DO'!O:O,MATCH(Dados!D2,'Metas DM & DO'!A:A,0)),AVERAGEIFS(W:W,C:C,C2,D:D,IF(D2="CORTE","FEL*",IF(D2="ARRASTE","SKD*",IF(D2="TRAÇAMENTO","GAR*",""))),B:B,B2,A:A,A2)),"-") -> 0,45882352941176474 | AM2: =IFERROR(IF(COUNTIF(Cadastros!B:B,D2)>0,AVERAGEIFS('Controle Mensal'!H:H,'Controle Mensal'!E:E,Dados!D2,'Controle Mensal'!B:B,Dados!B2,'Controle Mensal'!A:A,Dados!A2),AVERAGEIFS('Controle Mensal'!H:H,'Controle Mensal'!F:F,Dados!D2,'Controle Mensal'!B:B,Dados!B2,'Controle Mensal'!A:A,Dados!A2)),"-") -> 1 | AN2: =IF(AM2<0,"-",IF(AM2<AL2,"BOA","RUIM")) -> BOA | AO2: =IFERROR(IF(COUNTIF(Cadastros!B:B,D2)>0,INDEX('Metas DM & DO'!S:S,MATCH(Dados!D2,'Metas DM & DO'!A:A,0)),AVERAGEIFS(W:W,C:C,C2,D:D,IF(D2="CORTE","FEL*",IF(D2="ARRASTE","SKD*",IF(D2="TRAÇAMENTO","GAR*",""))),B:B,B2,A:A,A2)),"-") -> 0,74117647058823533 | AP2: =IFERROR(IF(COUNTIF(Cadastros!B:B,D2)>0,AVERAGEIFS('Controle Mensal'!N:N,'Controle Mensal'!E:E,Dados!D2,'Controle Mensal'!B:B,Dados!B2,'Controle Mensal'!A:A,Dados!A2),AVERAGEIFS('Controle Mensal'!N:N,'Controle Mensal'!F:F,Dados!D2,'Controle Mensal'!B:B,Dados!B2,'Controle Mensal'!A:A,Dados!A2)),"-") -> 1 | AQ2: =IF(AP2<0,"-",IF(AP2<AO2,"BOA","RUIM")) -> BOA | AR2: =IFERROR(AF2/M2,0) -> 0.071672355 | AS2: =IFERROR(M2/U2,"-") -> - | AT2: =IFERROR(IF(COUNTIF(Cadastros!B:B,D2)>0,_xlfn.MINIFS('BDT''s'!Q:Q,'BDT''s'!K:K,Dados!D2,'BDT''s'!B:B,Dados!B2,'BDT''s'!C:C,Dados!C2,'BDT''s'!A:A,Dados!A2),"-"),"-") -> 1000 | AU2: =IFERROR(IF(COUNTIF(Cadastros!B:B,D2)>0,_xlfn.MAXIFS('BDT''s'!Q:Q,'BDT''s'!K:K,Dados!D2,'BDT''s'!B:B,Dados!B2,'BDT''s'!C:C,Dados!C2,'BDT''s'!A:A,Dados!A2),"-"),"-") -> 1026 | AV2: =IFERROR(AU2-AT2,"-") -> 26
A3: =IFERROR(YEAR(H3),"-") -> 2026 | B3: =IFERROR(DATE(YEAR(H3),MONTH(H3),MONTH(H3)),"-") -> 46023 | C3: {=IFERROR(IF(COUNTA(_xlfn.UNIQUE(_xlfn._xlws.FILTER('BDT''s'!C:C,('BDT''s'!K:K=Dados!D3)*('BDT''s'!I:I>=Dados!E3)*('BDT''s'!I:I<=Dados!F3))))=1,INDEX(_xlfn.UNIQUE(_xlfn._xlws.FILTER('BDT''s'!C:C,('BDT''s'!K:K=Dados!D3)*('BDT''s'!I:I>=Dados!E3)*('BDT''s'!I:I<=Dados!F3))),1),#N/A),"-")} -> CONTRATO 1 | D3: FELLER BUNCHER 2 | E3: 46023 | F3: 46053 | G3: =IFERROR(F3-E3-I3+1,"-") -> 31 | H3: 46047 | J3: =IFERROR(H3-E3-I3+1,"-") -> 25 | K3: {=IFERROR(IF(COUNTIF(Cadastros!B:B,D3)>0,INDEX('Metas Mensais'!A:ZZ,MATCH(Dados!D3,'Metas Mensais'!A:A,0),MATCH(Dados!B3,'Metas Mensais'!2:2,0)+1),SUMIFS(K:K,C:C,C3,D:D,IF(D3="CORTE","FEL*",IF(D3="ARRASTE","SKD*",IF(D3="TRAÇAMENTO","GAR*",""))),B:B,B3,A:A,A3)),"-")} -> 12309.444 | L3: 0 | M3: =IFERROR(IF(COUNTIF(Cadastros!B:B,D3)>0,SUMIFS('BDT''s'!V:V,'BDT''s'!K:K,Dados!D3,'BDT''s'!C:C,Dados!C3,'BDT''s'!B:B,Dados!B3,'BDT''s'!A:A,Dados!A3),SUMIFS('BDT''s'!V:V,'BDT''s'!L:L,Dados!D3,'BDT''s'!C:C,Dados!C3,'BDT''s'!B:B,Dados!B3,'BDT''s'!A:A,Dados!A3)),"-") -> 4900 | N3: =IFERROR(M3/J3*G3,0) -> 6076 | O3: =IFERROR(IF(L3>0,N3/L3-1,N3/K3-1),0) -> -0.50639526 | P3: =IFERROR(IF(L3>0,L3/G3,K3/G3),"-") -> 397.07885 | Q3: =IFERROR(M3/J3,"-") -> 196 | R3: =IFERROR(IF(Q3>P3,"ALTO","BAIXO"),"-") -> BAIXO | S3: =IFERROR(IF(COUNTIF(Cadastros!B:B,D3)>0,ROUND(AVERAGEIFS('BDT''s'!E:E,'BDT''s'!K:K,Dados!D3,'BDT''s'!C:C,Dados!C3,'BDT''s'!B:B,Dados!B3,'BDT''s'!A:A,Dados!A3),2),ROUND(AVERAGEIFS('BDT''s'!E:E,'BDT''s'!L:L,Dados!D3,'BDT''s'!C:C,Dados!C3,'BDT''s'!B:B,Dados!B3,'BDT''s'!A:A,Dados!A3),2)),"-") -> 0.16 | T3: =IFERROR(M3/V3,"-") -> - | U3: =IFERROR(IF(COUNTIF(Cadastros!B:B,D3)>0,SUMIFS(Disponibilidade!Z:Z,Disponibilidade!E:E,Dados!D3,Disponibilidade!B:B,Dados!B3,Disponibilidade!A:A,Dados!A3),SUMIFS(Disponibilidade!Z:Z,Disponibilidade!F:F,Dados!D3,Disponibilidade!B:B,Dados!B3,Disponibilidade!A:A,Dados!A3)),"-") -> 0 | V3: =IFERROR(IF(COUNTIF(Cadastros!B:B,D3)>0,SUMIFS(Disponibilidade!AB:AB,Disponibilidade!E:E,Dados!D3,Disponibilidade!B:B,Dados!B3,Disponibilidade!A:A,Dados!A3),SUMIFS(Disponibilidade!AB:AB,Disponibilidade!F:F,Dados!D3,Disponibilidade!B:B,Dados!B3,Disponibilidade!A:A,Dados!A3)),"-") -> 0 | W3: =IFERROR(IF(COUNTIF(Cadastros!B:B,D3)>0,INDEX('Metas DM & DO'!X:X,MATCH(Dados!D3,'Metas DM & DO'!A:A,0)),SUMIFS(W:W,C:C,C3,D:D,IF(D3="CORTE","FEL*",IF(D3="ARRASTE","SKD*",IF(D3="TRAÇAMENTO","GAR*",""))),B:B,B3,A:A,A3)),"-") -> 5,2800000000000011 | X3: =IFERROR(W3*G3,"-") -> 163.68 | Y3: {=IFERROR(IF(COUNTIF(Cadastros!B:B,D3)>0,COUNTA(_xlfn.UNIQUE(_xlfn._xlws.FILTER('BDT''s'!N:N,('BDT''s'!C:C=Dados!C3)*('BDT''s'!K:K=Dados!D3)*('BDT''s'!B:B=Dados!B3)*('BDT''s'!N:N<>"SEM OPERADOR")))),COUNTA(_xlfn.UNIQUE(_xlfn._xlws.FILTER('BDT''s'!N:N,('BDT''s'!C:C=Dados!C3)*('BDT''s'!L:L=Dados!D3)*('BDT''s'!B:B=Dados!B3)*('BDT''s'!N:N<>"SEM OPERADOR"))))),"-")} -> 2 | Z3: =IFERROR(P3/2,"-") -> 198.53942 | AA3: =IFERROR(Z3*J3,"-") -> 4963.4856 | AB3: =IFERROR(K3/Y3,"-") -> 6154.7221 | AC3: =IFERROR(IF(AB3>AA3,"ALTO","BAIXO"),"-") -> ALTO | AD3: =IFERROR(X3/Y3,0) -> 81.84 | AE3: =IFERROR(IF(AD3>V3,"ALTO","BAIXO"),"-") -> ALTO | AF3: =IFERROR(IF(COUNTIF(Cadastros!B:B,D3)>0,SUMIFS(Diesel!J:J,Diesel!F:F,Dados!D3,Diesel!D:D,Dados!C3,Diesel!B:B,Dados!B3,Diesel!A:A,Dados!A3),SUMIFS(Diesel!J:J,Diesel!G:G,Dados!D3,Diesel!D:D,Dados!C3,Diesel!B:B,Dados!B3,Diesel!A:A,Dados!A3)),"-") -> 510 | AG3: =IFERROR(IF(COUNTIF(Cadastros!B:B,D3)>0,SUMIFS(Diesel!K:K,Diesel!F:F,Dados!D3,Diesel!D:D,Dados!C3,Diesel!B:B,Dados!B3,Diesel!A:A,Dados!A3),SUMIFS(Diesel!K:K,Diesel!G:G,Dados!D3,Diesel!D:D,Dados!C3,Diesel!B:B,Dados!B3,Diesel!A:A,Dados!A3)),"-") -> 25 | AH3: =IFERROR(IF(COUNTIF(Cadastros!B:B,D3)>0,ROUND(INDEX('Metas Diesel'!N:N,MATCH(Dados!D3,'Metas Diesel'!A:A))*COUNTIFS(Diesel!F:F,Dados!D3,Diesel!B:B,Dados!B3,Diesel!D:D,Dados!C3),3),SUMIFS(AH:AH,C:C,C3,D:D,IF(D3="CORTE","FEL*",IF(D3="ARRASTE","SKD*",IF(D3="TRAÇAMENTO","GAR*",""))),B:B,B3,A:A,A3)),"-") -> 645.5 | AI3: =IFERROR(AH3/AG3,"-") -> 25.82 | AJ3: =IFERROR(AF3/AG3,0) -> 20.4 | AK3: =IF(AJ3<0,"-",IF(AJ3<AI3,"BOA","RUIM")) -> BOA | AL3: =IFERROR(IF(COUNTIF(Cadastros!B:B,D3)>0,INDEX('Metas DM & DO'!O:O,MATCH(Dados!D3,'Metas DM & DO'!A:A,0)),AVERAGEIFS(W:W,C:C,C3,D:D,IF(D3="CORTE","FEL*",IF(D3="ARRASTE","SKD*",IF(D3="TRAÇAMENTO","GAR*",""))),B:B,B3,A:A,A3)),"-") -> 1 | AM3: =IFERROR(IF(COUNTIF(Cadastros!B:B,D3)>0,AVERAGEIFS('Controle Mensal'!H:H,'Controle Mensal'!E:E,Dados!D3,'Controle Mensal'!B:B,Dados!B3,'Controle Mensal'!A:A,Dados!A3),AVERAGEIFS('Controle Mensal'!H:H,'Controle Mensal'!F:F,Dados!D3,'Controle Mensal'!B:B,Dados!B3,'Controle Mensal'!A:A,Dados!A3)),"-") -> 1 | AN3: =IF(AM3<0,"-",IF(AM3<AL3,"BOA","RUIM")) -> BOA | AO3: =IFERROR(IF(COUNTIF(Cadastros!B:B,D3)>0,INDEX('Metas DM & DO'!S:S,MATCH(Dados!D3,'Metas DM & DO'!A:A,0)),AVERAGEIFS(W:W,C:C,C3,D:D,IF(D3="CORTE","FEL*",IF(D3="ARRASTE","SKD*",IF(D3="TRAÇAMENTO","GAR*",""))),B:B,B3,A:A,A3)),"-") -> 0,11999999999999977 | AP3: =IFERROR(IF(COUNTIF(Cadastros!B:B,D3)>0,AVERAGEIFS('Controle Mensal'!N:N,'Controle Mensal'!E:E,Dados!D3,'Controle Mensal'!B:B,Dados!B3,'Controle Mensal'!A:A,Dados!A3),AVERAGEIFS('Controle Mensal'!N:N,'Controle Mensal'!F:F,Dados!D3,'Controle Mensal'!B:B,Dados!B3,'Controle Mensal'!A:A,Dados!A3)),"-") -> 1 | AQ3: =IF(AP3<0,"-",IF(AP3<AO3,"BOA","RUIM")) -> BOA | AR3: =IFERROR(AF3/M3,0) -> 0.10408163 | AS3: =IFERROR(M3/U3,"-") -> - | AT3: =IFERROR(IF(COUNTIF(Cadastros!B:B,D3)>0,_xlfn.MINIFS('BDT''s'!Q:Q,'BDT''s'!K:K,Dados!D3,'BDT''s'!B:B,Dados!B3,'BDT''s'!C:C,Dados!C3,'BDT''s'!A:A,Dados!A3),"-"),"-") -> 2000 | AU3: =IFERROR(IF(COUNTIF(Cadastros!B:B,D3)>0,_xlfn.MAXIFS('BDT''s'!Q:Q,'BDT''s'!K:K,Dados!D3,'BDT''s'!B:B,Dados!B3,'BDT''s'!C:C,Dados!C3,'BDT''s'!A:A,Dados!A3),"-"),"-") -> 2030 | AV3: =IFERROR(AU3-AT3,"-") -> 30
A4: =IFERROR(YEAR(H4),"-") -> 2026 | B4: =IFERROR(DATE(YEAR(H4),MONTH(H4),MONTH(H4)),"-") -> 46023 | C4: {=IFERROR(IF(COUNTA(_xlfn.UNIQUE(_xlfn._xlws.FILTER('BDT''s'!C:C,('BDT''s'!K:K=Dados!D4)*('BDT''s'!I:I>=Dados!E4)*('BDT''s'!I:I<=Dados!F4))))=1,INDEX(_xlfn.UNIQUE(_xlfn._xlws.FILTER('BDT''s'!C:C,('BDT''s'!K:K=Dados!D4)*('BDT''s'!I:I>=Dados!E4)*('BDT''s'!I:I<=Dados!F4))),1),#N/A),"-")} -> CONTRATO 1 | D4: SKIDDER 1 | E4: 46023 | F4: 46053 | G4: =IFERROR(F4-E4-I4+1,"-") -> 31 | H4: 46047 | J4: =IFERROR(H4-E4-I4+1,"-") -> 25 | K4: {=IFERROR(IF(COUNTIF(Cadastros!B:B,D4)>0,INDEX('Metas Mensais'!A:ZZ,MATCH(Dados!D4,'Metas Mensais'!A:A,0),MATCH(Dados!B4,'Metas Mensais'!3:3,0)+1),SUMIFS(K:K,C:C,C4,D:D,IF(D4="CORTE","FEL*",IF(D4="ARRASTE","SKD*",IF(D4="TRAÇAMENTO","GAR*",""))),B:B,B4,A:A,A4)),"-")} -> 14071.429 | L4: 0 | M4: =IFERROR(IF(COUNTIF(Cadastros!B:B,D4)>0,SUMIFS('BDT''s'!V:V,'BDT''s'!K:K,Dados!D4,'BDT''s'!C:C,Dados!C4,'BDT''s'!B:B,Dados!B4,'BDT''s'!A:A,Dados!A4),SUMIFS('BDT''s'!V:V,'BDT''s'!L:L,Dados!D4,'BDT''s'!C:C,Dados!C4,'BDT''s'!B:B,Dados!B4,'BDT''s'!A:A,Dados!A4)),"-") -> 2510 | N4: =IFERROR(M4/J4*G4,0) -> 3112.4 | O4: =IFERROR(IF(L4>0,N4/L4-1,N4/K4-1),0) -> -0.77881421 | P4: =IFERROR(IF(L4>0,L4/G4,K4/G4),"-") -> 453.91705 | Q4: =IFERROR(M4/J4,"-") -> 100.4 | R4: =IFERROR(IF(Q4>P4,"ALTO","BAIXO"),"-") -> BAIXO | S4: =IFERROR(IF(COUNTIF(Cadastros!B:B,D4)>0,ROUND(AVERAGEIFS('BDT''s'!E:E,'BDT''s'!K:K,Dados!D4,'BDT''s'!C:C,Dados!C4,'BDT''s'!B:B,Dados!B4,'BDT''s'!A:A,Dados!A4),2),ROUND(AVERAGEIFS('BDT''s'!E:E,'BDT''s'!L:L,Dados!D4,'BDT''s'!C:C,Dados!C4,'BDT''s'!B:B,Dados!B4,'BDT''s'!A:A,Dados!A4),2)),"-") -> 0.15 | T4: =IFERROR(M4/V4,"-") -> - | U4: =IFERROR(IF(COUNTIF(Cadastros!B:B,D4)>0,SUMIFS(Disponibilidade!Z:Z,Disponibilidade!E:E,Dados!D4,Disponibilidade!B:B,Dados!B4,Disponibilidade!A:A,Dados!A4),SUMIFS(Disponibilidade!Z:Z,Disponibilidade!F:F,Dados!D4,Disponibilidade!B:B,Dados!B4,Disponibilidade!A:A,Dados!A4)),"-") -> 0 | V4: =IFERROR(IF(COUNTIF(Cadastros!B:B,D4)>0,SUMIFS(Disponibilidade!AB:AB,Disponibilidade!E:E,Dados!D4,Disponibilidade!B:B,Dados!B4,Disponibilidade!A:A,Dados!A4),SUMIFS(Disponibilidade!AB:AB,Disponibilidade!F:F,Dados!D4,Disponibilidade!B:B,Dados!B4,Disponibilidade!A:A,Dados!A4)),"-") -> 0 | W4: =IFERROR(IF(COUNTIF(Cadastros!B:B,D4)>0,INDEX('Metas DM & DO'!X:X,MATCH(Dados!D4,'Metas DM & DO'!A:A,0)),SUMIFS(W:W,C:C,C4,D:D,IF(D4="CORTE","FEL*",IF(D4="ARRASTE","SKD*",IF(D4="TRAÇAMENTO","GAR*",""))),B:B,B4,A:A,A4)),"-") -> - | X4: =IFERROR(W4*G4,"-") -> - | Y4: {=IFERROR(IF(COUNTIF(Cadastros!B:B,D4)>0,COUNTA(_xlfn.UNIQUE(_xlfn._xlws.FILTER('BDT''s'!N:N,('BDT''s'!C:C=Dados!C4)*('BDT''s'!K:K=Dados!D4)*('BDT''s'!B:B=Dados!B4)*('BDT''s'!N:N<>"SEM OPERADOR")))),COUNTA(_xlfn.UNIQUE(_xlfn._xlws.FILTER('BDT''s'!N:N,('BDT''s'!C:C=Dados!C4)*('BDT''s'!L:L=Dados!D4)*('BDT''s'!B:B=Dados!B4)*('BDT''s'!N:N<>"SEM OPERADOR"))))),"-")} -> 2 | Z4: =IFERROR(P4/2,"-") -> 226.95853 | AA4: =IFERROR(Z4*J4,"-") -> 5673.9631 | AB4: =IFERROR(K4/Y4,"-") -> 7035.7143 | AC4: =IFERROR(IF(AB4>AA4,"ALTO","BAIXO"),"-") -> ALTO | AD4: =IFERROR(X4/Y4,0) -> 0 | AE4: =IFERROR(IF(AD4>V4,"ALTO","BAIXO"),"-") -> BAIXO | AF4: =IFERROR(IF(COUNTIF(Cadastros!B:B,D4)>0,SUMIFS(Diesel!J:J,Diesel!F:F,Dados!D4,Diesel!D:D,Dados!C4,Diesel!B:B,Dados!B4,Diesel!A:A,Dados!A4),SUMIFS(Diesel!J:J,Diesel!G:G,Dados!D4,Diesel!D:D,Dados!C4,Diesel!B:B,Dados!B4,Diesel!A:A,Dados!A4)),"-") -> 370 | AG4: =IFERROR(IF(COUNTIF(Cadastros!B:B,D4)>0,SUMIFS(Diesel!K:K,Diesel!F:F,Dados!D4,Diesel!D:D,Dados!C4,Diesel!B:B,Dados!B4,Diesel!A:A,Dados!A4),SUMIFS(Diesel!K:K,Diesel!G:G,Dados!D4,Diesel!D:D,Dados!C4,Diesel!B:B,Dados!B4,Diesel!A:A,Dados!A4)),"-") -> 15 | AH4: =IFERROR(IF(COUNTIF(Cadastros!B:B,D4)>0,ROUND(INDEX('Metas Diesel'!N:N,MATCH(Dados!D4,'Metas Diesel'!A:A))*COUNTIFS(Diesel!F:F,Dados!D4,Diesel!B:B,Dados!B4,Diesel!D:D,Dados!C4),3),SUMIFS(AH:AH,C:C,C4,D:D,IF(D4="CORTE","FEL*",IF(D4="ARRASTE","SKD*",IF(D4="TRAÇAMENTO","GAR*",""))),B:B,B4,A:A,A4)),"-") -> 426.333 | AI4: =IFERROR(AH4/AG4,"-") -> 28.4222 | AJ4: =IFERROR(AF4/AG4,0) -> 24.666667 | AK4: =IF(AJ4<0,"-",IF(AJ4<AI4,"BOA","RUIM")) -> BOA | AL4: =IFERROR(IF(COUNTIF(Cadastros!B:B,D4)>0,INDEX('Metas DM & DO'!O:O,MATCH(Dados!D4,'Metas DM & DO'!A:A,0)),AVERAGEIFS(W:W,C:C,C4,D:D,IF(D4="CORTE","FEL*",IF(D4="ARRASTE","SKD*",IF(D4="TRAÇAMENTO","GAR*",""))),B:B,B4,A:A,A4)),"-") -> - | AM4: =IFERROR(IF(COUNTIF(Cadastros!B:B,D4)>0,AVERAGEIFS('Controle Mensal'!H:H,'Controle Mensal'!E:E,Dados!D4,'Controle Mensal'!B:B,Dados!B4,'Controle Mensal'!A:A,Dados!A4),AVERAGEIFS('Controle Mensal'!H:H,'Controle Mensal'!F:F,Dados!D4,'Controle Mensal'!B:B,Dados!B4,'Controle Mensal'!A:A,Dados!A4)),"-") -> 1 | AN4: =IF(AM4<0,"-",IF(AM4<AL4,"BOA","RUIM")) -> BOA | AO4: =IFERROR(IF(COUNTIF(Cadastros!B:B,D4)>0,INDEX('Metas DM & DO'!S:S,MATCH(Dados!D4,'Metas DM & DO'!A:A,0)),AVERAGEIFS(W:W,C:C,C4,D:D,IF(D4="CORTE","FEL*",IF(D4="ARRASTE","SKD*",IF(D4="TRAÇAMENTO","GAR*",""))),B:B,B4,A:A,A4)),"-") -> - | AP4: =IFERROR(IF(COUNTIF(Cadastros!B:B,D4)>0,AVERAGEIFS('Controle Mensal'!N:N,'Controle Mensal'!E:E,Dados!D4,'Controle Mensal'!B:B,Dados!B4,'Controle Mensal'!A:A,Dados!A4),AVERAGEIFS('Controle Mensal'!N:N,'Controle Mensal'!F:F,Dados!D4,'Controle Mensal'!B:B,Dados!B4,'Controle Mensal'!A:A,Dados!A4)),"-") -> 1 | AQ4: =IF(AP4<0,"-",IF(AP4<AO4,"BOA","RUIM")) -> BOA | AR4: =IFERROR(AF4/M4,0) -> 0.14741036 | AS4: =IFERROR(M4/U4,"-") -> - | AT4: =IFERROR(IF(COUNTIF(Cadastros!B:B,D4)>0,_xlfn.MINIFS('BDT''s'!Q:Q,'BDT''s'!K:K,Dados!D4,'BDT''s'!B:B,Dados!B4,'BDT''s'!C:C,Dados!C4,'BDT''s'!A:A,Dados!A4),"-"),"-") -> 1200 | AU4: =IFERROR(IF(COUNTIF(Cadastros!B:B,D4)>0,_xlfn.MAXIFS('BDT''s'!Q:Q,'BDT''s'!K:K,Dados!D4,'BDT''s'!B:B,Dados!B4,'BDT''s'!C:C,Dados!C4,'BDT''s'!A:A,Dados!A4),"-"),"-") -> 1219 | AV4: =IFERROR(AU4-AT4,"-") -> 19
A5: =IFERROR(YEAR(H5),"-") -> 2026 | B5: =IFERROR(DATE(YEAR(H5),MONTH(H5),MONTH(H5)),"-") -> 46023 | C5: {=IFERROR(IF(COUNTA(_xlfn.UNIQUE(_xlfn._xlws.FILTER('BDT''s'!C:C,('BDT''s'!K:K=Dados!D5)*('BDT''s'!I:I>=Dados!E5)*('BDT''s'!I:I<=Dados!F5))))=1,INDEX(_xlfn.UNIQUE(_xlfn._xlws.FILTER('BDT''s'!C:C,('BDT''s'!K:K=Dados!D5)*('BDT''s'!I:I>=Dados!E5)*('BDT''s'!I:I<=Dados!F5))),1),#N/A),"-")} -> CONTRATO 1 | D5: SKIDDER 2 | E5: 46023 | F5: 46053 | G5: =IFERROR(F5-E5-I5+1,"-") -> 31 | H5: 46047 | J5: =IFERROR(H5-E5-I5+1,"-") -> 25 | K5: {=IFERROR(IF(COUNTIF(Cadastros!B:B,D5)>0,INDEX('Metas Mensais'!A:ZZ,MATCH(Dados!D5,'Metas Mensais'!A:A,0),MATCH(Dados!B5,'Metas Mensais'!4:4,0)+1),SUMIFS(K:K,C:C,C5,D:D,IF(D5="CORTE","FEL*",IF(D5="ARRASTE","SKD*",IF(D5="TRAÇAMENTO","GAR*",""))),B:B,B5,A:A,A5)),"-")} -> 9069.4444 | L5: 0 | M5: =IFERROR(IF(COUNTIF(Cadastros!B:B,D5)>0,SUMIFS('BDT''s'!V:V,'BDT''s'!K:K,Dados!D5,'BDT''s'!C:C,Dados!C5,'BDT''s'!B:B,Dados!B5,'BDT''s'!A:A,Dados!A5),SUMIFS('BDT''s'!V:V,'BDT''s'!L:L,Dados!D5,'BDT''s'!C:C,Dados!C5,'BDT''s'!B:B,Dados!B5,'BDT''s'!A:A,Dados!A5)),"-") -> 3020 | N5: =IFERROR(M5/J5*G5,0) -> 3744.8 | O5: =IFERROR(IF(L5>0,N5/L5-1,N5/K5-1),0) -> -0.58709709 | P5: =IFERROR(IF(L5>0,L5/G5,K5/G5),"-") -> 292.56272 | Q5: =IFERROR(M5/J5,"-") -> 120.8 | R5: =IFERROR(IF(Q5>P5,"ALTO","BAIXO"),"-") -> BAIXO | S5: =IFERROR(IF(COUNTIF(Cadastros!B:B,D5)>0,ROUND(AVERAGEIFS('BDT''s'!E:E,'BDT''s'!K:K,Dados!D5,'BDT''s'!C:C,Dados!C5,'BDT''s'!B:B,Dados!B5,'BDT''s'!A:A,Dados!A5),2),ROUND(AVERAGEIFS('BDT''s'!E:E,'BDT''s'!L:L,Dados!D5,'BDT''s'!C:C,Dados!C5,'BDT''s'!B:B,Dados!B5,'BDT''s'!A:A,Dados!A5),2)),"-") -> 0.16 | T5: =IFERROR(M5/V5,"-") -> - | U5: =IFERROR(IF(COUNTIF(Cadastros!B:B,D5)>0,SUMIFS(Disponibilidade!Z:Z,Disponibilidade!E:E,Dados!D5,Disponibilidade!B:B,Dados!B5,Disponibilidade!A:A,Dados!A5),SUMIFS(Disponibilidade!Z:Z,Disponibilidade!F:F,Dados!D5,Disponibilidade!B:B,Dados!B5,Disponibilidade!A:A,Dados!A5)),"-") -> 0 | V5: =IFERROR(IF(COUNTIF(Cadastros!B:B,D5)>0,SUMIFS(Disponibilidade!AB:AB,Disponibilidade!E:E,Dados!D5,Disponibilidade!B:B,Dados!B5,Disponibilidade!A:A,Dados!A5),SUMIFS(Disponibilidade!AB:AB,Disponibilidade!F:F,Dados!D5,Disponibilidade!B:B,Dados!B5,Disponibilidade!A:A,Dados!A5)),"-") -> 0 | W5: =IFERROR(IF(COUNTIF(Cadastros!B:B,D5)>0,INDEX('Metas DM & DO'!X:X,MATCH(Dados!D5,'Metas DM & DO'!A:A,0)),SUMIFS(W:W,C:C,C5,D:D,IF(D5="CORTE","FEL*",IF(D5="ARRASTE","SKD*",IF(D5="TRAÇAMENTO","GAR*",""))),B:B,B5,A:A,A5)),"-") -> 12 | X5: =IFERROR(W5*G5,"-") -> 372 | Y5: {=IFERROR(IF(COUNTIF(Cadastros!B:B,D5)>0,COUNTA(_xlfn.UNIQUE(_xlfn._xlws.FILTER('BDT''s'!N:N,('BDT''s'!C:C=Dados!C5)*('BDT''s'!K:K=Dados!D5)*('BDT''s'!B:B=Dados!B5)*('BDT''s'!N:N<>"SEM OPERADOR")))),COUNTA(_xlfn.UNIQUE(_xlfn._xlws.FILTER('BDT''s'!N:N,('BDT''s'!C:C=Dados!C5)*('BDT''s'!L:L=Dados!D5)*('BDT''s'!B:B=Dados!B5)*('BDT''s'!N:N<>"SEM OPERADOR"))))),"-")} -> 2 | Z5: =IFERROR(P5/2,"-") -> 146.28136 | AA5: =IFERROR(Z5*J5,"-") -> 3657.0341 | AB5: =IFERROR(K5/Y5,"-") -> 4534.7222 | AC5: =IFERROR(IF(AB5>AA5,"ALTO","BAIXO"),"-") -> ALTO | AD5: =IFERROR(X5/Y5,0) -> 186 | AE5: =IFERROR(IF(AD5>V5,"ALTO","BAIXO"),"-") -> ALTO | AF5: =IFERROR(IF(COUNTIF(Cadastros!B:B,D5)>0,SUMIFS(Diesel!J:J,Diesel!F:F,Dados!D5,Diesel!D:D,Dados!C5,Diesel!B:B,Dados!B5,Diesel!A:A,Dados!A5),SUMIFS(Diesel!J:J,Diesel!G:G,Dados!D5,Diesel!D:D,Dados!C5,Diesel!B:B,Dados!B5,Diesel!A:A,Dados!A5)),"-") -> 630 | AG5: =IFERROR(IF(COUNTIF(Cadastros!B:B,D5)>0,SUMIFS(Diesel!K:K,Diesel!F:F,Dados!D5,Diesel!D:D,Dados!C5,Diesel!B:B,Dados!B5,Diesel!A:A,Dados!A5),SUMIFS(Diesel!K:K,Diesel!G:G,Dados!D5,Diesel!D:D,Dados!C5,Diesel!B:B,Dados!B5,Diesel!A:A,Dados!A5)),"-") -> 15 | AH5: =IFERROR(IF(COUNTIF(Cadastros!B:B,D5)>0,ROUND(INDEX('Metas Diesel'!N:N,MATCH(Dados!D5,'Metas Diesel'!A:A))*COUNTIFS(Diesel!F:F,Dados!D5,Diesel!B:B,Dados!B5,Diesel!D:D,Dados!C5),3),SUMIFS(AH:AH,C:C,C5,D:D,IF(D5="CORTE","FEL*",IF(D5="ARRASTE","SKD*",IF(D5="TRAÇAMENTO","GAR*",""))),B:B,B5,A:A,A5)),"-") -> 1106 | AI5: =IFERROR(AH5/AG5,"-") -> 73.733333 | AJ5: =IFERROR(AF5/AG5,0) -> 42 | AK5: =IF(AJ5<0,"-",IF(AJ5<AI5,"BOA","RUIM")) -> BOA | AL5: =IFERROR(IF(COUNTIF(Cadastros!B:B,D5)>0,INDEX('Metas DM & DO'!O:O,MATCH(Dados!D5,'Metas DM & DO'!A:A,0)),AVERAGEIFS(W:W,C:C,C5,D:D,IF(D5="CORTE","FEL*",IF(D5="ARRASTE","SKD*",IF(D5="TRAÇAMENTO","GAR*",""))),B:B,B5,A:A,A5)),"-") -> 0,5 | AM5: =IFERROR(IF(COUNTIF(Cadastros!B:B,D5)>0,AVERAGEIFS('Controle Mensal'!H:H,'Controle Mensal'!E:E,Dados!D5,'Controle Mensal'!B:B,Dados!B5,'Controle Mensal'!A:A,Dados!A5),AVERAGEIFS('Controle Mensal'!H:H,'Controle Mensal'!F:F,Dados!D5,'Controle Mensal'!B:B,Dados!B5,'Controle Mensal'!A:A,Dados!A5)),"-") -> 1 | AN5: =IF(AM5<0,"-",IF(AM5<AL5,"BOA","RUIM")) -> BOA | AO5: =IFERROR(IF(COUNTIF(Cadastros!B:B,D5)>0,INDEX('Metas DM & DO'!S:S,MATCH(Dados!D5,'Metas DM & DO'!A:A,0)),AVERAGEIFS(W:W,C:C,C5,D:D,IF(D5="CORTE","FEL*",IF(D5="ARRASTE","SKD*",IF(D5="TRAÇAMENTO","GAR*",""))),B:B,B5,A:A,A5)),"-") -> 0,5 | AP5: =IFERROR(IF(COUNTIF(Cadastros!B:B,D5)>0,AVERAGEIFS('Controle Mensal'!N:N,'Controle Mensal'!E:E,Dados!D5,'Controle Mensal'!B:B,Dados!B5,'Controle Mensal'!A:A,Dados!A5),AVERAGEIFS('Controle Mensal'!N:N,'Controle Mensal'!F:F,Dados!D5,'Controle Mensal'!B:B,Dados!B5,'Controle Mensal'!A:A,Dados!A5)),"-") -> 1 | AQ5: =IF(AP5<0,"-",IF(AP5<AO5,"BOA","RUIM")) -> BOA | AR5: =IFERROR(AF5/M5,0) -> 0.20860927 | AS5: =IFERROR(M5/U5,"-") -> - | AT5: =IFERROR(IF(COUNTIF(Cadastros!B:B,D5)>0,_xlfn.MINIFS('BDT''s'!Q:Q,'BDT''s'!K:K,Dados!D5,'BDT''s'!B:B,Dados!B5,'BDT''s'!C:C,Dados!C5,'BDT''s'!A:A,Dados!A5),"-"),"-") -> 2100 | AU5: =IFERROR(IF(COUNTIF(Cadastros!B:B,D5)>0,_xlfn.MAXIFS('BDT''s'!Q:Q,'BDT''s'!K:K,Dados!D5,'BDT''s'!B:B,Dados!B5,'BDT''s'!C:C,Dados!C5,'BDT''s'!A:A,Dados!A5),"-"),"-") -> 2130 | AV5: =IFERROR(AU5-AT5,"-") -> 30
A6: =IFERROR(YEAR(H6),"-") -> 2026 | B6: =IFERROR(DATE(YEAR(H6),MONTH(H6),MONTH(H6)),"-") -> 46023 | C6: {=IFERROR(IF(COUNTA(_xlfn.UNIQUE(_xlfn._xlws.FILTER('BDT''s'!C:C,('BDT''s'!K:K=Dados!D6)*('BDT''s'!I:I>=Dados!E6)*('BDT''s'!I:I<=Dados!F6))))=1,INDEX(_xlfn.UNIQUE(_xlfn._xlws.FILTER('BDT''s'!C:C,('BDT''s'!K:K=Dados!D6)*('BDT''s'!I:I>=Dados!E6)*('BDT''s'!I:I<=Dados!F6))),1),#N/A),"-")} -> CONTRATO 1 | D6: GARRA TRAÇADORA 1 | E6: 46023 | F6: 46053 | G6: =IFERROR(F6-E6-I6+1,"-") -> 31 | H6: 46047 | J6: =IFERROR(H6-E6-I6+1,"-") -> 25 | K6: {=IFERROR(IF(COUNTIF(Cadastros!B:B,D6)>0,INDEX('Metas Mensais'!A:ZZ,MATCH(Dados!D6,'Metas Mensais'!A:A,0),MATCH(Dados!B6,'Metas Mensais'!5:5,0)+1),SUMIFS(K:K,C:C,C6,D:D,IF(D6="CORTE","FEL*",IF(D6="ARRASTE","SKD*",IF(D6="TRAÇAMENTO","GAR*",""))),B:B,B6,A:A,A6)),"-")} -> 6743.0556 | L6: 0 | M6: =IFERROR(IF(COUNTIF(Cadastros!B:B,D6)>0,SUMIFS('BDT''s'!V:V,'BDT''s'!K:K,Dados!D6,'BDT''s'!C:C,Dados!C6,'BDT''s'!B:B,Dados!B6,'BDT''s'!A:A,Dados!A6),SUMIFS('BDT''s'!V:V,'BDT''s'!L:L,Dados!D6,'BDT''s'!C:C,Dados!C6,'BDT''s'!B:B,Dados!B6,'BDT''s'!A:A,Dados!A6)),"-") -> 2020 | N6: =IFERROR(M6/J6*G6,0) -> 2504.8 | O6: =IFERROR(IF(L6>0,N6/L6-1,N6/K6-1),0) -> -0.62853635 | P6: =IFERROR(IF(L6>0,L6/G6,K6/G6),"-") -> 217.51792 | Q6: =IFERROR(M6/J6,"-") -> 80.8 | R6: =IFERROR(IF(Q6>P6,"ALTO","BAIXO"),"-") -> BAIXO | S6: =IFERROR(IF(COUNTIF(Cadastros!B:B,D6)>0,ROUND(AVERAGEIFS('BDT''s'!E:E,'BDT''s'!K:K,Dados!D6,'BDT''s'!C:C,Dados!C6,'BDT''s'!B:B,Dados!B6,'BDT''s'!A:A,Dados!A6),2),ROUND(AVERAGEIFS('BDT''s'!E:E,'BDT''s'!L:L,Dados!D6,'BDT''s'!C:C,Dados!C6,'BDT''s'!B:B,Dados!B6,'BDT''s'!A:A,Dados!A6),2)),"-") -> 0.15 | T6: =IFERROR(M6/V6,"-") -> - | U6: =IFERROR(IF(COUNTIF(Cadastros!B:B,D6)>0,SUMIFS(Disponibilidade!Z:Z,Disponibilidade!E:E,Dados!D6,Disponibilidade!B:B,Dados!B6,Disponibilidade!A:A,Dados!A6),SUMIFS(Disponibilidade!Z:Z,Disponibilidade!F:F,Dados!D6,Disponibilidade!B:B,Dados!B6,Disponibilidade!A:A,Dados!A6)),"-") -> 0 | V6: =IFERROR(IF(COUNTIF(Cadastros!B:B,D6)>0,SUMIFS(Disponibilidade!AB:AB,Disponibilidade!E:E,Dados!D6,Disponibilidade!B:B,Dados!B6,Disponibilidade!A:A,Dados!A6),SUMIFS(Disponibilidade!AB:AB,Disponibilidade!F:F,Dados!D6,Disponibilidade!B:B,Dados!B6,Disponibilidade!A:A,Dados!A6)),"-") -> 0 | W6: =IFERROR(IF(COUNTIF(Cadastros!B:B,D6)>0,INDEX('Metas DM & DO'!X:X,MATCH(Dados!D6,'Metas DM & DO'!A:A,0)),SUMIFS(W:W,C:C,C6,D:D,IF(D6="CORTE","FEL*",IF(D6="ARRASTE","SKD*",IF(D6="TRAÇAMENTO","GAR*",""))),B:B,B6,A:A,A6)),"-") -> 2,2174055829228245 | X6: =IFERROR(W6*G6,"-") -> 68.739573 | Y6: {=IFERROR(IF(COUNTIF(Cadastros!B:B,D6)>0,COUNTA(_xlfn.UNIQUE(_xlfn._xlws.FILTER('BDT''s'!N:N,('BDT''s'!C:C=Dados!C6)*('BDT''s'!K:K=Dados!D6)*('BDT''s'!B:B=Dados!B6)*('BDT''s'!N:N<>"SEM OPERADOR")))),COUNTA(_xlfn.UNIQUE(_xlfn._xlws.FILTER('BDT''s'!N:N,('BDT''s'!C:C=Dados!C6)*('BDT''s'!L:L=Dados!D6)*('BDT''s'!B:B=Dados!B6)*('BDT''s'!N:N<>"SEM OPERADOR"))))),"-")} -> 2 | Z6: =IFERROR(P6/2,"-") -> 108.75896 | AA6: =IFERROR(Z6*J6,"-") -> 2718.974 | AB6: =IFERROR(K6/Y6,"-") -> 3371.5278 | AC6: =IFERROR(IF(AB6>AA6,"ALTO","BAIXO"),"-") -> ALTO | AD6: =IFERROR(X6/Y6,0) -> 34.369787 | AE6: =IFERROR(IF(AD6>V6,"ALTO","BAIXO"),"-") -> ALTO | AF6: =IFERROR(IF(COUNTIF(Cadastros!B:B,D6)>0,SUMIFS(Diesel!J:J,Diesel!F:F,Dados!D6,Diesel!D:D,Dados!C6,Diesel!B:B,Dados!B6,Diesel!A:A,Dados!A6),SUMIFS(Diesel!J:J,Diesel!G:G,Dados!D6,Diesel!D:D,Dados!C6,Diesel!B:B,Dados!B6,Diesel!A:A,Dados!A6)),"-") -> 0 | AG6: =IFERROR(IF(COUNTIF(Cadastros!B:B,D6)>0,SUMIFS(Diesel!K:K,Diesel!F:F,Dados!D6,Diesel!D:D,Dados!C6,Diesel!B:B,Dados!B6,Diesel!A:A,Dados!A6),SUMIFS(Diesel!K:K,Diesel!G:G,Dados!D6,Diesel!D:D,Dados!C6,Diesel!B:B,Dados!B6,Diesel!A:A,Dados!A6)),"-") -> 0 | AH6: =IFERROR(IF(COUNTIF(Cadastros!B:B,D6)>0,ROUND(INDEX('Metas Diesel'!N:N,MATCH(Dados!D6,'Metas Diesel'!A:A))*COUNTIFS(Diesel!F:F,Dados!D6,Diesel!B:B,Dados!B6,Diesel!D:D,Dados!C6),3),SUMIFS(AH:AH,C:C,C6,D:D,IF(D6="CORTE","FEL*",IF(D6="ARRASTE","SKD*",IF(D6="TRAÇAMENTO","GAR*",""))),B:B,B6,A:A,A6)),"-") -> 0 | AI6: =IFERROR(AH6/AG6,"-") -> - | AJ6: =IFERROR(AF6/AG6,0) -> 0 | AK6: =IF(AJ6<0,"-",IF(AJ6<AI6,"BOA","RUIM")) -> BOA | AL6: =IFERROR(IF(COUNTIF(Cadastros!B:B,D6)>0,INDEX('Metas DM & DO'!O:O,MATCH(Dados!D6,'Metas DM & DO'!A:A,0)),AVERAGEIFS(W:W,C:C,C6,D:D,IF(D6="CORTE","FEL*",IF(D6="ARRASTE","SKD*",IF(D6="TRAÇAMENTO","GAR*",""))),B:B,B6,A:A,A6)),"-") -> 0,91724137931034488 | AM6: =IFERROR(IF(COUNTIF(Cadastros!B:B,D6)>0,AVERAGEIFS('Controle Mensal'!H:H,'Controle Mensal'!E:E,Dados!D6,'Controle Mensal'!B:B,Dados!B6,'Controle Mensal'!A:A,Dados!A6),AVERAGEIFS('Controle Mensal'!H:H,'Controle Mensal'!F:F,Dados!D6,'Controle Mensal'!B:B,Dados!B6,'Controle Mensal'!A:A,Dados!A6)),"-") -> 1 | AN6: =IF(AM6<0,"-",IF(AM6<AL6,"BOA","RUIM")) -> BOA | AO6: =IFERROR(IF(COUNTIF(Cadastros!B:B,D6)>0,INDEX('Metas DM & DO'!S:S,MATCH(Dados!D6,'Metas DM & DO'!A:A,0)),AVERAGEIFS(W:W,C:C,C6,D:D,IF(D6="CORTE","FEL*",IF(D6="ARRASTE","SKD*",IF(D6="TRAÇAMENTO","GAR*",""))),B:B,B6,A:A,A6)),"-") -> 0,43601532567049806 | AP6: =IFERROR(IF(COUNTIF(Cadastros!B:B,D6)>0,AVERAGEIFS('Controle Mensal'!N:N,'Controle Mensal'!E:E,Dados!D6,'Controle Mensal'!B:B,Dados!B6,'Controle Mensal'!A:A,Dados!A6),AVERAGEIFS('Controle Mensal'!N:N,'Controle Mensal'!F:F,Dados!D6,'Controle Mensal'!B:B,Dados!B6,'Controle Mensal'!A:A,Dados!A6)),"-") -> 1 | AQ6: =IF(AP6<0,"-",IF(AP6<AO6,"BOA","RUIM")) -> BOA | AR6: =IFERROR(AF6/M6,0) -> 0 | AS6: =IFERROR(M6/U6,"-") -> - | AT6: =IFERROR(IF(COUNTIF(Cadastros!B:B,D6)>0,_xlfn.MINIFS('BDT''s'!Q:Q,'BDT''s'!K:K,Dados!D6,'BDT''s'!B:B,Dados!B6,'BDT''s'!C:C,Dados!C6,'BDT''s'!A:A,Dados!A6),"-"),"-") -> 500 | AU6: =IFERROR(IF(COUNTIF(Cadastros!B:B,D6)>0,_xlfn.MAXIFS('BDT''s'!Q:Q,'BDT''s'!K:K,Dados!D6,'BDT''s'!B:B,Dados!B6,'BDT''s'!C:C,Dados!C6,'BDT''s'!A:A,Dados!A6),"-"),"-") -> 529 | AV6: =IFERROR(AU6-AT6,"-") -> 29
A7: =IFERROR(YEAR(H7),"-") -> 2026 | B7: =IFERROR(DATE(YEAR(H7),MONTH(H7),MONTH(H7)),"-") -> 46023 | C7: {=IFERROR(IF(COUNTA(_xlfn.UNIQUE(_xlfn._xlws.FILTER('BDT''s'!C:C,('BDT''s'!K:K=Dados!D7)*('BDT''s'!I:I>=Dados!E7)*('BDT''s'!I:I<=Dados!F7))))=1,INDEX(_xlfn.UNIQUE(_xlfn._xlws.FILTER('BDT''s'!C:C,('BDT''s'!K:K=Dados!D7)*('BDT''s'!I:I>=Dados!E7)*('BDT''s'!I:I<=Dados!F7))),1),#N/A),"-")} -> CONTRATO 1 | D7: GARRA TRAÇADORA 2 | E7: 46023 | F7: 46043 | G7: =IFERROR(F7-E7-I7+1,"-") -> 21 | H7: 46047 | J7: =IFERROR(H7-E7-I7+1,"-") -> 25 | K7: {=IFERROR(IF(COUNTIF(Cadastros!B:B,D7)>0,INDEX('Metas Mensais'!A:ZZ,MATCH(Dados!D7,'Metas Mensais'!A:A,0),MATCH(Dados!B7,'Metas Mensais'!6:6,0)+1),SUMIFS(K:K,C:C,C7,D:D,IF(D7="CORTE","FEL*",IF(D7="ARRASTE","SKD*",IF(D7="TRAÇAMENTO","GAR*",""))),B:B,B7,A:A,A7)),"-")} -> 7950 | L7: 0 | M7: =IFERROR(IF(COUNTIF(Cadastros!B:B,D7)>0,SUMIFS('BDT''s'!V:V,'BDT''s'!K:K,Dados!D7,'BDT''s'!C:C,Dados!C7,'BDT''s'!B:B,Dados!B7,'BDT''s'!A:A,Dados!A7),SUMIFS('BDT''s'!V:V,'BDT''s'!L:L,Dados!D7,'BDT''s'!C:C,Dados!C7,'BDT''s'!B:B,Dados!B7,'BDT''s'!A:A,Dados!A7)),"-") -> 1950 | N7: =IFERROR(M7/J7*G7,0) -> 1638 | O7: =IFERROR(IF(L7>0,N7/L7-1,N7/K7-1),0) -> -0.79396226 | P7: =IFERROR(IF(L7>0,L7/G7,K7/G7),"-") -> 378.57143 | Q7: =IFERROR(M7/J7,"-") -> 78 | R7: =IFERROR(IF(Q7>P7,"ALTO","BAIXO"),"-") -> BAIXO | S7: =IFERROR(IF(COUNTIF(Cadastros!B:B,D7)>0,ROUND(AVERAGEIFS('BDT''s'!E:E,'BDT''s'!K:K,Dados!D7,'BDT''s'!C:C,Dados!C7,'BDT''s'!B:B,Dados!B7,'BDT''s'!A:A,Dados!A7),2),ROUND(AVERAGEIFS('BDT''s'!E:E,'BDT''s'!L:L,Dados!D7,'BDT''s'!C:C,Dados!C7,'BDT''s'!B:B,Dados!B7,'BDT''s'!A:A,Dados!A7),2)),"-") -> 0.16 | T7: =IFERROR(M7/V7,"-") -> - | U7: =IFERROR(IF(COUNTIF(Cadastros!B:B,D7)>0,SUMIFS(Disponibilidade!Z:Z,Disponibilidade!E:E,Dados!D7,Disponibilidade!B:B,Dados!B7,Disponibilidade!A:A,Dados!A7),SUMIFS(Disponibilidade!Z:Z,Disponibilidade!F:F,Dados!D7,Disponibilidade!B:B,Dados!B7,Disponibilidade!A:A,Dados!A7)),"-") -> 0 | V7: =IFERROR(IF(COUNTIF(Cadastros!B:B,D7)>0,SUMIFS(Disponibilidade!AB:AB,Disponibilidade!E:E,Dados!D7,Disponibilidade!B:B,Dados!B7,Disponibilidade!A:A,Dados!A7),SUMIFS(Disponibilidade!AB:AB,Disponibilidade!F:F,Dados!D7,Disponibilidade!B:B,Dados!B7,Disponibilidade!A:A,Dados!A7)),"-") -> 0 | W7: =IFERROR(IF(COUNTIF(Cadastros!B:B,D7)>0,INDEX('Metas DM & DO'!X:X,MATCH(Dados!D7,'Metas DM & DO'!A:A,0)),SUMIFS(W:W,C:C,C7,D:D,IF(D7="CORTE","FEL*",IF(D7="ARRASTE","SKD*",IF(D7="TRAÇAMENTO","GAR*",""))),B:B,B7,A:A,A7)),"-") -> - | X7: =IFERROR(W7*G7,"-") -> - | Y7: {=IFERROR(IF(COUNTIF(Cadastros!B:B,D7)>0,COUNTA(_xlfn.UNIQUE(_xlfn._xlws.FILTER('BDT''s'!N:N,('BDT''s'!C:C=Dados!C7)*('BDT''s'!K:K=Dados!D7)*('BDT''s'!B:B=Dados!B7)*('BDT''s'!N:N<>"SEM OPERADOR")))),COUNTA(_xlfn.UNIQUE(_xlfn._xlws.FILTER('BDT''s'!N:N,('BDT''s'!C:C=Dados!C7)*('BDT''s'!L:L=Dados!D7)*('BDT''s'!B:B=Dados!B7)*('BDT''s'!N:N<>"SEM OPERADOR"))))),"-")} -> 2 | Z7: =IFERROR(P7/2,"-") -> 189.28571 | AA7: =IFERROR(Z7*J7,"-") -> 4732.1429 | AB7: =IFERROR(K7/Y7,"-") -> 3975 | AC7: =IFERROR(IF(AB7>AA7,"ALTO","BAIXO"),"-") -> BAIXO | AD7: =IFERROR(X7/Y7,0) -> 0 | AE7: =IFERROR(IF(AD7>V7,"ALTO","BAIXO"),"-") -> BAIXO | AF7: =IFERROR(IF(COUNTIF(Cadastros!B:B,D7)>0,SUMIFS(Diesel!J:J,Diesel!F:F,Dados!D7,Diesel!D:D,Dados!C7,Diesel!B:B,Dados!B7,Diesel!A:A,Dados!A7),SUMIFS(Diesel!J:J,Diesel!G:G,Dados!D7,Diesel!D:D,Dados!C7,Diesel!B:B,Dados!B7,Diesel!A:A,Dados!A7)),"-") -> 380 | AG7: =IFERROR(IF(COUNTIF(Cadastros!B:B,D7)>0,SUMIFS(Diesel!K:K,Diesel!F:F,Dados!D7,Diesel!D:D,Dados!C7,Diesel!B:B,Dados!B7,Diesel!A:A,Dados!A7),SUMIFS(Diesel!K:K,Diesel!G:G,Dados!D7,Diesel!D:D,Dados!C7,Diesel!B:B,Dados!B7,Diesel!A:A,Dados!A7)),"-") -> 11 | AH7: =IFERROR(IF(COUNTIF(Cadastros!B:B,D7)>0,ROUND(INDEX('Metas Diesel'!N:N,MATCH(Dados!D7,'Metas Diesel'!A:A))*COUNTIFS(Diesel!F:F,Dados!D7,Diesel!B:B,Dados!B7,Diesel!D:D,Dados!C7),3),SUMIFS(AH:AH,C:C,C7,D:D,IF(D7="CORTE","FEL*",IF(D7="ARRASTE","SKD*",IF(D7="TRAÇAMENTO","GAR*",""))),B:B,B7,A:A,A7)),"-") -> 215.167 | AI7: =IFERROR(AH7/AG7,"-") -> 19.560636 | AJ7: =IFERROR(AF7/AG7,0) -> 34.545455 | AK7: =IF(AJ7<0,"-",IF(AJ7<AI7,"BOA","RUIM")) -> RUIM | AL7: =IFERROR(IF(COUNTIF(Cadastros!B:B,D7)>0,INDEX('Metas DM & DO'!O:O,MATCH(Dados!D7,'Metas DM & DO'!A:A,0)),AVERAGEIFS(W:W,C:C,C7,D:D,IF(D7="CORTE","FEL*",IF(D7="ARRASTE","SKD*",IF(D7="TRAÇAMENTO","GAR*",""))),B:B,B7,A:A,A7)),"-") -> - | AM7: =IFERROR(IF(COUNTIF(Cadastros!B:B,D7)>0,AVERAGEIFS('Controle Mensal'!H:H,'Controle Mensal'!E:E,Dados!D7,'Controle Mensal'!B:B,Dados!B7,'Controle Mensal'!A:A,Dados!A7),AVERAGEIFS('Controle Mensal'!H:H,'Controle Mensal'!F:F,Dados!D7,'Controle Mensal'!B:B,Dados!B7,'Controle Mensal'!A:A,Dados!A7)),"-") -> 1 | AN7: =IF(AM7<0,"-",IF(AM7<AL7,"BOA","RUIM")) -> BOA | AO7: =IFERROR(IF(COUNTIF(Cadastros!B:B,D7)>0,INDEX('Metas DM & DO'!S:S,MATCH(Dados!D7,'Metas DM & DO'!A:A,0)),AVERAGEIFS(W:W,C:C,C7,D:D,IF(D7="CORTE","FEL*",IF(D7="ARRASTE","SKD*",IF(D7="TRAÇAMENTO","GAR*",""))),B:B,B7,A:A,A7)),"-") -> - | AP7: =IFERROR(IF(COUNTIF(Cadastros!B:B,D7)>0,AVERAGEIFS('Controle Mensal'!N:N,'Controle Mensal'!E:E,Dados!D7,'Controle Mensal'!B:B,Dados!B7,'Controle Mensal'!A:A,Dados!A7),AVERAGEIFS('Controle Mensal'!N:N,'Controle Mensal'!F:F,Dados!D7,'Controle Mensal'!B:B,Dados!B7,'Controle Mensal'!A:A,Dados!A7)),"-") -> 1 | AQ7: =IF(AP7<0,"-",IF(AP7<AO7,"BOA","RUIM")) -> BOA | AR7: =IFERROR(AF7/M7,0) -> 0.19487179 | AS7: =IFERROR(M7/U7,"-") -> - | AT7: =IFERROR(IF(COUNTIF(Cadastros!B:B,D7)>0,_xlfn.MINIFS('BDT''s'!Q:Q,'BDT''s'!K:K,Dados!D7,'BDT''s'!B:B,Dados!B7,'BDT''s'!C:C,Dados!C7,'BDT''s'!A:A,Dados!A7),"-"),"-") -> 700 | AU7: =IFERROR(IF(COUNTIF(Cadastros!B:B,D7)>0,_xlfn.MAXIFS('BDT''s'!Q:Q,'BDT''s'!K:K,Dados!D7,'BDT''s'!B:B,Dados!B7,'BDT''s'!C:C,Dados!C7,'BDT''s'!A:A,Dados!A7),"-"),"-") -> 720 | AV7: =IFERROR(AU7-AT7,"-") -> 20
A8: =IFERROR(YEAR(H8),"-") -> 2026 | B8: =IFERROR(DATE(YEAR(H8),MONTH(H8),MONTH(H8)),"-") -> 46023 | C8: CONTRATO 1 | D8: CORTE | E8: 46023 | F8: 46053 | G8: =IFERROR(F8-E8-I8+1,"-") -> 31 | H8: 46047 | J8: =IFERROR(H8-E8-I8+1,"-") -> 25 | K8: {=IFERROR(IF(COUNTIF(Cadastros!B:B,D8)>0,INDEX('Metas Mensais'!A:ZZ,MATCH(Dados!D8,'Metas Mensais'!A:A,0),MATCH(Dados!B8,'Metas Mensais'!#REF!,0)+1),SUMIFS(K:K,C:C,C8,D:D,IF(D8="CORTE","FEL*",IF(D8="ARRASTE","SKD*",IF(D8="TRAÇAMENTO","GAR*",""))),B:B,B8,A:A,A8)),"-")} -> 21112.871 | L8: 0 | M8: =IFERROR(IF(COUNTIF(Cadastros!B:B,D8)>0,SUMIFS('BDT''s'!V:V,'BDT''s'!K:K,Dados!D8,'BDT''s'!C:C,Dados!C8,'BDT''s'!B:B,Dados!B8,'BDT''s'!A:A,Dados!A8),SUMIFS('BDT''s'!V:V,'BDT''s'!L:L,Dados!D8,'BDT''s'!C:C,Dados!C8,'BDT''s'!B:B,Dados!B8,'BDT''s'!A:A,Dados!A8)),"-") -> 7830 | N8: =IFERROR(M8/J8*G8,0) -> 9709.2 | O8: =IFERROR(IF(L8>0,N8/L8-1,N8/K8-1),0) -> -0.54012886 | P8: =IFERROR(IF(L8>0,L8/G8,K8/G8),"-") -> 681.06035 | Q8: =IFERROR(M8/J8,"-") -> 313.2 | R8: =IFERROR(IF(Q8>P8,"ALTO","BAIXO"),"-") -> BAIXO | S8: =IFERROR(IF(COUNTIF(Cadastros!B:B,D8)>0,ROUND(AVERAGEIFS('BDT''s'!E:E,'BDT''s'!K:K,Dados!D8,'BDT''s'!C:C,Dados!C8,'BDT''s'!B:B,Dados!B8,'BDT''s'!A:A,Dados!A8),2),ROUND(AVERAGEIFS('BDT''s'!E:E,'BDT''s'!L:L,Dados!D8,'BDT''s'!C:C,Dados!C8,'BDT''s'!B:B,Dados!B8,'BDT''s'!A:A,Dados!A8),2)),"-") -> 0.16 | T8: =IFERROR(M8/V8,"-") -> - | U8: =IFERROR(IF(COUNTIF(Cadastros!B:B,D8)>0,SUMIFS(Disponibilidade!Z:Z,Disponibilidade!E:E,Dados!D8,Disponibilidade!B:B,Dados!B8,Disponibilidade!A:A,Dados!A8),SUMIFS(Disponibilidade!Z:Z,Disponibilidade!F:F,Dados!D8,Disponibilidade!B:B,Dados!B8,Disponibilidade!A:A,Dados!A8)),"-") -> 0 | V8: =IFERROR(IF(COUNTIF(Cadastros!B:B,D8)>0,SUMIFS(Disponibilidade!AB:AB,Disponibilidade!E:E,Dados!D8,Disponibilidade!B:B,Dados!B8,Disponibilidade!A:A,Dados!A8),SUMIFS(Disponibilidade!AB:AB,Disponibilidade!F:F,Dados!D8,Disponibilidade!B:B,Dados!B8,Disponibilidade!A:A,Dados!A8)),"-") -> 0 | W8: =IFERROR(IF(COUNTIF(Cadastros!B:B,D8)>0,INDEX('Metas DM & DO'!X:X,MATCH(Dados!D8,'Metas DM & DO'!A:A,0)),SUMIFS(W:W,C:C,C8,D:D,IF(D8="CORTE","FEL*",IF(D8="ARRASTE","SKD*",IF(D8="TRAÇAMENTO","GAR*",""))),B:B,B8,A:A,A8)),"-") -> 0 | X8: =IFERROR(W8*G8,"-") -> 0 | Y8: {=IFERROR(IF(COUNTIF(Cadastros!B:B,D8)>0,COUNTA(_xlfn.UNIQUE(_xlfn._xlws.FILTER('BDT''s'!N:N,('BDT''s'!C:C=Dados!C8)*('BDT''s'!K:K=Dados!D8)*('BDT''s'!B:B=Dados!B8)*('BDT''s'!N:N<>"SEM OPERADOR")))),COUNTA(_xlfn.UNIQUE(_xlfn._xlws.FILTER('BDT''s'!N:N,('BDT''s'!C:C=Dados!C8)*('BDT''s'!L:L=Dados!D8)*('BDT''s'!B:B=Dados!B8)*('BDT''s'!N:N<>"SEM OPERADOR"))))),"-")} -> 4 | Z8: =IFERROR(P8/2,"-") -> 340.53018 | AA8: =IFERROR(Z8*J8,"-") -> 8513.2544 | AB8: =IFERROR(K8/Y8,"-") -> 5278.2177 | AC8: =IFERROR(IF(AB8>AA8,"ALTO","BAIXO"),"-") -> BAIXO | AD8: =IFERROR(X8/Y8,0) -> 0 | AE8: =IFERROR(IF(AD8>V8,"ALTO","BAIXO"),"-") -> BAIXO | AF8: =IFERROR(IF(COUNTIF(Cadastros!B:B,D8)>0,SUMIFS(Diesel!J:J,Diesel!F:F,Dados!D8,Diesel!D:D,Dados!C8,Diesel!B:B,Dados!B8,Diesel!A:A,Dados!A8),SUMIFS(Diesel!J:J,Diesel!G:G,Dados!D8,Diesel!D:D,Dados!C8,Diesel!B:B,Dados!B8,Diesel!A:A,Dados!A8)),"-") -> 720 | AG8: =IFERROR(IF(COUNTIF(Cadastros!B:B,D8)>0,SUMIFS(Diesel!K:K,Diesel!F:F,Dados!D8,Diesel!D:D,Dados!C8,Diesel!B:B,Dados!B8,Diesel!A:A,Dados!A8),SUMIFS(Diesel!K:K,Diesel!G:G,Dados!D8,Diesel!D:D,Dados!C8,Diesel!B:B,Dados!B8,Diesel!A:A,Dados!A8)),"-") -> 43 | AH8: =IFERROR(IF(COUNTIF(Cadastros!B:B,D8)>0,ROUND(INDEX('Metas Diesel'!N:N,MATCH(Dados!D8,'Metas Diesel'!A:A))*COUNTIFS(Diesel!F:F,Dados!D8,Diesel!B:B,Dados!B8,Diesel!D:D,Dados!C8),3),SUMIFS(AH:AH,C:C,C8,D:D,IF(D8="CORTE","FEL*",IF(D8="ARRASTE","SKD*",IF(D8="TRAÇAMENTO","GAR*",""))),B:B,B8,A:A,A8)),"-") -> 1116.833 | AI8: =IFERROR(AH8/AG8,"-") -> 25.97286 | AJ8: =IFERROR(AF8/AG8,0) -> 16.744186 | AK8: =IF(AJ8<0,"-",IF(AJ8<AI8,"BOA","RUIM")) -> BOA | AL8: =IFERROR(IF(COUNTIF(Cadastros!B:B,D8)>0,INDEX('Metas DM & DO'!O:O,MATCH(Dados!D8,'Metas DM & DO'!A:A,0)),AVERAGEIFS(W:W,C:C,C8,D:D,IF(D8="CORTE","FEL*",IF(D8="ARRASTE","SKD*",IF(D8="TRAÇAMENTO","GAR*",""))),B:B,B8,A:A,A8)),"-") -> - | AM8: =IFERROR(IF(COUNTIF(Cadastros!B:B,D8)>0,AVERAGEIFS('Controle Mensal'!H:H,'Controle Mensal'!E:E,Dados!D8,'Controle Mensal'!B:B,Dados!B8,'Controle Mensal'!A:A,Dados!A8),AVERAGEIFS('Controle Mensal'!H:H,'Controle Mensal'!F:F,Dados!D8,'Controle Mensal'!B:B,Dados!B8,'Controle Mensal'!A:A,Dados!A8)),"-") -> 1 | AN8: =IF(AM8<0,"-",IF(AM8<AL8,"BOA","RUIM")) -> BOA | AO8: =IFERROR(IF(COUNTIF(Cadastros!B:B,D8)>0,INDEX('Metas DM & DO'!S:S,MATCH(Dados!D8,'Metas DM & DO'!A:A,0)),AVERAGEIFS(W:W,C:C,C8,D:D,IF(D8="CORTE","FEL*",IF(D8="ARRASTE","SKD*",IF(D8="TRAÇAMENTO","GAR*",""))),B:B,B8,A:A,A8)),"-") -> - | AP8: =IFERROR(IF(COUNTIF(Cadastros!B:B,D8)>0,AVERAGEIFS('Controle Mensal'!N:N,'Controle Mensal'!E:E,Dados!D8,'Controle Mensal'!B:B,Dados!B8,'Controle Mensal'!A:A,Dados!A8),AVERAGEIFS('Controle Mensal'!N:N,'Controle Mensal'!F:F,Dados!D8,'Controle Mensal'!B:B,Dados!B8,'Controle Mensal'!A:A,Dados!A8)),"-") -> 1 | AQ8: =IF(AP8<0,"-",IF(AP8<AO8,"BOA","RUIM")) -> BOA | AR8: =IFERROR(AF8/M8,0) -> 0.091954023 | AS8: =IFERROR(M8/U8,"-") -> - | AT8: =IFERROR(IF(COUNTIF(Cadastros!B:B,D8)>0,_xlfn.MINIFS('BDT''s'!Q:Q,'BDT''s'!K:K,Dados!D8,'BDT''s'!B:B,Dados!B8,'BDT''s'!C:C,Dados!C8,'BDT''s'!A:A,Dados!A8),"-"),"-") -> - | AU8: =IFERROR(IF(COUNTIF(Cadastros!B:B,D8)>0,_xlfn.MAXIFS('BDT''s'!Q:Q,'BDT''s'!K:K,Dados!D8,'BDT''s'!B:B,Dados!B8,'BDT''s'!C:C,Dados!C8,'BDT''s'!A:A,Dados!A8),"-"),"-") -> - | AV8: =IFERROR(AU8-AT8,"-") -> -
A9: =IFERROR(YEAR(H9),"-") -> 2026 | B9: =IFERROR(DATE(YEAR(H9),MONTH(H9),MONTH(H9)),"-") -> 46023 | C9: CONTRATO 2 | D9: CORTE | E9: 46023 | F9: 46053 | G9: =IFERROR(F9-E9-I9+1,"-") -> 31 | H9: 46047 | J9: =IFERROR(H9-E9-I9+1,"-") -> 25 | K9: {=IFERROR(IF(COUNTIF(Cadastros!B:B,D9)>0,INDEX('Metas Mensais'!A:ZZ,MATCH(Dados!D9,'Metas Mensais'!A:A,0),MATCH(Dados!B9,'Metas Mensais'!8:8,0)+1),SUMIFS(K:K,C:C,C9,D:D,IF(D9="CORTE","FEL*",IF(D9="ARRASTE","SKD*",IF(D9="TRAÇAMENTO","GAR*",""))),B:B,B9,A:A,A9)),"-")} -> 0 | L9: 0 | M9: =IFERROR(IF(COUNTIF(Cadastros!B:B,D9)>0,SUMIFS('BDT''s'!V:V,'BDT''s'!K:K,Dados!D9,'BDT''s'!C:C,Dados!C9,'BDT''s'!B:B,Dados!B9,'BDT''s'!A:A,Dados!A9),SUMIFS('BDT''s'!V:V,'BDT''s'!L:L,Dados!D9,'BDT''s'!C:C,Dados!C9,'BDT''s'!B:B,Dados!B9,'BDT''s'!A:A,Dados!A9)),"-") -> 0 | N9: =IFERROR(M9/J9*G9,0) -> 0 | O9: =IFERROR(IF(L9>0,N9/L9-1,N9/K9-1),0) -> 0 | P9: =IFERROR(IF(L9>0,L9/G9,K9/G9),"-") -> 0 | Q9: =IFERROR(M9/J9,"-") -> 0 | R9: =IFERROR(IF(Q9>P9,"ALTO","BAIXO"),"-") -> BAIXO | S9: =IFERROR(IF(COUNTIF(Cadastros!B:B,D9)>0,ROUND(AVERAGEIFS('BDT''s'!E:E,'BDT''s'!K:K,Dados!D9,'BDT''s'!C:C,Dados!C9,'BDT''s'!B:B,Dados!B9,'BDT''s'!A:A,Dados!A9),2),ROUND(AVERAGEIFS('BDT''s'!E:E,'BDT''s'!L:L,Dados!D9,'BDT''s'!C:C,Dados!C9,'BDT''s'!B:B,Dados!B9,'BDT''s'!A:A,Dados!A9),2)),"-") -> - | T9: =IFERROR(M9/V9,"-") -> - | U9: =IFERROR(IF(COUNTIF(Cadastros!B:B,D9)>0,SUMIFS(Disponibilidade!Z:Z,Disponibilidade!E:E,Dados!D9,Disponibilidade!B:B,Dados!B9,Disponibilidade!A:A,Dados!A9),SUMIFS(Disponibilidade!Z:Z,Disponibilidade!F:F,Dados!D9,Disponibilidade!B:B,Dados!B9,Disponibilidade!A:A,Dados!A9)),"-") -> 0 | V9: =IFERROR(IF(COUNTIF(Cadastros!B:B,D9)>0,SUMIFS(Disponibilidade!AB:AB,Disponibilidade!E:E,Dados!D9,Disponibilidade!B:B,Dados!B9,Disponibilidade!A:A,Dados!A9),SUMIFS(Disponibilidade!AB:AB,Disponibilidade!F:F,Dados!D9,Disponibilidade!B:B,Dados!B9,Disponibilidade!A:A,Dados!A9)),"-") -> 0 | W9: =IFERROR(IF(COUNTIF(Cadastros!B:B,D9)>0,INDEX('Metas DM & DO'!X:X,MATCH(Dados!D9,'Metas DM & DO'!A:A,0)),SUMIFS(W:W,C:C,C9,D:D,IF(D9="CORTE","FEL*",IF(D9="ARRASTE","SKD*",IF(D9="TRAÇAMENTO","GAR*",""))),B:B,B9,A:A,A9)),"-") -> 0 | X9: =IFERROR(W9*G9,"-") -> 0 | Y9: {=IFERROR(IF(COUNTIF(Cadastros!B:B,D9)>0,COUNTA(_xlfn.UNIQUE(_xlfn._xlws.FILTER('BDT''s'!N:N,('BDT''s'!C:C=Dados!C9)*('BDT''s'!K:K=Dados!D9)*('BDT''s'!B:B=Dados!B9)*('BDT''s'!N:N<>"SEM OPERADOR")))),COUNTA(_xlfn.UNIQUE(_xlfn._xlws.FILTER('BDT''s'!N:N,('BDT''s'!C:C=Dados!C9)*('BDT''s'!L:L=Dados!D9)*('BDT''s'!B:B=Dados!B9)*('BDT''s'!N:N<>"SEM OPERADOR"))))),"-")} -> 1 | Z9: =IFERROR(P9/2,"-") -> 0 | AA9: =IFERROR(Z9*J9,"-") -> 0 | AB9: =IFERROR(K9/Y9,"-") -> 0 | AC9: =IFERROR(IF(AB9>AA9,"ALTO","BAIXO"),"-") -> BAIXO | AD9: =IFERROR(X9/Y9,0) -> 0 | AE9: =IFERROR(IF(AD9>V9,"ALTO","BAIXO"),"-") -> BAIXO | AF9: =IFERROR(IF(COUNTIF(Cadastros!B:B,D9)>0,SUMIFS(Diesel!J:J,Diesel!F:F,Dados!D9,Diesel!D:D,Dados!C9,Diesel!B:B,Dados!B9,Diesel!A:A,Dados!A9),SUMIFS(Diesel!J:J,Diesel!G:G,Dados!D9,Diesel!D:D,Dados!C9,Diesel!B:B,Dados!B9,Diesel!A:A,Dados!A9)),"-") -> 0 | AG9: =IFERROR(IF(COUNTIF(Cadastros!B:B,D9)>0,SUMIFS(Diesel!K:K,Diesel!F:F,Dados!D9,Diesel!D:D,Dados!C9,Diesel!B:B,Dados!B9,Diesel!A:A,Dados!A9),SUMIFS(Diesel!K:K,Diesel!G:G,Dados!D9,Diesel!D:D,Dados!C9,Diesel!B:B,Dados!B9,Diesel!A:A,Dados!A9)),"-") -> 0 | AH9: =IFERROR(IF(COUNTIF(Cadastros!B:B,D9)>0,ROUND(INDEX('Metas Diesel'!N:N,MATCH(Dados!D9,'Metas Diesel'!A:A))*COUNTIFS(Diesel!F:F,Dados!D9,Diesel!B:B,Dados!B9,Diesel!D:D,Dados!C9),3),SUMIFS(AH:AH,C:C,C9,D:D,IF(D9="CORTE","FEL*",IF(D9="ARRASTE","SKD*",IF(D9="TRAÇAMENTO","GAR*",""))),B:B,B9,A:A,A9)),"-") -> 0 | AI9: =IFERROR(AH9/AG9,"-") -> - | AJ9: =IFERROR(AF9/AG9,0) -> 0 | AK9: =IF(AJ9<0,"-",IF(AJ9<AI9,"BOA","RUIM")) -> BOA | AL9: =IFERROR(IF(COUNTIF(Cadastros!B:B,D9)>0,INDEX('Metas DM & DO'!O:O,MATCH(Dados!D9,'Metas DM & DO'!A:A,0)),AVERAGEIFS(W:W,C:C,C9,D:D,IF(D9="CORTE","FEL*",IF(D9="ARRASTE","SKD*",IF(D9="TRAÇAMENTO","GAR*",""))),B:B,B9,A:A,A9)),"-") -> - | AM9: =IFERROR(IF(COUNTIF(Cadastros!B:B,D9)>0,AVERAGEIFS('Controle Mensal'!H:H,'Controle Mensal'!E:E,Dados!D9,'Controle Mensal'!B:B,Dados!B9,'Controle Mensal'!A:A,Dados!A9),AVERAGEIFS('Controle Mensal'!H:H,'Controle Mensal'!F:F,Dados!D9,'Controle Mensal'!B:B,Dados!B9,'Controle Mensal'!A:A,Dados!A9)),"-") -> 1 | AN9: =IF(AM9<0,"-",IF(AM9<AL9,"BOA","RUIM")) -> BOA | AO9: =IFERROR(IF(COUNTIF(Cadastros!B:B,D9)>0,INDEX('Metas DM & DO'!S:S,MATCH(Dados!D9,'Metas DM & DO'!A:A,0)),AVERAGEIFS(W:W,C:C,C9,D:D,IF(D9="CORTE","FEL*",IF(D9="ARRASTE","SKD*",IF(D9="TRAÇAMENTO","GAR*",""))),B:B,B9,A:A,A9)),"-") -> - | AP9: =IFERROR(IF(COUNTIF(Cadastros!B:B,D9)>0,AVERAGEIFS('Controle Mensal'!N:N,'Controle Mensal'!E:E,Dados!D9,'Controle Mensal'!B:B,Dados!B9,'Controle Mensal'!A:A,Dados!A9),AVERAGEIFS('Controle Mensal'!N:N,'Controle Mensal'!F:F,Dados!D9,'Controle Mensal'!B:B,Dados!B9,'Controle Mensal'!A:A,Dados!A9)),"-") -> 1 | AQ9: =IF(AP9<0,"-",IF(AP9<AO9,"BOA","RUIM")) -> BOA | AR9: =IFERROR(AF9/M9,0) -> 0 | AS9: =IFERROR(M9/U9,"-") -> - | AT9: =IFERROR(IF(COUNTIF(Cadastros!B:B,D9)>0,_xlfn.MINIFS('BDT''s'!Q:Q,'BDT''s'!K:K,Dados!D9,'BDT''s'!B:B,Dados!B9,'BDT''s'!C:C,Dados!C9,'BDT''s'!A:A,Dados!A9),"-"),"-") -> - | AU9: =IFERROR(IF(COUNTIF(Cadastros!B:B,D9)>0,_xlfn.MAXIFS('BDT''s'!Q:Q,'BDT''s'!K:K,Dados!D9,'BDT''s'!B:B,Dados!B9,'BDT''s'!C:C,Dados!C9,'BDT''s'!A:A,Dados!A9),"-"),"-") -> - | AV9: =IFERROR(AU9-AT9,"-") -> -
A10: =IFERROR(YEAR(H10),"-") -> 2026 | B10: =IFERROR(DATE(YEAR(H10),MONTH(H10),MONTH(H10)),"-") -> 46023 | C10: CONTRATO 3 | D10: CORTE | E10: 46023 | F10: 46053 | G10: =IFERROR(F10-E10-I10+1,"-") -> 31 | H10: 46047 | J10: =IFERROR(H10-E10-I10+1,"-") -> 25 | K10: {=IFERROR(IF(COUNTIF(Cadastros!B:B,D10)>0,INDEX('Metas Mensais'!A:ZZ,MATCH(Dados!D10,'Metas Mensais'!A:A,0),MATCH(Dados!B10,'Metas Mensais'!9:9,0)+1),SUMIFS(K:K,C:C,C10,D:D,IF(D10="CORTE","FEL*",IF(D10="ARRASTE","SKD*",IF(D10="TRAÇAMENTO","GAR*",""))),B:B,B10,A:A,A10)),"-")} -> 0 | L10: 0 | M10: =IFERROR(IF(COUNTIF(Cadastros!B:B,D10)>0,SUMIFS('BDT''s'!V:V,'BDT''s'!K:K,Dados!D10,'BDT''s'!C:C,Dados!C10,'BDT''s'!B:B,Dados!B10,'BDT''s'!A:A,Dados!A10),SUMIFS('BDT''s'!V:V,'BDT''s'!L:L,Dados!D10,'BDT''s'!C:C,Dados!C10,'BDT''s'!B:B,Dados!B10,'BDT''s'!A:A,Dados!A10)),"-") -> 0 | N10: =IFERROR(M10/J10*G10,0) -> 0 | O10: =IFERROR(IF(L10>0,N10/L10-1,N10/K10-1),0) -> 0 | P10: =IFERROR(IF(L10>0,L10/G10,K10/G10),"-") -> 0 | Q10: =IFERROR(M10/J10,"-") -> 0 | R10: =IFERROR(IF(Q10>P10,"ALTO","BAIXO"),"-") -> BAIXO | S10: =IFERROR(IF(COUNTIF(Cadastros!B:B,D10)>0,ROUND(AVERAGEIFS('BDT''s'!E:E,'BDT''s'!K:K,Dados!D10,'BDT''s'!C:C,Dados!C10,'BDT''s'!B:B,Dados!B10,'BDT''s'!A:A,Dados!A10),2),ROUND(AVERAGEIFS('BDT''s'!E:E,'BDT''s'!L:L,Dados!D10,'BDT''s'!C:C,Dados!C10,'BDT''s'!B:B,Dados!B10,'BDT''s'!A:A,Dados!A10),2)),"-") -> - | T10: =IFERROR(M10/V10,"-") -> - | U10: =IFERROR(IF(COUNTIF(Cadastros!B:B,D10)>0,SUMIFS(Disponibilidade!Z:Z,Disponibilidade!E:E,Dados!D10,Disponibilidade!B:B,Dados!B10,Disponibilidade!A:A,Dados!A10),SUMIFS(Disponibilidade!Z:Z,Disponibilidade!F:F,Dados!D10,Disponibilidade!B:B,Dados!B10,Disponibilidade!A:A,Dados!A10)),"-") -> 0 | V10: =IFERROR(IF(COUNTIF(Cadastros!B:B,D10)>0,SUMIFS(Disponibilidade!AB:AB,Disponibilidade!E:E,Dados!D10,Disponibilidade!B:B,Dados!B10,Disponibilidade!A:A,Dados!A10),SUMIFS(Disponibilidade!AB:AB,Disponibilidade!F:F,Dados!D10,Disponibilidade!B:B,Dados!B10,Disponibilidade!A:A,Dados!A10)),"-") -> 0 | W10: =IFERROR(IF(COUNTIF(Cadastros!B:B,D10)>0,INDEX('Metas DM & DO'!X:X,MATCH(Dados!D10,'Metas DM & DO'!A:A,0)),SUMIFS(W:W,C:C,C10,D:D,IF(D10="CORTE","FEL*",IF(D10="ARRASTE","SKD*",IF(D10="TRAÇAMENTO","GAR*",""))),B:B,B10,A:A,A10)),"-") -> 0 | X10: =IFERROR(W10*G10,"-") -> 0 | Y10: {=IFERROR(IF(COUNTIF(Cadastros!B:B,D10)>0,COUNTA(_xlfn.UNIQUE(_xlfn._xlws.FILTER('BDT''s'!N:N,('BDT''s'!C:C=Dados!C10)*('BDT''s'!K:K=Dados!D10)*('BDT''s'!B:B=Dados!B10)*('BDT''s'!N:N<>"SEM OPERADOR")))),COUNTA(_xlfn.UNIQUE(_xlfn._xlws.FILTER('BDT''s'!N:N,('BDT''s'!C:C=Dados!C10)*('BDT''s'!L:L=Dados!D10)*('BDT''s'!B:B=Dados!B10)*('BDT''s'!N:N<>"SEM OPERADOR"))))),"-")} -> 1 | Z10: =IFERROR(P10/2,"-") -> 0 | AA10: =IFERROR(Z10*J10,"-") -> 0 | AB10: =IFERROR(K10/Y10,"-") -> 0 | AC10: =IFERROR(IF(AB10>AA10,"ALTO","BAIXO"),"-") -> BAIXO | AD10: =IFERROR(X10/Y10,0) -> 0 | AE10: =IFERROR(IF(AD10>V10,"ALTO","BAIXO"),"-") -> BAIXO | AF10: =IFERROR(IF(COUNTIF(Cadastros!B:B,D10)>0,SUMIFS(Diesel!J:J,Diesel!F:F,Dados!D10,Diesel!D:D,Dados!C10,Diesel!B:B,Dados!B10,Diesel!A:A,Dados!A10),SUMIFS(Diesel!J:J,Diesel!G:G,Dados!D10,Diesel!D:D,Dados!C10,Diesel!B:B,Dados!B10,Diesel!A:A,Dados!A10)),"-") -> 0 | AG10: =IFERROR(IF(COUNTIF(Cadastros!B:B,D10)>0,SUMIFS(Diesel!K:K,Diesel!F:F,Dados!D10,Diesel!D:D,Dados!C10,Diesel!B:B,Dados!B10,Diesel!A:A,Dados!A10),SUMIFS(Diesel!K:K,Diesel!G:G,Dados!D10,Diesel!D:D,Dados!C10,Diesel!B:B,Dados!B10,Diesel!A:A,Dados!A10)),"-") -> 0 | AH10: =IFERROR(IF(COUNTIF(Cadastros!B:B,D10)>0,ROUND(INDEX('Metas Diesel'!N:N,MATCH(Dados!D10,'Metas Diesel'!A:A))*COUNTIFS(Diesel!F:F,Dados!D10,Diesel!B:B,Dados!B10,Diesel!D:D,Dados!C10),3),SUMIFS(AH:AH,C:C,C10,D:D,IF(D10="CORTE","FEL*",IF(D10="ARRASTE","SKD*",IF(D10="TRAÇAMENTO","GAR*",""))),B:B,B10,A:A,A10)),"-") -> 0 | AI10: =IFERROR(AH10/AG10,"-") -> - | AJ10: =IFERROR(AF10/AG10,0) -> 0 | AK10: =IF(AJ10<0,"-",IF(AJ10<AI10,"BOA","RUIM")) -> BOA | AL10: =IFERROR(IF(COUNTIF(Cadastros!B:B,D10)>0,INDEX('Metas DM & DO'!O:O,MATCH(Dados!D10,'Metas DM & DO'!A:A,0)),AVERAGEIFS(W:W,C:C,C10,D:D,IF(D10="CORTE","FEL*",IF(D10="ARRASTE","SKD*",IF(D10="TRAÇAMENTO","GAR*",""))),B:B,B10,A:A,A10)),"-") -> - | AM10: =IFERROR(IF(COUNTIF(Cadastros!B:B,D10)>0,AVERAGEIFS('Controle Mensal'!H:H,'Controle Mensal'!E:E,Dados!D10,'Controle Mensal'!B:B,Dados!B10,'Controle Mensal'!A:A,Dados!A10),AVERAGEIFS('Controle Mensal'!H:H,'Controle Mensal'!F:F,Dados!D10,'Controle Mensal'!B:B,Dados!B10,'Controle Mensal'!A:A,Dados!A10)),"-") -> 1 | AN10: =IF(AM10<0,"-",IF(AM10<AL10,"BOA","RUIM")) -> BOA | AO10: =IFERROR(IF(COUNTIF(Cadastros!B:B,D10)>0,INDEX('Metas DM & DO'!S:S,MATCH(Dados!D10,'Metas DM & DO'!A:A,0)),AVERAGEIFS(W:W,C:C,C10,D:D,IF(D10="CORTE","FEL*",IF(D10="ARRASTE","SKD*",IF(D10="TRAÇAMENTO","GAR*",""))),B:B,B10,A:A,A10)),"-") -> - | AP10: =IFERROR(IF(COUNTIF(Cadastros!B:B,D10)>0,AVERAGEIFS('Controle Mensal'!N:N,'Controle Mensal'!E:E,Dados!D10,'Controle Mensal'!B:B,Dados!B10,'Controle Mensal'!A:A,Dados!A10),AVERAGEIFS('Controle Mensal'!N:N,'Controle Mensal'!F:F,Dados!D10,'Controle Mensal'!B:B,Dados!B10,'Controle Mensal'!A:A,Dados!A10)),"-") -> 1 | AQ10: =IF(AP10<0,"-",IF(AP10<AO10,"BOA","RUIM")) -> BOA | AR10: =IFERROR(AF10/M10,0) -> 0 | AS10: =IFERROR(M10/U10,"-") -> - | AT10: =IFERROR(IF(COUNTIF(Cadastros!B:B,D10)>0,_xlfn.MINIFS('BDT''s'!Q:Q,'BDT''s'!K:K,Dados!D10,'BDT''s'!B:B,Dados!B10,'BDT''s'!C:C,Dados!C10,'BDT''s'!A:A,Dados!A10),"-"),"-") -> - | AU10: =IFERROR(IF(COUNTIF(Cadastros!B:B,D10)>0,_xlfn.MAXIFS('BDT''s'!Q:Q,'BDT''s'!K:K,Dados!D10,'BDT''s'!B:B,Dados!B10,'BDT''s'!C:C,Dados!C10,'BDT''s'!A:A,Dados!A10),"-"),"-") -> - | AV10: =IFERROR(AU10-AT10,"-") -> -
A11: =IFERROR(YEAR(H11),"-") -> 2026 | B11: =IFERROR(DATE(YEAR(H11),MONTH(H11),MONTH(H11)),"-") -> 46023 | C11: CONTRATO 1 | D11: ARRASTE | E11: 46023 | F11: 46053 | G11: =IFERROR(F11-E11-I11+1,"-") -> 31 | H11: 46047 | J11: =IFERROR(H11-E11-I11+1,"-") -> 25 | K11: {=IFERROR(IF(COUNTIF(Cadastros!B:B,D11)>0,INDEX('Metas Mensais'!A:ZZ,MATCH(Dados!D11,'Metas Mensais'!A:A,0),MATCH(Dados!B11,'Metas Mensais'!10:10,0)+1),SUMIFS(K:K,C:C,C11,D:D,IF(D11="CORTE","FEL*",IF(D11="ARRASTE","SKD*",IF(D11="TRAÇAMENTO","GAR*",""))),B:B,B11,A:A,A11)),"-")} -> 0 | L11: 0 | M11: =IFERROR(IF(COUNTIF(Cadastros!B:B,D11)>0,SUMIFS('BDT''s'!V:V,'BDT''s'!K:K,Dados!D11,'BDT''s'!C:C,Dados!C11,'BDT''s'!B:B,Dados!B11,'BDT''s'!A:A,Dados!A11),SUMIFS('BDT''s'!V:V,'BDT''s'!L:L,Dados!D11,'BDT''s'!C:C,Dados!C11,'BDT''s'!B:B,Dados!B11,'BDT''s'!A:A,Dados!A11)),"-") -> 5530 | N11: =IFERROR(M11/J11*G11,0) -> 6857.2 | O11: =IFERROR(IF(L11>0,N11/L11-1,N11/K11-1),0) -> 0 | P11: =IFERROR(IF(L11>0,L11/G11,K11/G11),"-") -> 0 | Q11: =IFERROR(M11/J11,"-") -> 221.2 | R11: =IFERROR(IF(Q11>P11,"ALTO","BAIXO"),"-") -> ALTO | S11: =IFERROR(IF(COUNTIF(Cadastros!B:B,D11)>0,ROUND(AVERAGEIFS('BDT''s'!E:E,'BDT''s'!K:K,Dados!D11,'BDT''s'!C:C,Dados!C11,'BDT''s'!B:B,Dados!B11,'BDT''s'!A:A,Dados!A11),2),ROUND(AVERAGEIFS('BDT''s'!E:E,'BDT''s'!L:L,Dados!D11,'BDT''s'!C:C,Dados!C11,'BDT''s'!B:B,Dados!B11,'BDT''s'!A:A,Dados!A11),2)),"-") -> 0.16 | T11: =IFERROR(M11/V11,"-") -> - | U11: =IFERROR(IF(COUNTIF(Cadastros!B:B,D11)>0,SUMIFS(Disponibilidade!Z:Z,Disponibilidade!E:E,Dados!D11,Disponibilidade!B:B,Dados!B11,Disponibilidade!A:A,Dados!A11),SUMIFS(Disponibilidade!Z:Z,Disponibilidade!F:F,Dados!D11,Disponibilidade!B:B,Dados!B11,Disponibilidade!A:A,Dados!A11)),"-") -> 0 | V11: =IFERROR(IF(COUNTIF(Cadastros!B:B,D11)>0,SUMIFS(Disponibilidade!AB:AB,Disponibilidade!E:E,Dados!D11,Disponibilidade!B:B,Dados!B11,Disponibilidade!A:A,Dados!A11),SUMIFS(Disponibilidade!AB:AB,Disponibilidade!F:F,Dados!D11,Disponibilidade!B:B,Dados!B11,Disponibilidade!A:A,Dados!A11)),"-") -> 0 | W11: =IFERROR(IF(COUNTIF(Cadastros!B:B,D11)>0,INDEX('Metas DM & DO'!X:X,MATCH(Dados!D11,'Metas DM & DO'!A:A,0)),SUMIFS(W:W,C:C,C11,D:D,IF(D11="CORTE","FEL*",IF(D11="ARRASTE","SKD*",IF(D11="TRAÇAMENTO","GAR*",""))),B:B,B11,A:A,A11)),"-") -> 0 | X11: =IFERROR(W11*G11,"-") -> 0 | Y11: {=IFERROR(IF(COUNTIF(Cadastros!B:B,D11)>0,COUNTA(_xlfn.UNIQUE(_xlfn._xlws.FILTER('BDT''s'!N:N,('BDT''s'!C:C=Dados!C11)*('BDT''s'!K:K=Dados!D11)*('BDT''s'!B:B=Dados!B11)*('BDT''s'!N:N<>"SEM OPERADOR")))),COUNTA(_xlfn.UNIQUE(_xlfn._xlws.FILTER('BDT''s'!N:N,('BDT''s'!C:C=Dados!C11)*('BDT''s'!L:L=Dados!D11)*('BDT''s'!B:B=Dados!B11)*('BDT''s'!N:N<>"SEM OPERADOR"))))),"-")} -> 4 | Z11: =IFERROR(P11/2,"-") -> 0 | AA11: =IFERROR(Z11*J11,"-") -> 0 | AB11: =IFERROR(K11/Y11,"-") -> 0 | AC11: =IFERROR(IF(AB11>AA11,"ALTO","BAIXO"),"-") -> BAIXO | AD11: =IFERROR(X11/Y11,0) -> 0 | AE11: =IFERROR(IF(AD11>V11,"ALTO","BAIXO"),"-") -> BAIXO | AF11: =IFERROR(IF(COUNTIF(Cadastros!B:B,D11)>0,SUMIFS(Diesel!J:J,Diesel!F:F,Dados!D11,Diesel!D:D,Dados!C11,Diesel!B:B,Dados!B11,Diesel!A:A,Dados!A11),SUMIFS(Diesel!J:J,Diesel!G:G,Dados!D11,Diesel!D:D,Dados!C11,Diesel!B:B,Dados!B11,Diesel!A:A,Dados!A11)),"-") -> 1000 | AG11: =IFERROR(IF(COUNTIF(Cadastros!B:B,D11)>0,SUMIFS(Diesel!K:K,Diesel!F:F,Dados!D11,Diesel!D:D,Dados!C11,Diesel!B:B,Dados!B11,Diesel!A:A,Dados!A11),SUMIFS(Diesel!K:K,Diesel!G:G,Dados!D11,Diesel!D:D,Dados!C11,Diesel!B:B,Dados!B11,Diesel!A:A,Dados!A11)),"-") -> 30 | AH11: =IFERROR(IF(COUNTIF(Cadastros!B:B,D11)>0,ROUND(INDEX('Metas Diesel'!N:N,MATCH(Dados!D11,'Metas Diesel'!A:A))*COUNTIFS(Diesel!F:F,Dados!D11,Diesel!B:B,Dados!B11,Diesel!D:D,Dados!C11),3),SUMIFS(AH:AH,C:C,C11,D:D,IF(D11="CORTE","FEL*",IF(D11="ARRASTE","SKD*",IF(D11="TRAÇAMENTO","GAR*",""))),B:B,B11,A:A,A11)),"-") -> 0 | AI11: =IFERROR(AH11/AG11,"-") -> 0 | AJ11: =IFERROR(AF11/AG11,0) -> 33.333333 | AK11: =IF(AJ11<0,"-",IF(AJ11<AI11,"BOA","RUIM")) -> RUIM | AL11: =IFERROR(IF(COUNTIF(Cadastros!B:B,D11)>0,INDEX('Metas DM & DO'!O:O,MATCH(Dados!D11,'Metas DM & DO'!A:A,0)),AVERAGEIFS(W:W,C:C,C11,D:D,IF(D11="CORTE","FEL*",IF(D11="ARRASTE","SKD*",IF(D11="TRAÇAMENTO","GAR*",""))),B:B,B11,A:A,A11)),"-") -> - | AM11: =IFERROR(IF(COUNTIF(Cadastros!B:B,D11)>0,AVERAGEIFS('Controle Mensal'!H:H,'Controle Mensal'!E:E,Dados!D11,'Controle Mensal'!B:B,Dados!B11,'Controle Mensal'!A:A,Dados!A11),AVERAGEIFS('Controle Mensal'!H:H,'Controle Mensal'!F:F,Dados!D11,'Controle Mensal'!B:B,Dados!B11,'Controle Mensal'!A:A,Dados!A11)),"-") -> 1 | AN11: =IF(AM11<0,"-",IF(AM11<AL11,"BOA","RUIM")) -> BOA | AO11: =IFERROR(IF(COUNTIF(Cadastros!B:B,D11)>0,INDEX('Metas DM & DO'!S:S,MATCH(Dados!D11,'Metas DM & DO'!A:A,0)),AVERAGEIFS(W:W,C:C,C11,D:D,IF(D11="CORTE","FEL*",IF(D11="ARRASTE","SKD*",IF(D11="TRAÇAMENTO","GAR*",""))),B:B,B11,A:A,A11)),"-") -> - | AP11: =IFERROR(IF(COUNTIF(Cadastros!B:B,D11)>0,AVERAGEIFS('Controle Mensal'!N:N,'Controle Mensal'!E:E,Dados!D11,'Controle Mensal'!B:B,Dados!B11,'Controle Mensal'!A:A,Dados!A11),AVERAGEIFS('Controle Mensal'!N:N,'Controle Mensal'!F:F,Dados!D11,'Controle Mensal'!B:B,Dados!B11,'Controle Mensal'!A:A,Dados!A11)),"-") -> 1 | AQ11: =IF(AP11<0,"-",IF(AP11<AO11,"BOA","RUIM")) -> BOA | AR11: =IFERROR(AF11/M11,0) -> 0.18083183 | AS11: =IFERROR(M11/U11,"-") -> - | AT11: =IFERROR(IF(COUNTIF(Cadastros!B:B,D11)>0,_xlfn.MINIFS('BDT''s'!Q:Q,'BDT''s'!K:K,Dados!D11,'BDT''s'!B:B,Dados!B11,'BDT''s'!C:C,Dados!C11,'BDT''s'!A:A,Dados!A11),"-"),"-") -> - | AU11: =IFERROR(IF(COUNTIF(Cadastros!B:B,D11)>0,_xlfn.MAXIFS('BDT''s'!Q:Q,'BDT''s'!K:K,Dados!D11,'BDT''s'!B:B,Dados!B11,'BDT''s'!C:C,Dados!C11,'BDT''s'!A:A,Dados!A11),"-"),"-") -> - | AV11: =IFERROR(AU11-AT11,"-") -> -
