Workbook

Sheet BDT's
A1: ANO | B1: MÊS | C1: CONTRATO | D1: BITOLA | E1: VMI | F1: FAIXA VMI | G1: FAZENDA | H1: TALHÃO | I1: DATA APONTAMENTO | J1: EQUIPAMENTO DIGITADO | K1: EQUIPAMENTO | L1: TIPO DE EQUIPAMENTO | M1: META BASE M³/H POR OPERAÇÃO | N1: OPERADOR | O1: TURNO | P1: MOVIMENTO ENTRE TALHÕES | Q1: HORÍMETRO ANTERIOR | R1: HORÍMETRO ATUAL | S1: HORAS RODADAS | T1: QUANTIDADE DE ÁRVORES | U1: VOLUME PRODUZIDO | V1: VOLUME AJUSTADO | W1: M³ / HORA RODADA | X1: HEC PRODUZIDO NO DIA | Y1: HEC PRODUZIDO NO DIA AJUSTADO | Z1: META BASE M³ POR TURNO | AA1: META BASE M³ POR HORA | AB1: META DESAFIO M³ POR TURNO | AC1: META DESAFIO M³ POR HORA | AD1: TETO META M³ POR TURNO | AE1: TETO META M³ POR HORA | AF1: STATUS META | AG1: FATOR | AH1: % COBERTURA | AI1: VOLUME TALHÃO | AJ1: STATUS DO TALHÃO
A2: =IFERROR(YEAR(I2),"-") -> 2026 | B2: =IFERROR(DATE(YEAR(I2),MONTH(I2),MONTH(I2)),"-") -> 46023 | C2: {=IFERROR(IF(INDEX('Cadastro Talhão'!A:A,MATCH(1,('Cadastro Talhão'!B:B='BDT''s'!G2)*('Cadastro Talhão'!C:C='BDT''s'!H2),0))=0,"-",INDEX('Cadastro Talhão'!A:A,MATCH(1,('Cadastro Talhão'!B:B='BDT''s'!G2)*('Cadastro Talhão'!C:C='BDT''s'!H2),0))),"-")} -> CONTRATO 1 | D2: {=IFERROR(INDEX('Cadastro Talhão'!H:H,MATCH(1,('Cadastro Talhão'!B:B='BDT''s'!G2)*('Cadastro Talhão'!C:C='BDT''s'!H2),0)),"-")} -> 1.9 | E2: {=IFERROR(INDEX('Cadastro Talhão'!F:F,MATCH(1,('Cadastro Talhão'!B:B='BDT''s'!G2)*('Cadastro Talhão'!C:C='BDT''s'!H2),0)),"-")} -> 0.15 | F2: =IFERROR(VLOOKUP(E2,VMI!A:B,2,FALSE),"-") -> 0,11 a 0,15 | G2: FAZENDA 1 | H2: 15 | I2: 46023 | J2: FELLER1 | K2: =IFERROR(VLOOKUP(J2,Cadastros!A:B,2,FALSE),"-") -> FELLER BUNCHER 1 | L2: =IFERROR(VLOOKUP(K2,Cadastros!B:D,3,FALSE),"-") -> CORTE | M2: {=IFERROR(INDEX(VMI!$A:$AAL,MATCH(1,(VMI!$A:$A=E2)*(VMI!$B:$B=F2),0),MATCH(L2,VMI!$1:$1,0)+1)*(AVERAGEIFS('Metas Produção'!I:I,'Metas Produção'!B:B,'BDT''s'!L2)),"-")} -> 86.557111 | N2: OPERADOR 1 | O2: TURNO 1 | P2: =IFERROR(COUNTIFS(O:O,O2,N:N,N2,I:I,I2,J:J,J2,C:C,C2),"-") -> 1 | Q2: 1000 | R2: 1010.2 | S2: =IFERROR(IF(R2="-",0,IF(R2-Q2<0,"-",R2-Q2)),"-") -> 10.2 | T2: {=IFERROR(U2/INDEX('Cadastro Talhão'!F:F,MATCH(1,('Cadastro Talhão'!B:B='BDT''s'!G2)*('Cadastro Talhão'!C:C='BDT''s'!H2)*('Cadastro Talhão'!A:A='BDT''s'!C2),0)),"-")} -> 4866.6667 | U2: 730 | V2: =IF(U2="-",0,IFERROR(IF(AJ2="FINALIZADO",AI2/SUMIFS(AG:AG,G:G,G2,H:H,H2,L:L,L2,A:A,A2,B:B,B2)*AG2,U2),U2)) -> 730 | W2: =IFERROR(U2/S2,"-") -> 71.568627 | X2: {=IFERROR(U2/INDEX('Cadastro Talhão'!G:G,MATCH(1,('Cadastro Talhão'!B:B=G2)*('Cadastro Talhão'!C:C=H2),0))*INDEX('Cadastro Talhão'!D:D,MATCH(1,('Cadastro Talhão'!B:B=G2)*('Cadastro Talhão'!C:C=H2),0)),"-")} -> 0.876 | Y2: {=IFERROR(V2/INDEX('Cadastro Talhão'!G:G,MATCH(1,('Cadastro Talhão'!B:B=G2)*('Cadastro Talhão'!C:C=H2),0))*INDEX('Cadastro Talhão'!D:D,MATCH(1,('Cadastro Talhão'!B:B=G2)*('Cadastro Talhão'!C:C=H2),0)),"-")} -> 0.876 | Z2: {=IFERROR(INDEX('Metas Produção'!$A:$ZZ,MATCH(K2, 'Metas Produção'!$A:$A, 0),MATCH(F2, 'Metas Produção'!$1:$1, 0)+1)*12,"-")} -> 1056.4112 | AA2: =IFERROR(Z2/12,"-") -> 88.034267 | AB2: {=IFERROR(INDEX('Metas Produção'!$A:$ZZ,MATCH(K2, 'Metas Produção'!$A:$A, 0),MATCH(F2, 'Metas Produção'!$1:$1, 0)+2)*12,"-")} -> 1083.6967 | AC2: =IFERROR(AB2/12,"-") -> 90.308055 | AD2: {=IFERROR(INDEX('Metas Produção'!$A:$ZZ,MATCH(K2, 'Metas Produção'!$A:$A, 0),MATCH(F2, 'Metas Produção'!$1:$1, 0)+3)*12,"-")} -> 1200 | AE2: =IFERROR(AD2/12,"-") -> 100 | AF2: =IFERROR(IF(W2="-","-",IF(W2<AA2,"BAIXO",IF(AND(W2>=AA2,W2<AC2),"MEDIO",IF(AND(W2>=AC2,W2<=AE2),"ALTO","-")))),"-") -> BAIXO | AG2: =IFERROR(U2/SUMIFS(U:U,G:G,G2,H:H,H2,L:L,L2,A:A,A2,B:B,B2),0) -> 0.24914676 | AH2: {=IFERROR(V2/INDEX('Cadastro Talhão'!G:G,MATCH(1,('Cadastro Talhão'!B:B=G2)*('Cadastro Talhão'!C:C=H2),0)),"-")} -> 0.073 | AI2: {=IFERROR(IF(AJ2="EM ANDAMENTO",U2,IF(AJ2="FINALIZADO",INDEX('Cadastro Talhão'!G:G,MATCH(1,('Cadastro Talhão'!B:B=G2)*('Cadastro Talhão'!C:C=H2),0)),"-")),"-")} -> 730 | AJ2: {=IFERROR(INDEX(Estoque!$A:$Z,MATCH(1,(Estoque!$E:$E='BDT''s'!G2)*(Estoque!$F:$F='BDT''s'!H2)*(Estoque!$B:$B='BDT''s'!B2),0),MATCH('BDT''s'!L2,Estoque!$1:$1,0)+4),"-")} -> EM ANDAMENTO
A3: =IFERROR(YEAR(I3),"-") -> 2026 | B3: =IFERROR(DATE(YEAR(I3),MONTH(I3),MONTH(I3)),"-") -> 46023 | C3: {=IFERROR(IF(INDEX('Cadastro Talhão'!A:A,MATCH(1,('Cadastro Talhão'!B:B='BDT''s'!G3)*('Cadastro Talhão'!C:C='BDT''s'!H3),0))=0,"-",INDEX('Cadastro Talhão'!A:A,MATCH(1,('Cadastro Talhão'!B:B='BDT''s'!G3)*('Cadastro Talhão'!C:C='BDT''s'!H3),0))),"-")} -> CONTRATO 1 | D3: {=IFERROR(INDEX('Cadastro Talhão'!H:H,MATCH(1,('Cadastro Talhão'!B:B='BDT''s'!G3)*('Cadastro Talhão'!C:C='BDT''s'!H3),0)),"-")} -> 1.9 | E3: {=IFERROR(INDEX('Cadastro Talhão'!F:F,MATCH(1,('Cadastro Talhão'!B:B='BDT''s'!G3)*('Cadastro Talhão'!C:C='BDT''s'!H3),0)),"-")} -> 0.15 | F3: =IFERROR(VLOOKUP(E3,VMI!A:B,2,FALSE),"-") -> 0,11 a 0,15 | G3: FAZENDA 1 | H3: 15 | I3: 46023 | J3: FELLER1 | K3: =IFERROR(VLOOKUP(J3,Cadastros!A:B,2,FALSE),"-") -> FELLER BUNCHER 1 | L3: =IFERROR(VLOOKUP(K3,Cadastros!B:D,3,FALSE),"-") -> CORTE | M3: {=IFERROR(INDEX(VMI!$A:$AAL,MATCH(1,(VMI!$A:$A=E3)*(VMI!$B:$B=F3),0),MATCH(L3,VMI!$1:$1,0)+1)*(AVERAGEIFS('Metas Produção'!I:I,'Metas Produção'!B:B,'BDT''s'!L3)),"-")} -> 86.557111 | N3: OPERADOR 2 | O3: TURNO 2 | P3: =IFERROR(COUNTIFS(O:O,O3,N:N,N3,I:I,I3,J:J,J3,C:C,C3),"-") -> 1 | Q3: =IFERROR(_xlfn.MAXIFS($R$1:R2,$K$1:K2,K3),"-") -> 1010.2 | R3: 1022 | S3: =IFERROR(IF(R3="-",0,IF(R3-Q3<0,"-",R3-Q3)),"-") -> 11.8 | T3: {=IFERROR(U3/INDEX('Cadastro Talhão'!F:F,MATCH(1,('Cadastro Talhão'!B:B='BDT''s'!G3)*('Cadastro Talhão'!C:C='BDT''s'!H3)*('Cadastro Talhão'!A:A='BDT''s'!C3),0)),"-")} -> 6666.6667 | U3: 1000 | V3: =IF(U3="-",0,IFERROR(IF(AJ3="FINALIZADO",AI3/SUMIFS(AG:AG,G:G,G3,H:H,H3,L:L,L3,A:A,A3,B:B,B3)*AG3,U3),U3)) -> 1000 | W3: =IFERROR(U3/S3,"-") -> 84.745763 | X3: {=IFERROR(U3/INDEX('Cadastro Talhão'!G:G,MATCH(1,('Cadastro Talhão'!B:B=G3)*('Cadastro Talhão'!C:C=H3),0))*INDEX('Cadastro Talhão'!D:D,MATCH(1,('Cadastro Talhão'!B:B=G3)*('Cadastro Talhão'!C:C=H3),0)),"-")} -> 1.2 | Y3: {=IFERROR(V3/INDEX('Cadastro Talhão'!G:G,MATCH(1,('Cadastro Talhão'!B:B=G3)*('Cadastro Talhão'!C:C=H3),0))*INDEX('Cadastro Talhão'!D:D,MATCH(1,('Cadastro Talhão'!B:B=G3)*('Cadastro Talhão'!C:C=H3),0)),"-")} -> 1.2 | Z3: {=IFERROR(INDEX('Metas Produção'!$A:$ZZ,MATCH(K3, 'Metas Produção'!$A:$A, 0),MATCH(F3, 'Metas Produção'!$1:$1, 0)+1)*12,"-")} -> 1056.4112 | AA3: =IFERROR(Z3/12,"-") -> 88.034267 | AB3: {=IFERROR(INDEX('Metas Produção'!$A:$ZZ,MATCH(K3, 'Metas Produção'!$A:$A, 0),MATCH(F3, 'Metas Produção'!$1:$1, 0)+2)*12,"-")} -> 1083.6967 | AC3: =IFERROR(AB3/12,"-") -> 90.308055 | AD3: {=IFERROR(INDEX('Metas Produção'!$A:$ZZ,MATCH(K3, 'Metas Produção'!$A:$A, 0),MATCH(F3, 'Metas Produção'!$1:$1, 0)+3)*12,"-")} -> 1200 | AE3: =IFERROR(AD3/12,"-") -> 100 | AF3: =IFERROR(IF(W3="-","-",IF(W3<AA3,"BAIXO",IF(AND(W3>=AA3,W3<AC3),"MEDIO",IF(AND(W3>=AC3,W3<=AE3),"ALTO","-")))),"-") -> BAIXO | AG3: =IFERROR(U3/SUMIFS(U:U,G:G,G3,H:H,H3,L:L,L3,A:A,A3,B:B,B3),0) -> 0.34129693 | AH3: {=IFERROR(V3/INDEX('Cadastro Talhão'!G:G,MATCH(1,('Cadastro Talhão'!B:B=G3)*('Cadastro Talhão'!C:C=H3),0)),"-")} -> 0.1 | AI3: {=IFERROR(IF(AJ3="EM ANDAMENTO",U3,IF(AJ3="FINALIZADO",INDEX('Cadastro Talhão'!G:G,MATCH(1,('Cadastro Talhão'!B:B=G3)*('Cadastro Talhão'!C:C=H3),0)),"-")),"-")} -> 1000 | AJ3: {=IFERROR(INDEX(Estoque!$A:$Z,MATCH(1,(Estoque!$E:$E='BDT''s'!G3)*(Estoque!$F:$F='BDT''s'!H3)*(Estoque!$B:$B='BDT''s'!B3),0),MATCH('BDT''s'!L3,Estoque!$1:$1,0)+4),"-")} -> EM ANDAMENTO
A4: =IFERROR(YEAR(I4),"-") -> 2026 | B4: =IFERROR(DATE(YEAR(I4),MONTH(I4),MONTH(I4)),"-") -> 46023 | C4: {=IFERROR(IF(INDEX('Cadastro Talhão'!A:A,MATCH(1,('Cadastro Talhão'!B:B='BDT''s'!G4)*('Cadastro Talhão'!C:C='BDT''s'!H4),0))=0,"-",INDEX('Cadastro Talhão'!A:A,MATCH(1,('Cadastro Talhão'!B:B='BDT''s'!G4)*('Cadastro Talhão'!C:C='BDT''s'!H4),0))),"-")} -> CONTRATO 1 | D4: {=IFERROR(INDEX('Cadastro Talhão'!H:H,MATCH(1,('Cadastro Talhão'!B:B='BDT''s'!G4)*('Cadastro Talhão'!C:C='BDT''s'!H4),0)),"-")} -> 1.9 | E4: {=IFERROR(INDEX('Cadastro Talhão'!F:F,MATCH(1,('Cadastro Talhão'!B:B='BDT''s'!G4)*('Cadastro Talhão'!C:C='BDT''s'!H4),0)),"-")} -> 0.16 | F4: =IFERROR(VLOOKUP(E4,VMI!A:B,2,FALSE),"-") -> 0,16 a 0,20 | G4: FAZENDA 1 | H4: 25 | I4: 46023 | J4: FELLER2 | K4: =IFERROR(VLOOKUP(J4,Cadastros!A:B,2,FALSE),"-") -> FELLER BUNCHER 2 | L4: =IFERROR(VLOOKUP(K4,Cadastros!B:D,3,FALSE),"-") -> CORTE | M4: {=IFERROR(INDEX(VMI!$A:$AAL,MATCH(1,(VMI!$A:$A=E4)*(VMI!$B:$B=F4),0),MATCH(L4,VMI!$1:$1,0)+1)*(AVERAGEIFS('Metas Produção'!I:I,'Metas Produção'!B:B,'BDT''s'!L4)),"-")} -> 125.2316 | N4: OPERADOR 3 | O4: TURNO 1 | P4: =IFERROR(COUNTIFS(O:O,O4,N:N,N4,I:I,I4,J:J,J4,C:C,C4),"-") -> 1 | Q4: 2000 | R4: 2011.1 | S4: =IFERROR(IF(R4="-",0,IF(R4-Q4<0,"-",R4-Q4)),"-") -> 11.1 | T4: {=IFERROR(U4/INDEX('Cadastro Talhão'!F:F,MATCH(1,('Cadastro Talhão'!B:B='BDT''s'!G4)*('Cadastro Talhão'!C:C='BDT''s'!H4)*('Cadastro Talhão'!A:A='BDT''s'!C4),0)),"-")} -> 7500 | U4: 1200 | V4: =IF(U4="-",0,IFERROR(IF(AJ4="FINALIZADO",AI4/SUMIFS(AG:AG,G:G,G4,H:H,H4,L:L,L4,A:A,A4,B:B,B4)*AG4,U4),U4)) -> 1200 | W4: =IFERROR(U4/S4,"-") -> 108.10811 | X4: {=IFERROR(U4/INDEX('Cadastro Talhão'!G:G,MATCH(1,('Cadastro Talhão'!B:B=G4)*('Cadastro Talhão'!C:C=H4),0))*INDEX('Cadastro Talhão'!D:D,MATCH(1,('Cadastro Talhão'!B:B=G4)*('Cadastro Talhão'!C:C=H4),0)),"-")} -> 0.92307692 | Y4: {=IFERROR(V4/INDEX('Cadastro Talhão'!G:G,MATCH(1,('Cadastro Talhão'!B:B=G4)*('Cadastro Talhão'!C:C=H4),0))*INDEX('Cadastro Talhão'!D:D,MATCH(1,('Cadastro Talhão'!B:B=G4)*('Cadastro Talhão'!C:C=H4),0)),"-")} -> 0.92307692 | Z4: {=IFERROR(INDEX('Metas Produção'!$A:$ZZ,MATCH(K4, 'Metas Produção'!$A:$A, 0),MATCH(F4, 'Metas Produção'!$1:$1, 0)+1)*12,"-")} -> 1477.1333 | AA4: =IFERROR(Z4/12,"-") -> 123.09444 | AB4: {=IFERROR(INDEX('Metas Produção'!$A:$ZZ,MATCH(K4, 'Metas Produção'!$A:$A, 0),MATCH(F4, 'Metas Produção'!$1:$1, 0)+2)*12,"-")} -> 1464.4344 | AC4: =IFERROR(AB4/12,"-") -> 122.0362 | AD4: {=IFERROR(INDEX('Metas Produção'!$A:$ZZ,MATCH(K4, 'Metas Produção'!$A:$A, 0),MATCH(F4, 'Metas Produção'!$1:$1, 0)+3)*12,"-")} -> 2022.4719 | AE4: =IFERROR(AD4/12,"-") -> 168.53933 | AF4: =IFERROR(IF(W4="-","-",IF(W4<AA4,"BAIXO",IF(AND(W4>=AA4,W4<AC4),"MEDIO",IF(AND(W4>=AC4,W4<=AE4),"ALTO","-")))),"-") -> BAIXO | AG4: =IFERROR(U4/SUMIFS(U:U,G:G,G4,H:H,H4,L:L,L4,A:A,A4,B:B,B4),0) -> 0.24489796 | AH4: {=IFERROR(V4/INDEX('Cadastro Talhão'!G:G,MATCH(1,('Cadastro Talhão'!B:B=G4)*('Cadastro Talhão'!C:C=H4),0)),"-")} -> 0.092307692 | AI4: {=IFERROR(IF(AJ4="EM ANDAMENTO",U4,IF(AJ4="FINALIZADO",INDEX('Cadastro Talhão'!G:G,MATCH(1,('Cadastro Talhão'!B:B=G4)*('Cadastro Talhão'!C:C=H4),0)),"-")),"-")} -> 1200 | AJ4: {=IFERROR(INDEX(Estoque!$A:$Z,MATCH(1,(Estoque!$E:$E='BDT''s'!G4)*(Estoque!$F:$F='BDT''s'!H4)*(Estoque!$B:$B='BDT''s'!B4),0),MATCH('BDT''s'!L4,Estoque!$1:$1,0)+4),"-")} -> EM ANDAMENTO
A5: =IFERROR(YEAR(I5),"-") -> 2026 | B5: =IFERROR(DATE(YEAR(I5),MONTH(I5),MONTH(I5)),"-") -> 46023 | C5: {=IFERROR(IF(INDEX('Cadastro Talhão'!A:A,MATCH(1,('Cadastro Talhão'!B:B='BDT''s'!G5)*('Cadastro Talhão'!C:C='BDT''s'!H5),0))=0,"-",INDEX('Cadastro Talhão'!A:A,MATCH(1,('Cadastro Talhão'!B:B='BDT''s'!G5)*('Cadastro Talhão'!C:C='BDT''s'!H5),0))),"-")} -> CONTRATO 1 | D5: {=IFERROR(INDEX('Cadastro Talhão'!H:H,MATCH(1,('Cadastro Talhão'!B:B='BDT''s'!G5)*('Cadastro Talhão'!C:C='BDT''s'!H5),0)),"-")} -> 1.9 | E5: {=IFERROR(INDEX('Cadastro Talhão'!F:F,MATCH(1,('Cadastro Talhão'!B:B='BDT''s'!G5)*('Cadastro Talhão'!C:C='BDT''s'!H5),0)),"-")} -> 0.16 | F5: =IFERROR(VLOOKUP(E5,VMI!A:B,2,FALSE),"-") -> 0,16 a 0,20 | G5: FAZENDA 1 | H5: 25 | I5: 46023 | J5: FELLER2 | K5: =IFERROR(VLOOKUP(J5,Cadastros!A:B,2,FALSE),"-") -> FELLER BUNCHER 2 | L5: =IFERROR(VLOOKUP(K5,Cadastros!B:D,3,FALSE),"-") -> CORTE | M5: {=IFERROR(INDEX(VMI!$A:$AAL,MATCH(1,(VMI!$A:$A=E5)*(VMI!$B:$B=F5),0),MATCH(L5,VMI!$1:$1,0)+1)*(AVERAGEIFS('Metas Produção'!I:I,'Metas Produção'!B:B,'BDT''s'!L5)),"-")} -> 125.2316 | N5: OPERADOR 4 | O5: TURNO 2 | P5: =IFERROR(COUNTIFS(O:O,O5,N:N,N5,I:I,I5,J:J,J5,C:C,C5),"-") -> 1 | Q5: =IFERROR(_xlfn.MAXIFS($R$1:R4,$K$1:K4,K5),"-") -> 2011.1 | R5: 2020 | S5: =IFERROR(IF(R5="-",0,IF(R5-Q5<0,"-",R5-Q5)),"-") -> 8.9 | T5: {=IFERROR(U5/INDEX('Cadastro Talhão'!F:F,MATCH(1,('Cadastro Talhão'!B:B='BDT''s'!G5)*('Cadastro Talhão'!C:C='BDT''s'!H5)*('Cadastro Talhão'!A:A='BDT''s'!C5),0)),"-")} -> 9375 | U5: 1500 | V5: =IF(U5="-",0,IFERROR(IF(AJ5="FINALIZADO",AI5/SUMIFS(AG:AG,G:G,G5,H:H,H5,L:L,L5,A:A,A5,B:B,B5)*AG5,U5),U5)) -> 1500 | W5: =IFERROR(U5/S5,"-") -> 168.53933 | X5: {=IFERROR(U5/INDEX('Cadastro Talhão'!G:G,MATCH(1,('Cadastro Talhão'!B:B=G5)*('Cadastro Talhão'!C:C=H5),0))*INDEX('Cadastro Talhão'!D:D,MATCH(1,('Cadastro Talhão'!B:B=G5)*('Cadastro Talhão'!C:C=H5),0)),"-")} -> 1.1538462 | Y5: {=IFERROR(V5/INDEX('Cadastro Talhão'!G:G,MATCH(1,('Cadastro Talhão'!B:B=G5)*('Cadastro Talhão'!C:C=H5),0))*INDEX('Cadastro Talhão'!D:D,MATCH(1,('Cadastro Talhão'!B:B=G5)*('Cadastro Talhão'!C:C=H5),0)),"-")} -> 1.1538462 | Z5: {=IFERROR(INDEX('Metas Produção'!$A:$ZZ,MATCH(K5, 'Metas Produção'!$A:$A, 0),MATCH(F5, 'Metas Produção'!$1:$1, 0)+1)*12,"-")} -> 1477.1333 | AA5: =IFERROR(Z5/12,"-") -> 123.09444 | AB5: {=IFERROR(INDEX('Metas Produção'!$A:$ZZ,MATCH(K5, 'Metas Produção'!$A:$A, 0),MATCH(F5, 'Metas Produção'!$1:$1, 0)+2)*12,"-")} -> 1464.4344 | AC5: =IFERROR(AB5/12,"-") -> 122.0362 | AD5: {=IFERROR(INDEX('Metas Produção'!$A:$ZZ,MATCH(K5, 'Metas Produção'!$A:$A, 0),MATCH(F5, 'Metas Produção'!$1:$1, 0)+3)*12,"-")} -> 2022.4719 | AE5: =IFERROR(AD5/12,"-") -> 168.53933 | AF5: =IFERROR(IF(W5="-","-",IF(W5<AA5,"BAIXO",IF(AND(W5>=AA5,W5<AC5),"MEDIO",IF(AND(W5>=AC5,W5<=AE5),"ALTO","-")))),"-") -> ALTO | AG5: =IFERROR(U5/SUMIFS(U:U,G:G,G5,H:H,H5,L:L,L5,A:A,A5,B:B,B5),0) -> 0.30612245 | AH5: {=IFERROR(V5/INDEX('Cadastro Talhão'!G:G,MATCH(1,('Cadastro Talhão'!B:B=G5)*('Cadastro Talhão'!C:C=H5),0)),"-")} -> 0.11538462 | AI5: {=IFERROR(IF(AJ5="EM ANDAMENTO",U5,IF(AJ5="FINALIZADO",INDEX('Cadastro Talhão'!G:G,MATCH(1,('Cadastro Talhão'!B:B=G5)*('Cadastro Talhão'!C:C=H5),0)),"-")),"-")} -> 1500 | AJ5: {=IFERROR(INDEX(Estoque!$A:$Z,MATCH(1,(Estoque!$E:$E='BDT''s'!G5)*(Estoque!$F:$F='BDT''s'!H5)*(Estoque!$B:$B='BDT''s'!B5),0),MATCH('BDT''s'!L5,Estoque!$1:$1,0)+4),"-")} -> EM ANDAMENTO
A6: =IFERROR(YEAR(I6),"-") -> 2026 | B6: =IFERROR(DATE(YEAR(I6),MONTH(I6),MONTH(I6)),"-") -> 46023 | C6: {=IFERROR(IF(INDEX('Cadastro Talhão'!A:A,MATCH(1,('Cadastro Talhão'!B:B='BDT''s'!G6)*('Cadastro Talhão'!C:C='BDT''s'!H6),0))=0,"-",INDEX('Cadastro Talhão'!A:A,MATCH(1,('Cadastro Talhão'!B:B='BDT''s'!G6)*('Cadastro Talhão'!C:C='BDT''s'!H6),0))),"-")} -> CONTRATO 1 | D6: {=IFERROR(INDEX('Cadastro Talhão'!H:H,MATCH(1,('Cadastro Talhão'!B:B='BDT''s'!G6)*('Cadastro Talhão'!C:C='BDT''s'!H6),0)),"-")} -> 1.9 | E6: {=IFERROR(INDEX('Cadastro Talhão'!F:F,MATCH(1,('Cadastro Talhão'!B:B='BDT''s'!G6)*('Cadastro Talhão'!C:C='BDT''s'!H6),0)),"-")} -> 0.15 | F6: =IFERROR(VLOOKUP(E6,VMI!A:B,2,FALSE),"-") -> 0,11 a 0,15 | G6: FAZENDA 1 | H6: 15 | I6: 46023 | J6: SKIDDER1 | K6: =IFERROR(VLOOKUP(J6,Cadastros!A:B,2,FALSE),"-") -> SKIDDER 1 | L6: =IFERROR(VLOOKUP(K6,Cadastros!B:D,3,FALSE),"-") -> ARRASTE | M6: {=IFERROR(INDEX(VMI!$A:$AAL,MATCH(1,(VMI!$A:$A=E6)*(VMI!$B:$B=F6),0),MATCH(L6,VMI!$1:$1,0)+1)*(AVERAGEIFS('Metas Produção'!I:I,'Metas Produção'!B:B,'BDT''s'!L6)),"-")} -> 132.35447 | N6: OPERADOR 5 | O6: TURNO 1 | P6: =IFERROR(COUNTIFS(O:O,O6,N:N,N6,I:I,I6,J:J,J6,C:C,C6),"-") -> 1 | Q6: 1200 | R6: 1208 | S6: =IFERROR(IF(R6="-",0,IF(R6-Q6<0,"-",R6-Q6)),"-") -> 8 | T6: {=IFERROR(U6/INDEX('Cadastro Talhão'!F:F,MATCH(1,('Cadastro Talhão'!B:B='BDT''s'!G6)*('Cadastro Talhão'!C:C='BDT''s'!H6)*('Cadastro Talhão'!A:A='BDT''s'!C6),0)),"-")} -> 3333.3333 | U6: 500 | V6: =IF(U6="-",0,IFERROR(IF(AJ6="FINALIZADO",AI6/SUMIFS(AG:AG,G:G,G6,H:H,H6,L:L,L6,A:A,A6,B:B,B6)*AG6,U6),U6)) -> 500 | W6: =IFERROR(U6/S6,"-") -> 62.5 | X6: {=IFERROR(U6/INDEX('Cadastro Talhão'!G:G,MATCH(1,('Cadastro Talhão'!B:B=G6)*('Cadastro Talhão'!C:C=H6),0))*INDEX('Cadastro Talhão'!D:D,MATCH(1,('Cadastro Talhão'!B:B=G6)*('Cadastro Talhão'!C:C=H6),0)),"-")} -> 0.6 | Y6: {=IFERROR(V6/INDEX('Cadastro Talhão'!G:G,MATCH(1,('Cadastro Talhão'!B:B=G6)*('Cadastro Talhão'!C:C=H6),0))*INDEX('Cadastro Talhão'!D:D,MATCH(1,('Cadastro Talhão'!B:B=G6)*('Cadastro Talhão'!C:C=H6),0)),"-")} -> 0.6 | Z6: {=IFERROR(INDEX('Metas Produção'!$A:$ZZ,MATCH(K6, 'Metas Produção'!$A:$A, 0),MATCH(F6, 'Metas Produção'!$1:$1, 0)+1)*12,"-")} -> 1688.5714 | AA6: =IFERROR(Z6/12,"-") -> 140.71429 | AB6: {=IFERROR(INDEX('Metas Produção'!$A:$ZZ,MATCH(K6, 'Metas Produção'!$A:$A, 0),MATCH(F6, 'Metas Produção'!$1:$1, 0)+2)*12,"-")} -> 1918.6652 | AC6: =IFERROR(AB6/12,"-") -> 159.88876 | AD6: {=IFERROR(INDEX('Metas Produção'!$A:$ZZ,MATCH(K6, 'Metas Produção'!$A:$A, 0),MATCH(F6, 'Metas Produção'!$1:$1, 0)+3)*12,"-")} -> 2280 | AE6: =IFERROR(AD6/12,"-") -> 190 | AF6: =IFERROR(IF(W6="-","-",IF(W6<AA6,"BAIXO",IF(AND(W6>=AA6,W6<AC6),"MEDIO",IF(AND(W6>=AC6,W6<=AE6),"ALTO","-")))),"-") -> BAIXO | AG6: =IFERROR(U6/SUMIFS(U:U,G:G,G6,H:H,H6,L:L,L6,A:A,A6,B:B,B6),0) -> 0.19920319 | AH6: {=IFERROR(V6/INDEX('Cadastro Talhão'!G:G,MATCH(1,('Cadastro Talhão'!B:B=G6)*('Cadastro Talhão'!C:C=H6),0)),"-")} -> 0.05 | AI6: {=IFERROR(IF(AJ6="EM ANDAMENTO",U6,IF(AJ6="FINALIZADO",INDEX('Cadastro Talhão'!G:G,MATCH(1,('Cadastro Talhão'!B:B=G6)*('Cadastro Talhão'!C:C=H6),0)),"-")),"-")} -> 500 | AJ6: {=IFERROR(INDEX(Estoque!$A:$Z,MATCH(1,(Estoque!$E:$E='BDT''s'!G6)*(Estoque!$F:$F='BDT''s'!H6)*(Estoque!$B:$B='BDT''s'!B6),0),MATCH('BDT''s'!L6,Estoque!$1:$1,0)+4),"-")} -> EM ANDAMENTO
A7: =IFERROR(YEAR(I7),"-") -> 2026 | B7: =IFERROR(DATE(YEAR(I7),MONTH(I7),MONTH(I7)),"-") -> 46023 | C7: {=IFERROR(IF(INDEX('Cadastro Talhão'!A:A,MATCH(1,('Cadastro Talhão'!B:B='BDT''s'!G7)*('Cadastro Talhão'!C:C='BDT''s'!H7),0))=0,"-",INDEX('Cadastro Talhão'!A:A,MATCH(1,('Cadastro Talhão'!B:B='BDT''s'!G7)*('Cadastro Talhão'!C:C='BDT''s'!H7),0))),"-")} -> CONTRATO 1 | D7: {=IFERROR(INDEX('Cadastro Talhão'!H:H,MATCH(1,('Cadastro Talhão'!B:B='BDT''s'!G7)*('Cadastro Talhão'!C:C='BDT''s'!H7),0)),"-")} -> 1.9 | E7: {=IFERROR(INDEX('Cadastro Talhão'!F:F,MATCH(1,('Cadastro Talhão'!B:B='BDT''s'!G7)*('Cadastro Talhão'!C:C='BDT''s'!H7),0)),"-")} -> 0.15 | F7: =IFERROR(VLOOKUP(E7,VMI!A:B,2,FALSE),"-") -> 0,11 a 0,15 | G7: FAZENDA 1 | H7: 15 | I7: 46023 | J7: SKIDDER1 | K7: =IFERROR(VLOOKUP(J7,Cadastros!A:B,2,FALSE),"-") -> SKIDDER 1 | L7: =IFERROR(VLOOKUP(K7,Cadastros!B:D,3,FALSE),"-") -> ARRASTE | M7: {=IFERROR(INDEX(VMI!$A:$AAL,MATCH(1,(VMI!$A:$A=E7)*(VMI!$B:$B=F7),0),MATCH(L7,VMI!$1:$1,0)+1)*(AVERAGEIFS('Metas Produção'!I:I,'Metas Produção'!B:B,'BDT''s'!L7)),"-")} -> 132.35447 | N7: OPERADOR 6 | O7: TURNO 2 | P7: =IFERROR(COUNTIFS(O:O,O7,N:N,N7,I:I,I7,J:J,J7,C:C,C7),"-") -> 1 | Q7: =IFERROR(_xlfn.MAXIFS($R$1:R6,$K$1:K6,K7),"-") -> 1208 | R7: 1215 | S7: =IFERROR(IF(R7="-",0,IF(R7-Q7<0,"-",R7-Q7)),"-") -> 7 | T7: {=IFERROR(U7/INDEX('Cadastro Talhão'!F:F,MATCH(1,('Cadastro Talhão'!B:B='BDT''s'!G7)*('Cadastro Talhão'!C:C='BDT''s'!H7)*('Cadastro Talhão'!A:A='BDT''s'!C7),0)),"-")} -> 4333.3333 | U7: 650 | V7: =IF(U7="-",0,IFERROR(IF(AJ7="FINALIZADO",AI7/SUMIFS(AG:AG,G:G,G7,H:H,H7,L:L,L7,A:A,A7,B:B,B7)*AG7,U7),U7)) -> 650 | W7: =IFERROR(U7/S7,"-") -> 92.857143 | X7: {=IFERROR(U7/INDEX('Cadastro Talhão'!G:G,MATCH(1,('Cadastro Talhão'!B:B=G7)*('Cadastro Talhão'!C:C=H7),0))*INDEX('Cadastro Talhão'!D:D,MATCH(1,('Cadastro Talhão'!B:B=G7)*('Cadastro Talhão'!C:C=H7),0)),"-")} -> 0.78 | Y7: {=IFERROR(V7/INDEX('Cadastro Talhão'!G:G,MATCH(1,('Cadastro Talhão'!B:B=G7)*('Cadastro Talhão'!C:C=H7),0))*INDEX('Cadastro Talhão'!D:D,MATCH(1,('Cadastro Talhão'!B:B=G7)*('Cadastro Talhão'!C:C=H7),0)),"-")} -> 0.78 | Z7: {=IFERROR(INDEX('Metas Produção'!$A:$ZZ,MATCH(K7, 'Metas Produção'!$A:$A, 0),MATCH(F7, 'Metas Produção'!$1:$1, 0)+1)*12,"-")} -> 1688.5714 | AA7: =IFERROR(Z7/12,"-") -> 140.71429 | AB7: {=IFERROR(INDEX('Metas Produção'!$A:$ZZ,MATCH(K7, 'Metas Produção'!$A:$A, 0),MATCH(F7, 'Metas Produção'!$1:$1, 0)+2)*12,"-")} -> 1918.6652 | AC7: =IFERROR(AB7/12,"-") -> 159.88876 | AD7: {=IFERROR(INDEX('Metas Produção'!$A:$ZZ,MATCH(K7, 'Metas Produção'!$A:$A, 0),MATCH(F7, 'Metas Produção'!$1:$1, 0)+3)*12,"-")} -> 2280 | AE7: =IFERROR(AD7/12,"-") -> 190 | AF7: =IFERROR(IF(W7="-","-",IF(W7<AA7,"BAIXO",IF(AND(W7>=AA7,W7<AC7),"MEDIO",IF(AND(W7>=AC7,W7<=AE7),"ALTO","-")))),"-") -> BAIXO | AG7: =IFERROR(U7/SUMIFS(U:U,G:G,G7,H:H,H7,L:L,L7,A:A,A7,B:B,B7),0) -> 0.25896414 | AH7: {=IFERROR(V7/INDEX('Cadastro Talhão'!G:G,MATCH(1,('Cadastro Talhão'!B:B=G7)*('Cadastro Talhão'!C:C=H7),0)),"-")} -> 0.065 | AI7: {=IFERROR(IF(AJ7="EM ANDAMENTO",U7,IF(AJ7="FINALIZADO",INDEX('Cadastro Talhão'!G:G,MATCH(1,('Cadastro Talhão'!B:B=G7)*('Cadastro Talhão'!C:C=H7),0)),"-")),"-")} -> 650 | AJ7: {=IFERROR(INDEX(Estoque!$A:$Z,MATCH(1,(Estoque!$E:$E='BDT''s'!G7)*(Estoque!$F:$F='BDT''s'!H7)*(Estoque!$B:$B='BDT''s'!B7),0),MATCH('BDT''s'!L7,Estoque!$1:$1,0)+4),"-")} -> EM ANDAMENTO
A8: =IFERROR(YEAR(I8),"-") -> 2026 | B8: =IFERROR(DATE(YEAR(I8),MONTH(I8),MONTH(I8)),"-") -> 46023 | C8: {=IFERROR(IF(INDEX('Cadastro Talhão'!A:A,MATCH(1,('Cadastro Talhão'!B:B='BDT''s'!G8)*('Cadastro Talhão'!C:C='BDT''s'!H8),0))=0,"-",INDEX('Cadastro Talhão'!A:A,MATCH(1,('Cadastro Talhão'!B:B='BDT''s'!G8)*('Cadastro Talhão'!C:C='BDT''s'!H8),0))),"-")} -> CONTRATO 1 | D8: {=IFERROR(INDEX('Cadastro Talhão'!H:H,MATCH(1,('Cadastro Talhão'!B:B='BDT''s'!G8)*('Cadastro Talhão'!C:C='BDT''s'!H8),0)),"-")} -> 1.9 | E8: {=IFERROR(INDEX('Cadastro Talhão'!F:F,MATCH(1,('Cadastro Talhão'!B:B='BDT''s'!G8)*('Cadastro Talhão'!C:C='BDT''s'!H8),0)),"-")} -> 0.16 | F8: =IFERROR(VLOOKUP(E8,VMI!A:B,2,FALSE),"-") -> 0,16 a 0,20 | G8: FAZENDA 1 | H8: 25 | I8: 46023 | J8: SKIDDER2 | K8: =IFERROR(VLOOKUP(J8,Cadastros!A:B,2,FALSE),"-") -> SKIDDER 2 | L8: =IFERROR(VLOOKUP(K8,Cadastros!B:D,3,FALSE),"-") -> ARRASTE | M8: {=IFERROR(INDEX(VMI!$A:$AAL,MATCH(1,(VMI!$A:$A=E8)*(VMI!$B:$B=F8),0),MATCH(L8,VMI!$1:$1,0)+1)*(AVERAGEIFS('Metas Produção'!I:I,'Metas Produção'!B:B,'BDT''s'!L8)),"-")} -> 96.809138 | N8: OPERADOR 7 | O8: TURNO 1 | P8: =IFERROR(COUNTIFS(O:O,O8,N:N,N8,I:I,I8,J:J,J8,C:C,C8),"-") -> 1 | Q8: 2100 | R8: 2109 | S8: =IFERROR(IF(R8="-",0,IF(R8-Q8<0,"-",R8-Q8)),"-") -> 9 | T8: {=IFERROR(U8/INDEX('Cadastro Talhão'!F:F,MATCH(1,('Cadastro Talhão'!B:B='BDT''s'!G8)*('Cadastro Talhão'!C:C='BDT''s'!H8)*('Cadastro Talhão'!A:A='BDT''s'!C8),0)),"-")} -> 4375 | U8: 700 | V8: =IF(U8="-",0,IFERROR(IF(AJ8="FINALIZADO",AI8/SUMIFS(AG:AG,G:G,G8,H:H,H8,L:L,L8,A:A,A8,B:B,B8)*AG8,U8),U8)) -> 700 | W8: =IFERROR(U8/S8,"-") -> 77.777778 | X8: {=IFERROR(U8/INDEX('Cadastro Talhão'!G:G,MATCH(1,('Cadastro Talhão'!B:B=G8)*('Cadastro Talhão'!C:C=H8),0))*INDEX('Cadastro Talhão'!D:D,MATCH(1,('Cadastro Talhão'!B:B=G8)*('Cadastro Talhão'!C:C=H8),0)),"-")} -> 0.53846154 | Y8: {=IFERROR(V8/INDEX('Cadastro Talhão'!G:G,MATCH(1,('Cadastro Talhão'!B:B=G8)*('Cadastro Talhão'!C:C=H8),0))*INDEX('Cadastro Talhão'!D:D,MATCH(1,('Cadastro Talhão'!B:B=G8)*('Cadastro Talhão'!C:C=H8),0)),"-")} -> 0.53846154 | Z8: {=IFERROR(INDEX('Metas Produção'!$A:$ZZ,MATCH(K8, 'Metas Produção'!$A:$A, 0),MATCH(F8, 'Metas Produção'!$1:$1, 0)+1)*12,"-")} -> 1088.3333 | AA8: =IFERROR(Z8/12,"-") -> 90.694444 | AB8: {=IFERROR(INDEX('Metas Produção'!$A:$ZZ,MATCH(K8, 'Metas Produção'!$A:$A, 0),MATCH(F8, 'Metas Produção'!$1:$1, 0)+2)*12,"-")} -> 1089.6987 | AC8: =IFERROR(AB8/12,"-") -> 90.808223 | AD8: {=IFERROR(INDEX('Metas Produção'!$A:$ZZ,MATCH(K8, 'Metas Produção'!$A:$A, 0),MATCH(F8, 'Metas Produção'!$1:$1, 0)+3)*12,"-")} -> 1440 | AE8: =IFERROR(AD8/12,"-") -> 120 | AF8: =IFERROR(IF(W8="-","-",IF(W8<AA8,"BAIXO",IF(AND(W8>=AA8,W8<AC8),"MEDIO",IF(AND(W8>=AC8,W8<=AE8),"ALTO","-")))),"-") -> BAIXO | AG8: =IFERROR(U8/SUMIFS(U:U,G:G,G8,H:H,H8,L:L,L8,A:A,A8,B:B,B8),0) -> 0.23178808 | AH8: {=IFERROR(V8/INDEX('Cadastro Talhão'!G:G,MATCH(1,('Cadastro Talhão'!B:B=G8)*('Cadastro Talhão'!C:C=H8),0)),"-")} -> 0.053846154 | AI8: {=IFERROR(IF(AJ8="EM ANDAMENTO",U8,IF(AJ8="FINALIZADO",INDEX('Cadastro Talhão'!G:G,MATCH(1,('Cadastro Talhão'!B:B=G8)*('Cadastro Talhão'!C:C=H8),0)),"-")),"-")} -> 700 | AJ8: {=IFERROR(INDEX(Estoque!$A:$Z,MATCH(1,(Estoque!$E:$E='BDT''s'!G8)*(Estoque!$F:$F='BDT''s'!H8)*(Estoque!$B:$B='BDT''s'!B8),0),MATCH('BDT''s'!L8,Estoque!$1:$1,0)+4),"-")} -> EM ANDAMENTO
A9: =IFERROR(YEAR(I9),"-") -> 2026 | B9: =IFERROR(DATE(YEAR(I9),MONTH(I9),MONTH(I9)),"-") -> 46023 | C9: {=IFERROR(IF(INDEX('Cadastro Talhão'!A:A,MATCH(1,('Cadastro Talhão'!B:B='BDT''s'!G9)*('Cadastro Talhão'!C:C='BDT''s'!H9),0))=0,"-",INDEX('Cadastro Talhão'!A:A,MATCH(1,('Cadastro Talhão'!B:B='BDT''s'!G9)*('Cadastro Talhão'!C:C='BDT''s'!H9),0))),"-")} -> CONTRATO 1 | D9: {=IFERROR(INDEX('Cadastro Talhão'!H:H,MATCH(1,('Cadastro Talhão'!B:B='BDT''s'!G9)*('Cadastro Talhão'!C:C='BDT''s'!H9),0)),"-")} -> 1.9 | E9: {=IFERROR(INDEX('Cadastro Talhão'!F:F,MATCH(1,('Cadastro Talhão'!B:B='BDT''s'!G9)*('Cadastro Talhão'!C:C='BDT''s'!H9),0)),"-")} -> 0.16 | F9: =IFERROR(VLOOKUP(E9,VMI!A:B,2,FALSE),"-") -> 0,16 a 0,20 | G9: FAZENDA 1 | H9: 25 | I9: 46023 | J9: SKIDDER2 | K9: =IFERROR(VLOOKUP(J9,Cadastros!A:B,2,FALSE),"-") -> SKIDDER 2 | L9: =IFERROR(VLOOKUP(K9,Cadastros!B:D,3,FALSE),"-") -> ARRASTE | M9: {=IFERROR(INDEX(VMI!$A:$AAL,MATCH(1,(VMI!$A:$A=E9)*(VMI!$B:$B=F9),0),MATCH(L9,VMI!$1:$1,0)+1)*(AVERAGEIFS('Metas Produção'!I:I,'Metas Produção'!B:B,'BDT''s'!L9)),"-")} -> 96.809138 | N9: OPERADOR 8 | O9: TURNO 2 | P9: =IFERROR(COUNTIFS(O:O,O9,N:N,N9,I:I,I9,J:J,J9,C:C,C9),"-") -> 1 | Q9: =IFERROR(_xlfn.MAXIFS($R$1:R8,$K$1:K8,K9),"-") -> 2109 | R9: 2120 | S9: =IFERROR(IF(R9="-",0,IF(R9-Q9<0,"-",R9-Q9)),"-") -> 11 | T9: {=IFERROR(U9/INDEX('Cadastro Talhão'!F:F,MATCH(1,('Cadastro Talhão'!B:B='BDT''s'!G9)*('Cadastro Talhão'!C:C='BDT''s'!H9)*('Cadastro Talhão'!A:A='BDT''s'!C9),0)),"-")} -> 5125 | U9: 820 | V9: =IF(U9="-",0,IFERROR(IF(AJ9="FINALIZADO",AI9/SUMIFS(AG:AG,G:G,G9,H:H,H9,L:L,L9,A:A,A9,B:B,B9)*AG9,U9),U9)) -> 820 | W9: =IFERROR(U9/S9,"-") -> 74.545455 | X9: {=IFERROR(U9/INDEX('Cadastro Talhão'!G:G,MATCH(1,('Cadastro Talhão'!B:B=G9)*('Cadastro Talhão'!C:C=H9),0))*INDEX('Cadastro Talhão'!D:D,MATCH(1,('Cadastro Talhão'!B:B=G9)*('Cadastro Talhão'!C:C=H9),0)),"-")} -> 0.63076923 | Y9: {=IFERROR(V9/INDEX('Cadastro Talhão'!G:G,MATCH(1,('Cadastro Talhão'!B:B=G9)*('Cadastro Talhão'!C:C=H9),0))*INDEX('Cadastro Talhão'!D:D,MATCH(1,('Cadastro Talhão'!B:B=G9)*('Cadastro Talhão'!C:C=H9),0)),"-")} -> 0.63076923 | Z9: {=IFERROR(INDEX('Metas Produção'!$A:$ZZ,MATCH(K9, 'Metas Produção'!$A:$A, 0),MATCH(F9, 'Metas Produção'!$1:$1, 0)+1)*12,"-")} -> 1088.3333 | AA9: =IFERROR(Z9/12,"-") -> 90.694444 | AB9: {=IFERROR(INDEX('Metas Produção'!$A:$ZZ,MATCH(K9, 'Metas Produção'!$A:$A, 0),MATCH(F9, 'Metas Produção'!$1:$1, 0)+2)*12,"-")} -> 1089.6987 | AC9: =IFERROR(AB9/12,"-") -> 90.808223 | AD9: {=IFERROR(INDEX('Metas Produção'!$A:$ZZ,MATCH(K9, 'Metas Produção'!$A:$A, 0),MATCH(F9, 'Metas Produção'!$1:$1, 0)+3)*12,"-")} -> 1440 | AE9: =IFERROR(AD9/12,"-") -> 120 | AF9: =IFERROR(IF(W9="-","-",IF(W9<AA9,"BAIXO",IF(AND(W9>=AA9,W9<AC9),"MEDIO",IF(AND(W9>=AC9,W9<=AE9),"ALTO","-")))),"-") -> BAIXO | AG9: =IFERROR(U9/SUMIFS(U:U,G:G,G9,H:H,H9,L:L,L9,A:A,A9,B:B,B9),0) -> 0.27152318 | AH9: {=IFERROR(V9/INDEX('Cadastro Talhão'!G:G,MATCH(1,('Cadastro Talhão'!B:B=G9)*('Cadastro Talhão'!C:C=H9),0)),"-")} -> 0.063076923 | AI9: {=IFERROR(IF(AJ9="EM ANDAMENTO",U9,IF(AJ9="FINALIZADO",INDEX('Cadastro Talhão'!G:G,MATCH(1,('Cadastro Talhão'!B:B=G9)*('Cadastro Talhão'!C:C=H9),0)),"-")),"-")} -> 820 | AJ9: {=IFERROR(INDEX(Estoque!$A:$Z,MATCH(1,(Estoque!$E:$E='BDT''s'!G9)*(Estoque!$F:$F='BDT''s'!H9)*(Estoque!$B:$B='BDT''s'!B9),0),MATCH('BDT''s'!L9,Estoque!$1:$1,0)+4),"-")} -> EM ANDAMENTO
A10: =IFERROR(YEAR(I10),"-") -> 2026 | B10: =IFERROR(DATE(YEAR(I10),MONTH(I10),MONTH(I10)),"-") -> 46023 | C10: {=IFERROR(IF(INDEX('Cadastro Talhão'!A:A,MATCH(1,('Cadastro Talhão'!B:B='BDT''s'!G10)*('Cadastro Talhão'!C:C='BDT''s'!H10),0))=0,"-",INDEX('Cadastro Talhão'!A:A,MATCH(1,('Cadastro Talhão'!B:B='BDT''s'!G10)*('Cadastro Talhão'!C:C='BDT''s'!H10),0))),"-")} -> CONTRATO 1 | D10: {=IFERROR(INDEX('Cadastro Talhão'!H:H,MATCH(1,('Cadastro Talhão'!B:B='BDT''s'!G10)*('Cadastro Talhão'!C:C='BDT''s'!H10),0)),"-")} -> 1.9 | E10: {=IFERROR(INDEX('Cadastro Talhão'!F:F,MATCH(1,('Cadastro Talhão'!B:B='BDT''s'!G10)*('Cadastro Talhão'!C:C='BDT''s'!H10),0)),"-")} -> 0.15 | F10: =IFERROR(VLOOKUP(E10,VMI!A:B,2,FALSE),"-") -> 0,11 a 0,15 | G10: FAZENDA 1 | H10: 15 | I10: 46023 | J10: GARRA1 | K10: =IFERROR(VLOOKUP(J10,Cadastros!A:B,2,FALSE),"-") -> GARRA TRAÇADORA 1 | L10: =IFERROR(VLOOKUP(K10,Cadastros!B:D,3,FALSE),"-") -> TRAÇAMENTO | M10: {=IFERROR(INDEX(VMI!$A:$AAL,MATCH(1,(VMI!$A:$A=E10)*(VMI!$B:$B=F10),0),MATCH(L10,VMI!$1:$1,0)+1)*(AVERAGEIFS('Metas Produção'!I:I,'Metas Produção'!B:B,'BDT''s'!L10)),"-")} -> 64.881272 | N10: OPERADOR 9 | O10: TURNO 1 | P10: =IFERROR(COUNTIFS(O:O,O10,N:N,N10,I:I,I10,J:J,J10,C:C,C10),"-") -> 1 | Q10: 500 | R10: 512 | S10: =IFERROR(IF(R10="-",0,IF(R10-Q10<0,"-",R10-Q10)),"-") -> 12 | T10: {=IFERROR(U10/INDEX('Cadastro Talhão'!F:F,MATCH(1,('Cadastro Talhão'!B:B='BDT''s'!G10)*('Cadastro Talhão'!C:C='BDT''s'!H10)*('Cadastro Talhão'!A:A='BDT''s'!C10),0)),"-")} -> 2866.6667 | U10: 430 | V10: =IF(U10="-",0,IFERROR(IF(AJ10="FINALIZADO",AI10/SUMIFS(AG:AG,G:G,G10,H:H,H10,L:L,L10,A:A,A10,B:B,B10)*AG10,U10),U10)) -> 430 | W10: =IFERROR(U10/S10,"-") -> 35.833333 | X10: {=IFERROR(U10/INDEX('Cadastro Talhão'!G:G,MATCH(1,('Cadastro Talhão'!B:B=G10)*('Cadastro Talhão'!C:C=H10),0))*INDEX('Cadastro Talhão'!D:D,MATCH(1,('Cadastro Talhão'!B:B=G10)*('Cadastro Talhão'!C:C=H10),0)),"-")} -> 0.516 | Y10: {=IFERROR(V10/INDEX('Cadastro Talhão'!G:G,MATCH(1,('Cadastro Talhão'!B:B=G10)*('Cadastro Talhão'!C:C=H10),0))*INDEX('Cadastro Talhão'!D:D,MATCH(1,('Cadastro Talhão'!B:B=G10)*('Cadastro Talhão'!C:C=H10),0)),"-")} -> 0.516 | Z10: {=IFERROR(INDEX('Metas Produção'!$A:$ZZ,MATCH(K10, 'Metas Produção'!$A:$A, 0),MATCH(F10, 'Metas Produção'!$1:$1, 0)+1)*12,"-")} -> 809.16667 | AA10: =IFERROR(Z10/12,"-") -> 67.430556 | AB10: {=IFERROR(INDEX('Metas Produção'!$A:$ZZ,MATCH(K10, 'Metas Produção'!$A:$A, 0),MATCH(F10, 'Metas Produção'!$1:$1, 0)+2)*12,"-")} -> 897.94381 | AC10: =IFERROR(AB10/12,"-") -> 74.828651 | AD10: {=IFERROR(INDEX('Metas Produção'!$A:$ZZ,MATCH(K10, 'Metas Produção'!$A:$A, 0),MATCH(F10, 'Metas Produção'!$1:$1, 0)+3)*12,"-")} -> 900 | AE10: =IFERROR(AD10/12,"-") -> 75 | AF10: =IFERROR(IF(W10="-","-",IF(W10<AA10,"BAIXO",IF(AND(W10>=AA10,W10<AC10),"MEDIO",IF(AND(W10>=AC10,W10<=AE10),"ALTO","-")))),"-") -> BAIXO | AG10: =IFERROR(U10/SUMIFS(U:U,G:G,G10,H:H,H10,L:L,L10,A:A,A10,B:B,B10),0) -> 0.21287129 | AH10: {=IFERROR(V10/INDEX('Cadastro Talhão'!G:G,MATCH(1,('Cadastro Talhão'!B:B=G10)*('Cadastro Talhão'!C:C=H10),0)),"-")} -> 0.043 | AI10: {=IFERROR(IF(AJ10="EM ANDAMENTO",U10,IF(AJ10="FINALIZADO",INDEX('Cadastro Talhão'!G:G,MATCH(1,('Cadastro Talhão'!B:B=G10)*('Cadastro Talhão'!C:C=H10),0)),"-")),"-")} -> 430 | AJ10: {=IFERROR(INDEX(Estoque!$A:$Z,MATCH(1,(Estoque!$E:$E='BDT''s'!G10)*(Estoque!$F:$F='BDT''s'!H10)*(Estoque!$B:$B='BDT''s'!B10),0),MATCH('BDT''s'!L10,Estoque!$1:$1,0)+4),"-")} -> EM ANDAMENTO
A11: =IFERROR(YEAR(I11),"-") -> 2026 | B11: =IFERROR(DATE(YEAR(I11),MONTH(I11),MONTH(I11)),"-") -> 46023 | C11: {=IFERROR(IF(INDEX('Cadastro Talhão'!A:A,MATCH(1,('Cadastro Talhão'!B:B='BDT''s'!G11)*('Cadastro Talhão'!C:C='BDT''s'!H11),0))=0,"-",INDEX('Cadastro Talhão'!A:A,MATCH(1,('Cadastro Talhão'!B:B='BDT''s'!G11)*('Cadastro Talhão'!C:C='BDT''s'!H11),0))),"-")} -> CONTRATO 1 | D11: {=IFERROR(INDEX('Cadastro Talhão'!H:H,MATCH(1,('Cadastro Talhão'!B:B='BDT''s'!G11)*('Cadastro Talhão'!C:C='BDT''s'!H11),0)),"-")} -> 1.9 | E11: {=IFERROR(INDEX('Cadastro Talhão'!F:F,MATCH(1,('Cadastro Talhão'!B:B='BDT''s'!G11)*('Cadastro Talhão'!C:C='BDT''s'!H11),0)),"-")} -> 0.15 | F11: =IFERROR(VLOOKUP(E11,VMI!A:B,2,FALSE),"-") -> 0,11 a 0,15 | G11: FAZENDA 1 | H11: 15 | I11: 46023 | J11: GARRA1 | K11: =IFERROR(VLOOKUP(J11,Cadastros!A:B,2,FALSE),"-") -> GARRA TRAÇADORA 1 | L11: =IFERROR(VLOOKUP(K11,Cadastros!B:D,3,FALSE),"-") -> TRAÇAMENTO | M11: {=IFERROR(INDEX(VMI!$A:$AAL,MATCH(1,(VMI!$A:$A=E11)*(VMI!$B:$B=F11),0),MATCH(L11,VMI!$1:$1,0)+1)*(AVERAGEIFS('Metas Produção'!I:I,'Metas Produção'!B:B,'BDT''s'!L11)),"-")} -> 64.881272 | N11: OPERADOR 10 | O11: TURNO 2 | P11: =IFERROR(COUNTIFS(O:O,O11,N:N,N11,I:I,I11,J:J,J11,C:C,C11),"-") -> 1 | Q11: =IFERROR(_xlfn.MAXIFS($R$1:R10,$K$1:K10,K11),"-") -> 512 | R11: 520 | S11: =IFERROR(IF(R11="-",0,IF(R11-Q11<0,"-",R11-Q11)),"-") -> 8 | T11: {=IFERROR(U11/INDEX('Cadastro Talhão'!F:F,MATCH(1,('Cadastro Talhão'!B:B='BDT''s'!G11)*('Cadastro Talhão'!C:C='BDT''s'!H11)*('Cadastro Talhão'!A:A='BDT''s'!C11),0)),"-")} -> 4000 | U11: 600 | V11: =IF(U11="-",0,IFERROR(IF(AJ11="FINALIZADO",AI11/SUMIFS(AG:AG,G:G,G11,H:H,H11,L:L,L11,A:A,A11,B:B,B11)*AG11,U11),U11)) -> 600 | W11: =IFERROR(U11/S11,"-") -> 75 | X11: {=IFERROR(U11/INDEX('Cadastro Talhão'!G:G,MATCH(1,('Cadastro Talhão'!B:B=G11)*('Cadastro Talhão'!C:C=H11),0))*INDEX('Cadastro Talhão'!D:D,MATCH(1,('Cadastro Talhão'!B:B=G11)*('Cadastro Talhão'!C:C=H11),0)),"-")} -> 0.72 | Y11: {=IFERROR(V11/INDEX('Cadastro Talhão'!G:G,MATCH(1,('Cadastro Talhão'!B:B=G11)*('Cadastro Talhão'!C:C=H11),0))*INDEX('Cadastro Talhão'!D:D,MATCH(1,('Cadastro Talhão'!B:B=G11)*('Cadastro Talhão'!C:C=H11),0)),"-")} -> 0.72 | Z11: {=IFERROR(INDEX('Metas Produção'!$A:$ZZ,MATCH(K11, 'Metas Produção'!$A:$A, 0),MATCH(F11, 'Metas Produção'!$1:$1, 0)+1)*12,"-")} -> 809.16667 | AA11: =IFERROR(Z11/12,"-") -> 67.430556 | AB11: {=IFERROR(INDEX('Metas Produção'!$A:$ZZ,MATCH(K11, 'Metas Produção'!$A:$A, 0),MATCH(F11, 'Metas Produção'!$1:$1, 0)+2)*12,"-")} -> 897.94381 | AC11: =IFERROR(AB11/12,"-") -> 74.828651 | AD11: {=IFERROR(INDEX('Metas Produção'!$A:$ZZ,MATCH(K11, 'Metas Produção'!$A:$A, 0),MATCH(F11, 'Metas Produção'!$1:$1, 0)+3)*12,"-")} -> 900 | AE11: =IFERROR(AD11/12,"-") -> 75 | AF11: =IFERROR(IF(W11="-","-",IF(W11<AA11,"BAIXO",IF(AND(W11>=AA11,W11<AC11),"MEDIO",IF(AND(W11>=AC11,W11<=AE11),"ALTO","-")))),"-") -> ALTO | AG11: =IFERROR(U11/SUMIFS(U:U,G:G,G11,H:H,H11,L:L,L11,A:A,A11,B:B,B11),0) -> 0.2970297 | AH11: {=IFERROR(V11/INDEX('Cadastro Talhão'!G:G,MATCH(1,('Cadastro Talhão'!B:B=G11)*('Cadastro Talhão'!C:C=H11),0)),"-")} -> 0.06 | AI11: {=IFERROR(IF(AJ11="EM ANDAMENTO",U11,IF(AJ11="FINALIZADO",INDEX('Cadastro Talhão'!G:G,MATCH(1,('Cadastro Talhão'!B:B=G11)*('Cadastro Talhão'!C:C=H11),0)),"-")),"-")} -> 600 | AJ11: {=IFERROR(INDEX(Estoque!$A:$Z,MATCH(1,(Estoque!$E:$E='BDT''s'!G11)*(Estoque!$F:$F='BDT''s'!H11)*(Estoque!$B:$B='BDT''s'!B11),0),MATCH('BDT''s'!L11,Estoque!$1:$1,0)+4),"-")} -> EM ANDAMENTO
A12: =IFERROR(YEAR(I12),"-") -> 2026 | B12: =IFERROR(DATE(YEAR(I12),MONTH(I12),MONTH(I12)),"-") -> 46023 | C12: {=IFERROR(IF(INDEX('Cadastro Talhão'!A:A,MATCH(1,('Cadastro Talhão'!B:B='BDT''s'!G12)*('Cadastro Talhão'!C:C='BDT''s'!H12),0))=0,"-",INDEX('Cadastro Talhão'!A:A,MATCH(1,('Cadastro Talhão'!B:B='BDT''s'!G12)*('Cadastro Talhão'!C:C='BDT''s'!H12),0))),"-")} -> CONTRATO 1 | D12: {=IFERROR(INDEX('Cadastro Talhão'!H:H,MATCH(1,('Cadastro Talhão'!B:B='BDT''s'!G12)*('Cadastro Talhão'!C:C='BDT''s'!H12),0)),"-")} -> 1.9 | E12: {=IFERROR(INDEX('Cadastro Talhão'!F:F,MATCH(1,('Cadastro Talhão'!B:B='BDT''s'!G12)*('Cadastro Talhão'!C:C='BDT''s'!H12),0)),"-")} -> 0.16 | F12: =IFERROR(VLOOKUP(E12,VMI!A:B,2,FALSE),"-") -> 0,16 a 0,20 | G12: FAZENDA 1 | H12: 25 | I12: 46023 | J12: GARRA2 | K12: =IFERROR(VLOOKUP(J12,Cadastros!A:B,2,FALSE),"-") -> GARRA TRAÇADORA 2 | L12: =IFERROR(VLOOKUP(K12,Cadastros!B:D,3,FALSE),"-") -> TRAÇAMENTO | M12: {=IFERROR(INDEX(VMI!$A:$AAL,MATCH(1,(VMI!$A:$A=E12)*(VMI!$B:$B=F12),0),MATCH(L12,VMI!$1:$1,0)+1)*(AVERAGEIFS('Metas Produção'!I:I,'Metas Produção'!B:B,'BDT''s'!L12)),"-")} -> 82.751429 | N12: OPERADOR 11 | O12: TURNO 1 | P12: =IFERROR(COUNTIFS(O:O,O12,N:N,N12,I:I,I12,J:J,J12,C:C,C12),"-") -> 1 | Q12: 700 | R12: 705 | S12: =IFERROR(IF(R12="-",0,IF(R12-Q12<0,"-",R12-Q12)),"-") -> 5 | T12: {=IFERROR(U12/INDEX('Cadastro Talhão'!F:F,MATCH(1,('Cadastro Talhão'!B:B='BDT''s'!G12)*('Cadastro Talhão'!C:C='BDT''s'!H12)*('Cadastro Talhão'!A:A='BDT''s'!C12),0)),"-")} -> 2187.5 | U12: 350 | V12: =IF(U12="-",0,IFERROR(IF(AJ12="FINALIZADO",AI12/SUMIFS(AG:AG,G:G,G12,H:H,H12,L:L,L12,A:A,A12,B:B,B12)*AG12,U12),U12)) -> 350 | W12: =IFERROR(U12/S12,"-") -> 70 | X12: {=IFERROR(U12/INDEX('Cadastro Talhão'!G:G,MATCH(1,('Cadastro Talhão'!B:B=G12)*('Cadastro Talhão'!C:C=H12),0))*INDEX('Cadastro Talhão'!D:D,MATCH(1,('Cadastro Talhão'!B:B=G12)*('Cadastro Talhão'!C:C=H12),0)),"-")} -> 0.26923077 | Y12: {=IFERROR(V12/INDEX('Cadastro Talhão'!G:G,MATCH(1,('Cadastro Talhão'!B:B=G12)*('Cadastro Talhão'!C:C=H12),0))*INDEX('Cadastro Talhão'!D:D,MATCH(1,('Cadastro Talhão'!B:B=G12)*('Cadastro Talhão'!C:C=H12),0)),"-")} -> 0.26923077 | Z12: {=IFERROR(INDEX('Metas Produção'!$A:$ZZ,MATCH(K12, 'Metas Produção'!$A:$A, 0),MATCH(F12, 'Metas Produção'!$1:$1, 0)+1)*12,"-")} -> 954 | AA12: =IFERROR(Z12/12,"-") -> 79.5 | AB12: {=IFERROR(INDEX('Metas Produção'!$A:$ZZ,MATCH(K12, 'Metas Produção'!$A:$A, 0),MATCH(F12, 'Metas Produção'!$1:$1, 0)+2)*12,"-")} -> 978.61935 | AC12: =IFERROR(AB12/12,"-") -> 81.551613 | AD12: {=IFERROR(INDEX('Metas Produção'!$A:$ZZ,MATCH(K12, 'Metas Produção'!$A:$A, 0),MATCH(F12, 'Metas Produção'!$1:$1, 0)+3)*12,"-")} -> 1152 | AE12: =IFERROR(AD12/12,"-") -> 96 | AF12: =IFERROR(IF(W12="-","-",IF(W12<AA12,"BAIXO",IF(AND(W12>=AA12,W12<AC12),"MEDIO",IF(AND(W12>=AC12,W12<=AE12),"ALTO","-")))),"-") -> BAIXO | AG12: =IFERROR(U12/SUMIFS(U:U,G:G,G12,H:H,H12,L:L,L12,A:A,A12,B:B,B12),0) -> 0.17948718 | AH12: {=IFERROR(V12/INDEX('Cadastro Talhão'!G:G,MATCH(1,('Cadastro Talhão'!B:B=G12)*('Cadastro Talhão'!C:C=H12),0)),"-")} -> 0.026923077 | AI12: {=IFERROR(IF(AJ12="EM ANDAMENTO",U12,IF(AJ12="FINALIZADO",INDEX('Cadastro Talhão'!G:G,MATCH(1,('Cadastro Talhão'!B:B=G12)*('Cadastro Talhão'!C:C=H12),0)),"-")),"-")} -> 350 | AJ12: {=IFERROR(INDEX(Estoque!$A:$Z,MATCH(1,(Estoque!$E:$E='BDT''s'!G12)*(Estoque!$F:$F='BDT''s'!H12)*(Estoque!$B:$B='BDT''s'!B12),0),MATCH('BDT''s'!L12,Estoque!$1:$1,0)+4),"-")} -> EM ANDAMENTO
A13: =IFERROR(YEAR(I13),"-") -> 2026 | B13: =IFERROR(DATE(YEAR(I13),MONTH(I13),MONTH(I13)),"-") -> 46023 | C13: {=IFERROR(IF(INDEX('Cadastro Talhão'!A:A,MATCH(1,('Cadastro Talhão'!B:B='BDT''s'!G13)*('Cadastro Talhão'!C:C='BDT''s'!H13),0))=0,"-",INDEX('Cadastro Talhão'!A:A,MATCH(1,('Cadastro Talhão'!B:B='BDT''s'!G13)*('Cadastro Talhão'!C:C='BDT''s'!H13),0))),"-")} -> CONTRATO 1 | D13: {=IFERROR(INDEX('Cadastro Talhão'!H:H,MATCH(1,('Cadastro Talhão'!B:B='BDT''s'!G13)*('Cadastro Talhão'!C:C='BDT''s'!H13),0)),"-")} -> 1.9 | E13: {=IFERROR(INDEX('Cadastro Talhão'!F:F,MATCH(1,('Cadastro Talhão'!B:B='BDT''s'!G13)*('Cadastro Talhão'!C:C='BDT''s'!H13),0)),"-")} -> 0.16 | F13: =IFERROR(VLOOKUP(E13,VMI!A:B,2,FALSE),"-") -> 0,16 a 0,20 | G13: FAZENDA 1 | H13: 25 | I13: 46023 | J13: GARRA2 | K13: =IFERROR(VLOOKUP(J13,Cadastros!A:B,2,FALSE),"-") -> GARRA TRAÇADORA 2 | L13: =IFERROR(VLOOKUP(K13,Cadastros!B:D,3,FALSE),"-") -> TRAÇAMENTO | M13: {=IFERROR(INDEX(VMI!$A:$AAL,MATCH(1,(VMI!$A:$A=E13)*(VMI!$B:$B=F13),0),MATCH(L13,VMI!$1:$1,0)+1)*(AVERAGEIFS('Metas Produção'!I:I,'Metas Produção'!B:B,'BDT''s'!L13)),"-")} -> 82.751429 | N13: OPERADOR 12 | O13: TURNO 2 | P13: =IFERROR(COUNTIFS(O:O,O13,N:N,N13,I:I,I13,J:J,J13,C:C,C13),"-") -> 1 | Q13: =IFERROR(_xlfn.MAXIFS($R$1:R12,$K$1:K12,K13),"-") -> 705 | R13: 715 | S13: =IFERROR(IF(R13="-",0,IF(R13-Q13<0,"-",R13-Q13)),"-") -> 10 | T13: {=IFERROR(U13/INDEX('Cadastro Talhão'!F:F,MATCH(1,('Cadastro Talhão'!B:B='BDT''s'!G13)*('Cadastro Talhão'!C:C='BDT''s'!H13)*('Cadastro Talhão'!A:A='BDT''s'!C13),0)),"-")} -> 5000 | U13: 800 | V13: =IF(U13="-",0,IFERROR(IF(AJ13="FINALIZADO",AI13/SUMIFS(AG:AG,G:G,G13,H:H,H13,L:L,L13,A:A,A13,B:B,B13)*AG13,U13),U13)) -> 800 | W13: =IFERROR(U13/S13,"-") -> 80 | X13: {=IFERROR(U13/INDEX('Cadastro Talhão'!G:G,MATCH(1,('Cadastro Talhão'!B:B=G13)*('Cadastro Talhão'!C:C=H13),0))*INDEX('Cadastro Talhão'!D:D,MATCH(1,('Cadastro Talhão'!B:B=G13)*('Cadastro Talhão'!C:C=H13),0)),"-")} -> 0.61538462 | Y13: {=IFERROR(V13/INDEX('Cadastro Talhão'!G:G,MATCH(1,('Cadastro Talhão'!B:B=G13)*('Cadastro Talhão'!C:C=H13),0))*INDEX('Cadastro Talhão'!D:D,MATCH(1,('Cadastro Talhão'!B:B=G13)*('Cadastro Talhão'!C:C=H13),0)),"-")} -> 0.61538462 | Z13: {=IFERROR(INDEX('Metas Produção'!$A:$ZZ,MATCH(K13, 'Metas Produção'!$A:$A, 0),MATCH(F13, 'Metas Produção'!$1:$1, 0)+1)*12,"-")} -> 954 | AA13: =IFERROR(Z13/12,"-") -> 79.5 | AB13: {=IFERROR(INDEX('Metas Produção'!$A:$ZZ,MATCH(K13, 'Metas Produção'!$A:$A, 0),MATCH(F13, 'Metas Produção'!$1:$1, 0)+2)*12,"-")} -> 978.61935 | AC13: =IFERROR(AB13/12,"-") -> 81.551613 | AD13: {=IFERROR(INDEX('Metas Produção'!$A:$ZZ,MATCH(K13, 'Metas Produção'!$A:$A, 0),MATCH(F13, 'Metas Produção'!$1:$1, 0)+3)*12,"-")} -> 1152 | AE13: =IFERROR(AD13/12,"-") -> 96 | AF13: =IFERROR(IF(W13="-","-",IF(W13<AA13,"BAIXO",IF(AND(W13>=AA13,W13<AC13),"MEDIO",IF(AND(W13>=AC13,W13<=AE13),"ALTO","-")))),"-") -> MEDIO | AG13: =IFERROR(U13/SUMIFS(U:U,G:G,G13,H:H,H13,L:L,L13,A:A,A13,B:B,B13),0) -> 0.41025641 | AH13: {=IFERROR(V13/INDEX('Cadastro Talhão'!G:G,MATCH(1,('Cadastro Talhão'!B:B=G13)*('Cadastro Talhão'!C:C=H13),0)),"-")} -> 0.061538462 | AI13: {=IFERROR(IF(AJ13="EM ANDAMENTO",U13,IF(AJ13="FINALIZADO",INDEX('Cadastro Talhão'!G:G,MATCH(1,('Cadastro Talhão'!B:B=G13)*('Cadastro Talhão'!C:C=H13),0)),"-")),"-")} -> 800 | AJ13: {=IFERROR(INDEX(Estoque!$A:$Z,MATCH(1,(Estoque!$E:$E='BDT''s'!G13)*(Estoque!$F:$F='BDT''s'!H13)*(Estoque!$B:$B='BDT''s'!B13),0),MATCH('BDT''s'!L13,Estoque!$1:$1,0)+4),"-")} -> EM ANDAMENTO
A14: =IFERROR(YEAR(I14),"-") -> 2026 | B14: =IFERROR(DATE(YEAR(I14),MONTH(I14),MONTH(I14)),"-") -> 46023 | C14: {=IFERROR(IF(INDEX('Cadastro Talhão'!A:A,MATCH(1,('Cadastro Talhão'!B:B='BDT''s'!G14)*('Cadastro Talhão'!C:C='BDT''s'!H14),0))=0,"-",INDEX('Cadastro Talhão'!A:A,MATCH(1,('Cadastro Talhão'!B:B='BDT''s'!G14)*('Cadastro Talhão'!C:C='BDT''s'!H14),0))),"-")} -> CONTRATO 1 | D14: {=IFERROR(INDEX('Cadastro Talhão'!H:H,MATCH(1,('Cadastro Talhão'!B:B='BDT''s'!G14)*('Cadastro Talhão'!C:C='BDT''s'!H14),0)),"-")} -> 1.9 | E14: {=IFERROR(INDEX('Cadastro Talhão'!F:F,MATCH(1,('Cadastro Talhão'!B:B='BDT''s'!G14)*('Cadastro Talhão'!C:C='BDT''s'!H14),0)),"-")} -> 0.15 | F14: =IFERROR(VLOOKUP(E14,VMI!A:B,2,FALSE),"-") -> 0,11 a 0,15 | G14: FAZENDA 1 | H14: 15 | I14: 46024 | J14: FELLER1 | K14: =IFERROR(VLOOKUP(J14,Cadastros!A:B,2,FALSE),"-") -> FELLER BUNCHER 1 | L14: =IFERROR(VLOOKUP(K14,Cadastros!B:D,3,FALSE),"-") -> CORTE | M14: {=IFERROR(INDEX(VMI!$A:$AAL,MATCH(1,(VMI!$A:$A=E14)*(VMI!$B:$B=F14),0),MATCH(L14,VMI!$1:$1,0)+1)*(AVERAGEIFS('Metas Produção'!I:I,'Metas Produção'!B:B,'BDT''s'!L14)),"-")} -> 86.557111 | N14: OPERADOR 1 | O14: TURNO 1 | P14: =IFERROR(COUNTIFS(O:O,O14,N:N,N14,I:I,I14,J:J,J14,C:C,C14),"-") -> 1 | Q14: =IFERROR(_xlfn.MAXIFS($R$1:R13,$K$1:K13,K14),"-") -> 1022 | R14: 1026 | S14: =IFERROR(IF(R14="-",0,IF(R14-Q14<0,"-",R14-Q14)),"-") -> 4 | T14: {=IFERROR(U14/INDEX('Cadastro Talhão'!F:F,MATCH(1,('Cadastro Talhão'!B:B='BDT''s'!G14)*('Cadastro Talhão'!C:C='BDT''s'!H14)*('Cadastro Talhão'!A:A='BDT''s'!C14),0)),"-")} -> 2666.6667 | U14: 400 | V14: =IF(U14="-",0,IFERROR(IF(AJ14="FINALIZADO",AI14/SUMIFS(AG:AG,G:G,G14,H:H,H14,L:L,L14,A:A,A14,B:B,B14)*AG14,U14),U14)) -> 400 | W14: =IFERROR(U14/S14,"-") -> 100 | X14: {=IFERROR(U14/INDEX('Cadastro Talhão'!G:G,MATCH(1,('Cadastro Talhão'!B:B=G14)*('Cadastro Talhão'!C:C=H14),0))*INDEX('Cadastro Talhão'!D:D,MATCH(1,('Cadastro Talhão'!B:B=G14)*('Cadastro Talhão'!C:C=H14),0)),"-")} -> 0.48 | Y14: {=IFERROR(V14/INDEX('Cadastro Talhão'!G:G,MATCH(1,('Cadastro Talhão'!B:B=G14)*('Cadastro Talhão'!C:C=H14),0))*INDEX('Cadastro Talhão'!D:D,MATCH(1,('Cadastro Talhão'!B:B=G14)*('Cadastro Talhão'!C:C=H14),0)),"-")} -> 0.48 | Z14: {=IFERROR(INDEX('Metas Produção'!$A:$ZZ,MATCH(K14, 'Metas Produção'!$A:$A, 0),MATCH(F14, 'Metas Produção'!$1:$1, 0)+1)*12,"-")} -> 1056.4112 | AA14: =IFERROR(Z14/12,"-") -> 88.034267 | AB14: {=IFERROR(INDEX('Metas Produção'!$A:$ZZ,MATCH(K14, 'Metas Produção'!$A:$A, 0),MATCH(F14, 'Metas Produção'!$1:$1, 0)+2)*12,"-")} -> 1083.6967 | AC14: =IFERROR(AB14/12,"-") -> 90.308055 | AD14: {=IFERROR(INDEX('Metas Produção'!$A:$ZZ,MATCH(K14, 'Metas Produção'!$A:$A, 0),MATCH(F14, 'Metas Produção'!$1:$1, 0)+3)*12,"-")} -> 1200 | AE14: =IFERROR(AD14/12,"-") -> 100 | AF14: =IFERROR(IF(W14="-","-",IF(W14<AA14,"BAIXO",IF(AND(W14>=AA14,W14<AC14),"MEDIO",IF(AND(W14>=AC14,W14<=AE14),"ALTO","-")))),"-") -> ALTO | AG14: =IFERROR(U14/SUMIFS(U:U,G:G,G14,H:H,H14,L:L,L14,A:A,A14,B:B,B14),0) -> 0.13651877 | AH14: {=IFERROR(V14/INDEX('Cadastro Talhão'!G:G,MATCH(1,('Cadastro Talhão'!B:B=G14)*('Cadastro Talhão'!C:C=H14),0)),"-")} -> 0.04 | AI14: {=IFERROR(IF(AJ14="EM ANDAMENTO",U14,IF(AJ14="FINALIZADO",INDEX('Cadastro Talhão'!G:G,MATCH(1,('Cadastro Talhão'!B:B=G14)*('Cadastro Talhão'!C:C=H14),0)),"-")),"-")} -> 400 | AJ14: {=IFERROR(INDEX(Estoque!$A:$Z,MATCH(1,(Estoque!$E:$E='BDT''s'!G14)*(Estoque!$F:$F='BDT''s'!H14)*(Estoque!$B:$B='BDT''s'!B14),0),MATCH('BDT''s'!L14,Estoque!$1:$1,0)+4),"-")} -> EM ANDAMENTO
A15: =IFERROR(YEAR(I15),"-") -> 2026 | B15: =IFERROR(DATE(YEAR(I15),MONTH(I15),MONTH(I15)),"-") -> 46023 | C15: {=IFERROR(IF(INDEX('Cadastro Talhão'!A:A,MATCH(1,('Cadastro Talhão'!B:B='BDT''s'!G15)*('Cadastro Talhão'!C:C='BDT''s'!H15),0))=0,"-",INDEX('Cadastro Talhão'!A:A,MATCH(1,('Cadastro Talhão'!B:B='BDT''s'!G15)*('Cadastro Talhão'!C:C='BDT''s'!H15),0))),"-")} -> CONTRATO 1 | D15: {=IFERROR(INDEX('Cadastro Talhão'!H:H,MATCH(1,('Cadastro Talhão'!B:B='BDT''s'!G15)*('Cadastro Talhão'!C:C='BDT''s'!H15),0)),"-")} -> 1.9 | E15: {=IFERROR(INDEX('Cadastro Talhão'!F:F,MATCH(1,('Cadastro Talhão'!B:B='BDT''s'!G15)*('Cadastro Talhão'!C:C='BDT''s'!H15),0)),"-")} -> 0.15 | F15: =IFERROR(VLOOKUP(E15,VMI!A:B,2,FALSE),"-") -> 0,11 a 0,15 | G15: FAZENDA 1 | H15: 15 | I15: 46024 | J15: FELLER1 | K15: =IFERROR(VLOOKUP(J15,Cadastros!A:B,2,FALSE),"-") -> FELLER BUNCHER 1 | L15: =IFERROR(VLOOKUP(K15,Cadastros!B:D,3,FALSE),"-") -> CORTE | M15: {=IFERROR(INDEX(VMI!$A:$AAL,MATCH(1,(VMI!$A:$A=E15)*(VMI!$B:$B=F15),0),MATCH(L15,VMI!$1:$1,0)+1)*(AVERAGEIFS('Metas Produção'!I:I,'Metas Produção'!B:B,'BDT''s'!L15)),"-")} -> 86.557111 | N15: OPERADOR 2 | O15: TURNO 2 | P15: =IFERROR(COUNTIFS(O:O,O15,N:N,N15,I:I,I15,J:J,J15,C:C,C15),"-") -> 1 | Q15: =IFERROR(_xlfn.MAXIFS($R$1:R14,$K$1:K14,K15),"-") -> 1026 | R15: 1035.2 | S15: =IFERROR(IF(R15="-",0,IF(R15-Q15<0,"-",R15-Q15)),"-") -> 9.2 | T15: {=IFERROR(U15/INDEX('Cadastro Talhão'!F:F,MATCH(1,('Cadastro Talhão'!B:B='BDT''s'!G15)*('Cadastro Talhão'!C:C='BDT''s'!H15)*('Cadastro Talhão'!A:A='BDT''s'!C15),0)),"-")} -> 5333.3333 | U15: 800 | V15: =IF(U15="-",0,IFERROR(IF(AJ15="FINALIZADO",AI15/SUMIFS(AG:AG,G:G,G15,H:H,H15,L:L,L15,A:A,A15,B:B,B15)*AG15,U15),U15)) -> 800 | W15: =IFERROR(U15/S15,"-") -> 86.956522 | X15: {=IFERROR(U15/INDEX('Cadastro Talhão'!G:G,MATCH(1,('Cadastro Talhão'!B:B=G15)*('Cadastro Talhão'!C:C=H15),0))*INDEX('Cadastro Talhão'!D:D,MATCH(1,('Cadastro Talhão'!B:B=G15)*('Cadastro Talhão'!C:C=H15),0)),"-")} -> 0.96 | Y15: {=IFERROR(V15/INDEX('Cadastro Talhão'!G:G,MATCH(1,('Cadastro Talhão'!B:B=G15)*('Cadastro Talhão'!C:C=H15),0))*INDEX('Cadastro Talhão'!D:D,MATCH(1,('Cadastro Talhão'!B:B=G15)*('Cadastro Talhão'!C:C=H15),0)),"-")} -> 0.96 | Z15: {=IFERROR(INDEX('Metas Produção'!$A:$ZZ,MATCH(K15, 'Metas Produção'!$A:$A, 0),MATCH(F15, 'Metas Produção'!$1:$1, 0)+1)*12,"-")} -> 1056.4112 | AA15: =IFERROR(Z15/12,"-") -> 88.034267 | AB15: {=IFERROR(INDEX('Metas Produção'!$A:$ZZ,MATCH(K15, 'Metas Produção'!$A:$A, 0),MATCH(F15, 'Metas Produção'!$1:$1, 0)+2)*12,"-")} -> 1083.6967 | AC15: =IFERROR(AB15/12,"-") -> 90.308055 | AD15: {=IFERROR(INDEX('Metas Produção'!$A:$ZZ,MATCH(K15, 'Metas Produção'!$A:$A, 0),MATCH(F15, 'Metas Produção'!$1:$1, 0)+3)*12,"-")} -> 1200 | AE15: =IFERROR(AD15/12,"-") -> 100 | AF15: =IFERROR(IF(W15="-","-",IF(W15<AA15,"BAIXO",IF(AND(W15>=AA15,W15<AC15),"MEDIO",IF(AND(W15>=AC15,W15<=AE15),"ALTO","-")))),"-") -> BAIXO | AG15: =IFERROR(U15/SUMIFS(U:U,G:G,G15,H:H,H15,L:L,L15,A:A,A15,B:B,B15),0) -> 0.27303754 | AH15: {=IFERROR(V15/INDEX('Cadastro Talhão'!G:G,MATCH(1,('Cadastro Talhão'!B:B=G15)*('Cadastro Talhão'!C:C=H15),0)),"-")} -> 0.08 | AI15: {=IFERROR(IF(AJ15="EM ANDAMENTO",U15,IF(AJ15="FINALIZADO",INDEX('Cadastro Talhão'!G:G,MATCH(1,('Cadastro Talhão'!B:B=G15)*('Cadastro Talhão'!C:C=H15),0)),"-")),"-")} -> 800 | AJ15: {=IFERROR(INDEX(Estoque!$A:$Z,MATCH(1,(Estoque!$E:$E='BDT''s'!G15)*(Estoque!$F:$F='BDT''s'!H15)*(Estoque!$B:$B='BDT''s'!B15),0),MATCH('BDT''s'!L15,Estoque!$1:$1,0)+4),"-")} -> EM ANDAMENTO
A16: =IFERROR(YEAR(I16),"-") -> 2026 | B16: =IFERROR(DATE(YEAR(I16),MONTH(I16),MONTH(I16)),"-") -> 46023 | C16: {=IFERROR(IF(INDEX('Cadastro Talhão'!A:A,MATCH(1,('Cadastro Talhão'!B:B='BDT''s'!G16)*('Cadastro Talhão'!C:C='BDT''s'!H16),0))=0,"-",INDEX('Cadastro Talhão'!A:A,MATCH(1,('Cadastro Talhão'!B:B='BDT''s'!G16)*('Cadastro Talhão'!C:C='BDT''s'!H16),0))),"-")} -> CONTRATO 1 | D16: {=IFERROR(INDEX('Cadastro Talhão'!H:H,MATCH(1,('Cadastro Talhão'!B:B='BDT''s'!G16)*('Cadastro Talhão'!C:C='BDT''s'!H16),0)),"-")} -> 1.9 | E16: {=IFERROR(INDEX('Cadastro Talhão'!F:F,MATCH(1,('Cadastro Talhão'!B:B='BDT''s'!G16)*('Cadastro Talhão'!C:C='BDT''s'!H16),0)),"-")} -> 0.16 | F16: =IFERROR(VLOOKUP(E16,VMI!A:B,2,FALSE),"-") -> 0,16 a 0,20 | G16: FAZENDA 1 | H16: 25 | I16: 46024 | J16: FELLER2 | K16: =IFERROR(VLOOKUP(J16,Cadastros!A:B,2,FALSE),"-") -> FELLER BUNCHER 2 | L16: =IFERROR(VLOOKUP(K16,Cadastros!B:D,3,FALSE),"-") -> CORTE | M16: {=IFERROR(INDEX(VMI!$A:$AAL,MATCH(1,(VMI!$A:$A=E16)*(VMI!$B:$B=F16),0),MATCH(L16,VMI!$1:$1,0)+1)*(AVERAGEIFS('Metas Produção'!I:I,'Metas Produção'!B:B,'BDT''s'!L16)),"-")} -> 125.2316 | N16: OPERADOR 3 | O16: TURNO 1 | P16: =IFERROR(COUNTIFS(O:O,O16,N:N,N16,I:I,I16,J:J,J16,C:C,C16),"-") -> 1 | Q16: =IFERROR(_xlfn.MAXIFS($R$1:R15,$K$1:K15,K16),"-") -> 2020 | R16: 2030 | S16: =IFERROR(IF(R16="-",0,IF(R16-Q16<0,"-",R16-Q16)),"-") -> 10 | T16: {=IFERROR(U16/INDEX('Cadastro Talhão'!F:F,MATCH(1,('Cadastro Talhão'!B:B='BDT''s'!G16)*('Cadastro Talhão'!C:C='BDT''s'!H16)*('Cadastro Talhão'!A:A='BDT''s'!C16),0)),"-")} -> 7500 | U16: 1200 | V16: =IF(U16="-",0,IFERROR(IF(AJ16="FINALIZADO",AI16/SUMIFS(AG:AG,G:G,G16,H:H,H16,L:L,L16,A:A,A16,B:B,B16)*AG16,U16),U16)) -> 1200 | W16: =IFERROR(U16/S16,"-") -> 120 | X16: {=IFERROR(U16/INDEX('Cadastro Talhão'!G:G,MATCH(1,('Cadastro Talhão'!B:B=G16)*('Cadastro Talhão'!C:C=H16),0))*INDEX('Cadastro Talhão'!D:D,MATCH(1,('Cadastro Talhão'!B:B=G16)*('Cadastro Talhão'!C:C=H16),0)),"-")} -> 0.92307692 | Y16: {=IFERROR(V16/INDEX('Cadastro Talhão'!G:G,MATCH(1,('Cadastro Talhão'!B:B=G16)*('Cadastro Talhão'!C:C=H16),0))*INDEX('Cadastro Talhão'!D:D,MATCH(1,('Cadastro Talhão'!B:B=G16)*('Cadastro Talhão'!C:C=H16),0)),"-")} -> 0.92307692 | Z16: {=IFERROR(INDEX('Metas Produção'!$A:$ZZ,MATCH(K16, 'Metas Produção'!$A:$A, 0),MATCH(F16, 'Metas Produção'!$1:$1, 0)+1)*12,"-")} -> 1477.1333 | AA16: =IFERROR(Z16/12,"-") -> 123.09444 | AB16: {=IFERROR(INDEX('Metas Produção'!$A:$ZZ,MATCH(K16, 'Metas Produção'!$A:$A, 0),MATCH(F16, 'Metas Produção'!$1:$1, 0)+2)*12,"-")} -> 1464.4344 | AC16: =IFERROR(AB16/12,"-") -> 122.0362 | AD16: {=IFERROR(INDEX('Metas Produção'!$A:$ZZ,MATCH(K16, 'Metas Produção'!$A:$A, 0),MATCH(F16, 'Metas Produção'!$1:$1, 0)+3)*12,"-")} -> 2022.4719 | AE16: =IFERROR(AD16/12,"-") -> 168.53933 | AF16: =IFERROR(IF(W16="-","-",IF(W16<AA16,"BAIXO",IF(AND(W16>=AA16,W16<AC16),"MEDIO",IF(AND(W16>=AC16,W16<=AE16),"ALTO","-")))),"-") -> BAIXO | AG16: =IFERROR(U16/SUMIFS(U:U,G:G,G16,H:H,H16,L:L,L16,A:A,A16,B:B,B16),0) -> 0.24489796 | AH16: {=IFERROR(V16/INDEX('Cadastro Talhão'!G:G,MATCH(1,('Cadastro Talhão'!B:B=G16)*('Cadastro Talhão'!C:C=H16),0)),"-")} -> 0.092307692 | AI16: {=IFERROR(IF(AJ16="EM ANDAMENTO",U16,IF(AJ16="FINALIZADO",INDEX('Cadastro Talhão'!G:G,MATCH(1,('Cadastro Talhão'!B:B=G16)*('Cadastro Talhão'!C:C=H16),0)),"-")),"-")} -> 1200 | AJ16: {=IFERROR(INDEX(Estoque!$A:$Z,MATCH(1,(Estoque!$E:$E='BDT''s'!G16)*(Estoque!$F:$F='BDT''s'!H16)*(Estoque!$B:$B='BDT''s'!B16),0),MATCH('BDT''s'!L16,Estoque!$1:$1,0)+4),"-")} -> EM ANDAMENTO
A17: =IFERROR(YEAR(I17),"-") -> 2026 | B17: =IFERROR(DATE(YEAR(I17),MONTH(I17),MONTH(I17)),"-") -> 46023 | C17: {=IFERROR(IF(INDEX('Cadastro Talhão'!A:A,MATCH(1,('Cadastro Talhão'!B:B='BDT''s'!G17)*('Cadastro Talhão'!C:C='BDT''s'!H17),0))=0,"-",INDEX('Cadastro Talhão'!A:A,MATCH(1,('Cadastro Talhão'!B:B='BDT''s'!G17)*('Cadastro Talhão'!C:C='BDT''s'!H17),0))),"-")} -> CONTRATO 1 | D17: {=IFERROR(INDEX('Cadastro Talhão'!H:H,MATCH(1,('Cadastro Talhão'!B:B='BDT''s'!G17)*('Cadastro Talhão'!C:C='BDT''s'!H17),0)),"-")} -> 1.9 | E17: {=IFERROR(INDEX('Cadastro Talhão'!F:F,MATCH(1,('Cadastro Talhão'!B:B='BDT''s'!G17)*('Cadastro Talhão'!C:C='BDT''s'!H17),0)),"-")} -> 0.16 | F17: =IFERROR(VLOOKUP(E17,VMI!A:B,2,FALSE),"-") -> 0,16 a 0,20 | G17: FAZENDA 1 | H17: 25 | I17: 46024 | J17: FELLER2 | K17: =IFERROR(VLOOKUP(J17,Cadastros!A:B,2,FALSE),"-") -> FELLER BUNCHER 2 | L17: =IFERROR(VLOOKUP(K17,Cadastros!B:D,3,FALSE),"-") -> CORTE | M17: {=IFERROR(INDEX(VMI!$A:$AAL,MATCH(1,(VMI!$A:$A=E17)*(VMI!$B:$B=F17),0),MATCH(L17,VMI!$1:$1,0)+1)*(AVERAGEIFS('Metas Produção'!I:I,'Metas Produção'!B:B,'BDT''s'!L17)),"-")} -> 125.2316 | N17: OPERADOR 4 | O17: TURNO 2 | P17: =IFERROR(COUNTIFS(O:O,O17,N:N,N17,I:I,I17,J:J,J17,C:C,C17),"-") -> 1 | Q17: =IFERROR(_xlfn.MAXIFS($R$1:R16,$K$1:K16,K17),"-") -> 2030 | R17: 2040 | S17: =IFERROR(IF(R17="-",0,IF(R17-Q17<0,"-",R17-Q17)),"-") -> 10 | T17: {=IFERROR(U17/INDEX('Cadastro Talhão'!F:F,MATCH(1,('Cadastro Talhão'!B:B='BDT''s'!G17)*('Cadastro Talhão'!C:C='BDT''s'!H17)*('Cadastro Talhão'!A:A='BDT''s'!C17),0)),"-")} -> 6250 | U17: 1000 | V17: =IF(U17="-",0,IFERROR(IF(AJ17="FINALIZADO",AI17/SUMIFS(AG:AG,G:G,G17,H:H,H17,L:L,L17,A:A,A17,B:B,B17)*AG17,U17),U17)) -> 1000 | W17: =IFERROR(U17/S17,"-") -> 100 | X17: {=IFERROR(U17/INDEX('Cadastro Talhão'!G:G,MATCH(1,('Cadastro Talhão'!B:B=G17)*('Cadastro Talhão'!C:C=H17),0))*INDEX('Cadastro Talhão'!D:D,MATCH(1,('Cadastro Talhão'!B:B=G17)*('Cadastro Talhão'!C:C=H17),0)),"-")} -> 0.76923077 | Y17: {=IFERROR(V17/INDEX('Cadastro Talhão'!G:G,MATCH(1,('Cadastro Talhão'!B:B=G17)*('Cadastro Talhão'!C:C=H17),0))*INDEX('Cadastro Talhão'!D:D,MATCH(1,('Cadastro Talhão'!B:B=G17)*('Cadastro Talhão'!C:C=H17),0)),"-")} -> 0.76923077 | Z17: {=IFERROR(INDEX('Metas Produção'!$A:$ZZ,MATCH(K17, 'Metas Produção'!$A:$A, 0),MATCH(F17, 'Metas Produção'!$1:$1, 0)+1)*12,"-")} -> 1477.1333 | AA17: =IFERROR(Z17/12,"-") -> 123.09444 | AB17: {=IFERROR(INDEX('Metas Produção'!$A:$ZZ,MATCH(K17, 'Metas Produção'!$A:$A, 0),MATCH(F17, 'Metas Produção'!$1:$1, 0)+2)*12,"-")} -> 1464.4344 | AC17: =IFERROR(AB17/12,"-") -> 122.0362 | AD17: {=IFERROR(INDEX('Metas Produção'!$A:$ZZ,MATCH(K17, 'Metas Produção'!$A:$A, 0),MATCH(F17, 'Metas Produção'!$1:$1, 0)+3)*12,"-")} -> 2022.4719 | AE17: =IFERROR(AD17/12,"-") -> 168.53933 | AF17: =IFERROR(IF(W17="-","-",IF(W17<AA17,"BAIXO",IF(AND(W17>=AA17,W17<AC17),"MEDIO",IF(AND(W17>=AC17,W17<=AE17),"ALTO","-")))),"-") -> BAIXO | AG17: =IFERROR(U17/SUMIFS(U:U,G:G,G17,H:H,H17,L:L,L17,A:A,A17,B:B,B17),0) -> 0.20408163 | AH17: {=IFERROR(V17/INDEX('Cadastro Talhão'!G:G,MATCH(1,('Cadastro Talhão'!B:B=G17)*('Cadastro Talhão'!C:C=H17),0)),"-")} -> 0.076923077 | AI17: {=IFERROR(IF(AJ17="EM ANDAMENTO",U17,IF(AJ17="FINALIZADO",INDEX('Cadastro Talhão'!G:G,MATCH(1,('Cadastro Talhão'!B:B=G17)*('Cadastro Talhão'!C:C=H17),0)),"-")),"-")} -> 1000 | AJ17: {=IFERROR(INDEX(Estoque!$A:$Z,MATCH(1,(Estoque!$E:$E='BDT''s'!G17)*(Estoque!$F:$F='BDT''s'!H17)*(Estoque!$B:$B='BDT''s'!B17),0),MATCH('BDT''s'!L17,Estoque!$1:$1,0)+4),"-")} -> EM ANDAMENTO
A18: =IFERROR(YEAR(I18),"-") -> 2026 | B18: =IFERROR(DATE(YEAR(I18),MONTH(I18),MONTH(I18)),"-") -> 46023 | C18: {=IFERROR(IF(INDEX('Cadastro Talhão'!A:A,MATCH(1,('Cadastro Talhão'!B:B='BDT''s'!G18)*('Cadastro Talhão'!C:C='BDT''s'!H18),0))=0,"-",INDEX('Cadastro Talhão'!A:A,MATCH(1,('Cadastro Talhão'!B:B='BDT''s'!G18)*('Cadastro Talhão'!C:C='BDT''s'!H18),0))),"-")} -> CONTRATO 1 | D18: {=IFERROR(INDEX('Cadastro Talhão'!H:H,MATCH(1,('Cadastro Talhão'!B:B='BDT''s'!G18)*('Cadastro Talhão'!C:C='BDT''s'!H18),0)),"-")} -> 1.9 | E18: {=IFERROR(INDEX('Cadastro Talhão'!F:F,MATCH(1,('Cadastro Talhão'!B:B='BDT''s'!G18)*('Cadastro Talhão'!C:C='BDT''s'!H18),0)),"-")} -> 0.15 | F18: =IFERROR(VLOOKUP(E18,VMI!A:B,2,FALSE),"-") -> 0,11 a 0,15 | G18: FAZENDA 1 | H18: 15 | I18: 46024 | J18: SKIDDER1 | K18: =IFERROR(VLOOKUP(J18,Cadastros!A:B,2,FALSE),"-") -> SKIDDER 1 | L18: =IFERROR(VLOOKUP(K18,Cadastros!B:D,3,FALSE),"-") -> ARRASTE | M18: {=IFERROR(INDEX(VMI!$A:$AAL,MATCH(1,(VMI!$A:$A=E18)*(VMI!$B:$B=F18),0),MATCH(L18,VMI!$1:$1,0)+1)*(AVERAGEIFS('Metas Produção'!I:I,'Metas Produção'!B:B,'BDT''s'!L18)),"-")} -> 132.35447 | N18: OPERADOR 5 | O18: TURNO 1 | P18: =IFERROR(COUNTIFS(O:O,O18,N:N,N18,I:I,I18,J:J,J18,C:C,C18),"-") -> 1 | Q18: =IFERROR(_xlfn.MAXIFS($R$1:R17,$K$1:K17,K18),"-") -> 1215 | R18: 1219 | S18: =IFERROR(IF(R18="-",0,IF(R18-Q18<0,"-",R18-Q18)),"-") -> 4 | T18: {=IFERROR(U18/INDEX('Cadastro Talhão'!F:F,MATCH(1,('Cadastro Talhão'!B:B='BDT''s'!G18)*('Cadastro Talhão'!C:C='BDT''s'!H18)*('Cadastro Talhão'!A:A='BDT''s'!C18),0)),"-")} -> 4000 | U18: 600 | V18: =IF(U18="-",0,IFERROR(IF(AJ18="FINALIZADO",AI18/SUMIFS(AG:AG,G:G,G18,H:H,H18,L:L,L18,A:A,A18,B:B,B18)*AG18,U18),U18)) -> 600 | W18: =IFERROR(U18/S18,"-") -> 150 | X18: {=IFERROR(U18/INDEX('Cadastro Talhão'!G:G,MATCH(1,('Cadastro Talhão'!B:B=G18)*('Cadastro Talhão'!C:C=H18),0))*INDEX('Cadastro Talhão'!D:D,MATCH(1,('Cadastro Talhão'!B:B=G18)*('Cadastro Talhão'!C:C=H18),0)),"-")} -> 0.72 | Y18: {=IFERROR(V18/INDEX('Cadastro Talhão'!G:G,MATCH(1,('Cadastro Talhão'!B:B=G18)*('Cadastro Talhão'!C:C=H18),0))*INDEX('Cadastro Talhão'!D:D,MATCH(1,('Cadastro Talhão'!B:B=G18)*('Cadastro Talhão'!C:C=H18),0)),"-")} -> 0.72 | Z18: {=IFERROR(INDEX('Metas Produção'!$A:$ZZ,MATCH(K18, 'Metas Produção'!$A:$A, 0),MATCH(F18, 'Metas Produção'!$1:$1, 0)+1)*12,"-")} -> 1688.5714 | AA18: =IFERROR(Z18/12,"-") -> 140.71429 | AB18: {=IFERROR(INDEX('Metas Produção'!$A:$ZZ,MATCH(K18, 'Metas Produção'!$A:$A, 0),MATCH(F18, 'Metas Produção'!$1:$1, 0)+2)*12,"-")} -> 1918.6652 | AC18: =IFERROR(AB18/12,"-") -> 159.88876 | AD18: {=IFERROR(INDEX('Metas Produção'!$A:$ZZ,MATCH(K18, 'Metas Produção'!$A:$A, 0),MATCH(F18, 'Metas Produção'!$1:$1, 0)+3)*12,"-")} -> 2280 | AE18: =IFERROR(AD18/12,"-") -> 190 | AF18: =IFERROR(IF(W18="-","-",IF(W18<AA18,"BAIXO",IF(AND(W18>=AA18,W18<AC18),"MEDIO",IF(AND(W18>=AC18,W18<=AE18),"ALTO","-")))),"-") -> MEDIO | AG18: =IFERROR(U18/SUMIFS(U:U,G:G,G18,H:H,H18,L:L,L18,A:A,A18,B:B,B18),0) -> 0.23904382 | AH18: {=IFERROR(V18/INDEX('Cadastro Talhão'!G:G,MATCH(1,('Cadastro Talhão'!B:B=G18)*('Cadastro Talhão'!C:C=H18),0)),"-")} -> 0.06 | AI18: {=IFERROR(IF(AJ18="EM ANDAMENTO",U18,IF(AJ18="FINALIZADO",INDEX('Cadastro Talhão'!G:G,MATCH(1,('Cadastro Talhão'!B:B=G18)*('Cadastro Talhão'!C:C=H18),0)),"-")),"-")} -> 600 | AJ18: {=IFERROR(INDEX(Estoque!$A:$Z,MATCH(1,(Estoque!$E:$E='BDT''s'!G18)*(Estoque!$F:$F='BDT''s'!H18)*(Estoque!$B:$B='BDT''s'!B18),0),MATCH('BDT''s'!L18,Estoque!$1:$1,0)+4),"-")} -> EM ANDAMENTO
